Workbook
Name Bùi_Bích_Phương: DATA!$A:$A

Sheet foxz

Sheet XNT
C2: NHẬP | O2: XUẤT
C3: Vỉ 500ml | D3: TẶNG Vỉ 500ml | E3: Thùng 500 ml | F3: TẶNG Thùng 500 ml | G3: Vỉ 350ml | H3: TẶNG Vỉ 350ml | I3: Thùng 350 ml | J3: TẶNG Thùng 350 ml | K3: Bình Ion | L3: TẶNG Bình Ion | M3: Bình RO | N3: TẶNG Bình RO | O3: Bộ phận | P3: Vỉ 500ml | Q3: TẶNG Vỉ 500ml | R3: Thùng 500 ml | S3: TẶNG Thùng 500 ml | T3: Vỉ 350ml | U3: TẶNG Vỉ 350ml | V3: Thùng 350 ml | W3: TẶNG Thùng 350 ml | X3: Bình Ion | Y3: TẶNG Bình Ion | Z3: Bình RO | AA3: TẶNG Bình RO
B4: Tồn Đầu kỳ | C4: ='KHO TỔNG'!C4 -> 885 | D4: ='KHO TỔNG'!D4 -> 0 | E4: ='KHO TỔNG'!E4 -> 0 | F4: ='KHO TỔNG'!F4 -> 0 | G4: ='KHO TỔNG'!G4 -> 71 | H4: ='KHO TỔNG'!H4 -> 0 | I4: ='KHO TỔNG'!I4 -> 0 | J4: ='KHO TỔNG'!J4 -> 0 | ... N4: ='KHO TỔNG'!N4 -> 0
B5: KHO TỔNG | C5: ='KHO TỔNG'!C133 -> 421 | D5: ='KHO TỔNG'!D133 -> 0 | E5: ='KHO TỔNG'!E133 -> 0 | F5: ='KHO TỔNG'!F133 -> 0 | G5: ='KHO TỔNG'!G133 -> 72 | H5: ='KHO TỔNG'!H133 -> 0 | I5: ='KHO TỔNG'!I133 -> 0 | J5: ='KHO TỔNG'!J133 -> 0 | ... N5: ='KHO TỔNG'!N133 -> 4 | O5: KHO TỔNG | P5: ='KHO TỔNG'!R133 -> 1130 | Q5: ='KHO TỔNG'!S133 -> 119 | R5: ='KHO TỔNG'!T133 -> 0 | S5: ='KHO TỔNG'!U133 -> 0 | T5: ='KHO TỔNG'!V133 -> 56 | U5: ='KHO TỔNG'!W133 -> 3 | V5: ='KHO TỔNG'!X133 -> 0 | W5: ='KHO TỔNG'!Y133 -> 0 | ... AA5: ='KHO TỔNG'!AC133 -> 5
B8: TỔNG NHẬP | C8: =SUM(C5:C7) -> 421 | D8: =SUM(D5:D7) -> 0 | E8: =SUM(E5:E7) -> 0 | F8: =SUM(F5:F7) -> 0 | G8: =SUM(G5:G7) -> 72 | H8: =SUM(H5:H7) -> 0 | I8: =SUM(I5:I7) -> 0 | J8: =SUM(J5:J7) -> 0 | ... N8: =SUM(N5:N7) -> 4 | O8: TỔNG XUẤT | P8: =SUM(P5:P7) -> 1130 | Q8: =SUM(Q5:Q7) -> 119 | R8: =SUM(R5:R7) -> 0 | S8: =SUM(S5:S7) -> 0 | T8: =SUM(T5:T7) -> 56 | U8: =SUM(U5:U7) -> 3 | V8: =SUM(V5:V7) -> 0 | W8: =SUM(W5:W7) -> 0 | ... AA8: =SUM(AA5:AA7) -> 5
O9: KHO VP | P9: ='KHO TỔNG'!R134 -> 176 | Q9: ='KHO TỔNG'!S134 -> -119 | R9: ='KHO TỔNG'!T134 -> 0 | S9: ='KHO TỔNG'!U134 -> 0 | T9: ='KHO TỔNG'!V134 -> 87 | U9: ='KHO TỔNG'!W134 -> -3 | V9: ='KHO TỔNG'!X134 -> 0 | W9: ='KHO TỔNG'!Y134 -> 0 | ... AA9: ='KHO TỔNG'!AC134 -> -1
O12: TỔNG TỒN CUỐI KỲ | P12: =C4+C8-P8 -> 176 | Q12: =D4+D8-Q8 -> -119 | R12: =E4+E8-R8 -> 0 | S12: =F4+F8-S8 -> 0 | T12: =G4+G8-T8 -> 87 | U12: =H4+H8-U8 -> -3 | V12: =I4+I8-V8 -> 0 | W12: =J4+J8-W8 -> 0 | ... AA12: =N4+N8-AA8 -> -1
N13: THỰC TẾ | O13: KHO VP
E14: CÔNG NỢ | O14: KHO HUẾ | P14: 17 | T14: 30
E15: chi tiết | F15: vỉ 500ml | G15: vỉ 350ml | H15: Ion | I15: RO | O15: KHO LẠI LAN | T15: 16 | X15: 9
E16: Thanh | F16: 2 | I16: 2 | O16: XE ĐIỆN
E17: nội bộ cty | G17: 5 | O17: KHO ĐÁ TRẮNG
E18: CTY | F18: 52 | G18: 33 | H18: 3
E19: BC | N19: CÔNG NỢ | O19: KHO | P19: =F24 -> 54 | T19: =G24 -> 38 | X19: =H24 -> 3 | Z19: =I24 -> 2
E20: QY
E21: MĐ | N21: CHÊNH LỆCH | O21: KHO | P21: =P13+P14+P15+P16+P17+P19-P12-Q12 -> 14 | R21: =R13+R14+R15+R16+R17+R19-R12-S12 -> 0 | T21: =T13+T14+T15+T16+T17+T19-T12-U12 -> 0 | V21: =V13+V14+V15+V16+V17+V19-V12-W12 -> 0 | X21: =X13+X14+X15+X16+X17+X19-X12-Y12 -> 0 | Z21: =Z13+Z14+Z15+Z16+Z17+Z19-Z12-AA12 -> 0
E22: MC
E23: CP
F24: =SUM(F16:F23) -> 54 | G24: =SUM(G16:G23) -> 38 | H24: =SUM(H16:H23) -> 3 | I24: =SUM(I16:I23) -> 2

Sheet KHO TỔNG
B1: KH | Q1: -
C2: NHẬP | AD2: THÀNH TIỀN | AE2: TÌNH TRẠNG | AF2: VẬN CHUYỂN | AG2: THÔNG TIN KH
C3: Vỉ 500ml | D3: TẶNG Vỉ 500ml | E3: Hộp 500 ml | F3: TẶNG Hộp 500 ml | G3: Vỉ 350ml | H3: TẶNG Vỉ 350ml | I3: Hộp 350 ml | J3: TẶNG Hộp 350 ml | K3: Bình Ion | L3: TẶNG Bình Ion | M3: Bình RO | N3: TẶNG Bình RO | P3: HỌ VÀ TÊN | Q3: BỘ PHẬN | R3: Vỉ 500ml | S3: TẶNG Vỉ 500ml | T3: Hộp 500 ml | U3: TẶNG Hộp 500 ml | V3: Vỉ 350ml | W3: TẶNG Vỉ 350ml | X3: Hộp 350 ml | Y3: TẶNG Hộp 350 ml | Z3: Bình Ion | AA3: TẶNG Bình Ion | AB3: Bình RO | AC3: TẶNG Bình RO
B4: Tồn Đầu kỳ | C4: 885 | G4: 71 | K4: 16 | M4: 116 | R4: 98000 | T4: 106000 | V4: 85000 | X4: 93000 | Z4: 52000 | AB4: 48000
A5: 46262 | B5: Kho Huế | C5: 50 | O5: còn lại của T8 | P5: Trạm Hồng Gai | Q5: Văn Phòng | R5: 90 | S5: 9
A6: 46263 | B6: Tăng áp | C6: 34 | G6: 50 | K6: 22 | M6: 11 | P6: Lương Minh Hương | Q6: Văn Phòng | R6: 200 | S6: 28
A7: 46268 | B7: Kho Huế | C7: 100 | P7: Xuất tặng | V7: 3
A8: 46268 | B8: Tăng áp | C8: 49 | P8: Lương Minh Hương | V8: 10 | W8: 1
A9: 46269 | B9: Viancontrol | C9: 9 | M9: 10 | P9: Đinh Thu Huế | Q9: Văn Phòng | R9: 100 | S9: 14
A10: 46269 | B10: Viancontrol | M10: 10 | N10: 1 | P10: Đinh Thu Huế | Q10: Văn Phòng | R10: 165 | S10: 16
A11: 46269 | B11: Kho Huế | C11: 60 | P11: Trương Thị Hải Yến | Q11: Văn Phòng | R11: 25 | V11: 20 | AB11: 125
A12: 46269 | B12: Tăng áp | C12: 60 | P12: Vũ Thị Tươi | Q12: Đá Trắng | Z12: 3
A13: 46270 | B13: Viancontrol | C13: 2 | M13: 11 | N13: 1 | O13: 46261 | P13: Đỗ Thị Thanh Hà | Q13: Hạ Long | Z13: 4
A14: 46270 | B14: trả BC | C14: 13 | O14: 46261 | P14: Phạm Thị Thu | Q14: Đá Trắng | R14: 10 | S14: 1
A15: 46272 | B15: Kho Huế | C15: 40 | G15: 22 | O15: 46262 | P15: Chế Thùy Dung | Q15: Văn Phòng | R15: 10 | S15: 1
A16: 46272 | B16: Tăng áp | K16: 20 | L16: 2 | M16: 20 | N16: 2 | O16: 46259 | P16: Phạm Vũ Quyền | Q16: Văn Phòng | R16: 2
A17: 46272 | B17: đơn cp | C17: 4 | O17: 46262 | P17: Trần Thị Thu Huyền | Q17: Hạ Long | V17: 3
O18: 46261 | P18: Đỗ Thị Liễu | Q18: Văn Phòng | R18: 2
O19: 46263 | P19: Bùi Ngọc Mai | Q19: Hà Tu | R19: 2
O20: 46263 | P20: Vũ Văn Thảo | Q20: Văn Phòng | R20: 10 | S20: 1
O21: 46263 | P21: Nguyễn Thị Hiếu | Q21: Hạ Long | R21: 30 | S21: 3
O22: 46263 | P22: Nguyễn Thị Thùy | Q22: Văn Phòng | R22: 5 | Z22: 2
O23: 46268 | P23: Nguyễn Văn Sơn | Q23: Hà Tu | AB23: 10 | AC23: 1
O24: 46269 | P24: Nguyễn Thị Ngà | Q24: Hồng Gai | Z24: 3
O25: 46269 | P25: Đỗ Thị Liễu | Q25: Văn Phòng | R25: 2
O26: 46263 | P26: Đinh Thu Huế | Q26: Văn Phòng | R26: 100 | S26: 14
O27: 46264 | P27: Nguyễn Thế Mạnh | Q27: Cao Xanh | V27: 2
O28: 46267 | P28: Đỗ Anh Ngọc | Q28: Cao Xanh | V28: 5
O29: 46268 | P29: Lê Thị Như Quỳnh | Q29: Cao Xanh | R29: 5
O30: 46268 | P30: Nguyễn Thị Dung | Q30: Tổ DV | R30: 2
O31: 46268 | P31: Đinh Thu Huế | Q31: Văn Phòng | R31: 10 | S31: 1
O32: 46269 | P32: Nguyễn Văn Sơn | Q32: Hà Tu | R32: 10 | S32: 1
O33: 46269 | P33: Bùi Hà Thu | Q33: Hà Lầm | R33: 10 | S33: 1
O34: 46269 | P34: Dư Văn Cẩm | Q34: Hồng Gai | R34: 10 | S34: 1
O35: 46269 | P35: Đỗ Anh Ngọc | Q35: Cao Xanh | R35: 2
O36: 46269 | P36: Lê Thị Như Quỳnh | Q36: Hồng Gai | R36: 2
O37: 46270 | P37: Đinh Thu Huế | Q37: Văn Phòng | R37: 50 | S37: 5
O38: 46271 | P38: Nguyễn Thị Mai Anh | Q38: Hồng Gai | R38: 2
O39: 46271 | P39: Trần Thị Tuyết Lan | Q39: Đá Trắng | R39: 10 | S39: 1
O40: 46271 | P40: Nguyễn Thị Chi | Q40: Hạ Long | Z40: 2
...

Sheet Lại Lan
B1: KH
C2: NHẬP | P2: XUẤT | AD2: THÀNH TIỀN | AE2: TÌNH TRẠNG | AF2: VẬN CHUYỂN
C3: Vỉ 500ml | D3: TẶNG Vỉ 500ml | E3: Thùng 500 ml | F3: TẶNG Thùng 500 ml | G3: Vỉ 350ml | H3: TẶNG Vỉ 350ml | I3: Thùng 350 ml | J3: TẶNG Thùng 350 ml | K3: Bình Ion | L3: TẶNG Bình Ion | M3: Bình RO | N3: TẶNG Bình RO | P3: Họ tên | Q3: Bộ phận | R3: Vỉ 500ml | S3: TẶNG Vỉ 500ml | T3: Thùng 500 ml | U3: TẶNG Thùng 500 ml | V3: Vỉ 350ml | W3: TẶNG Vỉ 350ml | X3: Thùng 350 ml | Y3: TẶNG Thùng 350 ml | Z3: Bình Ion | AA3: TẶNG Bình Ion | AB3: Bình RO | AC3: TẶNG Bình RO
A4: 46262 | B4: Tồn Đầu kỳ | C4: 77 | G4: 18 | K4: 22 | M4: 11
A5: 46263 | C5: 34 | G5: 50 | O5: 46262 | P5: sân Pick star | Q5: Công ty | R5: 11 | AF5: Vũ Thị Thúy Phương
A6: 46268 | C6: 49 | O6: 46262 | P6: trường LHP | Q6: Bãi Cháy | V6: 3 | AF6: Đinh Thu Huế
A7: 46269 | C7: 60 | O7: 46262 | P7: Huyền GS Hạ Long | Q7: XN | V7: 3 | AF7: Đinh Thu Huế
A8: 46270 | C8: 55 | G8: 11 | K8: 8 | M8: 1 | O8: 46262 | P8: xe điện | Q8: XN | R8: 22 | AF8: Trần Trọng Khoa
A9: 46272 | K9: 20 | L9: 2 | M9: 20 | N9: 2 | O9: 46263 | P9: Mai ghi số | Q9: XN | R9: 2 | AF9: Đinh Thu Huế
O10: 46263 | P10: a Thảo | Q10: XN | R10: 11
O11: 46263 | P11: hương biển | Q11: XN | R11: 33
O12: 46263 | P12: Thùy | Q12: XN | Z12: 2
O13: 46264 | P13: Huế đi ship | R13: 22
O14: 46264 | P14: Tuấn lấy nội bộ | R14: 2
O15: 46264 | P15: chi ship đơn CP | V15: 4
O16: 46264 | P16: Huế đi ship | Z16: 5
O17: 46264 | P17: Huế đi ship | AB17: 6
O18: 46266 | P18: ngõ 1 Lê Thanh Nghị | Q18: BC | R18: 3
O19: 46266 | P19: Thùy | Q19: XN | R19: 5
O20: 46266 | P20: Huế đi ship | Z20: 2
O21: 46267 | P21: Huế đi ship | Z21: 4
O22: 46268 | P22: Quỳnh lấy nội bộ | AB22: 2
O23: 46268 | P23: sơn Hà tu | Q23: XN | AB23: 3
O24: 46268 | P24: Nhung | Q24: Công ty | Z24: 2
O25: 46268 | P25: c nhã nhà trẻ hoa hồng | Q25: Công ty | Z25: 4
O26: 46268 | P26: xe điện | R26: 21
O27: 46268 | P27: Thị Thu | R27: 12
O28: 46269 | P28: xe điện | R28: 22 | V28: 16
O29: 46269 | P29: ngà | Z29: 3
O30: 46269 | P30: liễu | R30: 2
O31: 46270 | P31: xe điện | R31: 33
O32: 46270 | P32: ngọc anh ship | Q32: BC | R32: 2
O33: 46270 | P33: đỗ hà ship | Q33: BC | R33: 4
O34: 46271 | P34: đỗ hà ship | Q34: BC | V34: 2
O35: 46271 | P35: chi ship | Q35: XN | Z35: 2
O36: 46271 | P36: đỗ hà ship | Q36: BC | Z36: 2
O37: 46272 | P37: Xuân | R37: 3 | V37: 2 | Z37: 10 | AA37: 1
P38: Mai ghi số | R38: 2
P39: xe điện | R39: 36
P40: Hằng Bảo vệ | R40: 6
...

Sheet Huế
B1: KH
C2: NHẬP | P2: XUẤT | AD2: THÀNH TIỀN | AE2: TÌNH TRẠNG | AF2: VẬN CHUYỂN
C3: Vỉ 500ml | D3: TẶNG Vỉ 500ml | E3: Thùng 500 ml | F3: TẶNG Thùng 500 ml | G3: Vỉ 350ml | H3: TẶNG Vỉ 350ml | I3: Thùng 350 ml | J3: TẶNG Thùng 350 ml | K3: Bình Ion | L3: TẶNG Bình Ion | M3: Bình RO | N3: TẶNG Bình RO | P3: Họ tên | Q3: Bộ phận | R3: Vỉ 500ml | S3: TẶNG Vỉ 500ml | T3: Thùng 500 ml | U3: TẶNG Thùng 500 ml | V3: Vỉ 350ml | W3: TẶNG Vỉ 350ml | X3: Thùng 350 ml | Y3: TẶNG Thùng 350 ml | Z3: Bình Ion | AA3: TẶNG Bình Ion | AB3: Bình RO | AC3: TẶNG Bình RO
B4: Tồn Đầu kỳ | C4: 176 | G4: 16 | K4: 1
B5: 46268 | C5: 100 | O5: 46263 | P5: Huế bán | Q5: XN | R5: 113 | AF5: Vũ Thị Thúy Phương
B6: 46269 | C6: 60 | O6: 46263 | P6: xe điện | Q6: XN | R6: 44 | AF6: Đinh Thu Huế
B7: 46272 | C7: 55 | G7: 28 | O7: 46264 | P7: sếp Tâm- vỉ km | Q7: XN | V7: 1 | AF7: Đinh Thu Huế
O8: 46264 | P8: mạnh-cao xanh | Q8: XN | V8: 2 | AF8: Trần Trọng Khoa
O9: 46264 | P9: Huế bán | Q9: XN | R9: 11 | AF9: Đinh Thu Huế
O10: 46267 | P10: anh ngọc | Q10: XN | V10: 5
O11: 46268 | P11: Quỳnh búp bê | Q11: XN | R11: 5
O12: 46268 | P12: Dung tổ DV | Q12: XN | R12: 2
O13: 46269 | P13: cây xăng hà trung | Q13: BC | R13: 11
O14: 46269 | P14: Huế bán- Cưới hỏi | Q14: XN | R14: 11
O15: 46269 | P15: sơn hà tu- the bay | Q15: XN | R15: 11
O16: 46269 | P16: café lính | Q16: cty | R16: 11
O17: 46269 | P17: đôi cây hk - thị thu | Q17: XN | R17: 11
O18: 46269 | P18: vịt biển | Q18: CP | R18: 11
O19: 46269 | P19: thuhà lầm | Q19: XN | R19: 11
O20: 46269 | P20: cẩm- HG | Q20: XN | R20: 11
O21: 46269 | P21: a ngọc - CX | Q21: XN | R21: 2
O22: 46269 | P22: Quỳnh búp bê | Q22: XN | R22: 2
O23: 46269 | P23: FLC | Q23: BC | V23: 5
O24: 46270 | P24: huế bán- Thái Nguyên 1 | Q24: XN | R24: 55
O25: 46271 | P25: mai anh- HG | Q25: XN | R25: 2
O26: 46271 | P26: tuyết lan | Q26: XN | R26: 11
O27: 46271 | P27: Phương- béo | Q27: XN | V27: 1
O28: 46272 | P28: xe điện | R28: 22
O29: 46272 | P29: xe điện | R29: 17
O30: 46272 | P30: Hồng gai ship | Q30: cty | Z30: 1
P31: E tú ghi số lấy 11 vỉ 500 ship đơn ngõ 14 bãi muối
B102: TỔNG NHẬP | C102: =SUM(C5:C101) -> 215 | D102: =SUM(D5:D101) -> 0 | E102: =SUM(E5:E101) -> 0 | F102: =SUM(F5:F101) -> 0 | G102: =SUM(G5:G101) -> 28 | H102: =SUM(H5:H101) -> 0 | I102: =SUM(I5:I101) -> 0 | J102: =SUM(J5:J101) -> 0 | ... N102: =SUM(N5:N101) -> 0 | Q102: TỔNG XUẤT | R102: =SUM(R5:R101) -> 374 | S102: =SUM(S5:S101) -> 0 | T102: =SUM(T5:T101) -> 0 | U102: =SUM(U5:U101) -> 0 | V102: =SUM(V5:V101) -> 14 | W102: =SUM(W5:W101) -> 0 | X102: =SUM(X5:X101) -> 0 | Y102: =SUM(Y5:Y101) -> 0 | ... AC102: =SUM(AC5:AC101) -> 0
Q103: Tồn Cuối Kỳ | R103: =C4+C102-R102 -> 17 | S103: =D4+D102-S102 -> 0 | T103: =E4+E102-T102 -> 0 | U103: =F4+F102-U102 -> 0 | V103: =G4+G102-V102 -> 30 | W103: =H4+H102-W102 -> 0 | X103: =I4+I102-X102 -> 0 | Y103: =J4+J102-Y102 -> 0 | ... AC103: =N4+N102-AC102 -> 0

Sheet Xe điện
B1: KH
C2: NHẬP | P2: XUẤT | AD2: THÀNH TIỀN | AE2: TÌNH TRẠNG | AF2: VẬN CHUYỂN
C3: Vỉ 500ml | D3: TẶNG Vỉ 500ml | E3: Thùng 500 ml | F3: TẶNG Thùng 500 ml | G3: Vỉ 350ml | H3: TẶNG Vỉ 350ml | I3: Thùng 350 ml | J3: TẶNG Thùng 350 ml | K3: Bình Ion | L3: TẶNG Bình Ion | M3: Bình RO | N3: TẶNG Bình RO | P3: Họ tên | Q3: Bộ phận | R3: Vỉ 500ml | S3: TẶNG Vỉ 500ml | T3: Thùng 500 ml | U3: TẶNG Thùng 500 ml | V3: Vỉ 350ml | W3: TẶNG Vỉ 350ml | X3: Thùng 350 ml | Y3: TẶNG Thùng 350 ml | Z3: Bình Ion | AA3: TẶNG Bình Ion | AB3: Bình RO | AC3: TẶNG Bình RO
B4: Tồn Đầu kỳ | C4: 11
AF5: Vũ Thị Thúy Phương
AF6: Đinh Thu Huế
AF7: Đinh Thu Huế
AF8: Trần Trọng Khoa
AF9: Đinh Thu Huế
B101: TỔNG NHẬP | C101: =SUM(C5:C100) -> 0 | D101: =SUM(D5:D100) -> 0 | E101: =SUM(E5:E100) -> 0 | F101: =SUM(F5:F100) -> 0 | G101: =SUM(G5:G100) -> 0 | H101: =SUM(H5:H100) -> 0 | I101: =SUM(I5:I100) -> 0 | J101: =SUM(J5:J100) -> 0 | ... N101: =SUM(N5:N100) -> 0 | Q101: TỔNG XUẤT | R101: =SUM(R5:R100) -> 0 | S101: =SUM(S5:S100) -> 0 | T101: =SUM(T5:T100) -> 0 | U101: =SUM(U5:U100) -> 0 | V101: =SUM(V5:V100) -> 0 | W101: =SUM(W5:W100) -> 0 | X101: =SUM(X5:X100) -> 0 | Y101: =SUM(Y5:Y100) -> 0 | ... AC101: =SUM(AC5:AC100) -> 0
Q102: Tồn Cuối Kỳ | R102: =C4+C101-R101 -> 11 | S102: =D4+D101-S101 -> 0 | T102: =E4+E101-T101 -> 0 | U102: =F4+F101-U101 -> 0 | V102: =G4+G101-V101 -> 0 | W102: =H4+H101-W101 -> 0 | X102: =I4+I101-X101 -> 0 | Y102: =J4+J101-Y101 -> 0 | ... AC102: =N4+N101-AC101 -> 0

Sheet Theo dõi vỏ bình
D1: Lấy bình | E1: Trả Vỏ
B2: .../08/2025 | C2: Thảo (KD) | D2: 10 | E2: 10 | F2: (Trả 10 vỏ lấy tháng 8 ngày 14/10/2025)
B3: 17/9/2025 | C3: VP Xí nghiệp | D3: 10 | F3: Hiên - Kẹp chì
B4: 22/9/2025 | C4: Hồng Gai | D4: 5 | E4: 5
B5: 02/10/2025 | C5: Chị Thu Yết Kiêu | D5: 10 | F5: (10 bình ion)
B6: 14/10/2025 | C6: Thảo (KD) | D6: 10
B7: 14/10/2025 | C7: Quỳnh | D7: 15
C8: C Tươi | D8: 10
C10: Tổng cộng | D10: =SUM(D2:D9) -> 70 | E10: =SUM(E2:E9) -> 15 | F10: =D10-E10 -> 55
D12: Nợ cũ | E12: Lấy mới | F12: Trả vỏ | G12: Còn nợ
B13: Tháng 11 | C13: Thảo (KD) | D13: 10 | G13: =D13+E13-F13 -> 10
C14: C Tươi | D14: 10 | G14: =D14+E14-F14 -> 10
C15: Quỳnh | D15: 15 | E15: 15 | F15: 7 | G15: =D15+E15-F15 -> 23
C16: Hiên | D16: 10 | E16: 10 | F16: 10 | G16: =D16+E16-F16 -> 10
C17: Thu | E17: 10 | F17: 10 | G17: =D17+E17-F17 -> 0
C18: Tổng nợ | G18: =SUM(G13:G17) -> 53
B19: Tháng 12 | C19: Thảo (KD) | D19: 10 | G19: =D19+E19-F19 -> 10
C20: C Tươi | D20: 10 | E20: 23 | F20: 5 | G20: =D20+E20-F20 -> 28
C21: Quỳnh | D21: 23 | G21: =D21+E21-F21 -> 23
C22: Hiên | D22: 10 | G22: =D22+E22-F22 -> 10
C23: Thu | D23: 0 | G23: =D23+E23-F23 -> 0
C24: Tổng nợ | G24: =SUM(G19:G23) -> 71
D25: Nợ cũ | E25: Lấy mới | F25: Trả vỏ | G25: Còn nợ
B26: Tháng 1/2026 | C26: Thảo (KD) | D26: 10 | E26: 11 | F26: 10 | G26: =D26+E26-F26 -> 11
C27: C Tươi | D27: 28 | E27: 16 | F27: 12 | G27: =D27+E27-F27 -> 32
C28: Quỳnh | D28: 23 | G28: =D28+E28-F28 -> 23
C29: Hiên | D29: 10 | F29: 8 | G29: =D29+E29-F29 -> 2
C30: Thu | D30: 0 | G30: =D30+E30-F30 -> 0
C31: Thơ | E31: 11 | F31: 0 | G31: =D31+E31-F31 -> 11
C32: Dung Cương | E32: 11 | F32: 0 | G32: =D32+E32-F32 -> 11
C33: VPXN | E33: 10 | F33: 6 | G33: 4
E34: =E35+E36 -> 6 | F34: =F35+F36 -> 4
C35: Khoa | E35: 4 | F35: 2 | G35: =E35-F35 -> 2 | H35: Khoa trả trực tiếp cho xe CP
C36: Quỳnh | E36: 2 | F36: 2 | G36: =E36-F36 -> 0 | H36: Trả 4 vỏ từ VPXN (2 vỏ của Quỳnh + 2 vỏ thịt chó Long Bình)
C37: Yến KD | E37: 15 | G37: =D37+E37-F37 -> 15
D38: =SUM(D26:D37) -> 71 | E38: =SUM(E26:E37) -> 86 | F38: =SUM(F26:F37) -> 44 | G38: =SUM(G26:G37) -> 111
B40: Tháng 2/2026 | C40: Thảo (KD) | D40: 11 | E40: 11 | F40: 6 | G40: =D40+E40-F40 -> 16
C41: C Tươi | D41: 32 | G41: =D41+E41-F41 -> 32
C42: Quỳnh | D42: 23 | F42: 9 | G42: =D42+E42-F42 -> 14
C43: Hiên | D43: 2 | G43: =D43+E43-F43 -> 2
...

Sheet Đá Trắng
B1: KH
C2: NHẬP | P2: XUẤT | AD2: THÀNH TIỀN | AE2: TÌNH TRẠNG | AF2: VẬN CHUYỂN
C3: Vỉ 500ml | D3: TẶNG Vỉ 500ml | E3: Thùng 500 ml | F3: TẶNG Thùng 500 ml | G3: Vỉ 350ml | H3: TẶNG Vỉ 350ml | I3: Thùng 350 ml | J3: TẶNG Thùng 350 ml | K3: Bình Ion | L3: TẶNG Bình Ion | M3: Bình RO | N3: TẶNG Bình RO | P3: Họ tên | Q3: Bộ phận | R3: Vỉ 500ml | S3: TẶNG Vỉ 500ml | T3: Thùng 500 ml | U3: TẶNG Thùng 500 ml | V3: Vỉ 350ml | W3: TẶNG Vỉ 350ml | X3: Thùng 350 ml | Y3: TẶNG Thùng 350 ml | Z3: Bình Ion | AA3: TẶNG Bình Ion | AB3: Bình RO | AC3: TẶNG Bình RO
B4: Tồn Đầu kỳ | C4: 5
O5: đại long | R5: 5 | AF5: Vũ Thị Thúy Phương
AF6: Đinh Thu Huế
AF7: Đinh Thu Huế
AF8: Trần Trọng Khoa
AF10: Đinh Thu Huế
B102: TỔNG NHẬP | C102: =SUM(C5:C101) -> 0 | D102: =SUM(D5:D101) -> 0 | E102: =SUM(E5:E101) -> 0 | F102: =SUM(F5:F101) -> 0 | G102: =SUM(G5:G101) -> 0 | H102: =SUM(H5:H101) -> 0 | I102: =SUM(I5:I101) -> 0 | J102: =SUM(J5:J101) -> 0 | ... N102: =SUM(N5:N101) -> 0 | Q102: TỔNG XUẤT | R102: =SUM(R5:R101) -> 5 | S102: =SUM(S5:S101) -> 0 | T102: =SUM(T5:T101) -> 0 | U102: =SUM(U5:U101) -> 0 | V102: =SUM(V5:V101) -> 0 | W102: =SUM(W5:W101) -> 0 | X102: =SUM(X5:X101) -> 0 | Y102: =SUM(Y5:Y101) -> 0 | ... AC102: =SUM(AC5:AC101) -> 0
Q103: Tồn Cuối Kỳ | R103: =C4+C102-R102 -> 0 | S103: =D4+D102-S102 -> 0 | T103: =E4+E102-T102 -> 0 | U103: =F4+F102-U102 -> 0 | V103: =G4+G102-V102 -> 0 | W103: =H4+H102-W102 -> 0 | X103: =I4+I102-X102 -> 0 | Y103: =J4+J102-Y102 -> 0 | ... AC103: =N4+N102-AC102 -> 0

Sheet VB T9
A1: THÔNG TIN | B1: KHÁCH HÀNG | C1: ĐT | D1: NỢ CŨ | F1: NHẬP | H1: TRẢ VỎ | J1: NỢ VỎ MỚI | L1: Trả XN | N1: ĐẶT CỌC | O1: GHI CHÚ
D2: Úp | E2: Vòi | F2: Úp | G2: Vòi | H2: Úp | I2: Vòi | J2: Úp | K2: Vòi | L2: Úp | M2: Vòi
A3: Báo cáo chuẩn | D3: 70 | E3: 282 | F3: 52 | G3: 270 | H3: 19 | I3: 140 | J3: =D3+F3-H3 -> 103 | K3: =E3+G3-I3 -> 412
A4: tổng | J4: =SUM(J6:J93) -> 102 | K4: =SUM(K6:K93) -> 419
A5: chênh lệch | J5: =J4-J3 -> -1 | K5: =K4-K3 -> 7
A6: Trương Thị Hải Yến | B6: Công ty Công nghiệp Hóa chất mỏ Quảng Ninh | G6: 125 | J6: =D6+F6-H6 -> 0 | K6: =E6+G6-I6 -> 125
A7: Trương Thị Hải Yến | B7: Trạm y tế phường Cao Xanh | D7: 1 | J7: =D7+F7-H7 -> 1 | K7: =E7+G7-I7 -> 0
A8: Trần Lệ Hoa | B8: Ngân hàng SHB- cột 8 | D8: 5 | F8: 11 | J8: =D8+F8-H8 -> 16 | K8: =E8+G8-I8 -> 0
A9: Trần Lệ Hoa | B9: Văn Phòng Ủy ban nhân dân tỉnh Quảng Ninh | D9: 10 | E9: 35 | G9: 22 | H9: 1 | I9: 19 | J9: =D9+F9-H9 -> 9 | K9: =E9+G9-I9 -> 38 | O9: 9/9 trả
A10: Trần Lệ Hoa | B10: chung cư Cẩm Bình | D10: 1 | J10: =D10+F10-H10 -> 1 | K10: =E10+G10-I10 -> 0
A11: Trần Lệ Hoa | B11: kh lẻ | E11: 3 | J11: =D11+F11-H11 -> 0 | K11: =E11+G11-I11 -> 3
A12: Đinh Thu Huế | D12: 5 | E12: 91 | F12: 5 | G12: 47 | I12: 52 | J12: =D12+F12-H12 -> 10 | K12: =E12+G12-I12 -> 86
A13: Đỗ Thị Thanh Hà | B13: Công ty Hanet | F13: 6 | G13: 3 | J13: =D13+F13-H13 -> 6 | K13: =E13+G13-I13 -> 3
A14: Bùi Thị Thu | B14: Công ty du lịch Luxury | F14: 11 | J14: =D14+F14-H14 -> 11 | K14: =E14+G14-I14 -> 0
A15: Vũ Thị Tươi | B15: hộ gia đình | E15: 12 | G15: 11 | I15: 8 | J15: =D15+F15-H15 -> 0 | K15: =E15+G15-I15 -> 15
A16: Lê Thị Thanh Xuân | B16: Sở Dân tộc và Tôn giáo | G16: 16 | J16: =D16+F16-H16 -> 0 | K16: =E16+G16-I16 -> 16
A17: Lương Minh Hương | B17: Công ty CP kinh doanh than miền Bắc Vinacomin | G17: 24 | J17: =D17+F17-H17 -> 0 | K17: =E17+G17-I17 -> 24
A18: Phạm Tuyết Dung | B18: nhà mẹ Đông Triều | D18: 2 | F18: 6 | G18: 5 | J18: =D18+F18-H18 -> 8 | K18: =E18+G18-I18 -> 5
A19: Phạm Tuyết Dung | B19: nhà Hà Lầm | G19: 11 | I19: 5 | J19: =D19+F19-H19 -> 0 | K19: =E19+G19-I19 -> 6
A20: Nguyễn Thị Chi | B20: Văn phòng Công chứng Hạ Long | F20: 8 | G20: 3 | J20: =D20+F20-H20 -> 8 | K20: =E20+G20-I20 -> 3
A21: Nguyễn Thị Hiếu | B21: Nhà khách Tỉnh Quảng Ninh | F21: 5 | G21: =17+11 -> 28 | J21: =D21+F21-H21 -> 5 | K21: =E21+G21-I21 -> 28
A22: Phạm Phương Dung | B22: c Hằng-phố Nguyễn Lương Bằng | G22: 2 | J22: =D22+F22-H22 -> 0 | K22: =E22+G22-I22 -> 2 | O22: 2 VỎ NB CỦA HƯƠNG
A23: Phạm Phương Dung | B23: Kh lẻ | G23: 1 | I23: 1 | J23: =D23+F23-H23 -> 0 | K23: =E23+G23-I23 -> 0
A24: My Quawaco | B24: Nguyễn Ngọc- 755 Lê Thánh Tông | C24: 0904306818 | G24: 2 | J24: =D24+F24-H24 -> 0 | K24: =E24+G24-I24 -> 2
A25: SCC | B25: Liên Ngõ 2, số 2 phố Hải Phong | C25: 0856741990 | G25: 2 | J25: =D25+F25-H25 -> 0 | K25: =E25+G25-I25 -> 2 | O25: 0.14285714
A26: SCC | C26: 0979913393 | E26: 1 | J26: =D26+F26-H26 -> 0 | K26: =E26+G26-I26 -> 1 | N26: 50000
A27: SCC | B27: TNHH Hà Linh 79 A12/12 Monbay | C27: 0988221224 | G27: 2 | J27: =D27+F27-H27 -> 0 | K27: =E27+G27-I27 -> 2 | N27: 100000
A28: Phạm Thị Đan Thanh | B28: Kh lẻ | G28: 3 | J28: =D28+F28-H28 -> 0 | K28: =E28+G28-I28 -> 3
A29: Nguyễn Thị Huy | B29: Kh lẻ | G29: 2 | J29: =D29+F29-H29 -> 0 | K29: =E29+G29-I29 -> 2
A30: Đỗ Thị Vượng | B30: HuƠng | C30: 0942008368 | E30: 1 | J30: =D30+F30-H30 -> 0 | K30: =E30+G30-I30 -> 1
A31: KH đến mua trực tiếp | B31: Phạm Thị Thanh Huyền | C31: 0376984622 | G31: 2 | J31: =D31+F31-H31 -> 0 | K31: =E31+G31-I31 -> 2
A32: Nguyễn Thị Thùy | B32: Lương Văn Thạnh | C32: 0912155500 | E32: 2 | J32: =D32+F32-H32 -> 0 | K32: =E32+G32-I32 -> 2 | N32: 100000
A33: Vũ Thị Thu Vân | B33: Kh lẻ | E33: 1 | J33: =D33+F33-H33 -> 0 | K33: =E33+G33-I33 -> 1
A34: KH đến mua trực tiếp | B34: Đàm Hưng | C34: 090 4158188 | E34: 2 | J34: =D34+F34-H34 -> 0 | K34: =E34+G34-I34 -> 2 | N34: 100000
A35: Nguyễn Thị Thu Hiên | B35: Kh lẻ | E35: 15 | J35: =D35+F35-H35 -> 0 | K35: =E35+G35-I35 -> 15
A36: Nguyễn Phương Thảo | B36: Kh lẻ | E36: 14 | I36: 13 | J36: =D36+F36-H36 -> 0 | K36: =E36+G36-I36 -> 1
A37: Trần Thị Ánh Nguyệt | B37: Kh lẻ | D37: 10 | E37: 15 | J37: =D37+F37-H37 -> 10 | K37: =E37+G37-I37 -> 15 | N37: 1250000
A38: Hà Thị Hằng | B38: Xí nghiệp thiết kế than Hòn Gai | D38: 5 | J38: =D38+F38-H38 -> 5 | K38: =E38+G38-I38 -> 0
A39: Nguyễn Thị Ngà | B39: Công ty CP đầu tư nhà và hạ tầng -TKV | E39: 12 | J39: =D39+F39-H39 -> 0 | K39: =E39+G39-I39 -> 12
A40: chị Nghĩa -XNN Uông Bí | B40: CDC | E40: 2 | J40: =D40+F40-H40 -> 0 | K40: =E40+G40-I40 -> 2
...

Sheet VB T8
A1: THÔNG TIN | B1: KHÁCH HÀNG | C1: ĐT | D1: NỢ CŨ | F1: NHẬP | H1: TRẢ VỎ | J1: NỢ VỎ MỚI | L1: Trả XN | N1: ĐẶT CỌC | O1: GHI CHÚ
D2: Úp | E2: Vòi | F2: Úp | G2: Vòi | H2: Úp | I2: Vòi | J2: Úp | K2: Vòi | L2: Úp | M2: Vòi
A3: Báo cáo chuẩn | D3: 70 | E3: 282 | F3: 52 | G3: 270 | H3: 19 | I3: 140 | J3: =D3+F3-H3 -> 103 | K3: =E3+G3-I3 -> 412
A4: tổng | J4: =SUM(J6:J95) -> 103 | K4: =SUM(K6:K95) -> 439
A5: chênh lệch | J5: =J4-J3 -> 0 | K5: =K4-K3 -> 27
A6: Trương Thị Hải Yến | B6: Công ty Công nghiệp Hóa chất mỏ Quảng Ninh | G6: 125 | J6: =D6+F6-H6 -> 0 | K6: =E6+G6-I6 -> 125
A7: Trương Thị Hải Yến | B7: Trạm y tế phường Cao Xanh | D7: 1 | J7: =D7+F7-H7 -> 1 | K7: =E7+G7-I7 -> 0
A8: Trần Lệ Hoa | B8: Ngân hàng SHB- cột 8 | D8: 5 | F8: 11 | J8: =D8+F8-H8 -> 16 | K8: =E8+G8-I8 -> 0
A9: Trần Lệ Hoa | B9: Văn Phòng Ủy ban nhân dân tỉnh Quảng Ninh | D9: 10 | E9: 35 | G9: 22 | J9: =D9+F9-H9 -> 10 | K9: =E9+G9-I9 -> 57
A10: Trần Lệ Hoa | B10: chung cư Cẩm Bình | D10: 1 | J10: =D10+F10-H10 -> 1 | K10: =E10+G10-I10 -> 0
A11: Trần Lệ Hoa | B11: kh lẻ | E11: 3 | J11: =D11+F11-H11 -> 0 | K11: =E11+G11-I11 -> 3
A12: Đinh Thu Huế | B12: Trạm y tế phường Cao Xanh | D12: 5 | E12: 91 | F12: 5 | G12: 33 | I12: =23+21 -> 44 | J12: =D12+F12-H12 -> 10 | K12: =E12+G12-I12 -> 80
A13: Đinh Thu Huế | B13: Karaoke | G13: 12 | I13: 8 | J13: =D13+F13-H13 -> 0 | K13: =E13+G13-I13 -> 4
A14: Đinh Thu Huế | B14: Cạnh Vinmart Monbay | G14: 2 | J14: =D14+F14-H14 -> 0 | K14: =E14+G14-I14 -> 2 | P14: `
A15: Đỗ Thị Thanh Hà | B15: Công ty Hanet | F15: 6 | G15: 3 | J15: =D15+F15-H15 -> 6 | K15: =E15+G15-I15 -> 3
A16: Bùi Thị Thu | B16: Công ty du lịch Luxury | F16: 11 | J16: =D16+F16-H16 -> 11 | K16: =E16+G16-I16 -> 0
A17: Vũ Thị Tươi | B17: hộ gia đình | E17: 12 | G17: 11 | I17: 8 | J17: =D17+F17-H17 -> 0 | K17: =E17+G17-I17 -> 15
A18: Lê Thị Thanh Xuân | B18: Sở Dân tộc và Tôn giáo | G18: 16 | J18: =D18+F18-H18 -> 0 | K18: =E18+G18-I18 -> 16
A19: Lương Minh Hương | B19: Công ty CP kinh doanh than miền Bắc Vinacomin | G19: 24 | J19: =D19+F19-H19 -> 0 | K19: =E19+G19-I19 -> 24
A20: Phạm Tuyết Dung | B20: nhà mẹ Đông Triều | D20: 2 | F20: 6 | G20: 5 | J20: =D20+F20-H20 -> 8 | K20: =E20+G20-I20 -> 5
A21: Phạm Tuyết Dung | B21: nhà Hà Lầm | G21: 11 | I21: 5 | J21: =D21+F21-H21 -> 0 | K21: =E21+G21-I21 -> 6
A22: Nguyễn Thị Chi | B22: Văn phòng Công chứng Hạ Long | F22: 8 | G22: 3 | J22: =D22+F22-H22 -> 8 | K22: =E22+G22-I22 -> 3
A23: Nguyễn Thị Hiếu | B23: Nhà khách Tỉnh Quảng Ninh | F23: 5 | G23: =17+11 -> 28 | J23: =D23+F23-H23 -> 5 | K23: =E23+G23-I23 -> 28
A24: Phạm Phương Dung | B24: c Hằng-phố Nguyễn Lương Bằng | G24: 2 | J24: =D24+F24-H24 -> 0 | K24: =E24+G24-I24 -> 2
A25: Phạm Phương Dung | B25: Kh lẻ | G25: 1 | J25: =D25+F25-H25 -> 0 | K25: =E25+G25-I25 -> 1
A26: My Quawaco | B26: Nguyễn Ngọc- 755 Lê Thánh Tông | C26: 0904306818 | G26: 2 | J26: =D26+F26-H26 -> 0 | K26: =E26+G26-I26 -> 2
A27: SCC | B27: Liên Ngõ 2, số 2 phố Hải Phong | C27: 0856741990 | G27: 2 | J27: =D27+F27-H27 -> 0 | K27: =E27+G27-I27 -> 2 | O27: 0.14285714
A28: SCC | C28: 0979913393 | E28: 1 | J28: =D28+F28-H28 -> 0 | K28: =E28+G28-I28 -> 1 | N28: 50000
A29: SCC | B29: TNHH Hà Linh 79 A12/12 Monbay | C29: 0988221224 | G29: 2 | J29: =D29+F29-H29 -> 0 | K29: =E29+G29-I29 -> 2 | N29: 100000
A30: Phạm Thị Đan Thanh | B30: Kh lẻ | G30: 3 | J30: =D30+F30-H30 -> 0 | K30: =E30+G30-I30 -> 3
A31: Nguyễn Thị Huy | B31: Kh lẻ | G31: 2 | J31: =D31+F31-H31 -> 0 | K31: =E31+G31-I31 -> 2
A32: Đỗ Thị Vượng | B32: cô Oanh | C32: 0942008368 | E32: 1 | J32: =D32+F32-H32 -> 0 | K32: =E32+G32-I32 -> 1 | O32: trả diamond
A33: KH đến mua trực tiếp | B33: Phạm Thị Thanh Huyền | C33: 0376984622 | G33: 2 | J33: =D33+F33-H33 -> 0 | K33: =E33+G33-I33 -> 2 | O33: 4 vỏ trả 13/07
A34: Nguyễn Thị Thùy | B34: Lương Văn Thạnh | C34: 0912155500 | E34: 2 | J34: =D34+F34-H34 -> 0 | K34: =E34+G34-I34 -> 2 | N34: 100000
A35: Vũ Thị Thu Vân | B35: Kh lẻ | E35: 1 | J35: =D35+F35-H35 -> 0 | K35: =E35+G35-I35 -> 1
A36: KH đến mua trực tiếp | B36: Đàm Hưng | C36: 090 4158188 | E36: 2 | J36: =D36+F36-H36 -> 0 | K36: =E36+G36-I36 -> 2 | N36: 100000
A37: Nguyễn Thị Thu Hiên | B37: Kh lẻ | E37: 15 | J37: =D37+F37-H37 -> 0 | K37: =E37+G37-I37 -> 15
A38: Nguyễn Phương Thảo | B38: Kh lẻ | E38: 14 | I38: 13 | J38: =D38+F38-H38 -> 0 | K38: =E38+G38-I38 -> 1
A39: Trần Thị Ánh Nguyệt | B39: Kh lẻ | D39: 10 | E39: 15 | J39: =D39+F39-H39 -> 10 | K39: =E39+G39-I39 -> 15 | N39: 1250000
A40: Hà Thị Hằng | B40: Xí nghiệp thiết kế than Hòn Gai | D40: 5 | J40: =D40+F40-H40 -> 5 | K40: =E40+G40-I40 -> 0
...

Sheet DATA
A1: SCC | B1: SCC | C1: Chưa thanh toán | D1: TÌNH TRẠNG
A2: Bãi Cháy | B2: Bãi Cháy | C2: Đã thanh toán | D2: VẬN CHUYỂN
A3: Ban An toàn | B3: Ban An toàn | C3: Tình trạng | D3: BỐC HÀNG
A4: Ban kiểm soát | B4: Ban kiểm soát
A5: Ban Lãnh đạo | B5: Ban Lãnh đạo
A6: Ban QL | B6: Ban QL
A7: BP Kế toán | B7: BP Kế toán
A8: BP Kinh doanh | B8: BP Kinh doanh
A9: BP Kỹ thuật | B9: BP Kỹ thuật
A10: BP Quản trị | B10: BP Quản trị
A11: Bùi Bích Phương | B11: Cẩm Phả
A12: Bùi Diệu Ninh | B12: Đông Triều
A13: Bùi Đức Hoàng | B13: Miền Đông
A14: Bùi Hà Thu | B14: Móng Cái
A15: Bùi Hoàng Minh | B15: NMN DV
... A37: Bùi Thùy Dương | B37: Công ty
A38: Bùi Văn Tình
A39: CẨM PHẢ
A40: Cẩm Phả
A41: Cao Trường Sơn
A42: Chế Thùy Dung
A43: Chu Hoài Nam
A44: Đặng Thanh Tùng
A45: Đặng Thế Anh
A46: Đặng Thị Hường
A47: Đặng Thu Huyền
A48: Đặng Văn Thơ
A49: Đào Duy Tùng
... A470: Nguyễn Hoàng Anh
