Workbook

Sheet XUẤT
A1: ĐIỀU PHỐI QUAROMI | M1: CHỈ TIÊU | AA1: VẬN CHUYỂN
A3: STT | B3: Ngày | C3: Đơn hàng | D3: Công việc | E3: Kho | F3: Số lượng | J3: Người thực hiện | K3: Hỗ Trợ (trạm QL) | L3: Kết quả | M3: Chỉ tiêu | N3: Chỉ tiêu CBCNV | O3: Sản phẩm | P3: Số lượng | X3: Đơn giá | Y3: Doanh thu | Z3: Thu tiền | AA3: Người vận chuyển | AB3: Số lượng | AC3: Số tiền | AD3: GHI CHÚ
F4: Thùng | G4: Vỉ | H4: Bình | I4: Cộng | M4: XN/CTY | N4: CBCNV | P4: Vỉ 500ml | Q4: Vỉ 350 ml | R4: Hộp 500ml | S4: Hộp 350ml | T4: Bình kiềm | U4: Bình RO | V4: KM | W4: Cộng
P5: =SUBTOTAL(9,P6:P148) -> 727 | Q5: =SUBTOTAL(9,Q6:Q148) -> 183 | R5: =SUBTOTAL(9,R6:R148) -> 10 | S5: =SUBTOTAL(9,S6:S148) -> 8 | T5: =SUBTOTAL(9,T6:T148) -> 146 | U5: =SUBTOTAL(9,U6:U148) -> 59 | V5: =SUBTOTAL(9,V6:V148) -> 81 | W5: =SUBTOTAL(9,W6:W148) -> 1214 | AB5: =SUBTOTAL(9,AB6:AB148) -> 1133 | AC5: =SUBTOTAL(9,AC6:AC148) -> 5665000
A6: 17 | B6: 46273 | C6: Nhà Nghỉ Hà Duy, phố Trần Cao Vân, đường sông 3, 10 vỉ 500ml, ĐT 0977 367679 | D6: Vận chuyển | E6: Xe điện | G6: 11 | I6: 11 | J6: Phương + Huế | L6: Đã hoàn thành | M6: Xí nghiệp | N6: Nguyễn T.Phương Thanh | O6: Vỉ 500ml | P6: 10 | V6: 1 | W6: =SUM(P6:V6) -> 11 | X6: =SUMIFS('[1]Đơn giá'!C:C,'[1]Đơn giá'!B:B,[1]XUẤT!O6) -> #VALUE! | Y6: =X6*P6 -> #VALUE! | Z6: CK 14/9 | AA6: Đinh Thu Huế | AB6: =W6-V6 -> 10 | AC6: =AB6*5000 -> 50000
A7: 18 | B7: 46273 | C7: VNPT (Chị Yến): 0915 299 036, vỉ 350 ml | D7: Vận chuyển | E7: Tăng áp | G7: 11 | I7: 11 | J7: Phương + Huế | L7: Đã hoàn thành | M7: Xí nghiệp | N7: Nguyễn Thị Lan | O7: Vỉ 350ml | Q7: 10 | V7: 1 | W7: =SUM(P7:V7) -> 11 | X7: =SUMIFS('[1]Đơn giá'!C:C,'[1]Đơn giá'!B:B,[1]XUẤT!O7) -> #VALUE! | Y7: =X7*P7 -> #VALUE! | Z7: CK 18/9 | AA7: Đinh Thu Huế | AB7: =W7-V7 -> 10 | AC7: =AB7*5000 -> 50000
A8: 19 | B8: 46273 | C8: Tiểu thủ công nghiệp | D8: Vận chuyển | E8: Tăng áp | G8: 22 | I8: 22 | J8: Phương + Huế | L8: Đã hoàn thành | M8: Xí nghiệp | N8: Bùi Thị Thu | O8: Vỉ 500ml | P8: 20 | V8: 2 | W8: =SUM(P8:V8) -> 22 | X8: =SUMIFS('[1]Đơn giá'!C:C,'[1]Đơn giá'!B:B,[1]XUẤT!O8) -> #VALUE! | Y8: =X8*P8 -> #VALUE! | Z8: CK11/9 | AA8: Đinh Thu Huế | AB8: =W8-V8 -> 20 | AC8: =AB8*5000 -> 100000 | AD8: Chị Huế đã thu tiền
A9: 20 | B9: 46273 | C9: Sân pick cột 8 | D9: Vận chuyển | E9: Tăng áp | G9: 22 | I9: 22 | J9: Phương + Huế | L9: Đã hoàn thành | M9: Xí nghiệp | N9: Nguyễn Thị Thu Hiên | O9: Vỉ 500ml | P9: 10 | V9: 1 | W9: =SUM(P9:V9) -> 11 | X9: =SUMIFS('[1]Đơn giá'!C:C,'[1]Đơn giá'!B:B,[1]XUẤT!O9) -> #VALUE! | Y9: =X9*P9 -> #VALUE! | Z9: CK11/9 | AA9: Đinh Thu Huế | AB9: =W9-V9 -> 10 | AC9: =AB9*5000 -> 50000
A10: 21 | E10: Tăng áp | M10: Xí nghiệp | N10: Bùi Ngọc Mai | O10: Vỉ 500ml | P10: 10 | V10: 1 | W10: =SUM(P10:V10) -> 11 | X10: =SUMIFS('[1]Đơn giá'!C:C,'[1]Đơn giá'!B:B,[1]XUẤT!O10) -> #VALUE! | Y10: =X10*P10 -> #VALUE! | Z10: CK11/9 | AA10: Đinh Thu Huế | AB10: =W10-V10 -> 10 | AC10: =AB10*5000 -> 50000
A11: 22 | B11: 46273 | C11: Nguyễn Văn Hiếu phòng KT: đki 4 bình kiềm ship qua cửa hàng Monbay A2-01 ạ, ng nhận: Châm nhận +84964566350 - Thu tiền luôn (Quán rượu Mao Đài đối diện thư viện tỉnh) | D11: Vận chuyển | E11: Tăng áp | H11: 4 | I11: 4 | J11: Phương + Huế | L11: Đã hoàn thành | M11: Công ty | N11: Nguyễn văn hiếu (kỹ thuật) | O11: Bình kiềm | T11: 4 | W11: =SUM(P11:V11) -> 4 | X11: =SUMIFS('[1]Đơn giá'!C:C,'[1]Đơn giá'!B:B,[1]XUẤT!O11) -> #VALUE! | Y11: =T11*X11 -> #VALUE! | Z11: công ty thu tiền | AB11: =W11-V11 -> 4 | AC11: =AB11*5000 -> 20000
A12: 23 | B12: 46273 | C12: 3 vỉ to + 3 vỉ nhỏ Địa chỉ : số nhà 45, Lê Chân mới , tổ 7 khu Hồng Hà 2, ĐT: 0934639858 | D12: Vận chuyển | E12: Tăng áp | G12: 6 | I12: 6 | J12: Xuân | L12: Đã hoàn thành | M12: Bãi Cháy | O12: Vỉ 500ml | P12: 3 | W12: =SUM(P12:V12) -> 3 | X12: =SUMIFS('[1]Đơn giá'!C:C,'[1]Đơn giá'!B:B,[1]XUẤT!O12) -> #VALUE! | Y12: =X12*P12 -> #VALUE! | Z12: Bãi Cháy tự thu | AA12: Lê Thanh Xuân | AB12: =W12-V12 -> 3 | AC12: =AB12*5000 -> 15000 | AD12: BÃI CHÁY VAY
E13: Tăng áp | M13: Bãi Cháy | O13: Vỉ 350 ml | Q13: 3 | W13: =SUM(P13:V13) -> 3 | X13: 85000 | Y13: =Q13*X13 -> 255000 | Z13: Bãi Cháy tự thu | AA13: Lê Thanh Xuân | AB13: =W13-V13 -> 3 | AC13: =AB13*5000 -> 15000
A14: 24 | B14: 46273 | C14: Hồng Hạnh PCN: 0982835366 Phương Hiền gần chợ Loong Tổng 20+2 vỉ 350ml | D14: Vận chuyển | E14: Tăng áp | G14: 22 | I14: 22 | J14: Phương + Huyền + Ly tổ DV | L14: Đã hoàn thành | M14: Công ty | N14: Hồng Hạnh PCN | O14: Vỉ 350 ml | Q14: 20 | V14: 2 | W14: =SUM(P14:V14) -> 22 | X14: 85000 | Y14: =Q14*X14 -> 1700000 | Z14: công ty thu tiền | AA14: Tổ DVCTT | AB14: =W14-V14 -> 20 | AC14: =AB14*5000 -> 100000 | AD14: CÔNG TY VAY
A15: 25 | B15: 46273 | C15: Em Hà ở sảnh 2 chung cư sapphire. 2 vỉ 500ml, 0911898336 | D15: Vận chuyển | E15: Tăng áp | G15: 2 | I15: 2 | J15: Huyền + Ly tổ DV | L15: Đã hoàn thành | M15: Xí nghiệp | N15: Đoàn Thị Nhung | O15: Vỉ 500ml | P15: 2 | W15: =SUM(P15:V15) -> 2 | X15: =SUMIFS('[1]Đơn giá'!C:C,'[1]Đơn giá'!B:B,[1]XUẤT!O15) -> #VALUE! | Y15: =X15*P15 -> #VALUE! | Z15: CK11/9 | AA15: Tổ DVCTT | AB15: =W15-V15 -> 2 | AC15: =AB15*5000 -> 10000 | AD15: chị Huyền thu tiền
A16: 26 | B16: 46273 | C16: Em Quỳnh ở 94 Văn Lang ( sau trường Văn Lang) 2 vỉ 500ml, ĐT 0973367844 | D16: Vận chuyển | E16: Tăng áp | G16: 2 | I16: 2 | J16: Huyền + Ly tổ DV | L16: Đã hoàn thành | M16: Xí nghiệp | N16: Đoàn Thị Nhung | O16: Vỉ 500ml | P16: 2 | W16: =SUM(P16:V16) -> 2 | X16: =SUMIFS('[1]Đơn giá'!C:C,'[1]Đơn giá'!B:B,[1]XUẤT!O16) -> #VALUE! | Y16: =X16*P16 -> #VALUE! | Z16: CK9/9 | AA16: Tổ DVCTT | AB16: =W16-V16 -> 2 | AC16: =AB16*5000 -> 10000 | AD16: Chị Nguyệt thu ngân cũ thu tiền
A17: 27 | B17: 46273 | C17: 10+1 Vỉ bia Bà Hợi Cao Xanh | D17: Vận chuyển | E17: Tăng áp | G17: 11 | I17: 11 | J17: Phương + Huế | L17: Đã hoàn thành | M17: Xí nghiệp | N17: Đinh Thu Huế | O17: Vỉ 500ml | P17: 10 | V17: 1 | W17: =SUM(P17:V17) -> 11 | X17: =SUMIFS('[1]Đơn giá'!C:C,'[1]Đơn giá'!B:B,[1]XUẤT!O17) -> #VALUE! | Y17: =X17*P17 -> #VALUE! | AA17: Phương + Huế | AB17: =W17-V17 -> 10 | AC17: =AB17*5000 -> 50000 | AD17: vay công ty
A18: 28 | B18: 46273 | C18: 10+1 vỉ chế biến than qn | D18: Vận chuyển | G18: 11 | I18: 11 | J18: Phương + Huế | L18: Đã hoàn thành | M18: Xí nghiệp | N18: Nguyễn Thị Hồng Phương | O18: Vỉ 500ml | P18: 10 | V18: 1 | W18: =SUM(P18:V18) -> 11 | X18: =SUMIFS('[1]Đơn giá'!C:C,'[1]Đơn giá'!B:B,[1]XUẤT!O18) -> #VALUE! | Y18: =X18*P18 -> #VALUE! | Z18: CK11/9 | AA18: Phương + Huế | AB18: =W18-V18 -> 10 | AC18: =AB18*5000 -> 50000 | AD18: vay công ty
A19: 29 | B19: 46273 | C19: hồng hạnh pcn: 0936812781 Số 1 ngõ 5 phố hải long cạnh phòng khám đa khoa Hoàng Anh KH có nhu cầu 3 bình kiem 19l ship ngay, thu tiền + đổi vỏ | D19: Vận chuyển | H19: 3 | I19: 3 | J19: Hằng bảo vệ | L19: Đã hoàn thành | M19: Công ty | N19: Hồng Hạnh PCN | O19: Bình kiềm | T19: 3 | W19: =SUM(P19:V19) -> 3 | X19: =SUMIFS('[1]Đơn giá'!C:C,'[1]Đơn giá'!B:B,[1]XUẤT!O19) -> #VALUE! | Y19: =T19*X19 -> #VALUE! | Z19: Chị Hằng ghi số thu tiền | AA19: Nguyễn Thị Hằng | AB19: =W19-V19 -> 3 | AC19: =AB19*5000 -> 15000 | AD19: chị hằng đã thu tiền + 3 vỏ
A20: 30 | B20: 46273 | C20: chị Hằng đen ghi số | G20: 3 | M20: Xí nghiệp | N20: Nguyễn Thị Thúy Hằng | O20: Vỉ 500ml | P20: 3 | W20: =SUM(P20:V20) -> 3 | X20: =SUMIFS('[1]Đơn giá'!C:C,'[1]Đơn giá'!B:B,[1]XUẤT!O20) -> #VALUE! | Y20: =X20*P20 -> #VALUE! | AA20: Nguyễn Thị Thúy Hằng | AB20: =W20-V20 -> 3 | AC20: =AB20*5000 -> 15000
A21: 31 | B21: 46273 | C21: Lại Lan | G21: 2 | I21: 2 | M21: Xí nghiệp | N21: Lại Thị Lan | O21: Vỉ 500ml | P21: 2 | W21: =SUM(P21:V21) -> 2 | X21: =SUMIFS('[1]Đơn giá'!C:C,'[1]Đơn giá'!B:B,[1]XUẤT!O21) -> #VALUE! | Y21: =X21*P21 -> #VALUE! | Z21: CK9/9 | AA21: Lại Thị Lan | AB21: =W21-V21 -> 2 | AC21: =AB21*5000 -> 10000
A22: 32 | B22: 46273 | C22: Chị Hằng bảo vệ | G22: 4 | I22: 4 | J22: Hằng bảo vệ | M22: Xí nghiệp | N22: Nguyễn Thị Hằng | O22: Vỉ 500ml | P22: 4 | W22: =SUM(P22:V22) -> 4 | X22: =SUMIFS('[1]Đơn giá'!C:C,'[1]Đơn giá'!B:B,[1]XUẤT!O22) -> #VALUE! | Y22: =X22*P22 -> #VALUE! | AA22: Nguyễn Thị Hằng | AB22: =W22-V22 -> 4 | AC22: =AB22*5000 -> 20000 | AE22: xuất hóa đơn 15/9
A23: 33 | B23: 46274 | C23: KH lấy 10 + 1 thùng 500ml, cạnh tòa nhà Đa Năng Hà Tu, ĐT: 0902 009 566 | D23: 10 +1 thùng | E23: xe cp hạ luôn | F23: 11 | I23: 11 | J23: Xuân | M23: Xí nghiệp | N23: Đỗ Thị Liễu | O23: Hộp 500ml | R23: 10 | V23: 1 | W23: =SUM(P23:V23) -> 11 | X23: =SUMIFS('[1]Đơn giá'!C:C,'[1]Đơn giá'!B:B,[1]XUẤT!O23) -> #VALUE! | Y23: =R23*X23 -> #VALUE! | Z23: ck11/9 | AA23: Lê Thanh Xuân | AB23: =W23-V23 -> 10 | AC23: =AB23*5000 -> 50000 | AD23: Liễu thu tiền
A24: 34 | B24: 46274 | C24: Lại Lan, 1 bình kiềm | H24: 1 | I24: 1 | J24: Lại Lan | L24: hoàn thành | M24: Xí nghiệp | N24: Lại Thị Lan | O24: Bình kiềm | T24: 1 | W24: =SUM(P24:V24) -> 1 | X24: =SUMIFS('[1]Đơn giá'!C:C,'[1]Đơn giá'!B:B,[1]XUẤT!O24) -> #VALUE! | Y24: =X24*P24 -> #VALUE! | Z24: CK9/9 | AA24: Lại Thị Lan | AB24: =W24-V24 -> 1 | AC24: =AB24*5000 -> 5000 | AD24: Lại Lan thu tiền | AE24: xuất hóa đơn 15/9
A25: 35 | B25: 46274 | C25: Vũ Anh BKS: Sau nhà văn hóa khu 3, tỉnh ủy cột 5, dốc nhà máy in đi lên, đến nơi gọi chị để chị lên đường vì nhà chị ko có số em ạ, 0948910518, lấy 3 vỉ 500 và 1 vỉ 350, chị tên Thảo. | D25: 3 vỉ 500 + 1 vỉ 350 | E25: tăng áp | G25: 4 | I25: =H25+G25 -> 4 | J25: Lại Lan | L25: hoàn thành | M25: Công ty | N25: Vũ Anh BKS | O25: Bình kiềm | P25: 3 | Q25: 1 | W25: =SUM(P25:V25) -> 4 | X25: =SUMIFS('[1]Đơn giá'!C:C,'[1]Đơn giá'!B:B,[1]XUẤT!O25) -> #VALUE! | Y25: =X25*P25 -> #VALUE! | Z25: công ty thu tiền | AA25: Lại Thị Lan | AB25: =W25-V25 -> 4 | AC25: =AB25*5000 -> 20000 | AD25: CÔNG TY VAY
B26: 46274 | C26: Em chi | E26: tăng áp | H26: 2 | I26: =H26+G26 -> 2 | J26: Chi | L26: hoàn thành | M26: Xí nghiệp | N26: Nguyễn Thị Chi | O26: Bình kiềm | T26: 2 | W26: =SUM(P26:V26) -> 2 | X26: =SUMIFS('[1]Đơn giá'!C:C,'[1]Đơn giá'!B:B,[1]XUẤT!O26) -> #VALUE! | Y26: =T26*X26 -> #VALUE! | AA26: Nguyễn Thị Chi | AB26: =W26-V26 -> 2 | AC26: =AB26*5000 -> 10000
B27: 46274 | C27: Chị Xuân | E27: tăng áp | G27: 4 | I27: =H27+G27 -> 4 | J27: Chị Xuân | L27: hoàn thành | M27: Xí nghiệp | N27: Lê Thanh Xuân | O27: Vỉ 500ml | P27: 4 | W27: =SUM(P27:V27) -> 4 | X27: =SUMIFS('[1]Đơn giá'!C:C,'[1]Đơn giá'!B:B,[1]XUẤT!O27) -> #VALUE! | Y27: =X27*P27 -> #VALUE! | AA27: Lê Thanh Xuân | AB27: =W27-V27 -> 4 | AC27: =AB27*5000 -> 20000
A28: 1 | B28: 10/9/2026 | C28: 4 vỉ 500ml vào 315 Cao Xanh. Cửa hàng đt Dũng Tí, 098 4312638 | D28: Vận chuyển | E28: Hồng Gai | G28: 4 | I28: =H28+G28 -> 4 | J28: Tùng + Huế | L28: hoàn thành | M28: Xí nghiệp | N28: Mai Anh Dũng | O28: Vỉ 500ml | P28: 4 | W28: =SUM(P28:V28) -> 4 | X28: =SUMIFS('[1]Đơn giá'!C:C,'[1]Đơn giá'!B:B,[1]XUẤT!O28) -> #VALUE! | Y28: =X28*P28 -> #VALUE! | AA28: Đinh Thu Huế | AB28: =W28-V28 -> 4 | AC28: =AB28*5000 -> 20000
A29: 2 | B29: 10/9/2026 | C29: Tươi Đá Trắng số 19 Ba Đèo, 8 bình ion+ 11 vỉ 500 ml, 0915158863, chở đến điêm gọi chị tươi đến bốc | D29: Vận chuyển | E29: tăng áp | G29: 11 | I29: =H29+G29 -> 11 | J29: Tùng + Huế | M29: Xí nghiệp | N29: Vũ Thị Tươi | O29: Vỉ 500ml | P29: 10 | V29: 1 | W29: =SUM(P29:V29) -> 11 | X29: =SUMIFS('[1]Đơn giá'!C:C,'[1]Đơn giá'!B:B,[1]XUẤT!O29) -> #VALUE! | Y29: =X29*P29 -> #VALUE! | AA29: Vũ Thị Tươi | AB29: =W29-V29 -> 10 | AC29: =AB29*5000 -> 50000
E30: tăng áp | H30: 8 | I30: =H30+G30 -> 8 | J30: Tùng + Huế | M30: Xí nghiệp | N30: Vũ Thị Tươi | O30: Bình kiềm | T30: 7 | V30: 1 | W30: =SUM(P30:V30) -> 8 | X30: =SUMIFS('[1]Đơn giá'!C:C,'[1]Đơn giá'!B:B,[1]XUẤT!O30) -> #VALUE! | Y30: =T30*X30 -> #VALUE! | AA30: Vũ Thị Tươi | AB30: =W30-V30 -> 7 | AC30: =AB30*5000 -> 35000
A31: 3 | B31: 10/9/2026 | C31: 15 bình nước cho hội trường cơ sở 2 cạnh trụ sở liên cơ quan số 4, 0988167724 | D31: Vận chuyển | E31: tăng áp | H31: 15 | I31: =H31+G31 -> 15 | J31: Tùng + Huế | K31: Lại Lan + Chi | L31: hoàn thành | M31: Xí nghiệp | N31: Nguyễn Thị Hiếu | O31: Bình kiềm | T31: 15 | W31: =SUM(P31:V31) -> 15 | X31: =SUMIFS('[1]Đơn giá'!C:C,'[1]Đơn giá'!B:B,[1]XUẤT!O31) -> #VALUE! | Y31: =X31*P31 -> #VALUE! | AA31: Đinh Thu Huế | AB31: =W31-V31 -> 15 | AC31: =AB31*5000 -> 75000
A32: 4 | B32: 10/9/2026 | C32: Thư Tuyền PXD: E ơi ship giúp c 10 vỉ 500ml (980k) + 1 vỉ khuyến mãi đến nhà chú Thắng ở tổ 13 khu phố Hà Trung 2 (ship 10h30) +84972133886. | D32: Vận chuyển | E32: tăng áp | G32: 11 | I32: =H32+G32 -> 11 | J32: Tùng + Huế | L32: hoàn thành | M32: Công ty | N32: Thư Tuyền | O32: Vỉ 500ml | P32: 10 | V32: 1 | W32: =SUM(P32:V32) -> 11 | X32: =SUMIFS('[1]Đơn giá'!C:C,'[1]Đơn giá'!B:B,[1]XUẤT!O32) -> #VALUE! | Y32: =X32*P32 -> #VALUE! | Z32: công ty thu tiền | AA32: Đinh Thu Huế | AB32: =W32-V32 -> 10 | AC32: =AB32*5000 -> 50000 | AD32: CÔNG TY VAY
A33: 5 | B33: 10/9/2026 | C33: chiều 1 đơn karaoke Luxury yết kiêu 30+3 vỉ 500 | D33: Vận chuyển | E33: Hồng Gai | G33: 33 | I33: =H33+G33 -> 33 | J33: Tùng + Huế | K33: trạm Hồng Gai | L33: hoàn thành | M33: Xí nghiệp | N33: Đinh Thu Huế | O33: Vỉ 500ml | P33: 30 | V33: 3 | W33: =SUM(P33:V33) -> 33 | X33: =SUMIFS('[1]Đơn giá'!C:C,'[1]Đơn giá'!B:B,[1]XUẤT!O33) -> #VALUE! | Y33: =X33*P33 -> #VALUE! | AA33: Đinh Thu Huế | AB33: =W33-V33 -> 30 | AC33: =AB33*5000 -> 150000
A34: 6 | B34: 10/9/2026 | C34: 10 vỉ 500ml +1 nc, nhận ở trường dân tộc nội trú, phường Hạ long -0985515202 Phạm việt Hà | D34: Vận chuyển | E34: Văn phòng | G34: 11 | I34: =H34+G34 -> 11 | J34: Chị Vượng + Chi | K34: Trạm Hạ Long | L34: hoàn thành | M34: Diễn Vọng | N34: Chị Hiền Diễn Vọng | O34: Vỉ 500ml | P34: 30 | V34: 3 | W34: =SUM(P34:V34) -> 33 | X34: =SUMIFS('[1]Đơn giá'!C:C,'[1]Đơn giá'!B:B,[1]XUẤT!O34) -> #VALUE! | Y34: =X34*P34 -> #VALUE! | AA34: Trần Trọng Khoa | AB34: =W34-V34 -> 30 | AC34: =AB34*5000 -> 150000 | AD34: DIỄN VỌNG VAY
A35: 7 | B35: 10/9/2026 | C35: Hồng Hạnh P.CN Sân pick Star cạnh nhà hàng Lan Hương có nhu cầu 10+1 vỉ 500ml - 0979748188. SHip luôn | D35: Vận chuyển | E35: tăng áp | G35: 11 | I35: =H35+G35 -> 11 | J35: Lại Lan + Xuân | L35: hoàn thành | M35: Công ty | N35: Hồng Hạnh PCN | O35: Vỉ 500ml | P35: 5 | V35: 1 | W35: =SUM(P35:V35) -> 6 | X35: =SUMIFS('[1]Đơn giá'!C:C,'[1]Đơn giá'!B:B,[1]XUẤT!O35) -> #VALUE! | Y35: =X35*P35 -> #VALUE! | AA35: Lại Thị Lan | AB35: =W35-V35 -> 5 | AC35: =AB35*5000 -> 25000 | AD35: CÔNG TY VAY
E36: tăng áp | P36: 5 | W36: =SUM(P36:V36) -> 5 | X36: 98000 | Y36: =X36*P36 -> 490000 | AA36: Lê Thanh Xuân | AB36: =W36-V36 -> 5 | AC36: =AB36*5000 -> 25000
A37: 8 | B37: 10/9/2026 | C37: Lương Vân Mai bán lẻ | D37: Vận chuyển | E37: Văn phòng | G37: 2 | I37: =H37+G37 -> 2 | J37: Lương Thị Vân Mai | L37: hoàn thành | M37: Xí nghiệp | N37: Lương Thị Vân Mai | O37: Vỉ 500ml | P37: 2 | W37: =SUM(P37:V37) -> 2 | X37: =SUMIFS('[1]Đơn giá'!C:C,'[1]Đơn giá'!B:B,[1]XUẤT!O37) -> #VALUE! | Y37: =X37*P37 -> #VALUE! | AA37: Lương Thị Vân Mai | AB37: =W37-V37 -> 2 | AC37: =AB37*5000 -> 10000
A38: 9 | B38: 10/9/2026 | C38: Đơn bốc nước của Công ty 22 bình đến Đảng ủy phường Hạ Long | D38: Bốc xếp | E38: Cẩm Phả | H38: 22 | I38: =H38+G38 -> 22 | J38: 5 ghi số trạm Hạ Long và Liễu, Xuân | K38: Hạ Long | L38: hoàn thành | M38: Công ty | N38: Nguyễn Thị Chi | O38: Bình kiềm | T38: 20 | V38: 2 | W38: =SUM(P38:V38) -> 22 | X38: =SUMIFS('[1]Đơn giá'!C:C,'[1]Đơn giá'!B:B,[1]XUẤT!O38) -> #VALUE! | Y38: =T38*X38 -> #VALUE! | AA38: Nguyễn Thị Chi | AB38: =W38-V38 -> 20 | AC38: =AB38*5000 -> 100000
A39: 10 | B39: 10/9/2026 | C39: Hồng Hạnh PCN: 0852091985 khách hàng có nhu cầu ngay 20+2 vỉ 350 ml (cần ngay) đến 32 Phan Đăng Lưu, thu tiền luôn | D39: Vận chuyển | E39: Hồng Gai | G39: 22 | I39: =H39+G39 -> 22 | J39: Tùng + Huế | L39: hoàn thành | M39: Công ty | N39: Hồng Hạnh PCN | O39: Vỉ 500ml | Q39: 10 | V39: 2 | W39: =SUM(P39:V39) -> 12 | X39: 85000 | Y39: =Q39*X39 -> 850000 | Z39: TM11/9 | AA39: Đinh Thu Huế | AB39: =W39-V39 -> 10 | AC39: =AB39*5000 -> 50000 | AD39: CÔNG TY VAY
E40: Hồng Gai | M40: Công ty | O40: Vỉ 500ml | Q40: 10 | W40: =SUM(P40:V40) -> 10 | X40: 85000 | Y40: =Q40*X40 -> 850000 | Z40: TM11/9 | AA40: Đỗ Thị Vượng | AB40: =W40-V40 -> 10 | AC40: =AB40*5000 -> 50000
A41: 11 | B41: 10/9/2026 | C41: Chiị Bùi Thu lấy 8 vỉ ship ngã 3 thành công | D41: Vận chuyển | E41: Hồng Gai | G41: 8 | I41: =H41+G41 -> 8 | J41: Bùi Thị Thu | L41: hoàn thành | M41: Xí nghiệp | N41: Bùi Thị Thu | O41: Vỉ 500ml | P41: 8 | W41: =SUM(P41:V41) -> 8 | X41: =SUMIFS('[1]Đơn giá'!C:C,'[1]Đơn giá'!B:B,[1]XUẤT!O41) -> #VALUE! | Y41: =X41*P41 -> #VALUE! | AA41: Bùi Thị Thu | AB41: =W41-V41 -> 8 | AC41: =AB41*5000 -> 40000
...

Sheet CBCNV
A1: TT | B1: Họ và Tên | C1: Chức vụ | D1: Tổ/Trạm | E1: Sản phẩm
E2: Vỉ 500ml | G2: Vỉ 350ml | I2: Hộp 500ml | K2: Hộp 350ml | M2: Bình kiềm | O2: Bình RO
E3: Số lượng | F3: Thành tiền | G3: Số lượng | H3: Thành tiền | I3: Số lượng | J3: Thành tiền | K3: Số lượng | L3: Thành tiền | M3: Số lượng | N3: Thành tiền | O3: Số lượng | P3: Thành tiền | Q3: Xí nghiệp
B4: Cộng | E4: =SUM(E7:E200) -> 545 | F4: =SUM(F7:F200) -> 53410000 | G4: =SUM(G7:G200) -> 39 | H4: =SUM(H7:H200) -> 3315000 | I4: =SUM(I7:I200) -> 10 | J4: =SUM(J7:J200) -> 930000 | K4: =SUM(K7:K200) -> 6 | L4: =SUM(L7:L200) -> 636000 | ... P4: =SUM(P7:P200) -> 1968000
B5: Kiểm tra | E5: =SUMIFS(XUẤT!P:P,XUẤT!$M:$M,CBCNV!$Q$3)-E4 -> 0 | G5: =SUMIFS(XUẤT!Q:Q,XUẤT!M:M,CBCNV!$Q$3)-CBCNV!G4 -> 0 | I5: =SUMIFS(XUẤT!R:R,XUẤT!$M:$M,CBCNV!$Q$3)-CBCNV!I4 -> 0 | K5: =SUMIFS(XUẤT!S:S,XUẤT!M:M,CBCNV!$Q$3)-CBCNV!K4 -> 0 | M5: =SUMIFS(XUẤT!T:T,XUẤT!M:M,CBCNV!$Q$3)-CBCNV!M4 -> -20 | O5: =SUMIFS(XUẤT!U:U,XUẤT!M:M,CBCNV!$Q$3)-CBCNV!O4 -> 0
A7: 1 | B7: Trần Nam Trung | C7: Giám đốc | D7: Văn phòng | E7: =SUMIFS(XUẤT!P:P,XUẤT!N:N,CBCNV!B7,XUẤT!O:O,CBCNV!$E$2) -> 0 | F7: =E7*$T$10 -> 0 | G7: =SUMIFS(XUẤT!Q:Q,XUẤT!N:N,CBCNV!B7,XUẤT!O:O,CBCNV!$G$2) -> 0 | H7: =G7*$T$8 -> 0 | I7: =SUMIFS(XUẤT!R:R,XUẤT!N:N,CBCNV!B7,XUẤT!O:O,CBCNV!$I$2) -> 0 | J7: =I7*$T$9 -> 0 | K7: =SUMIFS(XUẤT!S:S,XUẤT!N:N,CBCNV!B7,XUẤT!O:O,CBCNV!$K$2) -> 0 | L7: =K7*$T$11 -> 0 | M7: =SUMIFS(XUẤT!T:T,XUẤT!N:N,CBCNV!B7,XUẤT!O:O,CBCNV!$M$2) -> 0 | N7: =M7*$T$12 -> 0 | O7: =SUMIFS(XUẤT!U:U,XUẤT!N:N,CBCNV!B7,XUẤT!O:O,CBCNV!$O$2) -> 0 | P7: =O7*$T$13 -> 0 | R7: STT | S7: Hàng hóa | T7: Giá bán
A8: 2 | B8: Đỗ Văn Cảnh | C8: P. Giám đốc | D8: Văn phòng | E8: =SUMIFS(XUẤT!P:P,XUẤT!N:N,CBCNV!B8,XUẤT!O:O,CBCNV!$E$2) -> 0 | F8: =E8*$T$10 -> 0 | G8: =SUMIFS(XUẤT!Q:Q,XUẤT!N:N,CBCNV!B8,XUẤT!O:O,CBCNV!$G$2) -> 0 | H8: =G8*$T$8 -> 0 | I8: =SUMIFS(XUẤT!R:R,XUẤT!N:N,CBCNV!B8,XUẤT!O:O,CBCNV!$I$2) -> 0 | J8: =I8*$T$9 -> 0 | K8: =SUMIFS(XUẤT!S:S,XUẤT!N:N,CBCNV!B8,XUẤT!O:O,CBCNV!$K$2) -> 0 | L8: =K8*$T$11 -> 0 | M8: =SUMIFS(XUẤT!T:T,XUẤT!N:N,CBCNV!B8,XUẤT!O:O,CBCNV!$M$2) -> 0 | N8: =M8*$T$12 -> 0 | O8: =SUMIFS(XUẤT!U:U,XUẤT!N:N,CBCNV!B8,XUẤT!O:O,CBCNV!$O$2) -> 0 | P8: =O8*$T$13 -> 0 | R8: 1 | S8: Vỉ 350ml | T8: 85000
A9: 3 | B9: Phạm Quang Tâm | C9: P. Giám Đốc | D9: Văn phòng | E9: =SUMIFS(XUẤT!P:P,XUẤT!N:N,CBCNV!B9,XUẤT!O:O,CBCNV!$E$2) -> 0 | F9: =E9*$T$10 -> 0 | G9: =SUMIFS(XUẤT!Q:Q,XUẤT!N:N,CBCNV!B9,XUẤT!O:O,CBCNV!$G$2) -> 0 | H9: =G9*$T$8 -> 0 | I9: =SUMIFS(XUẤT!R:R,XUẤT!N:N,CBCNV!B9,XUẤT!O:O,CBCNV!$I$2) -> 0 | J9: =I9*$T$9 -> 0 | K9: =SUMIFS(XUẤT!S:S,XUẤT!N:N,CBCNV!B9,XUẤT!O:O,CBCNV!$K$2) -> 0 | L9: =K9*$T$11 -> 0 | M9: =SUMIFS(XUẤT!T:T,XUẤT!N:N,CBCNV!B9,XUẤT!O:O,CBCNV!$M$2) -> 0 | N9: =M9*$T$12 -> 0 | O9: =SUMIFS(XUẤT!U:U,XUẤT!N:N,CBCNV!B9,XUẤT!O:O,CBCNV!$O$2) -> 0 | P9: =O9*$T$13 -> 0 | R9: 2 | S9: Hộp 500ml | T9: 93000
A10: 4 | B10: Vũ Thị Mai Huệ | C10: P. Giám Đốc | D10: Văn phòng | E10: =SUMIFS(XUẤT!P:P,XUẤT!N:N,CBCNV!B10,XUẤT!O:O,CBCNV!$E$2) -> 0 | F10: =E10*$T$10 -> 0 | G10: =SUMIFS(XUẤT!Q:Q,XUẤT!N:N,CBCNV!B10,XUẤT!O:O,CBCNV!$G$2) -> 0 | H10: =G10*$T$8 -> 0 | I10: =SUMIFS(XUẤT!R:R,XUẤT!N:N,CBCNV!B10,XUẤT!O:O,CBCNV!$I$2) -> 0 | J10: =I10*$T$9 -> 0 | K10: =SUMIFS(XUẤT!S:S,XUẤT!N:N,CBCNV!B10,XUẤT!O:O,CBCNV!$K$2) -> 0 | L10: =K10*$T$11 -> 0 | M10: =SUMIFS(XUẤT!T:T,XUẤT!N:N,CBCNV!B10,XUẤT!O:O,CBCNV!$M$2) -> 0 | N10: =M10*$T$12 -> 0 | O10: =SUMIFS(XUẤT!U:U,XUẤT!N:N,CBCNV!B10,XUẤT!O:O,CBCNV!$O$2) -> 0 | P10: =O10*$T$13 -> 0 | R10: 3 | S10: Vỉ 500ml | T10: 98000
A11: 5 | B11: Phạm Phương Dung | C11: TBP. Kinh doanh | D11: Văn phòng | E11: =SUMIFS(XUẤT!P:P,XUẤT!N:N,CBCNV!B11,XUẤT!O:O,CBCNV!$E$2) -> 2 | F11: =E11*$T$10 -> 196000 | G11: =SUMIFS(XUẤT!Q:Q,XUẤT!N:N,CBCNV!B11,XUẤT!O:O,CBCNV!$G$2) -> 5 | H11: =G11*$T$8 -> 425000 | I11: =SUMIFS(XUẤT!R:R,XUẤT!N:N,CBCNV!B11,XUẤT!O:O,CBCNV!$I$2) -> 0 | J11: =I11*$T$9 -> 0 | K11: =SUMIFS(XUẤT!S:S,XUẤT!N:N,CBCNV!B11,XUẤT!O:O,CBCNV!$K$2) -> 0 | L11: =K11*$T$11 -> 0 | M11: =SUMIFS(XUẤT!T:T,XUẤT!N:N,CBCNV!B11,XUẤT!O:O,CBCNV!$M$2) -> 0 | N11: =M11*$T$12 -> 0 | O11: =SUMIFS(XUẤT!U:U,XUẤT!N:N,CBCNV!B11,XUẤT!O:O,CBCNV!$O$2) -> 0 | P11: =O11*$T$13 -> 0 | R11: 4 | S11: Hộp 350ml | T11: 106000
A12: 6 | B12: Lại Thị Lan | C12: NV kinh doanh | D12: Văn phòng | E12: =SUMIFS(XUẤT!P:P,XUẤT!N:N,CBCNV!B12,XUẤT!O:O,CBCNV!$E$2) -> 2 | F12: =E12*$T$10 -> 196000 | G12: =SUMIFS(XUẤT!Q:Q,XUẤT!N:N,CBCNV!B12,XUẤT!O:O,CBCNV!$G$2) -> 0 | H12: =G12*$T$8 -> 0 | I12: =SUMIFS(XUẤT!R:R,XUẤT!N:N,CBCNV!B12,XUẤT!O:O,CBCNV!$I$2) -> 0 | J12: =I12*$T$9 -> 0 | K12: =SUMIFS(XUẤT!S:S,XUẤT!N:N,CBCNV!B12,XUẤT!O:O,CBCNV!$K$2) -> 0 | L12: =K12*$T$11 -> 0 | M12: =SUMIFS(XUẤT!T:T,XUẤT!N:N,CBCNV!B12,XUẤT!O:O,CBCNV!$M$2) -> 3 | N12: =M12*$T$12 -> 156000 | O12: =SUMIFS(XUẤT!U:U,XUẤT!N:N,CBCNV!B12,XUẤT!O:O,CBCNV!$O$2) -> 0 | P12: =O12*$T$13 -> 0 | R12: 5 | S12: Bình kiềm | T12: 52000
A13: 7 | B13: Nguyễn Huyền Thư | C13: NV kinh doanh | D13: Văn phòng | E13: =SUMIFS(XUẤT!P:P,XUẤT!N:N,CBCNV!B13,XUẤT!O:O,CBCNV!$E$2) -> 0 | F13: =E13*$T$10 -> 0 | G13: =SUMIFS(XUẤT!Q:Q,XUẤT!N:N,CBCNV!B13,XUẤT!O:O,CBCNV!$G$2) -> 0 | H13: =G13*$T$8 -> 0 | I13: =SUMIFS(XUẤT!R:R,XUẤT!N:N,CBCNV!B13,XUẤT!O:O,CBCNV!$I$2) -> 0 | J13: =I13*$T$9 -> 0 | K13: =SUMIFS(XUẤT!S:S,XUẤT!N:N,CBCNV!B13,XUẤT!O:O,CBCNV!$K$2) -> 0 | L13: =K13*$T$11 -> 0 | M13: =SUMIFS(XUẤT!T:T,XUẤT!N:N,CBCNV!B13,XUẤT!O:O,CBCNV!$M$2) -> 0 | N13: =M13*$T$12 -> 0 | O13: =SUMIFS(XUẤT!U:U,XUẤT!N:N,CBCNV!B13,XUẤT!O:O,CBCNV!$O$2) -> 0 | P13: =O13*$T$13 -> 0 | R13: 6 | S13: Bình RO | T13: 48000
A14: 8 | B14: Đoàn Thị Nhung | C14: NV kinh doanh | D14: Văn phòng | E14: =SUMIFS(XUẤT!P:P,XUẤT!N:N,CBCNV!B14,XUẤT!O:O,CBCNV!$E$2) -> 4 | F14: =E14*$T$10 -> 392000 | G14: =SUMIFS(XUẤT!Q:Q,XUẤT!N:N,CBCNV!B14,XUẤT!O:O,CBCNV!$G$2) -> 0 | H14: =G14*$T$8 -> 0 | I14: =SUMIFS(XUẤT!R:R,XUẤT!N:N,CBCNV!B14,XUẤT!O:O,CBCNV!$I$2) -> 0 | J14: =I14*$T$9 -> 0 | K14: =SUMIFS(XUẤT!S:S,XUẤT!N:N,CBCNV!B14,XUẤT!O:O,CBCNV!$K$2) -> 0 | L14: =K14*$T$11 -> 0 | M14: =SUMIFS(XUẤT!T:T,XUẤT!N:N,CBCNV!B14,XUẤT!O:O,CBCNV!$M$2) -> 0 | N14: =M14*$T$12 -> 0 | O14: =SUMIFS(XUẤT!U:U,XUẤT!N:N,CBCNV!B14,XUẤT!O:O,CBCNV!$O$2) -> 0 | P14: =O14*$T$13 -> 0
A15: 9 | B15: Phạm Thị Thu (A) | C15: NV kinh doanh | D15: Văn phòng | E15: =SUMIFS(XUẤT!P:P,XUẤT!N:N,CBCNV!B15,XUẤT!O:O,CBCNV!$E$2) -> 0 | F15: =E15*$T$10 -> 0 | G15: =SUMIFS(XUẤT!Q:Q,XUẤT!N:N,CBCNV!B15,XUẤT!O:O,CBCNV!$G$2) -> 0 | H15: =G15*$T$8 -> 0 | I15: =SUMIFS(XUẤT!R:R,XUẤT!N:N,CBCNV!B15,XUẤT!O:O,CBCNV!$I$2) -> 0 | J15: =I15*$T$9 -> 0 | K15: =SUMIFS(XUẤT!S:S,XUẤT!N:N,CBCNV!B15,XUẤT!O:O,CBCNV!$K$2) -> 0 | L15: =K15*$T$11 -> 0 | M15: =SUMIFS(XUẤT!T:T,XUẤT!N:N,CBCNV!B15,XUẤT!O:O,CBCNV!$M$2) -> 0 | N15: =M15*$T$12 -> 0 | O15: =SUMIFS(XUẤT!U:U,XUẤT!N:N,CBCNV!B15,XUẤT!O:O,CBCNV!$O$2) -> 0 | P15: =O15*$T$13 -> 0
A16: 10 | B16: Trương Thị Hải Yến | C16: NV kinh doanh | D16: Văn phòng | E16: =SUMIFS(XUẤT!P:P,XUẤT!N:N,CBCNV!B16,XUẤT!O:O,CBCNV!$E$2) -> 20 | F16: =E16*$T$10 -> 1960000 | G16: =SUMIFS(XUẤT!Q:Q,XUẤT!N:N,CBCNV!B16,XUẤT!O:O,CBCNV!$G$2) -> 0 | H16: =G16*$T$8 -> 0 | I16: =SUMIFS(XUẤT!R:R,XUẤT!N:N,CBCNV!B16,XUẤT!O:O,CBCNV!$I$2) -> 0 | J16: =I16*$T$9 -> 0 | K16: =SUMIFS(XUẤT!S:S,XUẤT!N:N,CBCNV!B16,XUẤT!O:O,CBCNV!$K$2) -> 0 | L16: =K16*$T$11 -> 0 | M16: =SUMIFS(XUẤT!T:T,XUẤT!N:N,CBCNV!B16,XUẤT!O:O,CBCNV!$M$2) -> 0 | N16: =M16*$T$12 -> 0 | O16: =SUMIFS(XUẤT!U:U,XUẤT!N:N,CBCNV!B16,XUẤT!O:O,CBCNV!$O$2) -> 4 | P16: =O16*$T$13 -> 192000
A17: 11 | B17: Lương Minh Hương | C17: NV kinh doanh | D17: Văn phòng | E17: =SUMIFS(XUẤT!P:P,XUẤT!N:N,CBCNV!B17,XUẤT!O:O,CBCNV!$E$2) -> 10 | F17: =E17*$T$10 -> 980000 | G17: =SUMIFS(XUẤT!Q:Q,XUẤT!N:N,CBCNV!B17,XUẤT!O:O,CBCNV!$G$2) -> 0 | H17: =G17*$T$8 -> 0 | I17: =SUMIFS(XUẤT!R:R,XUẤT!N:N,CBCNV!B17,XUẤT!O:O,CBCNV!$I$2) -> 0 | J17: =I17*$T$9 -> 0 | K17: =SUMIFS(XUẤT!S:S,XUẤT!N:N,CBCNV!B17,XUẤT!O:O,CBCNV!$K$2) -> 6 | L17: =K17*$T$11 -> 636000 | M17: =SUMIFS(XUẤT!T:T,XUẤT!N:N,CBCNV!B17,XUẤT!O:O,CBCNV!$M$2) -> 6 | N17: =M17*$T$12 -> 312000 | O17: =SUMIFS(XUẤT!U:U,XUẤT!N:N,CBCNV!B17,XUẤT!O:O,CBCNV!$O$2) -> 9 | P17: =O17*$T$13 -> 432000
A18: 12 | B18: Hoàng Hồng Nhung | C18: NV kinh doanh | D18: Văn phòng | E18: =SUMIFS(XUẤT!P:P,XUẤT!N:N,CBCNV!B18,XUẤT!O:O,CBCNV!$E$2) -> 0 | F18: =E18*$T$10 -> 0 | G18: =SUMIFS(XUẤT!Q:Q,XUẤT!N:N,CBCNV!B18,XUẤT!O:O,CBCNV!$G$2) -> 0 | H18: =G18*$T$8 -> 0 | I18: =SUMIFS(XUẤT!R:R,XUẤT!N:N,CBCNV!B18,XUẤT!O:O,CBCNV!$I$2) -> 0 | J18: =I18*$T$9 -> 0 | K18: =SUMIFS(XUẤT!S:S,XUẤT!N:N,CBCNV!B18,XUẤT!O:O,CBCNV!$K$2) -> 0 | L18: =K18*$T$11 -> 0 | M18: =SUMIFS(XUẤT!T:T,XUẤT!N:N,CBCNV!B18,XUẤT!O:O,CBCNV!$M$2) -> 0 | N18: =M18*$T$12 -> 0 | O18: =SUMIFS(XUẤT!U:U,XUẤT!N:N,CBCNV!B18,XUẤT!O:O,CBCNV!$O$2) -> 0 | P18: =O18*$T$13 -> 0
A19: 13 | B19: Nguyễn Phương Thảo | C19: NV kinh doanh | D19: Văn phòng | E19: =SUMIFS(XUẤT!P:P,XUẤT!N:N,CBCNV!B19,XUẤT!O:O,CBCNV!$E$2) -> 0 | F19: =E19*$T$10 -> 0 | G19: =SUMIFS(XUẤT!Q:Q,XUẤT!N:N,CBCNV!B19,XUẤT!O:O,CBCNV!$G$2) -> 0 | H19: =G19*$T$8 -> 0 | I19: =SUMIFS(XUẤT!R:R,XUẤT!N:N,CBCNV!B19,XUẤT!O:O,CBCNV!$I$2) -> 0 | J19: =I19*$T$9 -> 0 | K19: =SUMIFS(XUẤT!S:S,XUẤT!N:N,CBCNV!B19,XUẤT!O:O,CBCNV!$K$2) -> 0 | L19: =K19*$T$11 -> 0 | M19: =SUMIFS(XUẤT!T:T,XUẤT!N:N,CBCNV!B19,XUẤT!O:O,CBCNV!$M$2) -> 0 | N19: =M19*$T$12 -> 0 | O19: =SUMIFS(XUẤT!U:U,XUẤT!N:N,CBCNV!B19,XUẤT!O:O,CBCNV!$O$2) -> 0 | P19: =O19*$T$13 -> 0
A20: 14 | B20: Phạm Thị Đan Thanh | C20: NV kinh doanh | D20: Văn phòng | E20: =SUMIFS(XUẤT!P:P,XUẤT!N:N,CBCNV!B20,XUẤT!O:O,CBCNV!$E$2) -> 10 | F20: =E20*$T$10 -> 980000 | G20: =SUMIFS(XUẤT!Q:Q,XUẤT!N:N,CBCNV!B20,XUẤT!O:O,CBCNV!$G$2) -> 0 | H20: =G20*$T$8 -> 0 | I20: =SUMIFS(XUẤT!R:R,XUẤT!N:N,CBCNV!B20,XUẤT!O:O,CBCNV!$I$2) -> 0 | J20: =I20*$T$9 -> 0 | K20: =SUMIFS(XUẤT!S:S,XUẤT!N:N,CBCNV!B20,XUẤT!O:O,CBCNV!$K$2) -> 0 | L20: =K20*$T$11 -> 0 | M20: =SUMIFS(XUẤT!T:T,XUẤT!N:N,CBCNV!B20,XUẤT!O:O,CBCNV!$M$2) -> 0 | N20: =M20*$T$12 -> 0 | O20: =SUMIFS(XUẤT!U:U,XUẤT!N:N,CBCNV!B20,XUẤT!O:O,CBCNV!$O$2) -> 0 | P20: =O20*$T$13 -> 0
A21: 15 | B21: Phan Hồng Hạnh | C21: NV kinh doanh | D21: Văn phòng | E21: =SUMIFS(XUẤT!P:P,XUẤT!N:N,CBCNV!B21,XUẤT!O:O,CBCNV!$E$2) -> 13 | F21: =E21*$T$10 -> 1274000 | G21: =SUMIFS(XUẤT!Q:Q,XUẤT!N:N,CBCNV!B21,XUẤT!O:O,CBCNV!$G$2) -> 0 | H21: =G21*$T$8 -> 0 | I21: =SUMIFS(XUẤT!R:R,XUẤT!N:N,CBCNV!B21,XUẤT!O:O,CBCNV!$I$2) -> 0 | J21: =I21*$T$9 -> 0 | K21: =SUMIFS(XUẤT!S:S,XUẤT!N:N,CBCNV!B21,XUẤT!O:O,CBCNV!$K$2) -> 0 | L21: =K21*$T$11 -> 0 | M21: =SUMIFS(XUẤT!T:T,XUẤT!N:N,CBCNV!B21,XUẤT!O:O,CBCNV!$M$2) -> 0 | N21: =M21*$T$12 -> 0 | O21: =SUMIFS(XUẤT!U:U,XUẤT!N:N,CBCNV!B21,XUẤT!O:O,CBCNV!$O$2) -> 0 | P21: =O21*$T$13 -> 0
A22: 16 | B22: Đỗ Thị Liễu | C22: CN kẹp chì | D22: Văn phòng | E22: =SUMIFS(XUẤT!P:P,XUẤT!N:N,CBCNV!B22,XUẤT!O:O,CBCNV!$E$2) -> 1 | F22: =E22*$T$10 -> 98000 | G22: =SUMIFS(XUẤT!Q:Q,XUẤT!N:N,CBCNV!B22,XUẤT!O:O,CBCNV!$G$2) -> 0 | H22: =G22*$T$8 -> 0 | I22: =SUMIFS(XUẤT!R:R,XUẤT!N:N,CBCNV!B22,XUẤT!O:O,CBCNV!$I$2) -> 10 | J22: =I22*$T$9 -> 930000 | K22: =SUMIFS(XUẤT!S:S,XUẤT!N:N,CBCNV!B22,XUẤT!O:O,CBCNV!$K$2) -> 0 | L22: =K22*$T$11 -> 0 | M22: =SUMIFS(XUẤT!T:T,XUẤT!N:N,CBCNV!B22,XUẤT!O:O,CBCNV!$M$2) -> 0 | N22: =M22*$T$12 -> 0 | O22: =SUMIFS(XUẤT!U:U,XUẤT!N:N,CBCNV!B22,XUẤT!O:O,CBCNV!$O$2) -> 0 | P22: =O22*$T$13 -> 0
A23: 17 | B23: Vũ Hữu Hoàng | C23: CN quản lý | D23: Văn phòng | E23: =SUMIFS(XUẤT!P:P,XUẤT!N:N,CBCNV!B23,XUẤT!O:O,CBCNV!$E$2) -> 0 | F23: =E23*$T$10 -> 0 | G23: =SUMIFS(XUẤT!Q:Q,XUẤT!N:N,CBCNV!B23,XUẤT!O:O,CBCNV!$G$2) -> 0 | H23: =G23*$T$8 -> 0 | I23: =SUMIFS(XUẤT!R:R,XUẤT!N:N,CBCNV!B23,XUẤT!O:O,CBCNV!$I$2) -> 0 | J23: =I23*$T$9 -> 0 | K23: =SUMIFS(XUẤT!S:S,XUẤT!N:N,CBCNV!B23,XUẤT!O:O,CBCNV!$K$2) -> 0 | L23: =K23*$T$11 -> 0 | M23: =SUMIFS(XUẤT!T:T,XUẤT!N:N,CBCNV!B23,XUẤT!O:O,CBCNV!$M$2) -> 0 | N23: =M23*$T$12 -> 0 | O23: =SUMIFS(XUẤT!U:U,XUẤT!N:N,CBCNV!B23,XUẤT!O:O,CBCNV!$O$2) -> 0 | P23: =O23*$T$13 -> 0
A24: 18 | B24: Lê Như Hùng | C24: NV kiểm tra | D24: Văn phòng | E24: =SUMIFS(XUẤT!P:P,XUẤT!N:N,CBCNV!B24,XUẤT!O:O,CBCNV!$E$2) -> 0 | F24: =E24*$T$10 -> 0 | G24: =SUMIFS(XUẤT!Q:Q,XUẤT!N:N,CBCNV!B24,XUẤT!O:O,CBCNV!$G$2) -> 0 | H24: =G24*$T$8 -> 0 | I24: =SUMIFS(XUẤT!R:R,XUẤT!N:N,CBCNV!B24,XUẤT!O:O,CBCNV!$I$2) -> 0 | J24: =I24*$T$9 -> 0 | K24: =SUMIFS(XUẤT!S:S,XUẤT!N:N,CBCNV!B24,XUẤT!O:O,CBCNV!$K$2) -> 0 | L24: =K24*$T$11 -> 0 | M24: =SUMIFS(XUẤT!T:T,XUẤT!N:N,CBCNV!B24,XUẤT!O:O,CBCNV!$M$2) -> 0 | N24: =M24*$T$12 -> 0 | O24: =SUMIFS(XUẤT!U:U,XUẤT!N:N,CBCNV!B24,XUẤT!O:O,CBCNV!$O$2) -> 0 | P24: =O24*$T$13 -> 0
A25: 19 | B25: Vũ Văn Thảo | C25: NV kiểm tra | D25: Văn phòng | E25: =SUMIFS(XUẤT!P:P,XUẤT!N:N,CBCNV!B25,XUẤT!O:O,CBCNV!$E$2) -> 0 | F25: =E25*$T$10 -> 0 | G25: =SUMIFS(XUẤT!Q:Q,XUẤT!N:N,CBCNV!B25,XUẤT!O:O,CBCNV!$G$2) -> 0 | H25: =G25*$T$8 -> 0 | I25: =SUMIFS(XUẤT!R:R,XUẤT!N:N,CBCNV!B25,XUẤT!O:O,CBCNV!$I$2) -> 0 | J25: =I25*$T$9 -> 0 | K25: =SUMIFS(XUẤT!S:S,XUẤT!N:N,CBCNV!B25,XUẤT!O:O,CBCNV!$K$2) -> 0 | L25: =K25*$T$11 -> 0 | M25: =SUMIFS(XUẤT!T:T,XUẤT!N:N,CBCNV!B25,XUẤT!O:O,CBCNV!$M$2) -> 0 | N25: =M25*$T$12 -> 0 | O25: =SUMIFS(XUẤT!U:U,XUẤT!N:N,CBCNV!B25,XUẤT!O:O,CBCNV!$O$2) -> 0 | P25: =O25*$T$13 -> 0
B26: Vũ Thành Long | C26: NVKD | D26: Văn phòng | E26: =SUMIFS(XUẤT!P:P,XUẤT!N:N,CBCNV!B26,XUẤT!O:O,CBCNV!$E$2) -> 5 | F26: =E26*$T$10 -> 490000 | G26: =SUMIFS(XUẤT!Q:Q,XUẤT!N:N,CBCNV!B26,XUẤT!O:O,CBCNV!$G$2) -> 0 | H26: =G26*$T$8 -> 0 | I26: =SUMIFS(XUẤT!R:R,XUẤT!N:N,CBCNV!B26,XUẤT!O:O,CBCNV!$I$2) -> 0 | J26: =I26*$T$9 -> 0 | K26: =SUMIFS(XUẤT!S:S,XUẤT!N:N,CBCNV!B26,XUẤT!O:O,CBCNV!$K$2) -> 0 | L26: =K26*$T$11 -> 0 | M26: =SUMIFS(XUẤT!T:T,XUẤT!N:N,CBCNV!B26,XUẤT!O:O,CBCNV!$M$2) -> 0 | N26: =M26*$T$12 -> 0 | O26: =SUMIFS(XUẤT!U:U,XUẤT!N:N,CBCNV!B26,XUẤT!O:O,CBCNV!$O$2) -> 0 | P26: =O26*$T$13 -> 0
A27: 20 | B27: Trần Thị Thắm | C27: Kế toán chính | D27: Văn phòng | E27: =SUMIFS(XUẤT!P:P,XUẤT!N:N,CBCNV!B27,XUẤT!O:O,CBCNV!$E$2) -> 0 | F27: =E27*$T$10 -> 0 | G27: =SUMIFS(XUẤT!Q:Q,XUẤT!N:N,CBCNV!B27,XUẤT!O:O,CBCNV!$G$2) -> 0 | H27: =G27*$T$8 -> 0 | I27: =SUMIFS(XUẤT!R:R,XUẤT!N:N,CBCNV!B27,XUẤT!O:O,CBCNV!$I$2) -> 0 | J27: =I27*$T$9 -> 0 | K27: =SUMIFS(XUẤT!S:S,XUẤT!N:N,CBCNV!B27,XUẤT!O:O,CBCNV!$K$2) -> 0 | L27: =K27*$T$11 -> 0 | M27: =SUMIFS(XUẤT!T:T,XUẤT!N:N,CBCNV!B27,XUẤT!O:O,CBCNV!$M$2) -> 0 | N27: =M27*$T$12 -> 0 | O27: =SUMIFS(XUẤT!U:U,XUẤT!N:N,CBCNV!B27,XUẤT!O:O,CBCNV!$O$2) -> 0 | P27: =O27*$T$13 -> 0
A28: 21 | B28: Vũ Thị Thúy Phương | C28: NV thủ kho | D28: Văn phòng | E28: =SUMIFS(XUẤT!P:P,XUẤT!N:N,CBCNV!B28,XUẤT!O:O,CBCNV!$E$2) -> 0 | F28: =E28*$T$10 -> 0 | G28: =SUMIFS(XUẤT!Q:Q,XUẤT!N:N,CBCNV!B28,XUẤT!O:O,CBCNV!$G$2) -> 0 | H28: =G28*$T$8 -> 0 | I28: =SUMIFS(XUẤT!R:R,XUẤT!N:N,CBCNV!B28,XUẤT!O:O,CBCNV!$I$2) -> 0 | J28: =I28*$T$9 -> 0 | K28: =SUMIFS(XUẤT!S:S,XUẤT!N:N,CBCNV!B28,XUẤT!O:O,CBCNV!$K$2) -> 0 | L28: =K28*$T$11 -> 0 | M28: =SUMIFS(XUẤT!T:T,XUẤT!N:N,CBCNV!B28,XUẤT!O:O,CBCNV!$M$2) -> 0 | N28: =M28*$T$12 -> 0 | O28: =SUMIFS(XUẤT!U:U,XUẤT!N:N,CBCNV!B28,XUẤT!O:O,CBCNV!$O$2) -> 0 | P28: =O28*$T$13 -> 0
A29: 22 | B29: Lê Hoàng Anh | C29: NV kế toán | D29: Văn phòng | E29: =SUMIFS(XUẤT!P:P,XUẤT!N:N,CBCNV!B29,XUẤT!O:O,CBCNV!$E$2) -> 0 | F29: =E29*$T$10 -> 0 | G29: =SUMIFS(XUẤT!Q:Q,XUẤT!N:N,CBCNV!B29,XUẤT!O:O,CBCNV!$G$2) -> 0 | H29: =G29*$T$8 -> 0 | I29: =SUMIFS(XUẤT!R:R,XUẤT!N:N,CBCNV!B29,XUẤT!O:O,CBCNV!$I$2) -> 0 | J29: =I29*$T$9 -> 0 | K29: =SUMIFS(XUẤT!S:S,XUẤT!N:N,CBCNV!B29,XUẤT!O:O,CBCNV!$K$2) -> 0 | L29: =K29*$T$11 -> 0 | M29: =SUMIFS(XUẤT!T:T,XUẤT!N:N,CBCNV!B29,XUẤT!O:O,CBCNV!$M$2) -> 0 | N29: =M29*$T$12 -> 0 | O29: =SUMIFS(XUẤT!U:U,XUẤT!N:N,CBCNV!B29,XUẤT!O:O,CBCNV!$O$2) -> 0 | P29: =O29*$T$13 -> 0
A30: 23 | B30: Phạm Thị Bích Hằng | C30: NV kế toán | D30: Văn phòng | E30: =SUMIFS(XUẤT!P:P,XUẤT!N:N,CBCNV!B30,XUẤT!O:O,CBCNV!$E$2) -> 0 | F30: =E30*$T$10 -> 0 | G30: =SUMIFS(XUẤT!Q:Q,XUẤT!N:N,CBCNV!B30,XUẤT!O:O,CBCNV!$G$2) -> 0 | H30: =G30*$T$8 -> 0 | I30: =SUMIFS(XUẤT!R:R,XUẤT!N:N,CBCNV!B30,XUẤT!O:O,CBCNV!$I$2) -> 0 | J30: =I30*$T$9 -> 0 | K30: =SUMIFS(XUẤT!S:S,XUẤT!N:N,CBCNV!B30,XUẤT!O:O,CBCNV!$K$2) -> 0 | L30: =K30*$T$11 -> 0 | M30: =SUMIFS(XUẤT!T:T,XUẤT!N:N,CBCNV!B30,XUẤT!O:O,CBCNV!$M$2) -> 0 | N30: =M30*$T$12 -> 0 | O30: =SUMIFS(XUẤT!U:U,XUẤT!N:N,CBCNV!B30,XUẤT!O:O,CBCNV!$O$2) -> 0 | P30: =O30*$T$13 -> 0
A31: 24 | B31: Đỗ Thị Thu Hoàn | C31: NV kế toán | D31: Văn phòng | E31: =SUMIFS(XUẤT!P:P,XUẤT!N:N,CBCNV!B31,XUẤT!O:O,CBCNV!$E$2) -> 0 | F31: =E31*$T$10 -> 0 | G31: =SUMIFS(XUẤT!Q:Q,XUẤT!N:N,CBCNV!B31,XUẤT!O:O,CBCNV!$G$2) -> 0 | H31: =G31*$T$8 -> 0 | I31: =SUMIFS(XUẤT!R:R,XUẤT!N:N,CBCNV!B31,XUẤT!O:O,CBCNV!$I$2) -> 0 | J31: =I31*$T$9 -> 0 | K31: =SUMIFS(XUẤT!S:S,XUẤT!N:N,CBCNV!B31,XUẤT!O:O,CBCNV!$K$2) -> 0 | L31: =K31*$T$11 -> 0 | M31: =SUMIFS(XUẤT!T:T,XUẤT!N:N,CBCNV!B31,XUẤT!O:O,CBCNV!$M$2) -> 0 | N31: =M31*$T$12 -> 0 | O31: =SUMIFS(XUẤT!U:U,XUẤT!N:N,CBCNV!B31,XUẤT!O:O,CBCNV!$O$2) -> 0 | P31: =O31*$T$13 -> 0
A32: 25 | B32: Nguyễn Thị Thu Quyên | C32: NV kế toán | D32: Văn phòng | E32: =SUMIFS(XUẤT!P:P,XUẤT!N:N,CBCNV!B32,XUẤT!O:O,CBCNV!$E$2) -> 0 | F32: =E32*$T$10 -> 0 | G32: =SUMIFS(XUẤT!Q:Q,XUẤT!N:N,CBCNV!B32,XUẤT!O:O,CBCNV!$G$2) -> 0 | H32: =G32*$T$8 -> 0 | I32: =SUMIFS(XUẤT!R:R,XUẤT!N:N,CBCNV!B32,XUẤT!O:O,CBCNV!$I$2) -> 0 | J32: =I32*$T$9 -> 0 | K32: =SUMIFS(XUẤT!S:S,XUẤT!N:N,CBCNV!B32,XUẤT!O:O,CBCNV!$K$2) -> 0 | L32: =K32*$T$11 -> 0 | M32: =SUMIFS(XUẤT!T:T,XUẤT!N:N,CBCNV!B32,XUẤT!O:O,CBCNV!$M$2) -> 0 | N32: =M32*$T$12 -> 0 | O32: =SUMIFS(XUẤT!U:U,XUẤT!N:N,CBCNV!B32,XUẤT!O:O,CBCNV!$O$2) -> 0 | P32: =O32*$T$13 -> 0
A33: 26 | B33: Ngô Thị Vân Anh | C33: PT. Quản trị | D33: Văn phòng | E33: =SUMIFS(XUẤT!P:P,XUẤT!N:N,CBCNV!B33,XUẤT!O:O,CBCNV!$E$2) -> 0 | F33: =E33*$T$10 -> 0 | G33: =SUMIFS(XUẤT!Q:Q,XUẤT!N:N,CBCNV!B33,XUẤT!O:O,CBCNV!$G$2) -> 0 | H33: =G33*$T$8 -> 0 | I33: =SUMIFS(XUẤT!R:R,XUẤT!N:N,CBCNV!B33,XUẤT!O:O,CBCNV!$I$2) -> 0 | J33: =I33*$T$9 -> 0 | K33: =SUMIFS(XUẤT!S:S,XUẤT!N:N,CBCNV!B33,XUẤT!O:O,CBCNV!$K$2) -> 0 | L33: =K33*$T$11 -> 0 | M33: =SUMIFS(XUẤT!T:T,XUẤT!N:N,CBCNV!B33,XUẤT!O:O,CBCNV!$M$2) -> 0 | N33: =M33*$T$12 -> 0 | O33: =SUMIFS(XUẤT!U:U,XUẤT!N:N,CBCNV!B33,XUẤT!O:O,CBCNV!$O$2) -> 0 | P33: =O33*$T$13 -> 0
A34: 27 | B34: Nguyễn Thị Lan | C34: NV Đảng - Đoàn | D34: Văn phòng | E34: =SUMIFS(XUẤT!P:P,XUẤT!N:N,CBCNV!B34,XUẤT!O:O,CBCNV!$E$2) -> 0 | F34: =E34*$T$10 -> 0 | G34: =SUMIFS(XUẤT!Q:Q,XUẤT!N:N,CBCNV!B34,XUẤT!O:O,CBCNV!$G$2) -> 10 | H34: =G34*$T$8 -> 850000 | I34: =SUMIFS(XUẤT!R:R,XUẤT!N:N,CBCNV!B34,XUẤT!O:O,CBCNV!$I$2) -> 0 | J34: =I34*$T$9 -> 0 | K34: =SUMIFS(XUẤT!S:S,XUẤT!N:N,CBCNV!B34,XUẤT!O:O,CBCNV!$K$2) -> 0 | L34: =K34*$T$11 -> 0 | M34: =SUMIFS(XUẤT!T:T,XUẤT!N:N,CBCNV!B34,XUẤT!O:O,CBCNV!$M$2) -> 0 | N34: =M34*$T$12 -> 0 | O34: =SUMIFS(XUẤT!U:U,XUẤT!N:N,CBCNV!B34,XUẤT!O:O,CBCNV!$O$2) -> 0 | P34: =O34*$T$13 -> 0
A35: 28 | B35: Nguyễn Thị Ngọc Chung | C35: Thủ quỹ - HC | D35: Văn phòng | E35: =SUMIFS(XUẤT!P:P,XUẤT!N:N,CBCNV!B35,XUẤT!O:O,CBCNV!$E$2) -> 0 | F35: =E35*$T$10 -> 0 | G35: =SUMIFS(XUẤT!Q:Q,XUẤT!N:N,CBCNV!B35,XUẤT!O:O,CBCNV!$G$2) -> 2 | H35: =G35*$T$8 -> 170000 | I35: =SUMIFS(XUẤT!R:R,XUẤT!N:N,CBCNV!B35,XUẤT!O:O,CBCNV!$I$2) -> 0 | J35: =I35*$T$9 -> 0 | K35: =SUMIFS(XUẤT!S:S,XUẤT!N:N,CBCNV!B35,XUẤT!O:O,CBCNV!$K$2) -> 0 | L35: =K35*$T$11 -> 0 | M35: =SUMIFS(XUẤT!T:T,XUẤT!N:N,CBCNV!B35,XUẤT!O:O,CBCNV!$M$2) -> 0 | N35: =M35*$T$12 -> 0 | O35: =SUMIFS(XUẤT!U:U,XUẤT!N:N,CBCNV!B35,XUẤT!O:O,CBCNV!$O$2) -> 0 | P35: =O35*$T$13 -> 0
A36: 29 | B36: Bùi Thị Diệu Linh | C36: NV LĐTL | D36: Văn phòng | E36: =SUMIFS(XUẤT!P:P,XUẤT!N:N,CBCNV!B36,XUẤT!O:O,CBCNV!$E$2) -> 0 | F36: =E36*$T$10 -> 0 | G36: =SUMIFS(XUẤT!Q:Q,XUẤT!N:N,CBCNV!B36,XUẤT!O:O,CBCNV!$G$2) -> 0 | H36: =G36*$T$8 -> 0 | I36: =SUMIFS(XUẤT!R:R,XUẤT!N:N,CBCNV!B36,XUẤT!O:O,CBCNV!$I$2) -> 0 | J36: =I36*$T$9 -> 0 | K36: =SUMIFS(XUẤT!S:S,XUẤT!N:N,CBCNV!B36,XUẤT!O:O,CBCNV!$K$2) -> 0 | L36: =K36*$T$11 -> 0 | M36: =SUMIFS(XUẤT!T:T,XUẤT!N:N,CBCNV!B36,XUẤT!O:O,CBCNV!$M$2) -> 0 | N36: =M36*$T$12 -> 0 | O36: =SUMIFS(XUẤT!U:U,XUẤT!N:N,CBCNV!B36,XUẤT!O:O,CBCNV!$O$2) -> 0 | P36: =O36*$T$13 -> 0
A37: 30 | B37: Đỗ Thị Hiền | C37: NV LĐTL | D37: Văn phòng | E37: =SUMIFS(XUẤT!P:P,XUẤT!N:N,CBCNV!B37,XUẤT!O:O,CBCNV!$E$2) -> 0 | F37: =E37*$T$10 -> 0 | G37: =SUMIFS(XUẤT!Q:Q,XUẤT!N:N,CBCNV!B37,XUẤT!O:O,CBCNV!$G$2) -> 0 | H37: =G37*$T$8 -> 0 | I37: =SUMIFS(XUẤT!R:R,XUẤT!N:N,CBCNV!B37,XUẤT!O:O,CBCNV!$I$2) -> 0 | J37: =I37*$T$9 -> 0 | K37: =SUMIFS(XUẤT!S:S,XUẤT!N:N,CBCNV!B37,XUẤT!O:O,CBCNV!$K$2) -> 0 | L37: =K37*$T$11 -> 0 | M37: =SUMIFS(XUẤT!T:T,XUẤT!N:N,CBCNV!B37,XUẤT!O:O,CBCNV!$M$2) -> 0 | N37: =M37*$T$12 -> 0 | O37: =SUMIFS(XUẤT!U:U,XUẤT!N:N,CBCNV!B37,XUẤT!O:O,CBCNV!$O$2) -> 0 | P37: =O37*$T$13 -> 0
A38: 31 | B38: Phạm Thu Quỳnh | C38: CN tạp vụ | D38: Văn phòng | E38: =SUMIFS(XUẤT!P:P,XUẤT!N:N,CBCNV!B38,XUẤT!O:O,CBCNV!$E$2) -> 1 | F38: =E38*$T$10 -> 98000 | G38: =SUMIFS(XUẤT!Q:Q,XUẤT!N:N,CBCNV!B38,XUẤT!O:O,CBCNV!$G$2) -> 0 | H38: =G38*$T$8 -> 0 | I38: =SUMIFS(XUẤT!R:R,XUẤT!N:N,CBCNV!B38,XUẤT!O:O,CBCNV!$I$2) -> 0 | J38: =I38*$T$9 -> 0 | K38: =SUMIFS(XUẤT!S:S,XUẤT!N:N,CBCNV!B38,XUẤT!O:O,CBCNV!$K$2) -> 0 | L38: =K38*$T$11 -> 0 | M38: =SUMIFS(XUẤT!T:T,XUẤT!N:N,CBCNV!B38,XUẤT!O:O,CBCNV!$M$2) -> 0 | N38: =M38*$T$12 -> 0 | O38: =SUMIFS(XUẤT!U:U,XUẤT!N:N,CBCNV!B38,XUẤT!O:O,CBCNV!$O$2) -> 0 | P38: =O38*$T$13 -> 0
... A200: 193 | B200: Trần Thị Trinh | C200: CN ghi số | D200: Đá Trắng | E200: =SUMIFS(XUẤT!P:P,XUẤT!N:N,CBCNV!B200,XUẤT!O:O,CBCNV!$E$2) -> 0 | F200: =E200*$T$10 -> 0 | G200: =SUMIFS(XUẤT!Q:Q,XUẤT!N:N,CBCNV!B200,XUẤT!O:O,CBCNV!$G$2) -> 0 | H200: =G200*$T$8 -> 0 | I200: =SUMIFS(XUẤT!R:R,XUẤT!N:N,CBCNV!B200,XUẤT!O:O,CBCNV!$I$2) -> 0 | J200: =I200*$T$9 -> 0 | K200: =SUMIFS(XUẤT!S:S,XUẤT!N:N,CBCNV!B200,XUẤT!O:O,CBCNV!$K$2) -> 0 | L200: =K200*$T$11 -> 0 | M200: =SUMIFS(XUẤT!T:T,XUẤT!N:N,CBCNV!B200,XUẤT!O:O,CBCNV!$M$2) -> 0 | N200: =M200*$T$12 -> 0 | O200: =SUMIFS(XUẤT!U:U,XUẤT!N:N,CBCNV!B200,XUẤT!O:O,CBCNV!$O$2) -> 0 | P200: =O200*$T$13 -> 0

Sheet TỒN
A1: THEO DÕI NHẬP, XUẤT NƯỚC QAROMI
A2: Tháng 9/2026
A4: STT | B4: Ngày | C4: Nhập | J4: Xuất | Q4: Tồn
C5: Vỉ 350ml | D5: Hộp 500ml | E5: Vỉ 500ml | F5: Hộp 350ml | G5: Bình kiềm | H5: Bình RO | I5: Cộng | J5: Vỉ 350ml | K5: Hộp 500ml | L5: Vỉ 500ml | M5: Hộp 350ml | N5: Bình kiềm | O5: Bình RO | P5: Cộng | Q5: Vỉ 350ml | R5: Hộp 500ml | S5: Vỉ 500ml | T5: Hộp 350ml | U5: Bình kiềm | V5: Bình RO | W5: Cộng
A6: 1 | B6: 46266 | J6: =SUMIFS(XUẤT!$W:$W,XUẤT!$B:$B,TỒN!$B$12,XUẤT!$O:$O,TỒN!#REF!) -> 0 | K6: =SUMIFS(XUẤT!$W:$W,XUẤT!$B:$B,TỒN!$B$12,XUẤT!$O:$O,TỒN!#REF!) -> 0 | L6: =SUMIFS(XUẤT!$W:$W,XUẤT!$B:$B,TỒN!$B$12,XUẤT!$O:$O,TỒN!#REF!) -> 0 | M6: =SUMIFS(XUẤT!$W:$W,XUẤT!$B:$B,TỒN!$B$12,XUẤT!$O:$O,TỒN!#REF!) -> 0 | N6: =SUMIFS(XUẤT!$W:$W,XUẤT!$B:$B,TỒN!$B$12,XUẤT!$O:$O,TỒN!#REF!) -> 0 | O6: =SUMIFS(XUẤT!$W:$W,XUẤT!$B:$B,TỒN!$B$12,XUẤT!$O:$O,TỒN!#REF!) -> 0 | P6: =SUM(J6:O6) -> 0
A7: 2 | B7: 46267 | J7: =SUMIFS(XUẤT!$W:$W,XUẤT!$B:$B,TỒN!$B$12,XUẤT!$O:$O,TỒN!#REF!) -> 0 | K7: =SUMIFS(XUẤT!$W:$W,XUẤT!$B:$B,TỒN!$B$12,XUẤT!$O:$O,TỒN!#REF!) -> 0 | L7: =SUMIFS(XUẤT!$W:$W,XUẤT!$B:$B,TỒN!$B$12,XUẤT!$O:$O,TỒN!#REF!) -> 0 | M7: =SUMIFS(XUẤT!$W:$W,XUẤT!$B:$B,TỒN!$B$12,XUẤT!$O:$O,TỒN!#REF!) -> 0 | N7: =SUMIFS(XUẤT!$W:$W,XUẤT!$B:$B,TỒN!$B$12,XUẤT!$O:$O,TỒN!#REF!) -> 0 | O7: =SUMIFS(XUẤT!$W:$W,XUẤT!$B:$B,TỒN!$B$12,XUẤT!$O:$O,TỒN!#REF!) -> 0 | P7: =SUM(J7:O7) -> 0
A8: 3 | B8: 46268 | J8: =SUMIFS(XUẤT!$W:$W,XUẤT!$B:$B,TỒN!$B$12,XUẤT!$O:$O,TỒN!J1) -> 0 | K8: =SUMIFS(XUẤT!$W:$W,XUẤT!$B:$B,TỒN!$B$12,XUẤT!$O:$O,TỒN!K1) -> 0 | L8: =SUMIFS(XUẤT!$W:$W,XUẤT!$B:$B,TỒN!$B$12,XUẤT!$O:$O,TỒN!L1) -> 0 | M8: =SUMIFS(XUẤT!$W:$W,XUẤT!$B:$B,TỒN!$B$12,XUẤT!$O:$O,TỒN!M1) -> 0 | N8: =SUMIFS(XUẤT!$W:$W,XUẤT!$B:$B,TỒN!$B$12,XUẤT!$O:$O,TỒN!N1) -> 0 | O8: =SUMIFS(XUẤT!$W:$W,XUẤT!$B:$B,TỒN!$B$12,XUẤT!$O:$O,TỒN!O1) -> 0 | P8: =SUM(J8:O8) -> 0
A9: 4 | B9: 46269 | J9: =SUMIFS(XUẤT!$W:$W,XUẤT!$B:$B,TỒN!$B$12,XUẤT!$O:$O,TỒN!J2) -> 0 | K9: =SUMIFS(XUẤT!$W:$W,XUẤT!$B:$B,TỒN!$B$12,XUẤT!$O:$O,TỒN!K2) -> 0 | L9: =SUMIFS(XUẤT!$W:$W,XUẤT!$B:$B,TỒN!$B$12,XUẤT!$O:$O,TỒN!L2) -> 0 | M9: =SUMIFS(XUẤT!$W:$W,XUẤT!$B:$B,TỒN!$B$12,XUẤT!$O:$O,TỒN!M2) -> 0 | N9: =SUMIFS(XUẤT!$W:$W,XUẤT!$B:$B,TỒN!$B$12,XUẤT!$O:$O,TỒN!N2) -> 0 | O9: =SUMIFS(XUẤT!$W:$W,XUẤT!$B:$B,TỒN!$B$12,XUẤT!$O:$O,TỒN!O2) -> 0 | P9: =SUM(J9:O9) -> 0
A10: 5 | B10: 46270 | J10: =SUMIFS(XUẤT!$W:$W,XUẤT!$B:$B,TỒN!$B$12,XUẤT!$O:$O,TỒN!J3) -> 0 | K10: =SUMIFS(XUẤT!$W:$W,XUẤT!$B:$B,TỒN!$B$12,XUẤT!$O:$O,TỒN!K3) -> 0 | L10: =SUMIFS(XUẤT!$W:$W,XUẤT!$B:$B,TỒN!$B$12,XUẤT!$O:$O,TỒN!L3) -> 0 | M10: =SUMIFS(XUẤT!$W:$W,XUẤT!$B:$B,TỒN!$B$12,XUẤT!$O:$O,TỒN!M3) -> 0 | N10: =SUMIFS(XUẤT!$W:$W,XUẤT!$B:$B,TỒN!$B$12,XUẤT!$O:$O,TỒN!N3) -> 0 | O10: =SUMIFS(XUẤT!$W:$W,XUẤT!$B:$B,TỒN!$B$12,XUẤT!$O:$O,TỒN!O3) -> 0 | P10: =SUM(J10:O10) -> 0
A11: 6 | B11: 46271 | J11: =SUMIFS(XUẤT!$W:$W,XUẤT!$B:$B,TỒN!$B$12,XUẤT!$O:$O,TỒN!J4) -> 0 | K11: =SUMIFS(XUẤT!$W:$W,XUẤT!$B:$B,TỒN!$B$12,XUẤT!$O:$O,TỒN!K4) -> 0 | L11: =SUMIFS(XUẤT!$W:$W,XUẤT!$B:$B,TỒN!$B$12,XUẤT!$O:$O,TỒN!L4) -> 0 | M11: =SUMIFS(XUẤT!$W:$W,XUẤT!$B:$B,TỒN!$B$12,XUẤT!$O:$O,TỒN!M4) -> 0 | N11: =SUMIFS(XUẤT!$W:$W,XUẤT!$B:$B,TỒN!$B$12,XUẤT!$O:$O,TỒN!N4) -> 0 | O11: =SUMIFS(XUẤT!$W:$W,XUẤT!$B:$B,TỒN!$B$12,XUẤT!$O:$O,TỒN!O4) -> 0 | P11: =SUM(J11:O11) -> 0
A12: 7 | B12: 46272 | J12: =SUMIFS(XUẤT!$W:$W,XUẤT!$B:$B,TỒN!$B$12,XUẤT!$O:$O,TỒN!J5) -> 0 | K12: =SUMIFS(XUẤT!$W:$W,XUẤT!$B:$B,TỒN!$B$12,XUẤT!$O:$O,TỒN!K5) -> 0 | L12: =SUMIFS(XUẤT!$W:$W,XUẤT!$B:$B,TỒN!$B$12,XUẤT!$O:$O,TỒN!L5) -> 0 | M12: =SUMIFS(XUẤT!$W:$W,XUẤT!$B:$B,TỒN!$B$12,XUẤT!$O:$O,TỒN!M5) -> 0 | N12: =SUMIFS(XUẤT!$W:$W,XUẤT!$B:$B,TỒN!$B$12,XUẤT!$O:$O,TỒN!N5) -> 0 | O12: =SUMIFS(XUẤT!$W:$W,XUẤT!$B:$B,TỒN!$B$12,XUẤT!$O:$O,TỒN!O5) -> 0 | P12: =SUM(J12:O12) -> 0
A13: 8 | B13: 46273 | J13: =SUMIFS(XUẤT!$W:$W,XUẤT!$B:$B,TỒN!$B$12,XUẤT!$O:$O,TỒN!J12) -> 0 | K13: =SUMIFS(XUẤT!$W:$W,XUẤT!$B:$B,TỒN!$B$12,XUẤT!$O:$O,TỒN!K12) -> 0 | L13: =SUMIFS(XUẤT!$W:$W,XUẤT!$B:$B,TỒN!$B$12,XUẤT!$O:$O,TỒN!L12) -> 0 | M13: =SUMIFS(XUẤT!$W:$W,XUẤT!$B:$B,TỒN!$B$12,XUẤT!$O:$O,TỒN!M12) -> 0 | N13: =SUMIFS(XUẤT!$W:$W,XUẤT!$B:$B,TỒN!$B$12,XUẤT!$O:$O,TỒN!N12) -> 0 | O13: =SUMIFS(XUẤT!$W:$W,XUẤT!$B:$B,TỒN!$B$12,XUẤT!$O:$O,TỒN!O12) -> 0 | P13: =SUM(J13:O13) -> 0
A14: 9 | B14: 46274 | J14: =SUMIFS(XUẤT!$W:$W,XUẤT!$B:$B,TỒN!$B$12,XUẤT!$O:$O,TỒN!J13) -> 0 | K14: =SUMIFS(XUẤT!$W:$W,XUẤT!$B:$B,TỒN!$B$12,XUẤT!$O:$O,TỒN!K13) -> 0 | L14: =SUMIFS(XUẤT!$W:$W,XUẤT!$B:$B,TỒN!$B$12,XUẤT!$O:$O,TỒN!L13) -> 0 | M14: =SUMIFS(XUẤT!$W:$W,XUẤT!$B:$B,TỒN!$B$12,XUẤT!$O:$O,TỒN!M13) -> 0 | N14: =SUMIFS(XUẤT!$W:$W,XUẤT!$B:$B,TỒN!$B$12,XUẤT!$O:$O,TỒN!N13) -> 0 | O14: =SUMIFS(XUẤT!$W:$W,XUẤT!$B:$B,TỒN!$B$12,XUẤT!$O:$O,TỒN!O13) -> 0 | P14: =SUM(J14:O14) -> 0
A15: 10 | B15: 46275 | J15: =SUMIFS(XUẤT!$W:$W,XUẤT!$B:$B,TỒN!$B$12,XUẤT!$O:$O,TỒN!J14) -> 0 | K15: =SUMIFS(XUẤT!$W:$W,XUẤT!$B:$B,TỒN!$B$12,XUẤT!$O:$O,TỒN!K14) -> 0 | L15: =SUMIFS(XUẤT!$W:$W,XUẤT!$B:$B,TỒN!$B$12,XUẤT!$O:$O,TỒN!L14) -> 0 | M15: =SUMIFS(XUẤT!$W:$W,XUẤT!$B:$B,TỒN!$B$12,XUẤT!$O:$O,TỒN!M14) -> 0 | N15: =SUMIFS(XUẤT!$W:$W,XUẤT!$B:$B,TỒN!$B$12,XUẤT!$O:$O,TỒN!N14) -> 0 | O15: =SUMIFS(XUẤT!$W:$W,XUẤT!$B:$B,TỒN!$B$12,XUẤT!$O:$O,TỒN!O14) -> 0 | P15: =SUM(J15:O15) -> 0
A16: 11 | B16: 46276 | J16: =SUMIFS(XUẤT!$W:$W,XUẤT!$B:$B,TỒN!$B$12,XUẤT!$O:$O,TỒN!J15) -> 0 | K16: =SUMIFS(XUẤT!$W:$W,XUẤT!$B:$B,TỒN!$B$12,XUẤT!$O:$O,TỒN!K15) -> 0 | L16: =SUMIFS(XUẤT!$W:$W,XUẤT!$B:$B,TỒN!$B$12,XUẤT!$O:$O,TỒN!L15) -> 0 | M16: =SUMIFS(XUẤT!$W:$W,XUẤT!$B:$B,TỒN!$B$12,XUẤT!$O:$O,TỒN!M15) -> 0 | N16: =SUMIFS(XUẤT!$W:$W,XUẤT!$B:$B,TỒN!$B$12,XUẤT!$O:$O,TỒN!N15) -> 0 | O16: =SUMIFS(XUẤT!$W:$W,XUẤT!$B:$B,TỒN!$B$12,XUẤT!$O:$O,TỒN!O15) -> 0 | P16: =SUM(J16:O16) -> 0
A17: 12 | B17: 46277 | J17: =SUMIFS(XUẤT!$W:$W,XUẤT!$B:$B,TỒN!$B$12,XUẤT!$O:$O,TỒN!J16) -> 0 | K17: =SUMIFS(XUẤT!$W:$W,XUẤT!$B:$B,TỒN!$B$12,XUẤT!$O:$O,TỒN!K16) -> 0 | L17: =SUMIFS(XUẤT!$W:$W,XUẤT!$B:$B,TỒN!$B$12,XUẤT!$O:$O,TỒN!L16) -> 0 | M17: =SUMIFS(XUẤT!$W:$W,XUẤT!$B:$B,TỒN!$B$12,XUẤT!$O:$O,TỒN!M16) -> 0 | N17: =SUMIFS(XUẤT!$W:$W,XUẤT!$B:$B,TỒN!$B$12,XUẤT!$O:$O,TỒN!N16) -> 0 | O17: =SUMIFS(XUẤT!$W:$W,XUẤT!$B:$B,TỒN!$B$12,XUẤT!$O:$O,TỒN!O16) -> 0 | P17: =SUM(J17:O17) -> 0
A18: 13 | B18: 46278 | J18: =SUMIFS(XUẤT!$W:$W,XUẤT!$B:$B,TỒN!$B$12,XUẤT!$O:$O,TỒN!J17) -> 0 | K18: =SUMIFS(XUẤT!$W:$W,XUẤT!$B:$B,TỒN!$B$12,XUẤT!$O:$O,TỒN!K17) -> 0 | L18: =SUMIFS(XUẤT!$W:$W,XUẤT!$B:$B,TỒN!$B$12,XUẤT!$O:$O,TỒN!L17) -> 0 | M18: =SUMIFS(XUẤT!$W:$W,XUẤT!$B:$B,TỒN!$B$12,XUẤT!$O:$O,TỒN!M17) -> 0 | N18: =SUMIFS(XUẤT!$W:$W,XUẤT!$B:$B,TỒN!$B$12,XUẤT!$O:$O,TỒN!N17) -> 0 | O18: =SUMIFS(XUẤT!$W:$W,XUẤT!$B:$B,TỒN!$B$12,XUẤT!$O:$O,TỒN!O17) -> 0 | P18: =SUM(J18:O18) -> 0
A19: 14 | B19: 46279 | J19: =SUMIFS(XUẤT!$W:$W,XUẤT!$B:$B,TỒN!$B$12,XUẤT!$O:$O,TỒN!J18) -> 0 | K19: =SUMIFS(XUẤT!$W:$W,XUẤT!$B:$B,TỒN!$B$12,XUẤT!$O:$O,TỒN!K18) -> 0 | L19: =SUMIFS(XUẤT!$W:$W,XUẤT!$B:$B,TỒN!$B$12,XUẤT!$O:$O,TỒN!L18) -> 0 | M19: =SUMIFS(XUẤT!$W:$W,XUẤT!$B:$B,TỒN!$B$12,XUẤT!$O:$O,TỒN!M18) -> 0 | N19: =SUMIFS(XUẤT!$W:$W,XUẤT!$B:$B,TỒN!$B$12,XUẤT!$O:$O,TỒN!N18) -> 0 | O19: =SUMIFS(XUẤT!$W:$W,XUẤT!$B:$B,TỒN!$B$12,XUẤT!$O:$O,TỒN!O18) -> 0 | P19: =SUM(J19:O19) -> 0
A20: 15 | B20: 46280 | J20: =SUMIFS(XUẤT!$W:$W,XUẤT!$B:$B,TỒN!$B$12,XUẤT!$O:$O,TỒN!J19) -> 0 | K20: =SUMIFS(XUẤT!$W:$W,XUẤT!$B:$B,TỒN!$B$12,XUẤT!$O:$O,TỒN!K19) -> 0 | L20: =SUMIFS(XUẤT!$W:$W,XUẤT!$B:$B,TỒN!$B$12,XUẤT!$O:$O,TỒN!L19) -> 0 | M20: =SUMIFS(XUẤT!$W:$W,XUẤT!$B:$B,TỒN!$B$12,XUẤT!$O:$O,TỒN!M19) -> 0 | N20: =SUMIFS(XUẤT!$W:$W,XUẤT!$B:$B,TỒN!$B$12,XUẤT!$O:$O,TỒN!N19) -> 0 | O20: =SUMIFS(XUẤT!$W:$W,XUẤT!$B:$B,TỒN!$B$12,XUẤT!$O:$O,TỒN!O19) -> 0 | P20: =SUM(J20:O20) -> 0
A21: 16 | B21: 46281 | J21: =SUMIFS(XUẤT!$W:$W,XUẤT!$B:$B,TỒN!$B$12,XUẤT!$O:$O,TỒN!J20) -> 0 | K21: =SUMIFS(XUẤT!$W:$W,XUẤT!$B:$B,TỒN!$B$12,XUẤT!$O:$O,TỒN!K20) -> 0 | L21: =SUMIFS(XUẤT!$W:$W,XUẤT!$B:$B,TỒN!$B$12,XUẤT!$O:$O,TỒN!L20) -> 0 | M21: =SUMIFS(XUẤT!$W:$W,XUẤT!$B:$B,TỒN!$B$12,XUẤT!$O:$O,TỒN!M20) -> 0 | N21: =SUMIFS(XUẤT!$W:$W,XUẤT!$B:$B,TỒN!$B$12,XUẤT!$O:$O,TỒN!N20) -> 0 | O21: =SUMIFS(XUẤT!$W:$W,XUẤT!$B:$B,TỒN!$B$12,XUẤT!$O:$O,TỒN!O20) -> 0 | P21: =SUM(J21:O21) -> 0
A22: 17 | B22: 46282 | J22: =SUMIFS(XUẤT!$W:$W,XUẤT!$B:$B,TỒN!$B$12,XUẤT!$O:$O,TỒN!J21) -> 0 | K22: =SUMIFS(XUẤT!$W:$W,XUẤT!$B:$B,TỒN!$B$12,XUẤT!$O:$O,TỒN!K21) -> 0 | L22: =SUMIFS(XUẤT!$W:$W,XUẤT!$B:$B,TỒN!$B$12,XUẤT!$O:$O,TỒN!L21) -> 0 | M22: =SUMIFS(XUẤT!$W:$W,XUẤT!$B:$B,TỒN!$B$12,XUẤT!$O:$O,TỒN!M21) -> 0 | N22: =SUMIFS(XUẤT!$W:$W,XUẤT!$B:$B,TỒN!$B$12,XUẤT!$O:$O,TỒN!N21) -> 0 | O22: =SUMIFS(XUẤT!$W:$W,XUẤT!$B:$B,TỒN!$B$12,XUẤT!$O:$O,TỒN!O21) -> 0 | P22: =SUM(J22:O22) -> 0
A23: 18 | B23: 46283 | J23: =SUMIFS(XUẤT!$W:$W,XUẤT!$B:$B,TỒN!$B$12,XUẤT!$O:$O,TỒN!J22) -> 0 | K23: =SUMIFS(XUẤT!$W:$W,XUẤT!$B:$B,TỒN!$B$12,XUẤT!$O:$O,TỒN!K22) -> 0 | L23: =SUMIFS(XUẤT!$W:$W,XUẤT!$B:$B,TỒN!$B$12,XUẤT!$O:$O,TỒN!L22) -> 0 | M23: =SUMIFS(XUẤT!$W:$W,XUẤT!$B:$B,TỒN!$B$12,XUẤT!$O:$O,TỒN!M22) -> 0 | N23: =SUMIFS(XUẤT!$W:$W,XUẤT!$B:$B,TỒN!$B$12,XUẤT!$O:$O,TỒN!N22) -> 0 | O23: =SUMIFS(XUẤT!$W:$W,XUẤT!$B:$B,TỒN!$B$12,XUẤT!$O:$O,TỒN!O22) -> 0 | P23: =SUM(J23:O23) -> 0
A24: 19 | B24: 46284 | J24: =SUMIFS(XUẤT!$W:$W,XUẤT!$B:$B,TỒN!$B$12,XUẤT!$O:$O,TỒN!J23) -> 0 | K24: =SUMIFS(XUẤT!$W:$W,XUẤT!$B:$B,TỒN!$B$12,XUẤT!$O:$O,TỒN!K23) -> 0 | L24: =SUMIFS(XUẤT!$W:$W,XUẤT!$B:$B,TỒN!$B$12,XUẤT!$O:$O,TỒN!L23) -> 0 | M24: =SUMIFS(XUẤT!$W:$W,XUẤT!$B:$B,TỒN!$B$12,XUẤT!$O:$O,TỒN!M23) -> 0 | N24: =SUMIFS(XUẤT!$W:$W,XUẤT!$B:$B,TỒN!$B$12,XUẤT!$O:$O,TỒN!N23) -> 0 | O24: =SUMIFS(XUẤT!$W:$W,XUẤT!$B:$B,TỒN!$B$12,XUẤT!$O:$O,TỒN!O23) -> 0 | P24: =SUM(J24:O24) -> 0
... A35: 30 | B35: 46295 | J35: =SUMIFS(XUẤT!$W:$W,XUẤT!$B:$B,TỒN!$B$12,XUẤT!$O:$O,TỒN!J34) -> 0 | K35: =SUMIFS(XUẤT!$W:$W,XUẤT!$B:$B,TỒN!$B$12,XUẤT!$O:$O,TỒN!K34) -> 0 | L35: =SUMIFS(XUẤT!$W:$W,XUẤT!$B:$B,TỒN!$B$12,XUẤT!$O:$O,TỒN!L34) -> 0 | M35: =SUMIFS(XUẤT!$W:$W,XUẤT!$B:$B,TỒN!$B$12,XUẤT!$O:$O,TỒN!M34) -> 0 | N35: =SUMIFS(XUẤT!$W:$W,XUẤT!$B:$B,TỒN!$B$12,XUẤT!$O:$O,TỒN!N34) -> 0 | O35: =SUMIFS(XUẤT!$W:$W,XUẤT!$B:$B,TỒN!$B$12,XUẤT!$O:$O,TỒN!O34) -> 0 | P35: =SUM(J35:O35) -> 0
B36: Cộng | C36: =SUM(C12:C35) -> 0 | D36: =SUM(D12:D35) -> 0 | E36: =SUM(E12:E35) -> 0 | F36: =SUM(F12:F35) -> 0 | G36: =SUM(G12:G35) -> 0 | H36: =SUM(H12:H35) -> 0 | I36: =SUM(I12:I35) -> 0 | J36: =SUM(J12:J35) -> 0 | ... W36: =SUM(W12:W35) -> 0

Sheet ĐIÈU PHỐI
A1: ĐIỀU PHỐI QAROMI
A3: STT | B3: Họ tên | C3: Tổ/Trạm | D3: Địa chỉ nhà | E3: SĐT | F3: Khu vực thực hiện | H3: TỔ BẢO VỆ THÁNG 9
A4: I | B4: Bốc xếp, vận chuyển | H4: Ngày | I4: Thứ | J4: Người thực hiện | L4: Bùi Đức Hoàng | M4: =COUNTIFS($J$5:$J$28,L4) -> 4
A5: 1 | B5: Đinh Thu Huế | C5: Tổ thị trường | D5: Cao Xanh | E5: 0963913555 | F5: Cao Xanh, Hồng Gai | H5: 7 | I5: 2 | J5: Bùi Đức Hoàng | L5: Nguyễn Thị Hằng | M5: =COUNTIFS($J$5:$J$28,L5) -> 3
A6: 2 | B6: Đặng Thị Huyền | C6: Tổ DVCTT | D6: Cứu Hỏa | E6: 0966785220 | H6: 8 | I6: 3 | J6: Nguyễn Thị Hằng | L6: Nguyễn Thị Thùy | M6: =COUNTIFS($J$5:$J$28,L6) -> 4
A7: 3 | B7: Trần Bích Ly | D7: Bãi Muối | E7: 0988168666 | H7: 9 | I7: 4 | J7: Nguyễn Thị Thùy | L7: Đỗ Thị Vượng | M7: =COUNTIFS($J$5:$J$28,L7) -> 3
A8: 4 | B8: Bùi Đức Hoàng | C8: Bảo vệ | D8: Cột 3 | E8: 0982916899 | H8: 10 | I8: 5 | J8: Đỗ Thị Vượng | L8: Trăng Thị Thơm | M8: =COUNTIFS($J$5:$J$28,L8) -> 3
A9: 5 | B9: Nguyễn Thị Thùy | D9: Hà Trung | E9: 0365577629 | H9: 11 | I9: 6 | J9: Nguyễn Thị Huy | L9: Dương Thị Thu | M9: =COUNTIFS($J$5:$J$28,L9) -> 2
A10: 6 | B10: Nguyễn Thị Hằng | D10: Cột 3 | E10: 0787224668 | H10: 12 | I10: 7 | J10: Trăng Thị Thơm | L10: Nguyễn Thị Huy | M10: =COUNTIFS($J$5:$J$28,L10) -> 4
A11: 7 | B11: Trăng Thị Thơm | D11: Hà Phong | E11: 0379221778
A12: 8 | B12: Đỗ Thị Vượng | D12: Cột 5 | E12: 0914988892 | H12: 14 | I12: 2 | J12: Đỗ Thị Vượng
A13: 9 | B13: Nguyễn Thị Huy | D13: Cột 3 | E13: 0388573628 | H13: 15 | I13: 3 | J13: Bùi Đức Hoàng | K13: nghỉ phép
A14: 10 | B14: Dương Thị Thu | D14: Yết Kiêu | E14: 0838980944 | H14: 16 | I14: 4 | J14: Nguyễn Thị Thùy
A15: 11 | B15: Nguyễn Thị Chi | C15: Hạ Long | D15: Cột 5 | E15: 0855198226 | F15: Cột 3, cột 5 | H15: 17 | I15: 5 | J15: Dương Thị Thu
A16: 12 | B16: Lê Thanh Xuân | C16: Hà Tu | D16: Hà Tu | E16: 0962672181 | F16: Tăng áp -> Hà Tu | H16: 18 | I16: 6 | J16: Trăng Thị Thơm
A17: 13 | B17: Nguyễn Văn Hưng | C17: Hà Lầm | E17: 0915196225 | F17: Hà Lầm | H17: 19 | I17: 7 | J17: Nguyễn Thị Hằng | K17: nghỉ phép
A18: 14 | B18: Trần Trọng Khoa | C18: Hồng Gai | E18: 0904099383 | F18: Hồng Gai | H18: 20 | I18: CN | J18: Nguyễn Thị Huy | L18: Tùng chạy xe
A19: 15 | B19: Nguyễn Thanh Xuyền | C19: Đá Trắng | E19: 0982757198 | F19: Đá Trắng | H19: 21 | I19: 2 | J19: Nguyễn Thị Hằng | K19: nghỉ phép | L19: Tùng chạy xe
A20: II | B20: Lái xe tải điện | H20: 22 | I20: 3 | J20: Trăng Thị Thơm
A21: 1 | B21: Nguyễn Thị Hồng Phương | D21: Yết Kiêu | E21: 0934399569 | H21: 23 | I21: 4 | J21: Dương Thị Thu
A22: 2 | B22: Đặng Thanh Tùng | D22: Cao Xanh | E22: 0968333882 | H22: 24 | I22: 5 | J22: Nguyễn Thị Thùy
H23: 25 | I23: 6 | J23: Nguyễn Thị Huy
A24: STT | B24: Thứ tự điều phối | H24: 26 | I24: 7 | J24: Đỗ Thị Vượng
A25: 1 | B25: Tổ Tiếp thị | H25: 27 | I25: CN | J25: Bùi Đức Hoàng
A26: 2 | B26: Tổ Dịch vụ | H26: 28 | I26: 2 | J26: Nguyễn Thị Huy
A27: 3 | B27: Tổ Bảo vệ | H27: 29 | I27: 3 | J27: Bùi Đức Hoàng
A28: 4 | B28: Trạm QL | H28: 30 | I28: 4 | J28: Nguyễn Thị Thùy

Sheet Vận chuyển
A1: TỔNG HỢP CHI PHÍ VẬN CHUYỂN, BỐC XẾP
A2: Tháng 9/2026
A4: STT | B4: Người thực hiện | C4: Tổ/Trạm | D4: Số lượng | E4: Số tiền
A5: 1 | B5: Xí nghiệp | D5: =SUMIFS(XUẤT!AB:AB,XUẤT!AA:AA,'Vận chuyển'!B5) -> 0 | E5: =D5*5000 -> 0
A6: 2 | B6: Đinh Thu Huế | C6: Tổ thị trường | D6: =SUMIFS(XUẤT!AB:AB,XUẤT!AA:AA,'Vận chuyển'!B6) -> 284 | E6: =D6*5000 -> 1420000
A7: 3 | B7: Tổ DVCTT | C7: Tổ DVCTT | D7: =SUMIFS(XUẤT!AB:AB,XUẤT!AA:AA,'Vận chuyển'!B7) -> 24 | E7: =D7*5000 -> 120000
A8: 5 | B8: Bùi Đức Hoàng | C8: Bảo vệ | D8: =SUMIFS(XUẤT!AB:AB,XUẤT!AA:AA,'Vận chuyển'!B8) -> 0 | E8: =D8*5000 -> 0
A9: 6 | B9: Nguyễn Thị Thùy | D9: =SUMIFS(XUẤT!AB:AB,XUẤT!AA:AA,'Vận chuyển'!B9) -> 1 | E9: =D9*5000 -> 5000
A10: 7 | B10: Nguyễn Thị Hằng | D10: =SUMIFS(XUẤT!AB:AB,XUẤT!AA:AA,'Vận chuyển'!B10) -> 21 | E10: =D10*5000 -> 105000
A11: 8 | B11: Trăng Thị Thơm | D11: =SUMIFS(XUẤT!AB:AB,XUẤT!AA:AA,'Vận chuyển'!B11) -> 0 | E11: =D11*5000 -> 0
A12: 9 | B12: Đỗ Thị Vượng | D12: =SUMIFS(XUẤT!AB:AB,XUẤT!AA:AA,'Vận chuyển'!B12) -> 10 | E12: =D12*5000 -> 50000
A13: 10 | B13: Nguyễn Thị Huy | D13: =SUMIFS(XUẤT!AB:AB,XUẤT!AA:AA,'Vận chuyển'!B13) -> 5 | E13: =D13*5000 -> 25000
A14: 11 | B14: Dương Thị Thu | D14: =SUMIFS(XUẤT!AB:AB,XUẤT!AA:AA,'Vận chuyển'!B14) -> 0 | E14: =D14*5000 -> 0
A15: 12 | B15: Nguyễn Thị Chi | C15: Hạ Long | D15: =SUMIFS(XUẤT!AB:AB,XUẤT!AA:AA,'Vận chuyển'!B15) -> 22 | E15: =D15*5000 -> 110000
A16: 13 | B16: Lê Thanh Xuân | C16: Hà Tu | D16: =SUMIFS(XUẤT!AB:AB,XUẤT!AA:AA,'Vận chuyển'!B16) -> 28 | E16: =D16*5000 -> 140000
A17: 14 | B17: Nguyễn Văn Hưng | C17: Hà Lầm | D17: =SUMIFS(XUẤT!AB:AB,XUẤT!AA:AA,'Vận chuyển'!B17) -> 25 | E17: =D17*5000 -> 125000
A18: 15 | B18: Trần Trọng Khoa | C18: Hồng Gai | D18: =SUMIFS(XUẤT!AB:AB,XUẤT!AA:AA,'Vận chuyển'!B18) -> 83 | E18: =D18*5000 -> 415000
A19: 16 | B19: Nguyễn Thanh Xuyền | C19: Đá Trắng | D19: =SUMIFS(XUẤT!AB:AB,XUẤT!AA:AA,'Vận chuyển'!B19) -> 0 | E19: =D19*5000 -> 0
A20: 17 | B20: Phạm Thị Đan Thanh | D20: =SUMIFS(XUẤT!AB:AB,XUẤT!AA:AA,'Vận chuyển'!B20) -> 2 | E20: =D20*5000 -> 10000
A21: 18 | B21: Mai Anh Dũng | C21: Văn phòng | D21: =SUMIFS(XUẤT!AB:AB,XUẤT!AA:AA,'Vận chuyển'!B21) -> 0 | E21: =D21*5000 -> 0
A22: 18 | B22: Vũ Thị Tươi | C22: Cao Xanh | D22: =SUMIFS(XUẤT!AB:AB,XUẤT!AA:AA,'Vận chuyển'!B22) -> 17 | E22: =D22*5000 -> 85000
A23: 19 | B23: Lương Thị Vân Mai | C23: Cao Xanh | D23: =SUMIFS(XUẤT!AB:AB,XUẤT!AA:AA,'Vận chuyển'!B23) -> 2 | E23: =D23*5000 -> 10000
A24: 20 | B24: Bùi Thị Thu | C24: Cao Xanh | D24: =SUMIFS(XUẤT!AB:AB,XUẤT!AA:AA,'Vận chuyển'!B24) -> 8 | E24: =D24*5000 -> 40000
A25: 21 | B25: Lại Thị Lan | C25: Tổ thị trường | D25: =SUMIFS(XUẤT!AB:AB,XUẤT!AA:AA,'Vận chuyển'!B25) -> 20 | E25: =D25*5000 -> 100000
A26: 22 | B26: Lưu Hải Yến | C26: Hồng Gai | D26: =SUMIFS(XUẤT!AB:AB,XUẤT!AA:AA,'Vận chuyển'!B26) -> 2 | E26: =D26*5000 -> 10000
A27: 23 | B27: Bùi Ngọc Nguyên | C27: Văn phòng | D27: =SUMIFS(XUẤT!AB:AB,XUẤT!AA:AA,'Vận chuyển'!B27) -> 4 | E27: =D27*5000 -> 20000
A28: 24 | B28: Lê Như Hùng | C28: Văn phòng | D28: =SUMIFS(XUẤT!AB:AB,XUẤT!AA:AA,'Vận chuyển'!B28) -> 10 | E28: =D28*5000 -> 50000
A29: 25 | B29: Mạc Thị Thanh Tú | C29: Hà Lầm | D29: =SUMIFS(XUẤT!AB:AB,XUẤT!AA:AA,'Vận chuyển'!B29) -> 3 | E29: =D29*5000 -> 15000
A30: 26 | B30: Bùi Hà Thu | C30: Hà Lầm | D30: =SUMIFS(XUẤT!AB:AB,XUẤT!AA:AA,'Vận chuyển'!B30) -> 20 | E30: =D30*5000 -> 100000
A31: 27 | B31: Phạm Thu Quỳnh | C31: Hà Lầm | D31: =SUMIFS(XUẤT!AB:AB,XUẤT!AA:AA,'Vận chuyển'!B31) -> 1 | E31: =D31*5000 -> 5000
A32: 28 | B32: Vũ Thị Thanh Thảo | C32: Hạ Long | D32: =SUMIFS(XUẤT!AB:AB,XUẤT!AA:AA,'Vận chuyển'!B32) -> 2 | E32: =D32*5000 -> 10000
A33: 29 | B33: Nguyễn Thị Thúy Hằng | D33: =SUMIFS(XUẤT!AB:AB,XUẤT!AA:AA,'Vận chuyển'!B33) -> 3 | E33: =D33*5000 -> 15000
A34: 30 | B34: Nguyễn Thị Hằng | C34: Bảo vệ | D34: =SUMIFS(XUẤT!AB:AB,XUẤT!AA:AA,'Vận chuyển'!B34) -> 21 | E34: =D34*5000 -> 105000
A35: 31 | B35: Nguyễn Thị Hiếu | D35: =SUMIFS(XUẤT!AB:AB,XUẤT!AA:AA,'Vận chuyển'!B35) -> 10 | E35: =D35*5000 -> 50000
A36: 32 | B36: Nguyễn Thị Hồng Phương | D36: =SUMIFS(XUẤT!AB:AB,XUẤT!AA:AA,'Vận chuyển'!B36) -> 93 | E36: =D36*5000 -> 465000
A37: 33 | B37: Tăng Thị Thơm | D37: =SUMIFS(XUẤT!AB:AB,XUẤT!AA:AA,'Vận chuyển'!B37) -> 3 | E37: =D37*5000 -> 15000
A38: 34 | B38: Phương + Huế | D38: =SUMIFS(XUẤT!AB:AB,XUẤT!AA:AA,'Vận chuyển'!B38) -> 20 | E38: =D38*5000 -> 100000
A39: 35 | B39: Yến Quảng Yên | D39: =SUMIFS(XUẤT!AB:AB,XUẤT!AA:AA,'Vận chuyển'!B39) -> 10 | E39: =D39*5000 -> 50000
A40: 36 | B40: Bùi Ngọc Mai | D40: =SUMIFS(XUẤT!AB:AB,XUẤT!AA:AA,'Vận chuyển'!B40) -> 2 | E40: =D40*5000 -> 10000
A41: 37 | B41: Thảo Cẩm Phả | D41: =SUMIFS(XUẤT!AB:AB,XUẤT!AA:AA,'Vận chuyển'!B41) -> 20 | E41: =D41*5000 -> 100000
...

Sheet Đơn giá
A3: STT | B3: Hàng hóa | C3: Giá bán
A4: 1 | B4: Vỉ 350ml | C4: 85000 | F4: Công ty
A5: 2 | B5: Hộp 350ml | C5: 93000 | F5: Xí nghiệp
A6: 3 | B6: Vỉ 500ml | C6: 98000
A7: 4 | B7: Hộp 500ml | C7: 106000
A8: 5 | B8: Bình kiềm | C8: 52000
A9: 6 | B9: Bình RO | C9: 48000

Sheet TỒN TỔNG
A1: STT | B1: NGÀY | C1: Kho | D1: TỒN CUỐI | I1: GHI CHÚ
D2: BÌNH RO | E2: BÌNH KIỀM | F2: Hộp 500 ML | G2: VỈ 500ML | H2: VỈ 350ML | I2: 8/9 VAY KHO CÔNG TY 22 VỈ 500ML – ĐƠN PHƯƠNG LÁI XE
A3: 1 | B3: 11/9/2026 | C3: Kho Huế | D3: ='TỒN KHO HUẾ'!R7 -> 0 | E3: ='TỒN KHO HUẾ'!S7 -> 0 | F3: ='TỒN KHO HUẾ'!T7 -> 0 | G3: ='TỒN KHO HUẾ'!U7 -> 40 | H3: ='TỒN KHO HUẾ'!V7 -> 8
A4: 2 | C4: Kho tăng áp | D4: ='TỒN KHO TĂNG ÁP'!R7 -> 0 | E4: ='TỒN KHO TĂNG ÁP'!S7 -> 21 | F4: ='TỒN KHO TĂNG ÁP'!T7 -> 0 | G4: ='TỒN KHO TĂNG ÁP'!U7 -> 139 | H4: ='TỒN KHO TĂNG ÁP'!V7 -> 57
A5: 3 | C5: Kho văn phòng | D5: ='Tồn kho văn phòng'!R6 -> 0 | E5: ='Tồn kho văn phòng'!S6 -> 0 | F5: ='Tồn kho văn phòng'!T6 -> 0 | G5: ='Tồn kho văn phòng'!U6 -> 51 | H5: ='Tồn kho văn phòng'!V6 -> 0
A6: 4 | B6: 46365 | C6: Kho Huế | D6: ='TỒN KHO HUẾ'!R8 -> 0 | E6: ='TỒN KHO HUẾ'!S8 -> 0 | F6: ='TỒN KHO HUẾ'!T8 -> 0 | G6: ='TỒN KHO HUẾ'!U8 -> 8 | H6: ='TỒN KHO HUẾ'!V8 -> 8
A7: 5 | C7: Kho tăng áp | D7: ='TỒN KHO TĂNG ÁP'!R8 -> 0 | E7: ='TỒN KHO TĂNG ÁP'!S8 -> 21 | F7: ='TỒN KHO TĂNG ÁP'!T8 -> 0 | G7: ='TỒN KHO TĂNG ÁP'!U8 -> 123 | H7: ='TỒN KHO TĂNG ÁP'!V8 -> 41
A8: 6 | C8: Kho văn phòng | D8: ='Tồn kho văn phòng'!R7 -> 0 | E8: ='Tồn kho văn phòng'!S7 -> 0 | F8: ='Tồn kho văn phòng'!T7 -> 0 | G8: ='Tồn kho văn phòng'!U7 -> 47 | H8: ='Tồn kho văn phòng'!V7 -> 0
A9: 7 | B9: 13/9/2026 | C9: Kho Huế | D9: ='TỒN KHO HUẾ'!R9 -> 0 | E9: ='TỒN KHO HUẾ'!S9 -> 0 | F9: ='TỒN KHO HUẾ'!T9 -> 0 | G9: ='TỒN KHO HUẾ'!U9 -> 0 | H9: ='TỒN KHO HUẾ'!V9 -> 8
A10: 8 | C10: Kho tăng áp | D10: ='TỒN KHO TĂNG ÁP'!R9 -> 0 | E10: ='TỒN KHO TĂNG ÁP'!S9 -> 21 | F10: ='TỒN KHO TĂNG ÁP'!T9 -> 0 | G10: ='TỒN KHO TĂNG ÁP'!U9 -> 44 | H10: ='TỒN KHO TĂNG ÁP'!V9 -> 41
A11: 9 | C11: Kho văn phòng | D11: ='Tồn kho văn phòng'!R8 -> 0 | E11: ='Tồn kho văn phòng'!S8 -> 0 | F11: ='Tồn kho văn phòng'!T8 -> 0 | G11: ='Tồn kho văn phòng'!U8 -> 29 | H11: ='Tồn kho văn phòng'!V8 -> 0
A12: 10 | C12: Tồn xe điện | D12: ='tồn xe'!O5 -> 0 | E12: ='tồn xe'!P5 -> 0 | F12: ='tồn xe'!Q5 -> 11 | G12: ='tồn xe'!R5 -> 0 | H12: ='tồn xe'!S5 -> 0
A13: 11 | B13: 14/9/2026 | C13: Kho Huế | D13: ='TỒN KHO HUẾ'!R10 -> 0 | E13: ='TỒN KHO HUẾ'!S10 -> 0 | F13: ='TỒN KHO HUẾ'!T10 -> 0 | G13: ='TỒN KHO HUẾ'!U10 -> 33 | H13: ='TỒN KHO HUẾ'!V10 -> 58
A14: 12 | C14: Kho tăng áp | D14: ='TỒN KHO TĂNG ÁP'!R10 -> 0 | E14: ='TỒN KHO TĂNG ÁP'!S10 -> 11 | F14: ='TỒN KHO TĂNG ÁP'!T10 -> 0 | G14: ='TỒN KHO TĂNG ÁP'!U10 -> 45 | H14: ='TỒN KHO TĂNG ÁP'!V10 -> 41
A15: 13 | C15: Kho văn phòng | D15: ='Tồn kho văn phòng'!R9 -> 0 | E15: ='Tồn kho văn phòng'!S9 -> 0 | F15: ='Tồn kho văn phòng'!T9 -> 0 | G15: ='Tồn kho văn phòng'!U9 -> 29 | H15: ='Tồn kho văn phòng'!V9 -> 0
A16: 14 | C16: Tồn xe điện | D16: ='tồn xe'!O6 -> 0 | E16: ='tồn xe'!P6 -> 0 | F16: ='tồn xe'!Q6 -> 0 | G16: ='tồn xe'!R6 -> 0 | H16: ='tồn xe'!S6 -> 0
A17: 15 | C17: Tồn kho Hà Lầm | D17: ='TỒN KHO HÀ LẦM'!R7 -> 0 | E17: ='TỒN KHO HÀ LẦM'!S7 -> 0 | F17: ='TỒN KHO HÀ LẦM'!T7 -> 0 | G17: ='TỒN KHO HÀ LẦM'!U7 -> 17 | H17: ='TỒN KHO HÀ LẦM'!V7 -> 30
A18: 16 | B18: 15/9/2026 | C18: Kho Huế | D18: ='TỒN KHO HUẾ'!R11 -> 0 | E18: ='TỒN KHO HUẾ'!S11 -> 0 | F18: ='TỒN KHO HUẾ'!T11 -> 0 | G18: ='TỒN KHO HUẾ'!U11 -> 39 | H18: ='TỒN KHO HUẾ'!V11 -> 58
A19: 17 | C19: Kho tăng áp | D19: ='TỒN KHO TĂNG ÁP'!R11 -> 0 | E19: ='TỒN KHO TĂNG ÁP'!S11 -> 11 | F19: ='TỒN KHO TĂNG ÁP'!T11 -> 0 | G19: ='TỒN KHO TĂNG ÁP'!U11 -> 99 | H19: ='TỒN KHO TĂNG ÁP'!V11 -> 39
