Workbook

Sheet XUẤT
A1: ĐIỀU PHỐI QUAROMI | M1: CHỈ TIÊU | AA1: VẬN CHUYỂN
A3: STT | B3: Ngày | C3: Đơn hàng | D3: Công việc | E3: Kho | F3: Số lượng | J3: Người thực hiện | K3: Hỗ Trợ (trạm QL) | L3: Kết quả | M3: Chỉ tiêu | N3: Chỉ tiêu CBCNV | O3: Sản phẩm | P3: Số lượng | X3: Đơn giá | Y3: Doanh thu | Z3: Thu tiền | AA3: Người vận chuyển | AB3: Số lượng | AC3: Số tiền | AD3: GHI CHÚ
M4: XN/CTY | N4: CBCNV | P4: Vỉ 500ml | Q4: Vỉ 350 ml | R4: Hộp 500ml | S4: Hộp 350ml | T4: Bình kiềm | U4: Bình RO | V4: KM | W4: Cộng
F5: 350 | G5: 500 | H5: Bình RO | I5: Bình Kiềm | P5: =SUBTOTAL(9,P6:P268) -> 255 | Q5: =SUBTOTAL(9,Q6:Q268) -> 144 | R5: =SUBTOTAL(9,R6:R268) -> 0 | S5: =SUBTOTAL(9,S6:S268) -> 0 | T5: =SUBTOTAL(9,T6:T268) -> 18 | U5: =SUBTOTAL(9,U6:U268) -> 95 | V5: =SUBTOTAL(9,V6:V268) -> 39 | W5: =SUBTOTAL(9,W6:W173) -> 551 | AB5: =SUBTOTAL(9,AB6:AB173) -> 496 | AC5: =SUBTOTAL(9,AC6:AC173) -> 2495000
A6: 1 | B6: 29/9/2026 | C6: ơi mai cho chị đăng kí 30 +3 RO vòi và 10 vỉ 500 em nhé .(VPUB Tỉnh QN).Chiều mai em nhé . 0977446067 | D6: vận chuyển | E6: Tăng áp | G6: 11 | J6: Anh Hoàng Bảo vệ, trạm Hạ Lomg | L6: hoàn thành | M6: Xí nghiệp | N6: Trần Lệ Hoa | O6: Bình RO | U6: 30 | V6: 3 | W6: =SUM(P6:V6) -> 33 | X6: =SUMIFS('Đơn giá'!C:C,'Đơn giá'!B:B,XUẤT!O6) -> 48000 | Y6: =X6*U6 -> 1440000 | AA6: Tô Phương, Phương lái xe | AB6: =W6-V6 -> 30 | AC6: =AB6*5000 -> 150000
A7: 2 | B7: 29/9/2026 | C7: 10 vỉ 350ml + 1 km đến lideco hộ em với nhé! Giao càng sớm càng tốt chị ạ!! | D7: vận chuyển | E7: Hồng Gai | G7: 11 | J7: Tô Phương, Phương lái xe | L7: hoàn thành | M7: Miền Đông | N7: Hiển | O7: Vỉ 350ml | Q7: 10 | V7: 1 | W7: =SUM(P7:V7) -> 11 | X7: =SUMIFS('Đơn giá'!C:C,'Đơn giá'!B:B,XUẤT!O7) -> 85000 | Y7: =X7*Q7 -> 850000 | AA7: Tô Phương, Phương lái xe | AB7: =W7-V7 -> 10 | AC7: =AB7*5000 -> 50000
A8: 3 | B8: 29/9/2026 | C8: Thư Tuyền PXD: E ơi ship giúp c 10 +1 vỉ 500ml (980k) đến nhà chú Thắng ở tổ 13 khu phố Hà Trung 2 (tầm 11h-11r chú ấy đi làm về) +84972133886. | D8: vận chuyển | E8: Tăng áp | G8: 11 | J8: Tô Phương, Phương lái xe | L8: hoàn thành | M8: Công ty | N8: Thư tuyền PXD | O8: Vỉ 500ml | P8: 10 | V8: 1 | W8: =SUM(P8:V8) -> 11 | X8: =SUMIFS('Đơn giá'!C:C,'Đơn giá'!B:B,XUẤT!O8) -> 98000 | Y8: =X8*P8 -> 980000 | Z8: CK29/9 | AA8: Tô Phương, Phương lái xe | AB8: =W8-V8 -> 10 | AC8: =AB8*5000 -> 50000
A9: 4 | B9: 29/9/2026 | C9: Minh HUệ PQT: 10+1 vỉ 350ml đến Lan Bò Quán, 6A Lê Thánh Tông, 089 8083222 ( CHiều ship, thu tiền luôn) | D9: vận chuyển | E9: Hà Lầm | G9: 11 | J9: Tô Phương, Phương lái xe | L9: hoàn thành | M9: Công ty | N9: Minh Huệ | O9: Vỉ 350ml | Q9: 10 | V9: 1 | W9: =SUM(P9:V9) -> 11 | X9: =SUMIFS('Đơn giá'!C:C,'Đơn giá'!B:B,XUẤT!O9) -> 85000 | Y9: =X9*Q9 -> 850000 | AA9: Tô Phương, Phương lái xe | AB9: =W9-V9 -> 10 | AC9: =AB9*5000 -> 50000
A10: 5 | B10: 29/9/2026 | C10: :Nguyễn Hải Ninh phòng KT đki 10+1 vỉ 500ml ship đến địa chỉ: Số nhà 260 tổ 61 khu Cao Thắng 7 phường Hà Lầm - sđt: 083 3762848 THU TIỀN LUÔN | D10: vận chuyển | E10: Hồng Gai | G10: 16 | J10: Tô Phương, Phương lái xe | L10: hoàn thành | M10: Công ty | N10: Hải Ninh | O10: Vỉ 500ml | P10: 10 | V10: 1 | W10: =SUM(P10:V10) -> 11 | X10: =SUMIFS('Đơn giá'!C:C,'Đơn giá'!B:B,XUẤT!O10) -> 98000 | Y10: =X10*P10 -> 980000 | AA10: Tô Phương, Phương lái xe | AB10: =W10-V10 -> 10 | AC10: =AB10*5000 -> 50000
A11: 1 | B11: 30/9/2026 | C11: Nguyễn Thái Sơn phòng KT đki 15+1 vỉ 350ml đến trường mầm non Hạ long, 0904110068, THU TIỀN LUÔN | D11: vận chuyển | E11: Hồng Gai | J11: Tô Phương, Phương lái xe | M11: Công ty | N11: Thái Sơn | O11: Vỉ 350ml | Q11: 15 | V11: 1 | W11: =SUM(P11:V11) -> 16 | X11: =SUMIFS('Đơn giá'!C:C,'Đơn giá'!B:B,XUẤT!O11) -> 85000 | Y11: =X11*Q11 -> 1275000 | AA11: Tô Phương, Phương lái xe | AB11: =W11-V11 -> 15 | AC11: =AB11*5000 -> 75000
A12: 2 | B12: 30/9/2026 | C12: Công ty cổ phần xe khách quảng ninhTổ 4 phường hạ long, 5 bình RO, THU CỌC 300.000 | D12: vận chuyển | E12: Tăng áp | G12: 11 | J12: Tô Phương, Phương lái xe | L12: hoàn thành | M12: Xí nghiệp | N12: Dung ghi số Hạ Long | O12: Bình RO | U12: 5 | W12: =SUM(P12:V12) -> 5 | X12: =SUMIFS('Đơn giá'!C:C,'Đơn giá'!B:B,XUẤT!O12) -> 48000 | Y12: =X12*U12 -> 240000 | AA12: Tô Phương, Phương lái xe | AB12: =W12-V12 -> 5 | AC12: =AB12*5000 -> 25000
A13: 3 | B13: 30/9/2026 | C13: Số nhà 41 tổ 6 khu 5. Đi vào ngõ 56 cạnh công an phường Hạ long (đối diện chợ Hồng Hà), lên thẳng dốc, nhà đối diện nhà văn hoá khu 5, 0913265778, 10+1 vỉ 500 m | D13: vận chuyển | G13: 5 | J13: Tô Phương, Phương lái xe | M13: Xí nghiệp | N13: Nguyễn Thị Huy | O13: Vỉ 500ml | P13: 10 | V13: 1 | W13: =SUM(P13:V13) -> 11 | X13: =SUMIFS('Đơn giá'!C:C,'Đơn giá'!B:B,XUẤT!O13) -> 98000 | Y13: =X13*P13 -> 980000 | AA13: Tô Phương, Phương lái xe | AB13: =W13-V13 -> 10 | AC13: =AB13*5000 -> 50000
A14: 4 | B14: 30/9/2026 | C14: Bảo Long PCN: SN 11 kho gạo Yết Kiêu - 0963069266 - ship luôn 5 vỉ 500ml thu tiền luôn | E14: Tăng áp | J14: Tô Phương, Phương lái xe | M14: Công ty | N14: Bảo Long PCN | O14: Vỉ 500ml | P14: 5 | W14: =SUM(P14:V14) -> 5 | X14: =SUMIFS('Đơn giá'!C:C,'Đơn giá'!B:B,XUẤT!O14) -> 98000 | Y14: =X14*P14 -> 490000 | Z14: CK1/10 | AA14: Tô Phương, Phương lái xe | AB14: =W14-V14 -> 5 | AC14: =AB14*5000 -> 25000
A15: 5 | B15: 30/9/2026 | C15: UBND phường Hạ Long 10 bình Ro | D15: vận chuyển | E15: Tăng áp | G15: 2 | J15: Tô Phương, Phương lái xe chở hàng | K15: Trạm Hạ Long | L15: hoàn thành | M15: Xí nghiệp | N15: Nguyễn Văn Sơn | O15: Bình RO | U15: 10 | V15: 1 | W15: =SUM(P15:V15) -> 11 | X15: =SUMIFS('Đơn giá'!C:C,'Đơn giá'!B:B,XUẤT!O15) -> 48000 | Y15: =X15*U15 -> 480000 | AA15: Tô Phương, Phương lái xe | AB15: =W15-V15 -> 10 | AC15: =AB15*5000 -> 50000
A16: 6 | B16: 30/9/2026 | C16: 3 vỉ 350 sang trường mâm non Hạ Long, thu tiền luôn 0904110068 | D16: vận chuyển | E16: Hồng Gai | G16: 5 | J16: Tô Phương, Phương lái xe | M16: Xí nghiệp | N16: Đoàn Thị Nhung | O16: Vỉ 350ml | Q16: 3 | W16: =SUM(P16:V16) -> 3 | X16: =SUMIFS('Đơn giá'!C:C,'Đơn giá'!B:B,XUẤT!O16) -> 85000 | Y16: =Q16*X16 -> 255000 | Z16: Thảo Pý Cẩm Phả thu tiền | AA16: Đinh Thu Huế | AB16: =W16-V16 -> 3 | AC16: =AB16*5000 -> 15000
A17: 7 | B17: 30/9/2026 | C17: chuyển sang cho chị 5 vỉ nước 500m, 0972502235, để sảnh chung cư sapphre | D17: vận chuyển | E17: Hồng Gai | J17: Tô Phương, Phương lái xe | M17: Uông Bí | N17: Thúy Nghĩa | O17: Vỉ 500ml | P17: 5 | W17: =SUM(P17:V17) -> 5 | X17: =SUMIFS('Đơn giá'!C:C,'Đơn giá'!B:B,XUẤT!O17) -> 98000 | Y17: =P17*X17 -> 490000 | AA17: Tô Phương, Phương lái xe | AB17: =W17-V17 -> 5 | AC17: =AB17*5000 -> 25000
B18: 30/9/2026 | C18: Hùng kều trạm | D18: vận chuyển | E18: Tăng áp | G18: 5 | J18: Vũ Mạnh Hùng | M18: Xí nghiệp | N18: Vũ Mạnh Hùng | O18: Bình kiềm | T18: 1 | W18: =SUM(P18:V18) -> 1 | X18: =SUMIFS('Đơn giá'!C:C,'Đơn giá'!B:B,XUẤT!O18) -> 52000 | Y18: =T18*X18 -> 52000 | AA18: Vũ Mạnh Hùng | AB18: =W18-V18 -> 1 | AC18: =AB18*5000 -> 5000
B19: 30/9/2026 | C19: Áo cưới 5 vỉ 350 ( Viết hóa đơn cho VNPT của chị Lan Bình) | D19: vận chuyển | E19: Hồng Gai | J19: Đinh Thu Huế | M19: Xí nghiệp | N19: Phạm Phương Dung | O19: Vỉ 350ml | Q19: 5 | W19: =SUM(P19:V19) -> 5 | X19: =SUMIFS('Đơn giá'!C:C,'Đơn giá'!B:B,XUẤT!O19) -> 85000 | Y19: =Q19*X19 -> 425000 | AA19: Đinh Thu Huế | AB19: =W19-V19 -> 5 | AC19: =AB19*5000 -> 25000
A20: 8 | B20: 30/9/2026 | C20: Xuân trạm 3 bình ion | D20: vận chuyển | E20: Tăng áp | G20: 22 | J20: Lê Thanh Xuân | L20: hoàn thành | M20: Xí nghiệp | N20: Lê Thanh Xuân | O20: Bình kiềm | T20: 3 | W20: =SUM(P20:V20) -> 3 | X20: =SUMIFS('Đơn giá'!C:C,'Đơn giá'!B:B,XUẤT!O20) -> 52000 | Y20: =T20*X20 -> 156000 | AA20: Lê Thanh Xuân | AB20: =W20-V20 -> 3 | AC20: =AB20*5000 -> 15000
A21: 1 | B21: 1/10 | C21: Minh Hue PQT: Số nhà 09, đường lương đình của, cạnh công ty xe khách quảng ninh. Phía sau lưng UBND phường hạ Long 0355047656 : ship khách 20 vỉ 350ml, 2 vỉ Minh Huệ qua xí nghiệp lấy (Minh HUệ thanh toán tiền) | D21: vận chuyển | E21: Tăng áp | G21: 33 | J21: Tô Phương, Phương lái xe | L21: hoàn thành | M21: Công ty | N21: Minh Huệ | O21: Vỉ 350ml | Q21: 20 | V21: 2 | W21: =SUM(P21:V21) -> 22 | X21: =SUMIFS('Đơn giá'!C:C,'Đơn giá'!B:B,XUẤT!O21) -> 85000 | Y21: =Q21*X21 -> 1700000 | AA21: Tô Phương, Phương lái xe | AB21: =W21-V21 -> 20 | AC21: =AB21*5000 -> 100000
A22: 2 | B22: 1/10 | C22: 1 đơn 30 +3 vỉ 500ml tạp hóa cô sinh chợ cao xanh 3h chiều, chị Huế tự bốc | D22: vận chuyển | E22: Hồng Gai | G22: 11 | J22: Đinh Thu Huế | L22: hoàn thành | M22: Xí nghiệp | N22: Đinh Thu Huế | O22: Vỉ 500ml | P22: 30 | V22: 3 | W22: =SUM(P22:V22) -> 33 | X22: =SUMIFS('Đơn giá'!C:C,'Đơn giá'!B:B,XUẤT!O22) -> 98000 | Y22: =X22*P22 -> 2940000 | AA22: Đinh Thu Huế | AB22: =W22-V22 -> 30 | AC22: =AB22*5000 -> 150000
A23: 3 | B23: 1/10 | C23: E ơi cho chị đk 10 vỉ tặng 1 ở quán bia Cây Dừa sáng nay nhé (chị Cúc) | D23: vận chuyển | E23: Tăng áp | G23: 5 | J23: Tô Phương, Phương lái xe | L23: hoàn thành | M23: Xí nghiệp | N23: Tăng Thị Cúc | O23: Vỉ 500ml | P23: 10 | V23: 1 | W23: =SUM(P23:V23) -> 11 | X23: =SUMIFS('Đơn giá'!C:C,'Đơn giá'!B:B,XUẤT!O23) -> 98000 | Y23: =P23*X23 -> 980000 | AA23: Tô Phương, Phương lái xe | AB23: =W23-V23 -> 10 | AC23: =AB23*5000 -> 50000
A24: 4 | B24: 1/10 | C24: Cho chị 5 vỉ 500 nhà máy đóng tàu hạ Long, 0968244602 | D24: vận chuyển | E24: Bãi Cháy | G24: 11 | J24: Tô Phương, Phương lái xe | L24: hoàn thành | M24: Xí nghiệp | N24: Nguyễn Thị Hiếu | O24: Vỉ 500ml | P24: 5 | W24: =SUM(P24:V24) -> 5 | X24: =SUMIFS('Đơn giá'!C:C,'Đơn giá'!B:B,XUẤT!O24) -> 98000 | Y24: =X24*P24 -> 490000 | Z24: CK1/10 | AA24: Kim Anh Bãi Cháy | AB24: =W24-V24 -> 5 | AC24: =AB24*5000 -> 25000
A25: 5 | B25: 1/10 | C25: 10+1 bình Ro đến Lideco bãi muối, ĐT0369946536 | D25: vận chuyển | E25: Tăng áp | G25: 3 | J25: Tô Phương, Phương lái xe | K25: Trạm Hà Lầm | L25: hoàn thành | M25: Xí nghiệp | N25: Nguyễn Thị Thu Hiên | O25: Bình RO | U25: 10 | V25: 1 | W25: =SUM(P25:V25) -> 11 | X25: =SUMIFS('Đơn giá'!C:C,'Đơn giá'!B:B,XUẤT!O25) -> 48000 | Y25: =U25*X25 -> 480000 | AA25: Tô Phương, Phương lái xe | AB25: =W25-V25 -> 10 | AC25: =AB25*5000 -> 50000
A26: 6 | B26: 1/10 | C26: 3 Bình Ro đến quảng trường, ĐT0355922271 | D26: vận chuyển | E26: Tăng áp | G26: 11 | J26: Tô Phương, Phương lái xe | L26: hoàn thành | M26: Xí nghiệp | N26: Nguyễn Thị Thu Hiên | O26: Bình RO | U26: 3 | W26: =SUM(P26:V26) -> 3 | X26: =SUMIFS('Đơn giá'!C:C,'Đơn giá'!B:B,XUẤT!O26) -> 48000 | Y26: =U26*X26 -> 144000 | AA26: Tô Phương, Phương lái xe | AB26: =W26-V26 -> 3 | AC26: =AB26*5000 -> 15000
A27: 7 | B27: 1/10 | C27: 10 +1 bình nước thường : Melatect Cao Xanh, ĐT 0377218927 | D27: vận chuyển | E27: Hồng Gai | G27: 11 | J27: Tô Phương, Phương lái xe | K27: Trạm Cao Xanh | L27: hoàn thành | M27: Xí nghiệp | N27: Bùi Ngọc Nguyên | O27: Bình RO | U27: 10 | V27: 1 | W27: =SUM(P27:V27) -> 11 | X27: =SUMIFS('Đơn giá'!C:C,'Đơn giá'!B:B,XUẤT!O27) -> 48000 | Y27: =U27*X27 -> 480000 | AA27: Nguyễn Thị Thúy Hằng | AB27: =W27-V27 -> 10 | AC27: =AB27*5000 -> 50000
A28: 8 | B28: 1/10 | C28: Trường THPT Hạ Long (C Hà) đăng ký 10 +1 vỉ loại 350ml ( màng co); viết hóa đơn về cho trường nhé, '0867339411 | D28: vận chuyển | E28: Tăng áp | G28: 11 | J28: Tô Phương, Phương lái xe | L28: hoàn thành | M28: Xí nghiệp | N28: Trương Thị Hải Yến | O28: Vỉ 350ml | Q28: 10 | V28: 1 | W28: =SUM(P28:V28) -> 11 | X28: =SUMIFS('Đơn giá'!C:C,'Đơn giá'!B:B,XUẤT!O28) -> 85000 | Y28: =Q28*X28 -> 850000 | AA28: Tô Phương, Phương lái xe | AB28: =W28-V28 -> 10 | AC28: =AB28*5000 -> 50000
A29: 9 | B29: 1/10 | C29: Hóa chất mỏ Quảng Ninh, 17 bình RO + 12 vỉ 500 + 2 vỉ 350 trả nợ tháng 9 bao gồm nợ khuyến mại | D29: vận chuyển | E29: Xe Cẩm Phả chở | J29: Đinh Thu Huế | K29: Trạm Cao Xanh | L29: hoàn thành | M29: Xí nghiệp | N29: Trương Thị Hải Yến | O29: Vỉ 350ml | Q29: 2 | W29: =SUM(P29:V29) -> 2 | X29: 85000 | Y29: =Q29*X29 -> 170000 | AA29: Tô Phương, Phương lái xe | AB29: =W29-V29 -> 2 | AC29: =AB29*5000 -> 10000
B30: 1/10 | L30: hoàn thành | M30: Xí nghiệp | N30: Trương Thị Hải Yến | O30: Bình RO | U30: 16 | V30: 1 | W30: =SUM(P30:V30) -> 17
A31: 10 | B31: 1/10 | C31: Mai Hạnh PXD: 5 bình nc có vòi ion kiềm Đến 71 giếng đồn 0334624668 (THU TIỀN LUÔN - Khách cần ship luôn) | D31: vận chuyển | E31: Hồng Gai | F31: 15 | J31: Tô Phương, Phương lái xe | L31: hoàn thành | M31: Công ty | O31: Bình kiềm | T31: 5 | W31: =SUM(P31:V31) -> 5 | X31: =SUMIFS('Đơn giá'!C:C,'Đơn giá'!B:B,XUẤT!O31) -> 52000 | Y31: =T31*X31 -> 260000 | Z31: CK2/10+cọc 300k | AA31: Tô Phương, Phương lái xe | AB31: =W31-V31 -> 5 | AC31: =AB31*5000 -> 25000
A32: 11 | B32: 1/10 | C32: Cô Vân +84983132288 Trường tiểu học Quang Trung. Cơ sở 2 đối diện Go ấy ship 14+1 vỉ 350ml (A HÙng Quế thanh toán) | D32: vận chuyển | E32: Tăng áp | F32: 3 | J32: Đan Thanh, chị Hoa, Chị Vượng | L32: hoàn thành | M32: Công ty | N32: Hùng Quế | O32: Vỉ 350ml | Q32: 14 | V32: 1 | W32: =SUM(P32:V32) -> 15 | X32: 85000 | Y32: =T32+X32 -> 85000 | AA32: Tô Phương, Phương lái xe | AB32: =W32-V32 -> 14 | AC32: =AB32*5000 -> 70000
A33: 12 | B33: 1/10 | C33: Em ơi cho chị 3 vỉ 500 đến nhà máy đóng tàu nhé, ĐT0968244602 | D33: vận chuyển | E33: Bãi Cháy | J33: Kim Anh BC | L33: hoàn thành | M33: Xí nghiệp | N33: Nguyễn Thị Hiếu | O33: Vỉ 500ml | P33: 3 | W33: =SUM(P33:V33) -> 3 | X33: 85000 | Y33: =T33+X33 -> 85000 | AA33: Kim Anh Bãi Cháy | AB33: =W33-V33 -> 3 | AC33: =AB33*5000 -> 15000
A34: 13 | B34: 1/10 | C34: Bùi Linh XD: 1 bình kiềm đến KS Aurara cọt 3 thu tiền luôn 0903026655, THU CỌC 60.000đ | D34: vận chuyển | E34: Tăng áp | F34: 6 | J34: Chị Huy | L34: hoàn thành | M34: Công ty | N34: Bùi Linh PXD | O34: Bình kiềm | T34: 1 | W34: =SUM(P34:V34) -> 1 | X34: =SUMIFS('Đơn giá'!C:C,'Đơn giá'!B:B,XUẤT!O34) -> 52000 | Y34: =T34*X34 -> 52000 | Z34: TM1/10 | AA34: Nguyễn Thị Huy | AB34: =W34-V34 -> 1 | AC34: =AB34*5000 -> 5000
A35: 28 | B35: 1/10 | C35: Vũ Anh BKs: Ship chị 6 vỉ 350ml Đến trường mầm non uk ha long, Khách hàng viết hoá đơn | D35: vận chuyển | E35: Hồng Gai | J35: Đinh Thu Huế | L35: hoàn thành | M35: Công ty | N35: Vũ Anh BKS | O35: Vỉ 350ml | Q35: 6 | W35: =SUM(P35:V35) -> 6 | X35: =SUMIFS('Đơn giá'!C:C,'Đơn giá'!B:B,XUẤT!O35) -> 85000 | Y35: =Q35*X35 -> 510000 | Z35: CK1/10 | AA35: Đinh Thu Huế | AB35: =W35-V35 -> 6 | AC35: =AB35*5000 -> 30000
A36: 1 | B36: 46297 | C36: E đăng ký 10v+1 loại 500ml, và 2vi loại 350ml lấy trog sáng nay, sđt khách hàng 0368809123 sn 66 quán tóc Vân Nguyễn (UB TP đi xuống ạ. C | D36: Vận chuyển | E36: Hồng Gai | F36: 2 | G36: 11 | J36: Tô Phương, Huế | L36: Hoàn thành | M36: Xí nghiệp | N36: Nguyễn Thị Tấm | O36: Vỉ 500ml | P36: 10 | V36: 1 | W36: =SUM(P36:V36) -> 11 | X36: =SUMIFS('Đơn giá'!C:C,'Đơn giá'!B:B,XUẤT!O36) -> 98000 | Y36: =P36*X36 -> 980000 | Z36: CK2/10 | AA36: Huế + Tô Phương | AB36: =W36-V36 -> 10 | AC36: =AB36*5000 -> 50000
B37: 46297 | C37: E đăng ký 10v+1 loại 500ml, và 2vi loại 350ml lấy trog sáng nay, sđt khách hàng 0368809123 sn 66 quán tóc Vân Nguyễn (UB TP đi xuống ạ. C | D37: Vận chuyển | E37: Hồng Gai | J37: Tô Phương, Huế | K37: Tăng áp | L37: Hoàn thành | M37: Xí nghiệp | N37: Nguyễn Thị Tấm | O37: Vỉ 350ml | Q37: 2 | W37: =SUM(P37:V37) -> 2 | X37: =SUMIFS('Đơn giá'!C:C,'Đơn giá'!B:B,XUẤT!O37) -> 85000 | Y37: =Q37*X37 -> 170000 | Z37: CK2/10 | AA37: Huế + Tô Phương | AB37: =W37-V37 -> 2 | AC37: =AB37*5000 -> 10000
A38: 2 | B38: 46297 | C38: E gửi đơn ship trường cấp cấp 1 Lê Hồng Phong Cột 3, cạnh CDC ,Tên lớp ở trên cửa lớp cứ bê đến nơi là dc ạ. Ship giúp e trưa nay lúc 11h nhé. Lớp 4A5 : 3 vỉ nhỏ Lớp 3A3: 2 vỉ nhỏ Lớp 1A6 : 2 vỉ nhỏ Lớp 2A6 : 2 vỉ nhỏ, 2 vỉ nhỏ lớp 3A2, lớp 5A2: 3 vỉ nhỏ | D38: Vận chuyển | E38: Hồng Gai | F38: 11 | J38: Tô Phương, Huế | L38: Hoàn thành | M38: Bãi Cháy | N38: Bãi Cháy | O38: Vỉ 350ml | Q38: 14 | W38: =SUM(P38:V38) -> 14 | X38: =SUMIFS('Đơn giá'!C:C,'Đơn giá'!B:B,XUẤT!O38) -> 85000 | Y38: =Q38*X38 -> 1190000 | AA38: Huế + Tô Phương | AB38: =W38-V38 -> 14 | AC38: =AB38*5000 -> 70000
A39: 3 | B39: 46297 | C39: Minh Hằng PXD: 2 bình thường (thu tiền luôn, thu cọc vỏ bình 2x 60,000=120,000đ) . Thương - 0387111662 shland coffee, b38 MKL monbay, cạnh trường UK | D39: Vận chuyển | E39: Hồng Gai | H39: 2 | J39: Tô Phương, Huế | L39: Hoàn thành | M39: Công ty | N39: Minh Hằng PXD | O39: Bình RO | U39: 2 | W39: =SUM(P39:V39) -> 2 | X39: =SUMIFS('Đơn giá'!C:C,'Đơn giá'!B:B,XUẤT!O39) -> 48000 | Y39: =U39*X39 -> 96000 | AA39: Huế + Tô Phương | AB39: =W39-V39 -> 2 | AC39: =AB39*5000 -> 10000
A40: 6 | B40: 46297 | C40: Cho chị 2 vir500+1 vỉ km nhà máy đóng tàu nhé. ĐT 0968244602, lấy khuyến mại của ngày 1/10 | D40: Vận chuyển | E40: Bãi Cháy | G40: 2 | J40: Bãi Cháy | L40: Hoàn thành | M40: Xí nghiệp | N40: Nguyễn Thị Hiếu | O40: Vỉ 500ml | P40: 2 | V40: 1 | W40: =SUM(P40:V40) -> 3 | X40: =SUMIFS('Đơn giá'!C:C,'Đơn giá'!B:B,XUẤT!O40) -> 98000 | Y40: =V40*X40 -> 98000 | AA40: Huế + Tô Phương | AB40: =W40-V40 -> 2 | AC40: =AB40*5000 -> 10000
A41: 7 | B41: 46297 | C41: cho e 3 vỉ 350ml trường mầm non hạ long . 090 4110068 ạ | D41: Vận chuyển | E41: Hồng Gai | F41: 3 | J41: Tô Phương, Huế | L41: Hoàn thành | M41: Cẩm Phả | O41: Vỉ 350ml | Q41: 3 | W41: =SUM(P41:V41) -> 3 | X41: =SUMIFS('Đơn giá'!C:C,'Đơn giá'!B:B,XUẤT!O41) -> 85000 | Y41: =Q41*X41 -> 255000 | AA41: Huế + Tô Phương | AB41: =W41-V41 -> 3 | AC41: =AB41*5000 -> 15000
...

Sheet CBCNV
A1: TT | B1: Họ và Tên | C1: Chức vụ | D1: Tổ/Trạm | E1: Sản phẩm
E2: Vỉ 500ml | G2: Vỉ 350ml | I2: Hộp 500ml | K2: Hộp 350ml | M2: Bình kiềm | O2: Bình RO
E3: Số lượng | F3: Thành tiền | G3: Số lượng | H3: Thành tiền | I3: Số lượng | J3: Thành tiền | K3: Số lượng | L3: Thành tiền | M3: Số lượng | N3: Thành tiền | O3: Số lượng | P3: Thành tiền | Q3: Xí nghiệp
B4: Cộng | E4: =SUM(E7:E200) -> 173 | F4: =SUM(F7:F200) -> 16954000 | G4: =SUM(G7:G200) -> 32 | H4: =SUM(H7:H200) -> 2720000 | I4: =SUM(I7:I200) -> 0 | J4: =SUM(J7:J200) -> 0 | K4: =SUM(K7:K200) -> 0 | L4: =SUM(L7:L200) -> 0 | ... P4: =SUM(P7:P200) -> 4032000
B5: Kiểm tra | E5: =SUMIFS(XUẤT!P:P,XUẤT!$M:$M,CBCNV!$Q$3)-E4 -> 10 | G5: =SUMIFS(XUẤT!Q:Q,XUẤT!M:M,CBCNV!$Q$3)-CBCNV!G4 -> 0 | I5: =SUMIFS(XUẤT!R:R,XUẤT!$M:$M,CBCNV!$Q$3)-CBCNV!I4 -> 0 | K5: =SUMIFS(XUẤT!S:S,XUẤT!M:M,CBCNV!$Q$3)-CBCNV!K4 -> 0 | M5: =SUMIFS(XUẤT!T:T,XUẤT!M:M,CBCNV!$Q$3)-CBCNV!M4 -> 0 | O5: =SUMIFS(XUẤT!U:U,XUẤT!M:M,CBCNV!$Q$3)-CBCNV!O4 -> 5
A7: 1 | B7: Trần Nam Trung | C7: Giám đốc | D7: Văn phòng | E7: =SUMIFS(XUẤT!P:P,XUẤT!N:N,CBCNV!B7,XUẤT!O:O,CBCNV!$E$2) -> 0 | F7: =E7*$T$10 -> 0 | G7: =SUMIFS(XUẤT!Q:Q,XUẤT!N:N,CBCNV!B7,XUẤT!O:O,CBCNV!$G$2) -> 0 | H7: =G7*$T$8 -> 0 | I7: =SUMIFS(XUẤT!R:R,XUẤT!N:N,CBCNV!B7,XUẤT!O:O,CBCNV!$I$2) -> 0 | J7: =I7*$T$9 -> 0 | K7: =SUMIFS(XUẤT!S:S,XUẤT!N:N,CBCNV!B7,XUẤT!O:O,CBCNV!$K$2) -> 0 | L7: =K7*$T$11 -> 0 | M7: =SUMIFS(XUẤT!T:T,XUẤT!N:N,CBCNV!B7,XUẤT!O:O,CBCNV!$M$2) -> 0 | N7: =M7*$T$12 -> 0 | O7: =SUMIFS(XUẤT!U:U,XUẤT!N:N,CBCNV!B7,XUẤT!O:O,CBCNV!$O$2) -> 0 | P7: =O7*$T$13 -> 0 | R7: STT | S7: Hàng hóa | T7: Giá bán
A8: 2 | B8: Đỗ Văn Cảnh | C8: P. Giám đốc | D8: Văn phòng | E8: =SUMIFS(XUẤT!P:P,XUẤT!N:N,CBCNV!B8,XUẤT!O:O,CBCNV!$E$2) -> 0 | F8: =E8*$T$10 -> 0 | G8: =SUMIFS(XUẤT!Q:Q,XUẤT!N:N,CBCNV!B8,XUẤT!O:O,CBCNV!$G$2) -> 0 | H8: =G8*$T$8 -> 0 | I8: =SUMIFS(XUẤT!R:R,XUẤT!N:N,CBCNV!B8,XUẤT!O:O,CBCNV!$I$2) -> 0 | J8: =I8*$T$9 -> 0 | K8: =SUMIFS(XUẤT!S:S,XUẤT!N:N,CBCNV!B8,XUẤT!O:O,CBCNV!$K$2) -> 0 | L8: =K8*$T$11 -> 0 | M8: =SUMIFS(XUẤT!T:T,XUẤT!N:N,CBCNV!B8,XUẤT!O:O,CBCNV!$M$2) -> 0 | N8: =M8*$T$12 -> 0 | O8: =SUMIFS(XUẤT!U:U,XUẤT!N:N,CBCNV!B8,XUẤT!O:O,CBCNV!$O$2) -> 0 | P8: =O8*$T$13 -> 0 | R8: 1 | S8: Vỉ 350ml | T8: 85000
A9: 3 | B9: Phạm Quang Tâm | C9: P. Giám Đốc | D9: Văn phòng | E9: =SUMIFS(XUẤT!P:P,XUẤT!N:N,CBCNV!B9,XUẤT!O:O,CBCNV!$E$2) -> 0 | F9: =E9*$T$10 -> 0 | G9: =SUMIFS(XUẤT!Q:Q,XUẤT!N:N,CBCNV!B9,XUẤT!O:O,CBCNV!$G$2) -> 0 | H9: =G9*$T$8 -> 0 | I9: =SUMIFS(XUẤT!R:R,XUẤT!N:N,CBCNV!B9,XUẤT!O:O,CBCNV!$I$2) -> 0 | J9: =I9*$T$9 -> 0 | K9: =SUMIFS(XUẤT!S:S,XUẤT!N:N,CBCNV!B9,XUẤT!O:O,CBCNV!$K$2) -> 0 | L9: =K9*$T$11 -> 0 | M9: =SUMIFS(XUẤT!T:T,XUẤT!N:N,CBCNV!B9,XUẤT!O:O,CBCNV!$M$2) -> 0 | N9: =M9*$T$12 -> 0 | O9: =SUMIFS(XUẤT!U:U,XUẤT!N:N,CBCNV!B9,XUẤT!O:O,CBCNV!$O$2) -> 0 | P9: =O9*$T$13 -> 0 | R9: 2 | S9: Hộp 500ml | T9: 93000
A10: 4 | B10: Vũ Thị Mai Huệ | C10: P. Giám Đốc | D10: Văn phòng | E10: =SUMIFS(XUẤT!P:P,XUẤT!N:N,CBCNV!B10,XUẤT!O:O,CBCNV!$E$2) -> 0 | F10: =E10*$T$10 -> 0 | G10: =SUMIFS(XUẤT!Q:Q,XUẤT!N:N,CBCNV!B10,XUẤT!O:O,CBCNV!$G$2) -> 0 | H10: =G10*$T$8 -> 0 | I10: =SUMIFS(XUẤT!R:R,XUẤT!N:N,CBCNV!B10,XUẤT!O:O,CBCNV!$I$2) -> 0 | J10: =I10*$T$9 -> 0 | K10: =SUMIFS(XUẤT!S:S,XUẤT!N:N,CBCNV!B10,XUẤT!O:O,CBCNV!$K$2) -> 0 | L10: =K10*$T$11 -> 0 | M10: =SUMIFS(XUẤT!T:T,XUẤT!N:N,CBCNV!B10,XUẤT!O:O,CBCNV!$M$2) -> 0 | N10: =M10*$T$12 -> 0 | O10: =SUMIFS(XUẤT!U:U,XUẤT!N:N,CBCNV!B10,XUẤT!O:O,CBCNV!$O$2) -> 0 | P10: =O10*$T$13 -> 0 | R10: 3 | S10: Vỉ 500ml | T10: 98000
A11: 5 | B11: Phạm Phương Dung | C11: TBP. Kinh doanh | D11: Văn phòng | E11: =SUMIFS(XUẤT!P:P,XUẤT!N:N,CBCNV!B11,XUẤT!O:O,CBCNV!$E$2) -> 0 | F11: =E11*$T$10 -> 0 | G11: =SUMIFS(XUẤT!Q:Q,XUẤT!N:N,CBCNV!B11,XUẤT!O:O,CBCNV!$G$2) -> 5 | H11: =G11*$T$8 -> 425000 | I11: =SUMIFS(XUẤT!R:R,XUẤT!N:N,CBCNV!B11,XUẤT!O:O,CBCNV!$I$2) -> 0 | J11: =I11*$T$9 -> 0 | K11: =SUMIFS(XUẤT!S:S,XUẤT!N:N,CBCNV!B11,XUẤT!O:O,CBCNV!$K$2) -> 0 | L11: =K11*$T$11 -> 0 | M11: =SUMIFS(XUẤT!T:T,XUẤT!N:N,CBCNV!B11,XUẤT!O:O,CBCNV!$M$2) -> 0 | N11: =M11*$T$12 -> 0 | O11: =SUMIFS(XUẤT!U:U,XUẤT!N:N,CBCNV!B11,XUẤT!O:O,CBCNV!$O$2) -> 0 | P11: =O11*$T$13 -> 0 | R11: 4 | S11: Hộp 350ml | T11: 106000
A12: 6 | B12: Lại Thị Lan | C12: NV kinh doanh | D12: Văn phòng | E12: =SUMIFS(XUẤT!P:P,XUẤT!N:N,CBCNV!B12,XUẤT!O:O,CBCNV!$E$2) -> 0 | F12: =E12*$T$10 -> 0 | G12: =SUMIFS(XUẤT!Q:Q,XUẤT!N:N,CBCNV!B12,XUẤT!O:O,CBCNV!$G$2) -> 0 | H12: =G12*$T$8 -> 0 | I12: =SUMIFS(XUẤT!R:R,XUẤT!N:N,CBCNV!B12,XUẤT!O:O,CBCNV!$I$2) -> 0 | J12: =I12*$T$9 -> 0 | K12: =SUMIFS(XUẤT!S:S,XUẤT!N:N,CBCNV!B12,XUẤT!O:O,CBCNV!$K$2) -> 0 | L12: =K12*$T$11 -> 0 | M12: =SUMIFS(XUẤT!T:T,XUẤT!N:N,CBCNV!B12,XUẤT!O:O,CBCNV!$M$2) -> 0 | N12: =M12*$T$12 -> 0 | O12: =SUMIFS(XUẤT!U:U,XUẤT!N:N,CBCNV!B12,XUẤT!O:O,CBCNV!$O$2) -> 0 | P12: =O12*$T$13 -> 0 | R12: 5 | S12: Bình kiềm | T12: 52000
A13: 7 | B13: Nguyễn Huyền Thư | C13: NV kinh doanh | D13: Văn phòng | E13: =SUMIFS(XUẤT!P:P,XUẤT!N:N,CBCNV!B13,XUẤT!O:O,CBCNV!$E$2) -> 0 | F13: =E13*$T$10 -> 0 | G13: =SUMIFS(XUẤT!Q:Q,XUẤT!N:N,CBCNV!B13,XUẤT!O:O,CBCNV!$G$2) -> 0 | H13: =G13*$T$8 -> 0 | I13: =SUMIFS(XUẤT!R:R,XUẤT!N:N,CBCNV!B13,XUẤT!O:O,CBCNV!$I$2) -> 0 | J13: =I13*$T$9 -> 0 | K13: =SUMIFS(XUẤT!S:S,XUẤT!N:N,CBCNV!B13,XUẤT!O:O,CBCNV!$K$2) -> 0 | L13: =K13*$T$11 -> 0 | M13: =SUMIFS(XUẤT!T:T,XUẤT!N:N,CBCNV!B13,XUẤT!O:O,CBCNV!$M$2) -> 0 | N13: =M13*$T$12 -> 0 | O13: =SUMIFS(XUẤT!U:U,XUẤT!N:N,CBCNV!B13,XUẤT!O:O,CBCNV!$O$2) -> 0 | P13: =O13*$T$13 -> 0 | R13: 6 | S13: Bình RO | T13: 48000
A14: 8 | B14: Đoàn Thị Nhung | C14: NV kinh doanh | D14: Văn phòng | E14: =SUMIFS(XUẤT!P:P,XUẤT!N:N,CBCNV!B14,XUẤT!O:O,CBCNV!$E$2) -> 0 | F14: =E14*$T$10 -> 0 | G14: =SUMIFS(XUẤT!Q:Q,XUẤT!N:N,CBCNV!B14,XUẤT!O:O,CBCNV!$G$2) -> 3 | H14: =G14*$T$8 -> 255000 | I14: =SUMIFS(XUẤT!R:R,XUẤT!N:N,CBCNV!B14,XUẤT!O:O,CBCNV!$I$2) -> 0 | J14: =I14*$T$9 -> 0 | K14: =SUMIFS(XUẤT!S:S,XUẤT!N:N,CBCNV!B14,XUẤT!O:O,CBCNV!$K$2) -> 0 | L14: =K14*$T$11 -> 0 | M14: =SUMIFS(XUẤT!T:T,XUẤT!N:N,CBCNV!B14,XUẤT!O:O,CBCNV!$M$2) -> 0 | N14: =M14*$T$12 -> 0 | O14: =SUMIFS(XUẤT!U:U,XUẤT!N:N,CBCNV!B14,XUẤT!O:O,CBCNV!$O$2) -> 0 | P14: =O14*$T$13 -> 0
A15: 9 | B15: Phạm Thị Thu (A) | C15: NV kinh doanh | D15: Văn phòng | E15: =SUMIFS(XUẤT!P:P,XUẤT!N:N,CBCNV!B15,XUẤT!O:O,CBCNV!$E$2) -> 0 | F15: =E15*$T$10 -> 0 | G15: =SUMIFS(XUẤT!Q:Q,XUẤT!N:N,CBCNV!B15,XUẤT!O:O,CBCNV!$G$2) -> 0 | H15: =G15*$T$8 -> 0 | I15: =SUMIFS(XUẤT!R:R,XUẤT!N:N,CBCNV!B15,XUẤT!O:O,CBCNV!$I$2) -> 0 | J15: =I15*$T$9 -> 0 | K15: =SUMIFS(XUẤT!S:S,XUẤT!N:N,CBCNV!B15,XUẤT!O:O,CBCNV!$K$2) -> 0 | L15: =K15*$T$11 -> 0 | M15: =SUMIFS(XUẤT!T:T,XUẤT!N:N,CBCNV!B15,XUẤT!O:O,CBCNV!$M$2) -> 0 | N15: =M15*$T$12 -> 0 | O15: =SUMIFS(XUẤT!U:U,XUẤT!N:N,CBCNV!B15,XUẤT!O:O,CBCNV!$O$2) -> 0 | P15: =O15*$T$13 -> 0
A16: 10 | B16: Trương Thị Hải Yến | C16: NV kinh doanh | D16: Văn phòng | E16: =SUMIFS(XUẤT!P:P,XUẤT!N:N,CBCNV!B16,XUẤT!O:O,CBCNV!$E$2) -> 3 | F16: =E16*$T$10 -> 294000 | G16: =SUMIFS(XUẤT!Q:Q,XUẤT!N:N,CBCNV!B16,XUẤT!O:O,CBCNV!$G$2) -> 12 | H16: =G16*$T$8 -> 1020000 | I16: =SUMIFS(XUẤT!R:R,XUẤT!N:N,CBCNV!B16,XUẤT!O:O,CBCNV!$I$2) -> 0 | J16: =I16*$T$9 -> 0 | K16: =SUMIFS(XUẤT!S:S,XUẤT!N:N,CBCNV!B16,XUẤT!O:O,CBCNV!$K$2) -> 0 | L16: =K16*$T$11 -> 0 | M16: =SUMIFS(XUẤT!T:T,XUẤT!N:N,CBCNV!B16,XUẤT!O:O,CBCNV!$M$2) -> 0 | N16: =M16*$T$12 -> 0 | O16: =SUMIFS(XUẤT!U:U,XUẤT!N:N,CBCNV!B16,XUẤT!O:O,CBCNV!$O$2) -> 16 | P16: =O16*$T$13 -> 768000
A17: 11 | B17: Lương Minh Hương | C17: NV kinh doanh | D17: Văn phòng | E17: =SUMIFS(XUẤT!P:P,XUẤT!N:N,CBCNV!B17,XUẤT!O:O,CBCNV!$E$2) -> 0 | F17: =E17*$T$10 -> 0 | G17: =SUMIFS(XUẤT!Q:Q,XUẤT!N:N,CBCNV!B17,XUẤT!O:O,CBCNV!$G$2) -> 0 | H17: =G17*$T$8 -> 0 | I17: =SUMIFS(XUẤT!R:R,XUẤT!N:N,CBCNV!B17,XUẤT!O:O,CBCNV!$I$2) -> 0 | J17: =I17*$T$9 -> 0 | K17: =SUMIFS(XUẤT!S:S,XUẤT!N:N,CBCNV!B17,XUẤT!O:O,CBCNV!$K$2) -> 0 | L17: =K17*$T$11 -> 0 | M17: =SUMIFS(XUẤT!T:T,XUẤT!N:N,CBCNV!B17,XUẤT!O:O,CBCNV!$M$2) -> 0 | N17: =M17*$T$12 -> 0 | O17: =SUMIFS(XUẤT!U:U,XUẤT!N:N,CBCNV!B17,XUẤT!O:O,CBCNV!$O$2) -> 0 | P17: =O17*$T$13 -> 0
A18: 12 | B18: Hoàng Hồng Nhung | C18: NV kinh doanh | D18: Văn phòng | E18: =SUMIFS(XUẤT!P:P,XUẤT!N:N,CBCNV!B18,XUẤT!O:O,CBCNV!$E$2) -> 0 | F18: =E18*$T$10 -> 0 | G18: =SUMIFS(XUẤT!Q:Q,XUẤT!N:N,CBCNV!B18,XUẤT!O:O,CBCNV!$G$2) -> 0 | H18: =G18*$T$8 -> 0 | I18: =SUMIFS(XUẤT!R:R,XUẤT!N:N,CBCNV!B18,XUẤT!O:O,CBCNV!$I$2) -> 0 | J18: =I18*$T$9 -> 0 | K18: =SUMIFS(XUẤT!S:S,XUẤT!N:N,CBCNV!B18,XUẤT!O:O,CBCNV!$K$2) -> 0 | L18: =K18*$T$11 -> 0 | M18: =SUMIFS(XUẤT!T:T,XUẤT!N:N,CBCNV!B18,XUẤT!O:O,CBCNV!$M$2) -> 0 | N18: =M18*$T$12 -> 0 | O18: =SUMIFS(XUẤT!U:U,XUẤT!N:N,CBCNV!B18,XUẤT!O:O,CBCNV!$O$2) -> 0 | P18: =O18*$T$13 -> 0
A19: 13 | B19: Nguyễn Phương Thảo | C19: NV kinh doanh | D19: Văn phòng | E19: =SUMIFS(XUẤT!P:P,XUẤT!N:N,CBCNV!B19,XUẤT!O:O,CBCNV!$E$2) -> 0 | F19: =E19*$T$10 -> 0 | G19: =SUMIFS(XUẤT!Q:Q,XUẤT!N:N,CBCNV!B19,XUẤT!O:O,CBCNV!$G$2) -> 0 | H19: =G19*$T$8 -> 0 | I19: =SUMIFS(XUẤT!R:R,XUẤT!N:N,CBCNV!B19,XUẤT!O:O,CBCNV!$I$2) -> 0 | J19: =I19*$T$9 -> 0 | K19: =SUMIFS(XUẤT!S:S,XUẤT!N:N,CBCNV!B19,XUẤT!O:O,CBCNV!$K$2) -> 0 | L19: =K19*$T$11 -> 0 | M19: =SUMIFS(XUẤT!T:T,XUẤT!N:N,CBCNV!B19,XUẤT!O:O,CBCNV!$M$2) -> 0 | N19: =M19*$T$12 -> 0 | O19: =SUMIFS(XUẤT!U:U,XUẤT!N:N,CBCNV!B19,XUẤT!O:O,CBCNV!$O$2) -> 0 | P19: =O19*$T$13 -> 0
A20: 14 | B20: Phạm Thị Đan Thanh | C20: NV kinh doanh | D20: Văn phòng | E20: =SUMIFS(XUẤT!P:P,XUẤT!N:N,CBCNV!B20,XUẤT!O:O,CBCNV!$E$2) -> 0 | F20: =E20*$T$10 -> 0 | G20: =SUMIFS(XUẤT!Q:Q,XUẤT!N:N,CBCNV!B20,XUẤT!O:O,CBCNV!$G$2) -> 0 | H20: =G20*$T$8 -> 0 | I20: =SUMIFS(XUẤT!R:R,XUẤT!N:N,CBCNV!B20,XUẤT!O:O,CBCNV!$I$2) -> 0 | J20: =I20*$T$9 -> 0 | K20: =SUMIFS(XUẤT!S:S,XUẤT!N:N,CBCNV!B20,XUẤT!O:O,CBCNV!$K$2) -> 0 | L20: =K20*$T$11 -> 0 | M20: =SUMIFS(XUẤT!T:T,XUẤT!N:N,CBCNV!B20,XUẤT!O:O,CBCNV!$M$2) -> 1 | N20: =M20*$T$12 -> 52000 | O20: =SUMIFS(XUẤT!U:U,XUẤT!N:N,CBCNV!B20,XUẤT!O:O,CBCNV!$O$2) -> 0 | P20: =O20*$T$13 -> 0
A21: 15 | B21: Phan Hồng Hạnh | C21: NV kinh doanh | D21: Văn phòng | E21: =SUMIFS(XUẤT!P:P,XUẤT!N:N,CBCNV!B21,XUẤT!O:O,CBCNV!$E$2) -> 0 | F21: =E21*$T$10 -> 0 | G21: =SUMIFS(XUẤT!Q:Q,XUẤT!N:N,CBCNV!B21,XUẤT!O:O,CBCNV!$G$2) -> 0 | H21: =G21*$T$8 -> 0 | I21: =SUMIFS(XUẤT!R:R,XUẤT!N:N,CBCNV!B21,XUẤT!O:O,CBCNV!$I$2) -> 0 | J21: =I21*$T$9 -> 0 | K21: =SUMIFS(XUẤT!S:S,XUẤT!N:N,CBCNV!B21,XUẤT!O:O,CBCNV!$K$2) -> 0 | L21: =K21*$T$11 -> 0 | M21: =SUMIFS(XUẤT!T:T,XUẤT!N:N,CBCNV!B21,XUẤT!O:O,CBCNV!$M$2) -> 0 | N21: =M21*$T$12 -> 0 | O21: =SUMIFS(XUẤT!U:U,XUẤT!N:N,CBCNV!B21,XUẤT!O:O,CBCNV!$O$2) -> 0 | P21: =O21*$T$13 -> 0
A22: 16 | B22: Đỗ Thị Liễu | C22: CN kẹp chì | D22: Văn phòng | E22: =SUMIFS(XUẤT!P:P,XUẤT!N:N,CBCNV!B22,XUẤT!O:O,CBCNV!$E$2) -> 0 | F22: =E22*$T$10 -> 0 | G22: =SUMIFS(XUẤT!Q:Q,XUẤT!N:N,CBCNV!B22,XUẤT!O:O,CBCNV!$G$2) -> 0 | H22: =G22*$T$8 -> 0 | I22: =SUMIFS(XUẤT!R:R,XUẤT!N:N,CBCNV!B22,XUẤT!O:O,CBCNV!$I$2) -> 0 | J22: =I22*$T$9 -> 0 | K22: =SUMIFS(XUẤT!S:S,XUẤT!N:N,CBCNV!B22,XUẤT!O:O,CBCNV!$K$2) -> 0 | L22: =K22*$T$11 -> 0 | M22: =SUMIFS(XUẤT!T:T,XUẤT!N:N,CBCNV!B22,XUẤT!O:O,CBCNV!$M$2) -> 0 | N22: =M22*$T$12 -> 0 | O22: =SUMIFS(XUẤT!U:U,XUẤT!N:N,CBCNV!B22,XUẤT!O:O,CBCNV!$O$2) -> 0 | P22: =O22*$T$13 -> 0
A23: 17 | B23: Vũ Hữu Hoàng | C23: CN quản lý | D23: Văn phòng | E23: =SUMIFS(XUẤT!P:P,XUẤT!N:N,CBCNV!B23,XUẤT!O:O,CBCNV!$E$2) -> 0 | F23: =E23*$T$10 -> 0 | G23: =SUMIFS(XUẤT!Q:Q,XUẤT!N:N,CBCNV!B23,XUẤT!O:O,CBCNV!$G$2) -> 0 | H23: =G23*$T$8 -> 0 | I23: =SUMIFS(XUẤT!R:R,XUẤT!N:N,CBCNV!B23,XUẤT!O:O,CBCNV!$I$2) -> 0 | J23: =I23*$T$9 -> 0 | K23: =SUMIFS(XUẤT!S:S,XUẤT!N:N,CBCNV!B23,XUẤT!O:O,CBCNV!$K$2) -> 0 | L23: =K23*$T$11 -> 0 | M23: =SUMIFS(XUẤT!T:T,XUẤT!N:N,CBCNV!B23,XUẤT!O:O,CBCNV!$M$2) -> 0 | N23: =M23*$T$12 -> 0 | O23: =SUMIFS(XUẤT!U:U,XUẤT!N:N,CBCNV!B23,XUẤT!O:O,CBCNV!$O$2) -> 0 | P23: =O23*$T$13 -> 0
A24: 18 | B24: Lê Như Hùng | C24: NV kiểm tra | D24: Văn phòng | E24: =SUMIFS(XUẤT!P:P,XUẤT!N:N,CBCNV!B24,XUẤT!O:O,CBCNV!$E$2) -> 0 | F24: =E24*$T$10 -> 0 | G24: =SUMIFS(XUẤT!Q:Q,XUẤT!N:N,CBCNV!B24,XUẤT!O:O,CBCNV!$G$2) -> 0 | H24: =G24*$T$8 -> 0 | I24: =SUMIFS(XUẤT!R:R,XUẤT!N:N,CBCNV!B24,XUẤT!O:O,CBCNV!$I$2) -> 0 | J24: =I24*$T$9 -> 0 | K24: =SUMIFS(XUẤT!S:S,XUẤT!N:N,CBCNV!B24,XUẤT!O:O,CBCNV!$K$2) -> 0 | L24: =K24*$T$11 -> 0 | M24: =SUMIFS(XUẤT!T:T,XUẤT!N:N,CBCNV!B24,XUẤT!O:O,CBCNV!$M$2) -> 0 | N24: =M24*$T$12 -> 0 | O24: =SUMIFS(XUẤT!U:U,XUẤT!N:N,CBCNV!B24,XUẤT!O:O,CBCNV!$O$2) -> 0 | P24: =O24*$T$13 -> 0
A25: 19 | B25: Vũ Văn Thảo | C25: NV kiểm tra | D25: Văn phòng | E25: =SUMIFS(XUẤT!P:P,XUẤT!N:N,CBCNV!B25,XUẤT!O:O,CBCNV!$E$2) -> 0 | F25: =E25*$T$10 -> 0 | G25: =SUMIFS(XUẤT!Q:Q,XUẤT!N:N,CBCNV!B25,XUẤT!O:O,CBCNV!$G$2) -> 0 | H25: =G25*$T$8 -> 0 | I25: =SUMIFS(XUẤT!R:R,XUẤT!N:N,CBCNV!B25,XUẤT!O:O,CBCNV!$I$2) -> 0 | J25: =I25*$T$9 -> 0 | K25: =SUMIFS(XUẤT!S:S,XUẤT!N:N,CBCNV!B25,XUẤT!O:O,CBCNV!$K$2) -> 0 | L25: =K25*$T$11 -> 0 | M25: =SUMIFS(XUẤT!T:T,XUẤT!N:N,CBCNV!B25,XUẤT!O:O,CBCNV!$M$2) -> 0 | N25: =M25*$T$12 -> 0 | O25: =SUMIFS(XUẤT!U:U,XUẤT!N:N,CBCNV!B25,XUẤT!O:O,CBCNV!$O$2) -> 0 | P25: =O25*$T$13 -> 0
B26: Vũ Thành Long | C26: NVKD | D26: Văn phòng | E26: =SUMIFS(XUẤT!P:P,XUẤT!N:N,CBCNV!B26,XUẤT!O:O,CBCNV!$E$2) -> 0 | F26: =E26*$T$10 -> 0 | G26: =SUMIFS(XUẤT!Q:Q,XUẤT!N:N,CBCNV!B26,XUẤT!O:O,CBCNV!$G$2) -> 0 | H26: =G26*$T$8 -> 0 | I26: =SUMIFS(XUẤT!R:R,XUẤT!N:N,CBCNV!B26,XUẤT!O:O,CBCNV!$I$2) -> 0 | J26: =I26*$T$9 -> 0 | K26: =SUMIFS(XUẤT!S:S,XUẤT!N:N,CBCNV!B26,XUẤT!O:O,CBCNV!$K$2) -> 0 | L26: =K26*$T$11 -> 0 | M26: =SUMIFS(XUẤT!T:T,XUẤT!N:N,CBCNV!B26,XUẤT!O:O,CBCNV!$M$2) -> 0 | N26: =M26*$T$12 -> 0 | O26: =SUMIFS(XUẤT!U:U,XUẤT!N:N,CBCNV!B26,XUẤT!O:O,CBCNV!$O$2) -> 0 | P26: =O26*$T$13 -> 0
A27: 20 | B27: Trần Thị Thắm | C27: Kế toán chính | D27: Văn phòng | E27: =SUMIFS(XUẤT!P:P,XUẤT!N:N,CBCNV!B27,XUẤT!O:O,CBCNV!$E$2) -> 0 | F27: =E27*$T$10 -> 0 | G27: =SUMIFS(XUẤT!Q:Q,XUẤT!N:N,CBCNV!B27,XUẤT!O:O,CBCNV!$G$2) -> 0 | H27: =G27*$T$8 -> 0 | I27: =SUMIFS(XUẤT!R:R,XUẤT!N:N,CBCNV!B27,XUẤT!O:O,CBCNV!$I$2) -> 0 | J27: =I27*$T$9 -> 0 | K27: =SUMIFS(XUẤT!S:S,XUẤT!N:N,CBCNV!B27,XUẤT!O:O,CBCNV!$K$2) -> 0 | L27: =K27*$T$11 -> 0 | M27: =SUMIFS(XUẤT!T:T,XUẤT!N:N,CBCNV!B27,XUẤT!O:O,CBCNV!$M$2) -> 0 | N27: =M27*$T$12 -> 0 | O27: =SUMIFS(XUẤT!U:U,XUẤT!N:N,CBCNV!B27,XUẤT!O:O,CBCNV!$O$2) -> 0 | P27: =O27*$T$13 -> 0
A28: 21 | B28: Vũ Thị Thúy Phương | C28: NV thủ kho | D28: Văn phòng | E28: =SUMIFS(XUẤT!P:P,XUẤT!N:N,CBCNV!B28,XUẤT!O:O,CBCNV!$E$2) -> 0 | F28: =E28*$T$10 -> 0 | G28: =SUMIFS(XUẤT!Q:Q,XUẤT!N:N,CBCNV!B28,XUẤT!O:O,CBCNV!$G$2) -> 0 | H28: =G28*$T$8 -> 0 | I28: =SUMIFS(XUẤT!R:R,XUẤT!N:N,CBCNV!B28,XUẤT!O:O,CBCNV!$I$2) -> 0 | J28: =I28*$T$9 -> 0 | K28: =SUMIFS(XUẤT!S:S,XUẤT!N:N,CBCNV!B28,XUẤT!O:O,CBCNV!$K$2) -> 0 | L28: =K28*$T$11 -> 0 | M28: =SUMIFS(XUẤT!T:T,XUẤT!N:N,CBCNV!B28,XUẤT!O:O,CBCNV!$M$2) -> 0 | N28: =M28*$T$12 -> 0 | O28: =SUMIFS(XUẤT!U:U,XUẤT!N:N,CBCNV!B28,XUẤT!O:O,CBCNV!$O$2) -> 0 | P28: =O28*$T$13 -> 0
A29: 22 | B29: Lê Hoàng Anh | C29: NV kế toán | D29: Văn phòng | E29: =SUMIFS(XUẤT!P:P,XUẤT!N:N,CBCNV!B29,XUẤT!O:O,CBCNV!$E$2) -> 0 | F29: =E29*$T$10 -> 0 | G29: =SUMIFS(XUẤT!Q:Q,XUẤT!N:N,CBCNV!B29,XUẤT!O:O,CBCNV!$G$2) -> 0 | H29: =G29*$T$8 -> 0 | I29: =SUMIFS(XUẤT!R:R,XUẤT!N:N,CBCNV!B29,XUẤT!O:O,CBCNV!$I$2) -> 0 | J29: =I29*$T$9 -> 0 | K29: =SUMIFS(XUẤT!S:S,XUẤT!N:N,CBCNV!B29,XUẤT!O:O,CBCNV!$K$2) -> 0 | L29: =K29*$T$11 -> 0 | M29: =SUMIFS(XUẤT!T:T,XUẤT!N:N,CBCNV!B29,XUẤT!O:O,CBCNV!$M$2) -> 0 | N29: =M29*$T$12 -> 0 | O29: =SUMIFS(XUẤT!U:U,XUẤT!N:N,CBCNV!B29,XUẤT!O:O,CBCNV!$O$2) -> 0 | P29: =O29*$T$13 -> 0
A30: 23 | B30: Phạm Thị Bích Hằng | C30: NV kế toán | D30: Văn phòng | E30: =SUMIFS(XUẤT!P:P,XUẤT!N:N,CBCNV!B30,XUẤT!O:O,CBCNV!$E$2) -> 0 | F30: =E30*$T$10 -> 0 | G30: =SUMIFS(XUẤT!Q:Q,XUẤT!N:N,CBCNV!B30,XUẤT!O:O,CBCNV!$G$2) -> 0 | H30: =G30*$T$8 -> 0 | I30: =SUMIFS(XUẤT!R:R,XUẤT!N:N,CBCNV!B30,XUẤT!O:O,CBCNV!$I$2) -> 0 | J30: =I30*$T$9 -> 0 | K30: =SUMIFS(XUẤT!S:S,XUẤT!N:N,CBCNV!B30,XUẤT!O:O,CBCNV!$K$2) -> 0 | L30: =K30*$T$11 -> 0 | M30: =SUMIFS(XUẤT!T:T,XUẤT!N:N,CBCNV!B30,XUẤT!O:O,CBCNV!$M$2) -> 0 | N30: =M30*$T$12 -> 0 | O30: =SUMIFS(XUẤT!U:U,XUẤT!N:N,CBCNV!B30,XUẤT!O:O,CBCNV!$O$2) -> 0 | P30: =O30*$T$13 -> 0
A31: 24 | B31: Đỗ Thị Thu Hoàn | C31: NV kế toán | D31: Văn phòng | E31: =SUMIFS(XUẤT!P:P,XUẤT!N:N,CBCNV!B31,XUẤT!O:O,CBCNV!$E$2) -> 0 | F31: =E31*$T$10 -> 0 | G31: =SUMIFS(XUẤT!Q:Q,XUẤT!N:N,CBCNV!B31,XUẤT!O:O,CBCNV!$G$2) -> 0 | H31: =G31*$T$8 -> 0 | I31: =SUMIFS(XUẤT!R:R,XUẤT!N:N,CBCNV!B31,XUẤT!O:O,CBCNV!$I$2) -> 0 | J31: =I31*$T$9 -> 0 | K31: =SUMIFS(XUẤT!S:S,XUẤT!N:N,CBCNV!B31,XUẤT!O:O,CBCNV!$K$2) -> 0 | L31: =K31*$T$11 -> 0 | M31: =SUMIFS(XUẤT!T:T,XUẤT!N:N,CBCNV!B31,XUẤT!O:O,CBCNV!$M$2) -> 0 | N31: =M31*$T$12 -> 0 | O31: =SUMIFS(XUẤT!U:U,XUẤT!N:N,CBCNV!B31,XUẤT!O:O,CBCNV!$O$2) -> 0 | P31: =O31*$T$13 -> 0
A32: 25 | B32: Nguyễn Thị Thu Quyên | C32: NV kế toán | D32: Văn phòng | E32: =SUMIFS(XUẤT!P:P,XUẤT!N:N,CBCNV!B32,XUẤT!O:O,CBCNV!$E$2) -> 0 | F32: =E32*$T$10 -> 0 | G32: =SUMIFS(XUẤT!Q:Q,XUẤT!N:N,CBCNV!B32,XUẤT!O:O,CBCNV!$G$2) -> 0 | H32: =G32*$T$8 -> 0 | I32: =SUMIFS(XUẤT!R:R,XUẤT!N:N,CBCNV!B32,XUẤT!O:O,CBCNV!$I$2) -> 0 | J32: =I32*$T$9 -> 0 | K32: =SUMIFS(XUẤT!S:S,XUẤT!N:N,CBCNV!B32,XUẤT!O:O,CBCNV!$K$2) -> 0 | L32: =K32*$T$11 -> 0 | M32: =SUMIFS(XUẤT!T:T,XUẤT!N:N,CBCNV!B32,XUẤT!O:O,CBCNV!$M$2) -> 0 | N32: =M32*$T$12 -> 0 | O32: =SUMIFS(XUẤT!U:U,XUẤT!N:N,CBCNV!B32,XUẤT!O:O,CBCNV!$O$2) -> 0 | P32: =O32*$T$13 -> 0
A33: 26 | B33: Ngô Thị Vân Anh | C33: PT. Quản trị | D33: Văn phòng | E33: =SUMIFS(XUẤT!P:P,XUẤT!N:N,CBCNV!B33,XUẤT!O:O,CBCNV!$E$2) -> 0 | F33: =E33*$T$10 -> 0 | G33: =SUMIFS(XUẤT!Q:Q,XUẤT!N:N,CBCNV!B33,XUẤT!O:O,CBCNV!$G$2) -> 0 | H33: =G33*$T$8 -> 0 | I33: =SUMIFS(XUẤT!R:R,XUẤT!N:N,CBCNV!B33,XUẤT!O:O,CBCNV!$I$2) -> 0 | J33: =I33*$T$9 -> 0 | K33: =SUMIFS(XUẤT!S:S,XUẤT!N:N,CBCNV!B33,XUẤT!O:O,CBCNV!$K$2) -> 0 | L33: =K33*$T$11 -> 0 | M33: =SUMIFS(XUẤT!T:T,XUẤT!N:N,CBCNV!B33,XUẤT!O:O,CBCNV!$M$2) -> 0 | N33: =M33*$T$12 -> 0 | O33: =SUMIFS(XUẤT!U:U,XUẤT!N:N,CBCNV!B33,XUẤT!O:O,CBCNV!$O$2) -> 0 | P33: =O33*$T$13 -> 0
A34: 27 | B34: Nguyễn Thị Lan | C34: NV Đảng - Đoàn | D34: Văn phòng | E34: =SUMIFS(XUẤT!P:P,XUẤT!N:N,CBCNV!B34,XUẤT!O:O,CBCNV!$E$2) -> 0 | F34: =E34*$T$10 -> 0 | G34: =SUMIFS(XUẤT!Q:Q,XUẤT!N:N,CBCNV!B34,XUẤT!O:O,CBCNV!$G$2) -> 0 | H34: =G34*$T$8 -> 0 | I34: =SUMIFS(XUẤT!R:R,XUẤT!N:N,CBCNV!B34,XUẤT!O:O,CBCNV!$I$2) -> 0 | J34: =I34*$T$9 -> 0 | K34: =SUMIFS(XUẤT!S:S,XUẤT!N:N,CBCNV!B34,XUẤT!O:O,CBCNV!$K$2) -> 0 | L34: =K34*$T$11 -> 0 | M34: =SUMIFS(XUẤT!T:T,XUẤT!N:N,CBCNV!B34,XUẤT!O:O,CBCNV!$M$2) -> 0 | N34: =M34*$T$12 -> 0 | O34: =SUMIFS(XUẤT!U:U,XUẤT!N:N,CBCNV!B34,XUẤT!O:O,CBCNV!$O$2) -> 0 | P34: =O34*$T$13 -> 0
A35: 28 | B35: Nguyễn Thị Ngọc Chung | C35: Thủ quỹ - HC | D35: Văn phòng | E35: =SUMIFS(XUẤT!P:P,XUẤT!N:N,CBCNV!B35,XUẤT!O:O,CBCNV!$E$2) -> 0 | F35: =E35*$T$10 -> 0 | G35: =SUMIFS(XUẤT!Q:Q,XUẤT!N:N,CBCNV!B35,XUẤT!O:O,CBCNV!$G$2) -> 0 | H35: =G35*$T$8 -> 0 | I35: =SUMIFS(XUẤT!R:R,XUẤT!N:N,CBCNV!B35,XUẤT!O:O,CBCNV!$I$2) -> 0 | J35: =I35*$T$9 -> 0 | K35: =SUMIFS(XUẤT!S:S,XUẤT!N:N,CBCNV!B35,XUẤT!O:O,CBCNV!$K$2) -> 0 | L35: =K35*$T$11 -> 0 | M35: =SUMIFS(XUẤT!T:T,XUẤT!N:N,CBCNV!B35,XUẤT!O:O,CBCNV!$M$2) -> 0 | N35: =M35*$T$12 -> 0 | O35: =SUMIFS(XUẤT!U:U,XUẤT!N:N,CBCNV!B35,XUẤT!O:O,CBCNV!$O$2) -> 0 | P35: =O35*$T$13 -> 0
A36: 29 | B36: Bùi Thị Diệu Linh | C36: NV LĐTL | D36: Văn phòng | E36: =SUMIFS(XUẤT!P:P,XUẤT!N:N,CBCNV!B36,XUẤT!O:O,CBCNV!$E$2) -> 0 | F36: =E36*$T$10 -> 0 | G36: =SUMIFS(XUẤT!Q:Q,XUẤT!N:N,CBCNV!B36,XUẤT!O:O,CBCNV!$G$2) -> 0 | H36: =G36*$T$8 -> 0 | I36: =SUMIFS(XUẤT!R:R,XUẤT!N:N,CBCNV!B36,XUẤT!O:O,CBCNV!$I$2) -> 0 | J36: =I36*$T$9 -> 0 | K36: =SUMIFS(XUẤT!S:S,XUẤT!N:N,CBCNV!B36,XUẤT!O:O,CBCNV!$K$2) -> 0 | L36: =K36*$T$11 -> 0 | M36: =SUMIFS(XUẤT!T:T,XUẤT!N:N,CBCNV!B36,XUẤT!O:O,CBCNV!$M$2) -> 0 | N36: =M36*$T$12 -> 0 | O36: =SUMIFS(XUẤT!U:U,XUẤT!N:N,CBCNV!B36,XUẤT!O:O,CBCNV!$O$2) -> 0 | P36: =O36*$T$13 -> 0
A37: 30 | B37: Đỗ Thị Hiền | C37: NV LĐTL | D37: Văn phòng | E37: =SUMIFS(XUẤT!P:P,XUẤT!N:N,CBCNV!B37,XUẤT!O:O,CBCNV!$E$2) -> 0 | F37: =E37*$T$10 -> 0 | G37: =SUMIFS(XUẤT!Q:Q,XUẤT!N:N,CBCNV!B37,XUẤT!O:O,CBCNV!$G$2) -> 0 | H37: =G37*$T$8 -> 0 | I37: =SUMIFS(XUẤT!R:R,XUẤT!N:N,CBCNV!B37,XUẤT!O:O,CBCNV!$I$2) -> 0 | J37: =I37*$T$9 -> 0 | K37: =SUMIFS(XUẤT!S:S,XUẤT!N:N,CBCNV!B37,XUẤT!O:O,CBCNV!$K$2) -> 0 | L37: =K37*$T$11 -> 0 | M37: =SUMIFS(XUẤT!T:T,XUẤT!N:N,CBCNV!B37,XUẤT!O:O,CBCNV!$M$2) -> 0 | N37: =M37*$T$12 -> 0 | O37: =SUMIFS(XUẤT!U:U,XUẤT!N:N,CBCNV!B37,XUẤT!O:O,CBCNV!$O$2) -> 0 | P37: =O37*$T$13 -> 0
A38: 31 | B38: Phạm Thu Quỳnh | C38: CN tạp vụ | D38: Văn phòng | E38: =SUMIFS(XUẤT!P:P,XUẤT!N:N,CBCNV!B38,XUẤT!O:O,CBCNV!$E$2) -> 0 | F38: =E38*$T$10 -> 0 | G38: =SUMIFS(XUẤT!Q:Q,XUẤT!N:N,CBCNV!B38,XUẤT!O:O,CBCNV!$G$2) -> 0 | H38: =G38*$T$8 -> 0 | I38: =SUMIFS(XUẤT!R:R,XUẤT!N:N,CBCNV!B38,XUẤT!O:O,CBCNV!$I$2) -> 0 | J38: =I38*$T$9 -> 0 | K38: =SUMIFS(XUẤT!S:S,XUẤT!N:N,CBCNV!B38,XUẤT!O:O,CBCNV!$K$2) -> 0 | L38: =K38*$T$11 -> 0 | M38: =SUMIFS(XUẤT!T:T,XUẤT!N:N,CBCNV!B38,XUẤT!O:O,CBCNV!$M$2) -> 0 | N38: =M38*$T$12 -> 0 | O38: =SUMIFS(XUẤT!U:U,XUẤT!N:N,CBCNV!B38,XUẤT!O:O,CBCNV!$O$2) -> 0 | P38: =O38*$T$13 -> 0
... A48: 41 | B48: Bùi Văn Tình | C48: NV kỹ thuật | D48: Văn phòng | E48: =SUMIFS(XUẤT!P:P,XUẤT!N:N,CBCNV!B48,XUẤT!O:O,CBCNV!$E$2) -> 0 | F48: =E48*$T$10 -> 0 | G48: =SUMIFS(XUẤT!Q:Q,XUẤT!N:N,CBCNV!B48,XUẤT!O:O,CBCNV!$G$2) -> 0 | H48: =G48*$T$8 -> 0 | I48: =SUMIFS(XUẤT!R:R,XUẤT!N:N,CBCNV!B48,XUẤT!O:O,CBCNV!$I$2) -> 0 | J48: =I48*$T$9 -> 0 | K48: =SUMIFS(XUẤT!S:S,XUẤT!N:N,CBCNV!B48,XUẤT!O:O,CBCNV!$K$2) -> 0 | L48: =K48*$T$11 -> 0 | M48: =SUMIFS(XUẤT!T:T,XUẤT!N:N,CBCNV!B48,XUẤT!O:O,CBCNV!$M$2) -> 0 | N48: =M48*$T$12 -> 0 | O48: =SUMIFS(XUẤT!U:U,XUẤT!N:N,CBCNV!B48,XUẤT!O:O,CBCNV!$O$2) -> 0 | P48: =O48*$T$13 -> 0
A49: 42 | B49: Chế Thùy Dung | C49: NV kỹ thuật | D49: Văn phòng | E49: =SUMIFS(XUẤT!P:P,XUẤT!N:N,XUẤT!N262,XUẤT!O:O,CBCNV!$E$2) -> 0 | F49: =E49*$T$10 -> 0 | G49: =SUMIFS(XUẤT!Q:Q,XUẤT!N:N,XUẤT!N262,XUẤT!O:O,CBCNV!$G$2) -> 0 | H49: =G49*$T$8 -> 0 | I49: =SUMIFS(XUẤT!R:R,XUẤT!N:N,XUẤT!N262,XUẤT!O:O,CBCNV!$I$2) -> 0 | J49: =I49*$T$9 -> 0 | K49: =SUMIFS(XUẤT!S:S,XUẤT!N:N,XUẤT!N262,XUẤT!O:O,CBCNV!$K$2) -> 0 | L49: =K49*$T$11 -> 0 | M49: =SUMIFS(XUẤT!T:T,XUẤT!N:N,XUẤT!N262,XUẤT!O:O,CBCNV!$M$2) -> 0 | N49: =M49*$T$12 -> 0 | O49: =SUMIFS(XUẤT!U:U,XUẤT!N:N,XUẤT!N262,XUẤT!O:O,CBCNV!$O$2) -> 0 | P49: =O49*$T$13 -> 0
A50: 43 | B50: Khổng Thị Thu Trang | C50: NV kỹ thuật | D50: Văn phòng | E50: =SUMIFS(XUẤT!P:P,XUẤT!N:N,CBCNV!B50,XUẤT!O:O,CBCNV!$E$2) -> 0 | F50: =E50*$T$10 -> 0 | G50: =SUMIFS(XUẤT!Q:Q,XUẤT!N:N,CBCNV!B50,XUẤT!O:O,CBCNV!$G$2) -> 0 | H50: =G50*$T$8 -> 0 | I50: =SUMIFS(XUẤT!R:R,XUẤT!N:N,CBCNV!B50,XUẤT!O:O,CBCNV!$I$2) -> 0 | J50: =I50*$T$9 -> 0 | K50: =SUMIFS(XUẤT!S:S,XUẤT!N:N,CBCNV!B50,XUẤT!O:O,CBCNV!$K$2) -> 0 | L50: =K50*$T$11 -> 0 | M50: =SUMIFS(XUẤT!T:T,XUẤT!N:N,CBCNV!B50,XUẤT!O:O,CBCNV!$M$2) -> 0 | N50: =M50*$T$12 -> 0 | O50: =SUMIFS(XUẤT!U:U,XUẤT!N:N,CBCNV!B50,XUẤT!O:O,CBCNV!$O$2) -> 0 | P50: =O50*$T$13 -> 0
...

Sheet TỒN
A1: THEO DÕI NHẬP, XUẤT NƯỚC QAROMI
A2: Tháng 9/2026
A4: STT | B4: Ngày | C4: Nhập | J4: Xuất | Q4: Tồn
C5: Vỉ 350ml | D5: Hộp 500ml | E5: Vỉ 500ml | F5: Hộp 350ml | G5: Bình kiềm | H5: Bình RO | I5: Cộng | J5: Vỉ 350ml | K5: Hộp 500ml | L5: Vỉ 500ml | M5: Hộp 350ml | N5: Bình kiềm | O5: Bình RO | P5: Cộng | Q5: Vỉ 350ml | R5: Hộp 500ml | S5: Vỉ 500ml | T5: Hộp 350ml | U5: Bình kiềm | V5: Bình RO | W5: Cộng
A6: 1 | B6: 46266 | J6: =SUMIFS(XUẤT!$W:$W,XUẤT!$B:$B,TỒN!$B$12,XUẤT!$O:$O,TỒN!#REF!) -> 0 | K6: =SUMIFS(XUẤT!$W:$W,XUẤT!$B:$B,TỒN!$B$12,XUẤT!$O:$O,TỒN!#REF!) -> 0 | L6: =SUMIFS(XUẤT!$W:$W,XUẤT!$B:$B,TỒN!$B$12,XUẤT!$O:$O,TỒN!#REF!) -> 0 | M6: =SUMIFS(XUẤT!$W:$W,XUẤT!$B:$B,TỒN!$B$12,XUẤT!$O:$O,TỒN!#REF!) -> 0 | N6: =SUMIFS(XUẤT!$W:$W,XUẤT!$B:$B,TỒN!$B$12,XUẤT!$O:$O,TỒN!#REF!) -> 0 | O6: =SUMIFS(XUẤT!$W:$W,XUẤT!$B:$B,TỒN!$B$12,XUẤT!$O:$O,TỒN!#REF!) -> 0 | P6: =SUM(J6:O6) -> 0
A7: 2 | B7: 46267 | J7: =SUMIFS(XUẤT!$W:$W,XUẤT!$B:$B,TỒN!$B$12,XUẤT!$O:$O,TỒN!#REF!) -> 0 | K7: =SUMIFS(XUẤT!$W:$W,XUẤT!$B:$B,TỒN!$B$12,XUẤT!$O:$O,TỒN!#REF!) -> 0 | L7: =SUMIFS(XUẤT!$W:$W,XUẤT!$B:$B,TỒN!$B$12,XUẤT!$O:$O,TỒN!#REF!) -> 0 | M7: =SUMIFS(XUẤT!$W:$W,XUẤT!$B:$B,TỒN!$B$12,XUẤT!$O:$O,TỒN!#REF!) -> 0 | N7: =SUMIFS(XUẤT!$W:$W,XUẤT!$B:$B,TỒN!$B$12,XUẤT!$O:$O,TỒN!#REF!) -> 0 | O7: =SUMIFS(XUẤT!$W:$W,XUẤT!$B:$B,TỒN!$B$12,XUẤT!$O:$O,TỒN!#REF!) -> 0 | P7: =SUM(J7:O7) -> 0
A8: 3 | B8: 46268 | J8: =SUMIFS(XUẤT!$W:$W,XUẤT!$B:$B,TỒN!$B$12,XUẤT!$O:$O,TỒN!J1) -> 0 | K8: =SUMIFS(XUẤT!$W:$W,XUẤT!$B:$B,TỒN!$B$12,XUẤT!$O:$O,TỒN!K1) -> 0 | L8: =SUMIFS(XUẤT!$W:$W,XUẤT!$B:$B,TỒN!$B$12,XUẤT!$O:$O,TỒN!L1) -> 0 | M8: =SUMIFS(XUẤT!$W:$W,XUẤT!$B:$B,TỒN!$B$12,XUẤT!$O:$O,TỒN!M1) -> 0 | N8: =SUMIFS(XUẤT!$W:$W,XUẤT!$B:$B,TỒN!$B$12,XUẤT!$O:$O,TỒN!N1) -> 0 | O8: =SUMIFS(XUẤT!$W:$W,XUẤT!$B:$B,TỒN!$B$12,XUẤT!$O:$O,TỒN!O1) -> 0 | P8: =SUM(J8:O8) -> 0
A9: 4 | B9: 46269 | J9: =SUMIFS(XUẤT!$W:$W,XUẤT!$B:$B,TỒN!$B$12,XUẤT!$O:$O,TỒN!J2) -> 0 | K9: =SUMIFS(XUẤT!$W:$W,XUẤT!$B:$B,TỒN!$B$12,XUẤT!$O:$O,TỒN!K2) -> 0 | L9: =SUMIFS(XUẤT!$W:$W,XUẤT!$B:$B,TỒN!$B$12,XUẤT!$O:$O,TỒN!L2) -> 0 | M9: =SUMIFS(XUẤT!$W:$W,XUẤT!$B:$B,TỒN!$B$12,XUẤT!$O:$O,TỒN!M2) -> 0 | N9: =SUMIFS(XUẤT!$W:$W,XUẤT!$B:$B,TỒN!$B$12,XUẤT!$O:$O,TỒN!N2) -> 0 | O9: =SUMIFS(XUẤT!$W:$W,XUẤT!$B:$B,TỒN!$B$12,XUẤT!$O:$O,TỒN!O2) -> 0 | P9: =SUM(J9:O9) -> 0
A10: 5 | B10: 46270 | J10: =SUMIFS(XUẤT!$W:$W,XUẤT!$B:$B,TỒN!$B$12,XUẤT!$O:$O,TỒN!J3) -> 0 | K10: =SUMIFS(XUẤT!$W:$W,XUẤT!$B:$B,TỒN!$B$12,XUẤT!$O:$O,TỒN!K3) -> 0 | L10: =SUMIFS(XUẤT!$W:$W,XUẤT!$B:$B,TỒN!$B$12,XUẤT!$O:$O,TỒN!L3) -> 0 | M10: =SUMIFS(XUẤT!$W:$W,XUẤT!$B:$B,TỒN!$B$12,XUẤT!$O:$O,TỒN!M3) -> 0 | N10: =SUMIFS(XUẤT!$W:$W,XUẤT!$B:$B,TỒN!$B$12,XUẤT!$O:$O,TỒN!N3) -> 0 | O10: =SUMIFS(XUẤT!$W:$W,XUẤT!$B:$B,TỒN!$B$12,XUẤT!$O:$O,TỒN!O3) -> 0 | P10: =SUM(J10:O10) -> 0
A11: 6 | B11: 46271 | J11: =SUMIFS(XUẤT!$W:$W,XUẤT!$B:$B,TỒN!$B$12,XUẤT!$O:$O,TỒN!J4) -> 0 | K11: =SUMIFS(XUẤT!$W:$W,XUẤT!$B:$B,TỒN!$B$12,XUẤT!$O:$O,TỒN!K4) -> 0 | L11: =SUMIFS(XUẤT!$W:$W,XUẤT!$B:$B,TỒN!$B$12,XUẤT!$O:$O,TỒN!L4) -> 0 | M11: =SUMIFS(XUẤT!$W:$W,XUẤT!$B:$B,TỒN!$B$12,XUẤT!$O:$O,TỒN!M4) -> 0 | N11: =SUMIFS(XUẤT!$W:$W,XUẤT!$B:$B,TỒN!$B$12,XUẤT!$O:$O,TỒN!N4) -> 0 | O11: =SUMIFS(XUẤT!$W:$W,XUẤT!$B:$B,TỒN!$B$12,XUẤT!$O:$O,TỒN!O4) -> 0 | P11: =SUM(J11:O11) -> 0
A12: 7 | B12: 46272 | J12: =SUMIFS(XUẤT!$W:$W,XUẤT!$B:$B,TỒN!$B$12,XUẤT!$O:$O,TỒN!J5) -> 0 | K12: =SUMIFS(XUẤT!$W:$W,XUẤT!$B:$B,TỒN!$B$12,XUẤT!$O:$O,TỒN!K5) -> 0 | L12: =SUMIFS(XUẤT!$W:$W,XUẤT!$B:$B,TỒN!$B$12,XUẤT!$O:$O,TỒN!L5) -> 0 | M12: =SUMIFS(XUẤT!$W:$W,XUẤT!$B:$B,TỒN!$B$12,XUẤT!$O:$O,TỒN!M5) -> 0 | N12: =SUMIFS(XUẤT!$W:$W,XUẤT!$B:$B,TỒN!$B$12,XUẤT!$O:$O,TỒN!N5) -> 0 | O12: =SUMIFS(XUẤT!$W:$W,XUẤT!$B:$B,TỒN!$B$12,XUẤT!$O:$O,TỒN!O5) -> 0 | P12: =SUM(J12:O12) -> 0
A13: 8 | B13: 46273 | J13: =SUMIFS(XUẤT!$W:$W,XUẤT!$B:$B,TỒN!$B$12,XUẤT!$O:$O,TỒN!J12) -> 0 | K13: =SUMIFS(XUẤT!$W:$W,XUẤT!$B:$B,TỒN!$B$12,XUẤT!$O:$O,TỒN!K12) -> 0 | L13: =SUMIFS(XUẤT!$W:$W,XUẤT!$B:$B,TỒN!$B$12,XUẤT!$O:$O,TỒN!L12) -> 0 | M13: =SUMIFS(XUẤT!$W:$W,XUẤT!$B:$B,TỒN!$B$12,XUẤT!$O:$O,TỒN!M12) -> 0 | N13: =SUMIFS(XUẤT!$W:$W,XUẤT!$B:$B,TỒN!$B$12,XUẤT!$O:$O,TỒN!N12) -> 0 | O13: =SUMIFS(XUẤT!$W:$W,XUẤT!$B:$B,TỒN!$B$12,XUẤT!$O:$O,TỒN!O12) -> 0 | P13: =SUM(J13:O13) -> 0
A14: 9 | B14: 46274 | J14: =SUMIFS(XUẤT!$W:$W,XUẤT!$B:$B,TỒN!$B$12,XUẤT!$O:$O,TỒN!J13) -> 0 | K14: =SUMIFS(XUẤT!$W:$W,XUẤT!$B:$B,TỒN!$B$12,XUẤT!$O:$O,TỒN!K13) -> 0 | L14: =SUMIFS(XUẤT!$W:$W,XUẤT!$B:$B,TỒN!$B$12,XUẤT!$O:$O,TỒN!L13) -> 0 | M14: =SUMIFS(XUẤT!$W:$W,XUẤT!$B:$B,TỒN!$B$12,XUẤT!$O:$O,TỒN!M13) -> 0 | N14: =SUMIFS(XUẤT!$W:$W,XUẤT!$B:$B,TỒN!$B$12,XUẤT!$O:$O,TỒN!N13) -> 0 | O14: =SUMIFS(XUẤT!$W:$W,XUẤT!$B:$B,TỒN!$B$12,XUẤT!$O:$O,TỒN!O13) -> 0 | P14: =SUM(J14:O14) -> 0
A15: 10 | B15: 46275 | J15: =SUMIFS(XUẤT!$W:$W,XUẤT!$B:$B,TỒN!$B$12,XUẤT!$O:$O,TỒN!J14) -> 0 | K15: =SUMIFS(XUẤT!$W:$W,XUẤT!$B:$B,TỒN!$B$12,XUẤT!$O:$O,TỒN!K14) -> 0 | L15: =SUMIFS(XUẤT!$W:$W,XUẤT!$B:$B,TỒN!$B$12,XUẤT!$O:$O,TỒN!L14) -> 0 | M15: =SUMIFS(XUẤT!$W:$W,XUẤT!$B:$B,TỒN!$B$12,XUẤT!$O:$O,TỒN!M14) -> 0 | N15: =SUMIFS(XUẤT!$W:$W,XUẤT!$B:$B,TỒN!$B$12,XUẤT!$O:$O,TỒN!N14) -> 0 | O15: =SUMIFS(XUẤT!$W:$W,XUẤT!$B:$B,TỒN!$B$12,XUẤT!$O:$O,TỒN!O14) -> 0 | P15: =SUM(J15:O15) -> 0
A16: 11 | B16: 46276 | J16: =SUMIFS(XUẤT!$W:$W,XUẤT!$B:$B,TỒN!$B$12,XUẤT!$O:$O,TỒN!J15) -> 0 | K16: =SUMIFS(XUẤT!$W:$W,XUẤT!$B:$B,TỒN!$B$12,XUẤT!$O:$O,TỒN!K15) -> 0 | L16: =SUMIFS(XUẤT!$W:$W,XUẤT!$B:$B,TỒN!$B$12,XUẤT!$O:$O,TỒN!L15) -> 0 | M16: =SUMIFS(XUẤT!$W:$W,XUẤT!$B:$B,TỒN!$B$12,XUẤT!$O:$O,TỒN!M15) -> 0 | N16: =SUMIFS(XUẤT!$W:$W,XUẤT!$B:$B,TỒN!$B$12,XUẤT!$O:$O,TỒN!N15) -> 0 | O16: =SUMIFS(XUẤT!$W:$W,XUẤT!$B:$B,TỒN!$B$12,XUẤT!$O:$O,TỒN!O15) -> 0 | P16: =SUM(J16:O16) -> 0
A17: 12 | B17: 46277 | J17: =SUMIFS(XUẤT!$W:$W,XUẤT!$B:$B,TỒN!$B$12,XUẤT!$O:$O,TỒN!J16) -> 0 | K17: =SUMIFS(XUẤT!$W:$W,XUẤT!$B:$B,TỒN!$B$12,XUẤT!$O:$O,TỒN!K16) -> 0 | L17: =SUMIFS(XUẤT!$W:$W,XUẤT!$B:$B,TỒN!$B$12,XUẤT!$O:$O,TỒN!L16) -> 0 | M17: =SUMIFS(XUẤT!$W:$W,XUẤT!$B:$B,TỒN!$B$12,XUẤT!$O:$O,TỒN!M16) -> 0 | N17: =SUMIFS(XUẤT!$W:$W,XUẤT!$B:$B,TỒN!$B$12,XUẤT!$O:$O,TỒN!N16) -> 0 | O17: =SUMIFS(XUẤT!$W:$W,XUẤT!$B:$B,TỒN!$B$12,XUẤT!$O:$O,TỒN!O16) -> 0 | P17: =SUM(J17:O17) -> 0
A18: 13 | B18: 46278 | J18: =SUMIFS(XUẤT!$W:$W,XUẤT!$B:$B,TỒN!$B$12,XUẤT!$O:$O,TỒN!J17) -> 0 | K18: =SUMIFS(XUẤT!$W:$W,XUẤT!$B:$B,TỒN!$B$12,XUẤT!$O:$O,TỒN!K17) -> 0 | L18: =SUMIFS(XUẤT!$W:$W,XUẤT!$B:$B,TỒN!$B$12,XUẤT!$O:$O,TỒN!L17) -> 0 | M18: =SUMIFS(XUẤT!$W:$W,XUẤT!$B:$B,TỒN!$B$12,XUẤT!$O:$O,TỒN!M17) -> 0 | N18: =SUMIFS(XUẤT!$W:$W,XUẤT!$B:$B,TỒN!$B$12,XUẤT!$O:$O,TỒN!N17) -> 0 | O18: =SUMIFS(XUẤT!$W:$W,XUẤT!$B:$B,TỒN!$B$12,XUẤT!$O:$O,TỒN!O17) -> 0 | P18: =SUM(J18:O18) -> 0
A19: 14 | B19: 46279 | J19: =SUMIFS(XUẤT!$W:$W,XUẤT!$B:$B,TỒN!$B$12,XUẤT!$O:$O,TỒN!J18) -> 0 | K19: =SUMIFS(XUẤT!$W:$W,XUẤT!$B:$B,TỒN!$B$12,XUẤT!$O:$O,TỒN!K18) -> 0 | L19: =SUMIFS(XUẤT!$W:$W,XUẤT!$B:$B,TỒN!$B$12,XUẤT!$O:$O,TỒN!L18) -> 0 | M19: =SUMIFS(XUẤT!$W:$W,XUẤT!$B:$B,TỒN!$B$12,XUẤT!$O:$O,TỒN!M18) -> 0 | N19: =SUMIFS(XUẤT!$W:$W,XUẤT!$B:$B,TỒN!$B$12,XUẤT!$O:$O,TỒN!N18) -> 0 | O19: =SUMIFS(XUẤT!$W:$W,XUẤT!$B:$B,TỒN!$B$12,XUẤT!$O:$O,TỒN!O18) -> 0 | P19: =SUM(J19:O19) -> 0
A20: 15 | B20: 46280 | J20: =SUMIFS(XUẤT!$W:$W,XUẤT!$B:$B,TỒN!$B$12,XUẤT!$O:$O,TỒN!J19) -> 0 | K20: =SUMIFS(XUẤT!$W:$W,XUẤT!$B:$B,TỒN!$B$12,XUẤT!$O:$O,TỒN!K19) -> 0 | L20: =SUMIFS(XUẤT!$W:$W,XUẤT!$B:$B,TỒN!$B$12,XUẤT!$O:$O,TỒN!L19) -> 0 | M20: =SUMIFS(XUẤT!$W:$W,XUẤT!$B:$B,TỒN!$B$12,XUẤT!$O:$O,TỒN!M19) -> 0 | N20: =SUMIFS(XUẤT!$W:$W,XUẤT!$B:$B,TỒN!$B$12,XUẤT!$O:$O,TỒN!N19) -> 0 | O20: =SUMIFS(XUẤT!$W:$W,XUẤT!$B:$B,TỒN!$B$12,XUẤT!$O:$O,TỒN!O19) -> 0 | P20: =SUM(J20:O20) -> 0
A21: 16 | B21: 46281 | J21: =SUMIFS(XUẤT!$W:$W,XUẤT!$B:$B,TỒN!$B$12,XUẤT!$O:$O,TỒN!J20) -> 0 | K21: =SUMIFS(XUẤT!$W:$W,XUẤT!$B:$B,TỒN!$B$12,XUẤT!$O:$O,TỒN!K20) -> 0 | L21: =SUMIFS(XUẤT!$W:$W,XUẤT!$B:$B,TỒN!$B$12,XUẤT!$O:$O,TỒN!L20) -> 0 | M21: =SUMIFS(XUẤT!$W:$W,XUẤT!$B:$B,TỒN!$B$12,XUẤT!$O:$O,TỒN!M20) -> 0 | N21: =SUMIFS(XUẤT!$W:$W,XUẤT!$B:$B,TỒN!$B$12,XUẤT!$O:$O,TỒN!N20) -> 0 | O21: =SUMIFS(XUẤT!$W:$W,XUẤT!$B:$B,TỒN!$B$12,XUẤT!$O:$O,TỒN!O20) -> 0 | P21: =SUM(J21:O21) -> 0
A22: 17 | B22: 46282 | J22: =SUMIFS(XUẤT!$W:$W,XUẤT!$B:$B,TỒN!$B$12,XUẤT!$O:$O,TỒN!J21) -> 0 | K22: =SUMIFS(XUẤT!$W:$W,XUẤT!$B:$B,TỒN!$B$12,XUẤT!$O:$O,TỒN!K21) -> 0 | L22: =SUMIFS(XUẤT!$W:$W,XUẤT!$B:$B,TỒN!$B$12,XUẤT!$O:$O,TỒN!L21) -> 0 | M22: =SUMIFS(XUẤT!$W:$W,XUẤT!$B:$B,TỒN!$B$12,XUẤT!$O:$O,TỒN!M21) -> 0 | N22: =SUMIFS(XUẤT!$W:$W,XUẤT!$B:$B,TỒN!$B$12,XUẤT!$O:$O,TỒN!N21) -> 0 | O22: =SUMIFS(XUẤT!$W:$W,XUẤT!$B:$B,TỒN!$B$12,XUẤT!$O:$O,TỒN!O21) -> 0 | P22: =SUM(J22:O22) -> 0
A23: 18 | B23: 46283 | J23: =SUMIFS(XUẤT!$W:$W,XUẤT!$B:$B,TỒN!$B$12,XUẤT!$O:$O,TỒN!J22) -> 0 | K23: =SUMIFS(XUẤT!$W:$W,XUẤT!$B:$B,TỒN!$B$12,XUẤT!$O:$O,TỒN!K22) -> 0 | L23: =SUMIFS(XUẤT!$W:$W,XUẤT!$B:$B,TỒN!$B$12,XUẤT!$O:$O,TỒN!L22) -> 0 | M23: =SUMIFS(XUẤT!$W:$W,XUẤT!$B:$B,TỒN!$B$12,XUẤT!$O:$O,TỒN!M22) -> 0 | N23: =SUMIFS(XUẤT!$W:$W,XUẤT!$B:$B,TỒN!$B$12,XUẤT!$O:$O,TỒN!N22) -> 0 | O23: =SUMIFS(XUẤT!$W:$W,XUẤT!$B:$B,TỒN!$B$12,XUẤT!$O:$O,TỒN!O22) -> 0 | P23: =SUM(J23:O23) -> 0
A24: 19 | B24: 46284 | J24: =SUMIFS(XUẤT!$W:$W,XUẤT!$B:$B,TỒN!$B$12,XUẤT!$O:$O,TỒN!J23) -> 0 | K24: =SUMIFS(XUẤT!$W:$W,XUẤT!$B:$B,TỒN!$B$12,XUẤT!$O:$O,TỒN!K23) -> 0 | L24: =SUMIFS(XUẤT!$W:$W,XUẤT!$B:$B,TỒN!$B$12,XUẤT!$O:$O,TỒN!L23) -> 0 | M24: =SUMIFS(XUẤT!$W:$W,XUẤT!$B:$B,TỒN!$B$12,XUẤT!$O:$O,TỒN!M23) -> 0 | N24: =SUMIFS(XUẤT!$W:$W,XUẤT!$B:$B,TỒN!$B$12,XUẤT!$O:$O,TỒN!N23) -> 0 | O24: =SUMIFS(XUẤT!$W:$W,XUẤT!$B:$B,TỒN!$B$12,XUẤT!$O:$O,TỒN!O23) -> 0 | P24: =SUM(J24:O24) -> 0
... A35: 30 | B35: 46295 | J35: =SUMIFS(XUẤT!$W:$W,XUẤT!$B:$B,TỒN!$B$12,XUẤT!$O:$O,TỒN!J34) -> 0 | K35: =SUMIFS(XUẤT!$W:$W,XUẤT!$B:$B,TỒN!$B$12,XUẤT!$O:$O,TỒN!K34) -> 0 | L35: =SUMIFS(XUẤT!$W:$W,XUẤT!$B:$B,TỒN!$B$12,XUẤT!$O:$O,TỒN!L34) -> 0 | M35: =SUMIFS(XUẤT!$W:$W,XUẤT!$B:$B,TỒN!$B$12,XUẤT!$O:$O,TỒN!M34) -> 0 | N35: =SUMIFS(XUẤT!$W:$W,XUẤT!$B:$B,TỒN!$B$12,XUẤT!$O:$O,TỒN!N34) -> 0 | O35: =SUMIFS(XUẤT!$W:$W,XUẤT!$B:$B,TỒN!$B$12,XUẤT!$O:$O,TỒN!O34) -> 0 | P35: =SUM(J35:O35) -> 0
B36: Cộng | C36: =SUM(C12:C35) -> 0 | D36: =SUM(D12:D35) -> 0 | E36: =SUM(E12:E35) -> 0 | F36: =SUM(F12:F35) -> 0 | G36: =SUM(G12:G35) -> 0 | H36: =SUM(H12:H35) -> 0 | I36: =SUM(I12:I35) -> 0 | J36: =SUM(J12:J35) -> 0 | ... W36: =SUM(W12:W35) -> 0

Sheet ĐIÈU PHỐI
A1: ĐIỀU PHỐI QAROMI
A3: STT | B3: Họ tên | C3: Tổ/Trạm | D3: Địa chỉ nhà | E3: SĐT | F3: Khu vực thực hiện | H3: TỔ BẢO VỆ THÁNG 9
A4: I | B4: Bốc xếp, vận chuyển | H4: Ngày | I4: Thứ | J4: Người thực hiện | L4: Bùi Đức Hoàng | M4: =COUNTIFS($J$5:$J$28,L4) -> 3
A5: 1 | B5: Đinh Thu Huế | C5: Tổ thị trường | D5: Cao Xanh | E5: 0963913555 | F5: Cao Xanh, Hồng Gai | H5: 1 | I5: 2 | L5: Nguyễn Thị Hằng | M5: =COUNTIFS($J$5:$J$28,L5) -> 3
A6: 2 | B6: Đặng Thị Huyền | C6: Tổ DVCTT | D6: Cứu Hỏa | E6: 0966785220 | H6: 8 | I6: 3 | J6: Nguyễn Thị Hằng | L6: Nguyễn Thị Thùy | M6: =COUNTIFS($J$5:$J$28,L6) -> 4
A7: 3 | B7: Trần Bích Ly | D7: Bãi Muối | E7: 0988168666 | H7: 9 | I7: 4 | J7: Nguyễn Thị Thùy | L7: Đỗ Thị Vượng | M7: =COUNTIFS($J$5:$J$28,L7) -> 3
A8: 4 | B8: Bùi Đức Hoàng | C8: Bảo vệ | D8: Cột 3 | E8: 0982916899 | H8: 10 | I8: 5 | J8: Đỗ Thị Vượng | L8: Trăng Thị Thơm | M8: =COUNTIFS($J$5:$J$28,L8) -> 3
A9: 5 | B9: Nguyễn Thị Thùy | D9: Hà Trung | E9: 0365577629 | H9: 11 | I9: 6 | J9: Nguyễn Thị Huy | L9: Dương Thị Thu | M9: =COUNTIFS($J$5:$J$28,L9) -> 2
A10: 6 | B10: Nguyễn Thị Hằng | D10: Cột 3 | E10: 0787224668 | H10: 12 | I10: 7 | J10: Trăng Thị Thơm | L10: Nguyễn Thị Huy | M10: =COUNTIFS($J$5:$J$28,L10) -> 4
A11: 7 | B11: Trăng Thị Thơm | D11: Hà Phong | E11: 0379221778
A12: 8 | B12: Đỗ Thị Vượng | D12: Cột 5 | E12: 0914988892 | H12: 14 | I12: 2 | J12: Đỗ Thị Vượng
A13: 9 | B13: Nguyễn Thị Huy | D13: Cột 3 | E13: 0388573628 | H13: 15 | I13: 3 | J13: Bùi Đức Hoàng | K13: nghỉ phép
A14: 10 | B14: Dương Thị Thu | D14: Yết Kiêu | E14: 0838980944 | H14: 16 | I14: 4 | J14: Nguyễn Thị Thùy
A15: 11 | B15: Nguyễn Thị Chi | C15: Hạ Long | D15: Cột 5 | E15: 0855198226 | F15: Cột 3, cột 5 | H15: 17 | I15: 5 | J15: Dương Thị Thu
A16: 12 | B16: Lê Thanh Xuân | C16: Hà Tu | D16: Hà Tu | E16: 0962672181 | F16: Tăng áp -> Hà Tu | H16: 18 | I16: 6 | J16: Trăng Thị Thơm
A17: 13 | B17: Nguyễn Văn Hưng | C17: Hà Lầm | E17: 0915196225 | F17: Hà Lầm | H17: 19 | I17: 7 | J17: Nguyễn Thị Hằng | K17: nghỉ phép
A18: 14 | B18: Trần Trọng Khoa | C18: Hồng Gai | E18: 0904099383 | F18: Hồng Gai | H18: 20 | I18: CN | J18: Nguyễn Thị Huy | L18: Tùng chạy xe
A19: 15 | B19: Nguyễn Thanh Xuyền | C19: Đá Trắng | E19: 0982757198 | F19: Đá Trắng | H19: 21 | I19: 2 | J19: Nguyễn Thị Hằng | K19: nghỉ phép | L19: Tùng chạy xe
A20: II | B20: Lái xe tải điện | H20: 22 | I20: 3 | J20: Trăng Thị Thơm
A21: 1 | B21: Nguyễn Thị Hồng Phương | D21: Yết Kiêu | E21: 0934399569 | H21: 23 | I21: 4 | J21: Dương Thị Thu
A22: 2 | B22: Đặng Thanh Tùng | D22: Cao Xanh | E22: 0968333882 | H22: 24 | I22: 5 | J22: Nguyễn Thị Thùy
H23: 25 | I23: 6 | J23: Nguyễn Thị Huy
A24: STT | B24: Thứ tự điều phối | H24: 26 | I24: 7 | J24: Đỗ Thị Vượng
A25: 1 | B25: Tổ Tiếp thị | H25: 27 | I25: CN | J25: Bùi Đức Hoàng
A26: 2 | B26: Tổ Dịch vụ | H26: 28 | I26: 2 | J26: Nguyễn Thị Huy
A27: 3 | B27: Tổ Bảo vệ | H27: 29 | I27: 3 | J27: Bùi Đức Hoàng
A28: 4 | B28: Trạm QL | H28: 30 | I28: 4 | J28: Nguyễn Thị Thùy

Sheet Vận chuyển
A1: TỔNG HỢP CHI PHÍ VẬN CHUYỂN, BỐC XẾP
A2: Tháng 9/2026
A4: STT | B4: Người thực hiện | C4: Tổ/Trạm | D4: Số lượng | E4: Số tiền
A5: 1 | B5: Xí nghiệp | D5: =SUMIFS(XUẤT!AB:AB,XUẤT!AA:AA,'Vận chuyển'!B5) -> 0 | E5: =D5*5000 -> 0
A6: 2 | B6: Đinh Thu Huế | C6: Tổ thị trường | D6: =SUMIFS(XUẤT!AB:AB,XUẤT!AA:AA,'Vận chuyển'!B6) -> 44 | E6: =D6*5000 -> 220000
A7: 3 | B7: Tổ DVCTT | C7: Tổ DVCTT | D7: =SUMIFS(XUẤT!AB:AB,XUẤT!AA:AA,'Vận chuyển'!B7) -> 0 | E7: =D7*5000 -> 0
A8: 5 | B8: Bùi Đức Hoàng | C8: Bảo vệ | D8: =SUMIFS(XUẤT!AB:AB,XUẤT!AA:AA,'Vận chuyển'!B8) -> 0 | E8: =D8*5000 -> 0
A9: 6 | B9: Nguyễn Thị Thùy | D9: =SUMIFS(XUẤT!AB:AB,XUẤT!AA:AA,'Vận chuyển'!B9) -> 0 | E9: =D9*5000 -> 0
A10: 7 | B10: Nguyễn Thị Hằng | D10: =SUMIFS(XUẤT!AB:AB,XUẤT!AA:AA,'Vận chuyển'!B10) -> 0 | E10: =D10*5000 -> 0
A11: 8 | B11: Tăng Thị Thơm | D11: =SUMIFS(XUẤT!AB:AB,XUẤT!AA:AA,'Vận chuyển'!B11) -> 0 | E11: =D11*5000 -> 0
A12: 9 | B12: Đỗ Thị Vượng | D12: =SUMIFS(XUẤT!AB:AB,XUẤT!AA:AA,'Vận chuyển'!B12) -> 2 | E12: =D12*5000 -> 10000
A13: 10 | B13: Nguyễn Thị Huy | D13: =SUMIFS(XUẤT!AB:AB,XUẤT!AA:AA,'Vận chuyển'!B13) -> 6 | E13: =D13*5000 -> 30000
A14: 11 | B14: Dương Thị Thu | D14: =SUMIFS(XUẤT!AB:AB,XUẤT!AA:AA,'Vận chuyển'!B14) -> 0 | E14: =D14*5000 -> 0
A15: 12 | B15: Nguyễn Thị Chi | C15: Hạ Long | D15: =SUMIFS(XUẤT!AB:AB,XUẤT!AA:AA,'Vận chuyển'!B15) -> 0 | E15: =D15*5000 -> 0
A16: 13 | B16: Lê Thanh Xuân | C16: Hà Tu | D16: =SUMIFS(XUẤT!AB:AB,XUẤT!AA:AA,'Vận chuyển'!B16) -> 3 | E16: =D16*5000 -> 15000
A17: 14 | B17: Nguyễn Văn Hưng | C17: Hà Lầm | D17: =SUMIFS(XUẤT!AB:AB,XUẤT!AA:AA,'Vận chuyển'!B17) -> 0 | E17: =D17*5000 -> 0
A18: 15 | B18: Trần Trọng Khoa | C18: Hồng Gai | D18: =SUMIFS(XUẤT!AB:AB,XUẤT!AA:AA,'Vận chuyển'!B18) -> 0 | E18: =D18*5000 -> 0
A19: 16 | B19: Nguyễn Thanh Xuyền | C19: Đá Trắng | D19: =SUMIFS(XUẤT!AB:AB,XUẤT!AA:AA,'Vận chuyển'!B19) -> 0 | E19: =D19*5000 -> 0
A20: 17 | B20: Phạm Thị Đan Thanh | D20: =SUMIFS(XUẤT!AB:AB,XUẤT!AA:AA,'Vận chuyển'!B20) -> 5 | E20: =D20*5000 -> 25000
A21: 18 | B21: Mai Anh Dũng | C21: Văn phòng | D21: =SUMIFS(XUẤT!AB:AB,XUẤT!AA:AA,'Vận chuyển'!B21) -> 0 | E21: =D21*5000 -> 0
A22: 18 | B22: Vũ Thị Tươi | C22: Cao Xanh | D22: =SUMIFS(XUẤT!AB:AB,XUẤT!AA:AA,'Vận chuyển'!B22) -> 0 | E22: =D22*5000 -> 0
A23: 19 | B23: Lương Thị Vân Mai | C23: Cao Xanh | D23: =SUMIFS(XUẤT!AB:AB,XUẤT!AA:AA,'Vận chuyển'!B23) -> 0 | E23: =D23*5000 -> 0
A24: 20 | B24: Bùi Thị Thu | C24: Cao Xanh | D24: =SUMIFS(XUẤT!AB:AB,XUẤT!AA:AA,'Vận chuyển'!B24) -> 0 | E24: =D24*5000 -> 0
A25: 21 | B25: Lại Thị Lan | C25: Tổ thị trường | D25: =SUMIFS(XUẤT!AB:AB,XUẤT!AA:AA,'Vận chuyển'!B25) -> 0 | E25: =D25*5000 -> 0
A26: 22 | B26: Lưu Hải Yến | C26: Hồng Gai | D26: =SUMIFS(XUẤT!AB:AB,XUẤT!AA:AA,'Vận chuyển'!B26) -> 0 | E26: =D26*5000 -> 0
A27: 23 | B27: Bùi Ngọc Nguyên | C27: Văn phòng | D27: =SUMIFS(XUẤT!AB:AB,XUẤT!AA:AA,'Vận chuyển'!B27) -> 0 | E27: =D27*5000 -> 0
A28: 24 | B28: Lê Như Hùng | C28: Văn phòng | D28: =SUMIFS(XUẤT!AB:AB,XUẤT!AA:AA,'Vận chuyển'!B28) -> 0 | E28: =D28*5000 -> 0
A29: 25 | B29: Mạc Thị Thanh Tú | C29: Hà Lầm | D29: =SUMIFS(XUẤT!AB:AB,XUẤT!AA:AA,'Vận chuyển'!B29) -> 0 | E29: =D29*5000 -> 0
A30: 26 | B30: Bùi Hà Thu | C30: Hà Lầm | D30: =SUMIFS(XUẤT!AB:AB,XUẤT!AA:AA,'Vận chuyển'!B30) -> 0 | E30: =D30*5000 -> 0
A31: 27 | B31: Phạm Thu Quỳnh | C31: Hà Lầm | D31: =SUMIFS(XUẤT!AB:AB,XUẤT!AA:AA,'Vận chuyển'!B31) -> 0 | E31: =D31*5000 -> 0
A32: 28 | B32: Vũ Thị Thanh Thảo | C32: Hạ Long | D32: =SUMIFS(XUẤT!AB:AB,XUẤT!AA:AA,'Vận chuyển'!B32) -> 0 | E32: =D32*5000 -> 0
A33: 29 | B33: Nguyễn Thị Thúy Hằng | D33: =SUMIFS(XUẤT!AB:AB,XUẤT!AA:AA,'Vận chuyển'!B33) -> 10 | E33: =D33*5000 -> 50000
A34: 30 | B34: Nguyễn Thị Hằng | C34: Bảo vệ | D34: =SUMIFS(XUẤT!AB:AB,XUẤT!AA:AA,'Vận chuyển'!B34) -> 0 | E34: =D34*5000 -> 0
A35: 31 | B35: Nguyễn Thị Hiếu | C35: Ghi số | D35: =SUMIFS(XUẤT!AB:AB,XUẤT!AA:AA,'Vận chuyển'!B35) -> 0 | E35: =D35*5000 -> 0
A36: 32 | B36: Nguyễn Thị Hồng Phương | C36: Lai xe | D36: =SUMIFS(XUẤT!AB:AB,XUẤT!AA:AA,'Vận chuyển'!B36) -> 0 | E36: =D36*5000 -> 0
A37: 33 | B37: Tăng Thị Thơm | D37: =SUMIFS(XUẤT!AB:AB,XUẤT!AA:AA,'Vận chuyển'!B37) -> 0 | E37: =D37*5000 -> 0
A38: 34 | B38: Phương + Huế | D38: =SUMIFS(XUẤT!AB:AB,XUẤT!AA:AA,'Vận chuyển'!B38) -> 0 | E38: =D38*5000 -> 0
A39: 35 | B39: Yến Quảng Yên | D39: =SUMIFS(XUẤT!AB:AB,XUẤT!AA:AA,'Vận chuyển'!B39) -> 0 | E39: =D39*5000 -> 0
A40: 36 | B40: Bùi Ngọc Mai | D40: =SUMIFS(XUẤT!AB:AB,XUẤT!AA:AA,'Vận chuyển'!B40) -> 0 | E40: =D40*5000 -> 0
A41: 37 | B41: Thảo Cẩm Phả | D41: =SUMIFS(XUẤT!AB:AB,XUẤT!AA:AA,'Vận chuyển'!B41) -> 0 | E41: =D41*5000 -> 0
...

Sheet Đơn giá
A3: STT | B3: Hàng hóa | C3: Giá bán | I3: SL | J3: ĐG | K3: tiền
A4: 1 | B4: Vỉ 350ml | C4: 85000 | F4: Công ty | I4: 688 | J4: 98000 | K4: =I4*J4 -> 67424000
A5: 2 | B5: Hộp 350ml | C5: 93000 | F5: Xí nghiệp | I5: 80 | J5: 93000 | K5: =I5*J5 -> 7440000
A6: 3 | B6: Vỉ 500ml | C6: 98000 | I6: 62 | J6: 48000 | K6: =I6*J6 -> 2976000
A7: 4 | B7: Hộp 500ml | C7: 106000 | I7: 147 | J7: 52000 | K7: =I7*J7 -> 7644000
A8: 5 | B8: Bình kiềm | C8: 52000 | I8: 18 | J8: 93000 | K8: =I8*J8 -> 1674000
A9: 6 | B9: Bình RO | C9: 48000 | J9: Tổng | K9: =SUM(K4:K8) -> 87158000

Sheet TỒN TỔNG
A1: STT | B1: NGÀY | C1: Kho | D1: TỒN CUỐI | I1: GHI CHÚ
D2: BÌNH RO | E2: BÌNH KIỀM | F2: Hộp 500 ML | G2: VỈ 500ML | H2: VỈ 350ML | I2: 8/9 VAY KHO CÔNG TY 22 VỈ 500ML – ĐƠN PHƯƠNG LÁI XE
A3: 1 | B3: 11/9/2026 | C3: Kho Huế | D3: ='TỒN KHO HUẾ'!#REF! -> #REF! | E3: ='TỒN KHO HUẾ'!#REF! -> #REF! | F3: ='TỒN KHO HUẾ'!#REF! -> #REF! | G3: ='TỒN KHO HUẾ'!#REF! -> #REF! | H3: ='TỒN KHO HUẾ'!#REF! -> #REF!
A4: 2 | C4: Kho tăng áp | D4: ='TỒN KHO TĂNG ÁP'!#REF! -> #REF! | E4: ='TỒN KHO TĂNG ÁP'!#REF! -> #REF! | F4: ='TỒN KHO TĂNG ÁP'!#REF! -> #REF! | G4: ='TỒN KHO TĂNG ÁP'!#REF! -> #REF! | H4: ='TỒN KHO TĂNG ÁP'!#REF! -> #REF!
A5: 3 | C5: Kho văn phòng | D5: ='Tồn kho VP'!R6 -> 0 | E5: ='Tồn kho VP'!S6 -> 0 | F5: ='Tồn kho VP'!T6 -> 0 | G5: ='Tồn kho VP'!U6 -> 51 | H5: ='Tồn kho VP'!V6 -> 0
A6: 4 | B6: 46365 | C6: Kho Huế | D6: ='TỒN KHO HUẾ'!#REF! -> #REF! | E6: ='TỒN KHO HUẾ'!#REF! -> #REF! | F6: ='TỒN KHO HUẾ'!#REF! -> #REF! | G6: ='TỒN KHO HUẾ'!#REF! -> #REF! | H6: ='TỒN KHO HUẾ'!#REF! -> #REF!
A7: 5 | C7: Kho tăng áp | D7: ='TỒN KHO TĂNG ÁP'!#REF! -> #REF! | E7: ='TỒN KHO TĂNG ÁP'!#REF! -> #REF! | F7: ='TỒN KHO TĂNG ÁP'!#REF! -> #REF! | G7: ='TỒN KHO TĂNG ÁP'!#REF! -> #REF! | H7: ='TỒN KHO TĂNG ÁP'!#REF! -> #REF!
A8: 6 | C8: Kho văn phòng | D8: ='Tồn kho VP'!R7 -> 0 | E8: ='Tồn kho VP'!S7 -> 0 | F8: ='Tồn kho VP'!T7 -> 0 | G8: ='Tồn kho VP'!U7 -> 47 | H8: ='Tồn kho VP'!V7 -> 0
