Workbook

Sheet XUẤT
A1: ĐIỀU PHỐI QUAROMI | M1: CHỈ TIÊU | AA1: VẬN CHUYỂN
A3: STT | B3: Ngày | C3: Đơn hàng | D3: Công việc | E3: Kho | F3: Số lượng | J3: Người thực hiện | K3: Hỗ Trợ (trạm QL) | L3: Kết quả | M3: Chỉ tiêu | N3: Chỉ tiêu CBCNV | O3: Sản phẩm | P3: Số lượng | X3: Đơn giá | Y3: Doanh thu | Z3: Thu tiền | AA3: Người vận chuyển | AB3: Số lượng | AC3: Số tiền | AD3: GHI CHÚ
F4: Thùng | G4: Vỉ | H4: Bình | I4: Cộng | M4: XN/CTY | N4: CBCNV | P4: Vỉ 500ml | Q4: Vỉ 350 ml | R4: Hộp 500ml | S4: Hộp 350ml | T4: Bình kiềm | U4: Bình RO | V4: KM | W4: Cộng
P5: =SUBTOTAL(9,P6:P256) -> 1019 | Q5: =SUBTOTAL(9,Q6:Q256) -> 67 | R5: =SUBTOTAL(9,R6:R256) -> 10 | S5: =SUBTOTAL(9,S6:S256) -> 6 | T5: =SUBTOTAL(9,T6:T256) -> 109 | U5: =SUBTOTAL(9,U6:U256) -> 79 | V5: =SUBTOTAL(9,V6:V256) -> 89 | W5: =SUBTOTAL(9,W6:W161) -> 746 | AB5: =SUBTOTAL(9,AB6:AB161) -> 693 | AC5: =SUBTOTAL(9,AC6:AC161) -> 3465000
A6: 9 | B6: 46272 | C6: Nguyễn Giang Qtri: công ty luật minh hà: 275 hà trung, 5+1 vỉ 500ml | D6: Vận chuyển | G6: 6 | I6: =H6+G6 -> 6 | J6: Phương + Huế | L6: Đã hoàn thành | M6: Công ty | O6: Vỉ 500ml | P6: 5 | V6: 1 | W6: =SUM(P6:V6) -> 6 | X6: =SUMIFS('Đơn giá'!C:C,'Đơn giá'!B:B,XUẤT!O6) -> 98000 | Y6: =X6*P6 -> 490000 | AB6: =W6-V6 -> 5 | AC6: =AB6*5000 -> 25000
A7: 10 | B7: 46272 | C7: Hồng Hạnh PCN: 0367338092 Mộc baby store cao xanh đường Vạn Hạnh có nhu cầu 1 bình kiềm ship từ 08h đến 10h sáng nay, khách hàng thanh toán! | D7: Vận chuyển | H7: 1 | I7: =H7+G7 -> 1 | J7: A Khoa - Trạm Hồng Gai | L7: Đã hoàn thành | M7: Công ty | O7: Bình kiềm | P7: 1 | W7: =SUM(P7:V7) -> 1 | X7: =SUMIFS('Đơn giá'!C:C,'Đơn giá'!B:B,XUẤT!O7) -> 52000 | Y7: =X7*P7 -> 52000 | AB7: =W7-V7 -> 1
A8: 11 | B8: 46272 | C8: Đơn bốc miền đông: 10+1 bình úp đến khách hàng anh Lân: 0363831668 - 10 bình úp tới công trường lideco bãi muối. | D8: Bốc xếp | H8: 11 | I8: =H8+G8 -> 11 | J8: Chú Hưng - Trạm Hà Lầm | L8: Đã hoàn thành | M8: Miền Đông | O8: Bình RO | P8: 10 | V8: 1 | W8: =SUM(P8:V8) -> 11 | X8: =SUMIFS('Đơn giá'!C:C,'Đơn giá'!B:B,XUẤT!O8) -> 48000 | Y8: =X8*P8 -> 480000 | AB8: =W8-V8 -> 10 | AC8: =AB8*5000 -> 50000
A9: 12 | B9: 46272 | C9: Hồng Hạnh PCN: 0913060333 A Cường gần KS Trang Yến cenco 5 Yết Kiêu cạnh nhà Hạnh Phạm có nhu cầu 10 vỉ 500ml ship trong sáng nay, THU TIỀN LUÔN | D9: Vận chuyển | G9: 11 | I9: =H9+G9 -> 11 | J9: Phương + Huế | L9: Đã hoàn thành | M9: Công ty | O9: Vỉ 500ml | P9: 10 | V9: 1 | W9: =SUM(P9:V9) -> 11 | X9: =SUMIFS('Đơn giá'!C:C,'Đơn giá'!B:B,XUẤT!O9) -> 98000 | Y9: =X9*P9 -> 980000 | AB9: =W9-V9 -> 10 | AC9: =AB9*5000 -> 50000
A10: 13 | B10: 46272 | C10: Minh Hạnh PCN: Ship 2 vỉ 500ml đến chợ cột 2 mặt sau khách sạn Cốc Mốc. 0984016322 | D10: Vận chuyển | G10: 2 | I10: =H10+G10 -> 2 | J10: Đan Thanh | L10: Đã hoàn thành | M10: Công ty | O10: Vỉ 500ml | P10: 2 | W10: =SUM(P10:V10) -> 2 | X10: =SUMIFS('Đơn giá'!C:C,'Đơn giá'!B:B,XUẤT!O10) -> 98000 | Y10: =X10*P10 -> 196000 | AB10: =W10-V10 -> 2 | AC10: =AB10*5000 -> 10000
A11: 16 | B11: 46272 | C11: Minh Hải PKD: Mai Trang +84335190193 - ngõ 14 Bãi muối - 10+1 vỉ 500ml - THU TIÊN LUÔN | D11: Vận chuyển | G11: 11 | I11: =H11+G11 -> 11 | J11: Trạm hà Lầm | L11: Đã hoàn thành | M11: Công ty | O11: Vỉ 500ml | P11: 10 | V11: 1 | W11: =SUM(P11:V11) -> 11 | X11: =SUMIFS('Đơn giá'!C:C,'Đơn giá'!B:B,XUẤT!O11) -> 98000 | Y11: =X11*P11 -> 980000 | AB11: =W11-V11 -> 10 | AC11: =AB11*5000 -> 50000 | AD11: CÔNG TY VAY
A12: 12 | B12: 21/9/2026 | C12: Sếp Mạnh: Thủy 0904218278 - 10 +1 bình kiềm kiềm đơn của sếp Mạnh đến VP Vietravel đường 25/4. | D12: vận chuyển | E12: Văn phòng | H12: 11 | I12: =F12+G12+H12 -> 11 | J12: Nguyễn Văn Khoa (Cẩm Phả) | L12: hoàn thành | M12: Công ty | N12: Sếp Mạnh | O12: Bình kiềm | T12: 10 | V12: 1 | W12: =SUM(P12:V12) -> 11 | X12: =SUMIFS('Đơn giá'!C:C,'Đơn giá'!B:B,XUẤT!O12) -> 52000 | Y12: =X12*T12 -> 520000 | AA12: Nguyễn Văn Khoa (Cẩm Phả) | AB12: =W12-V12 -> 10 | AC12: =AB12*5000 -> 50000
A13: 17 | B13: 46273 | C13: Nhà Nghỉ Hà Duy, phố Trần Cao Vân, đường sông 3, 10 vỉ 500ml, ĐT 0977 367679 | D13: Vận chuyển | E13: Xe điện | G13: 11 | I13: 11 | J13: Phương + Huế | L13: Đã hoàn thành | M13: Xí nghiệp | N13: Nguyễn T.Phương Thanh | O13: Vỉ 500ml | P13: 10 | V13: 1 | W13: =SUM(P13:V13) -> 11 | X13: =SUMIFS('Đơn giá'!C:C,'Đơn giá'!B:B,XUẤT!O13) -> 98000 | Y13: =X13*P13 -> 980000 | Z13: CK 14/9 | AA13: Đinh Thu Huế | AB13: =W13-V13 -> 10 | AC13: =AB13*5000 -> 50000 | AE13: xuất hóa đơn 15/9
A14: 18 | B14: 46273 | C14: VNPT (Chị Yến): 0915 299 036, vỉ 350 ml | D14: Vận chuyển | E14: tăng áp | G14: 11 | I14: 11 | J14: Phương + Huế | L14: Đã hoàn thành | M14: Xí nghiệp | N14: Nguyễn Thị Lan | O14: Vỉ 350ml | Q14: 10 | V14: 1 | W14: =SUM(P14:V14) -> 11 | X14: =SUMIFS('Đơn giá'!C:C,'Đơn giá'!B:B,XUẤT!O14) -> 85000 | Y14: =X14*Q14 -> 850000 | Z14: CK 18/9 | AA14: Đinh Thu Huế | AB14: =W14-V14 -> 10 | AC14: =AB14*5000 -> 50000
A15: 19 | B15: 46273 | C15: Tiểu thủ công nghiệp | D15: Vận chuyển | E15: tăng áp | G15: 22 | I15: 22 | J15: Phương + Huế | L15: Đã hoàn thành | M15: Xí nghiệp | N15: Bùi Thị Thu | O15: Vỉ 500ml | P15: 20 | V15: 2 | W15: =SUM(P15:V15) -> 22 | X15: =SUMIFS('Đơn giá'!C:C,'Đơn giá'!B:B,XUẤT!O15) -> 98000 | Y15: =X15*P15 -> 1960000 | Z15: CK11/9 | AA15: Đinh Thu Huế | AB15: =W15-V15 -> 20 | AC15: =AB15*5000 -> 100000 | AD15: Chị Huế đã thu tiền | AE15: xuất hóa đơn 15/9
A16: 20 | B16: 46273 | C16: Sân pick cột 8 | D16: Vận chuyển | E16: tăng áp | G16: 22 | I16: 22 | J16: Phương + Huế | L16: Đã hoàn thành | M16: Xí nghiệp | N16: Nguyễn Thị Thu Hiên | O16: Vỉ 500ml | P16: 10 | V16: 1 | W16: =SUM(P16:V16) -> 11 | X16: =SUMIFS('Đơn giá'!C:C,'Đơn giá'!B:B,XUẤT!O16) -> 98000 | Y16: =X16*P16 -> 980000 | Z16: CK11/9 | AA16: Đinh Thu Huế | AB16: =W16-V16 -> 10 | AC16: =AB16*5000 -> 50000
A17: 21 | D17: Vận chuyển | E17: tăng áp | L17: Đã hoàn thành | M17: Xí nghiệp | N17: Lương Thị Vân Mai | O17: Vỉ 500ml | P17: 10 | V17: 1 | W17: =SUM(P17:V17) -> 11 | X17: =SUMIFS('Đơn giá'!C:C,'Đơn giá'!B:B,XUẤT!O17) -> 98000 | Y17: =X17*P17 -> 980000 | Z17: CK11/9 | AA17: Đinh Thu Huế | AB17: =W17-V17 -> 10 | AC17: =AB17*5000 -> 50000
A18: 22 | B18: 46273 | C18: Nguyễn Văn Hiếu phòng KT: đki 4 bình kiềm ship qua cửa hàng Monbay A2-01 ạ, ng nhận: Châm nhận +84964566350 - Thu tiền luôn (Quán rượu Mao Đài đối diện thư viện tỉnh) | D18: Vận chuyển | E18: tăng áp | H18: 4 | I18: 4 | J18: Phương + Huế | L18: Đã hoàn thành | M18: Công ty | N18: Nguyễn văn hiếu (kỹ thuật) | O18: Bình kiềm | T18: 4 | W18: =SUM(P18:V18) -> 4 | X18: =SUMIFS('Đơn giá'!C:C,'Đơn giá'!B:B,XUẤT!O18) -> 52000 | Y18: =T18*X18 -> 208000 | Z18: công ty thu tiền | AB18: =W18-V18 -> 4 | AC18: =AB18*5000 -> 20000
A19: 23 | B19: 46273 | C19: 3 vỉ to + 3 vỉ nhỏ Địa chỉ : số nhà 45, Lê Chân mới , tổ 7 khu Hồng Hà 2, ĐT: 0934639858 | D19: Vận chuyển | G19: 6 | I19: 6 | J19: Xuân | L19: Đã hoàn thành | M19: Bãi Cháy | O19: Vỉ 500ml | P19: 3 | W19: =SUM(P19:V19) -> 3 | X19: =SUMIFS('Đơn giá'!C:C,'Đơn giá'!B:B,XUẤT!O19) -> 98000 | Y19: =X19*P19 -> 294000 | Z19: Bãi Cháy tự thu | AA19: Lê Thanh Xuân | AB19: =W19-V19 -> 3 | AC19: =AB19*5000 -> 15000 | AD19: BÃI CHÁY VAY
M20: Bãi Cháy | O20: Vỉ 350 ml | Q20: 3 | W20: =SUM(P20:V20) -> 3 | X20: 85000 | Y20: =Q20*X20 -> 255000 | Z20: Bãi Cháy tự thu | AA20: Lê Thanh Xuân | AB20: =W20-V20 -> 3 | AC20: =AB20*5000 -> 15000
A21: 24 | B21: 46273 | C21: Hồng Hạnh PCN: 0982835366 Phương Hiền gần chợ Loong Tổng 20+2 vỉ 350ml | D21: Vận chuyển | E21: tăng áp | G21: 22 | I21: 22 | J21: Phương + Huyền + Ly tổ DV | L21: Đã hoàn thành | M21: Công ty | N21: Hồng Hạnh PCN | O21: Vỉ 350 ml | Q21: 20 | V21: 2 | W21: =SUM(P21:V21) -> 22 | X21: 85000 | Y21: =Q21*X21 -> 1700000 | Z21: công ty thu tiền | AA21: Nguyễn Viết Tạo | AB21: =W21-V21 -> 20 | AC21: =AB21*5000 -> 100000 | AD21: CÔNG TY VAY
A22: 25 | B22: 46273 | C22: Em Hà ở sảnh 2 chung cư sapphire. 2 vỉ 500ml, 0911898336 | D22: Vận chuyển | E22: Hồng Gai | G22: 2 | I22: 2 | J22: Huyền + Ly tổ DV | L22: Đã hoàn thành | M22: Xí nghiệp | N22: Đoàn Thị Nhung | O22: Vỉ 500ml | P22: 2 | W22: =SUM(P22:V22) -> 2 | X22: =SUMIFS('Đơn giá'!C:C,'Đơn giá'!B:B,XUẤT!O22) -> 98000 | Y22: =X22*P22 -> 196000 | Z22: CK11/9 | AA22: Nguyễn Viết Tạo | AB22: =W22-V22 -> 2 | AC22: =AB22*5000 -> 10000 | AD22: chị Huyền thu tiền
A23: 26 | B23: 46273 | C23: Em Quỳnh ở 94 Văn Lang ( sau trường Văn Lang) 2 vỉ 500ml, ĐT 0973367844 | D23: Vận chuyển | E23: Hồng Gai | G23: 2 | I23: 2 | J23: Huyền + Ly tổ DV | L23: Đã hoàn thành | M23: Xí nghiệp | N23: Đoàn Thị Nhung | O23: Vỉ 500ml | P23: 2 | W23: =SUM(P23:V23) -> 2 | X23: =SUMIFS('Đơn giá'!C:C,'Đơn giá'!B:B,XUẤT!O23) -> 98000 | Y23: =X23*P23 -> 196000 | Z23: CK9/9 | AA23: Nguyễn Viết Tạo | AB23: =W23-V23 -> 2 | AC23: =AB23*5000 -> 10000 | AD23: Chị Nguyệt thu ngân cũ thu tiền
A24: 27 | B24: 46273 | C24: 10+1 Vỉ bia Bà Hợi Cao Xanh | D24: Vận chuyển | G24: 11 | I24: 11 | J24: Phương + Huế | L24: Đã hoàn thành | M24: Xí nghiệp | N24: Đinh Thu Huế | O24: Vỉ 500ml | P24: 10 | V24: 1 | W24: =SUM(P24:V24) -> 11 | X24: =SUMIFS('Đơn giá'!C:C,'Đơn giá'!B:B,XUẤT!O24) -> 98000 | Y24: =X24*P24 -> 980000 | Z24: TM29/9 | AA24: Huế + Phương lái xe | AB24: =W24-V24 -> 10 | AC24: =AB24*5000 -> 50000 | AD24: vay công ty
A25: 28 | B25: 46273 | C25: 10+1 vỉ chế biến than qn | D25: Vận chuyển | G25: 11 | I25: 11 | J25: Phương + Huế | L25: Đã hoàn thành | M25: Xí nghiệp | N25: Nguyễn Thị Hồng Phương | O25: Vỉ 500ml | P25: 10 | V25: 1 | W25: =SUM(P25:V25) -> 11 | X25: =SUMIFS('Đơn giá'!C:C,'Đơn giá'!B:B,XUẤT!O25) -> 98000 | Y25: =X25*P25 -> 980000 | Z25: CK11/9 | AA25: Huế + Phương lái xe | AB25: =W25-V25 -> 10 | AC25: =AB25*5000 -> 50000 | AD25: vay công ty
A26: 29 | B26: 46273 | C26: hồng hạnh pcn: 0936812781 Số 1 ngõ 5 phố hải long cạnh phòng khám đa khoa Hoàng Anh KH có nhu cầu 3 bình kiem 19l ship ngay, thu tiền + đổi vỏ | D26: Vận chuyển | E26: tăng áp | H26: 3 | I26: 3 | J26: Hằng bảo vệ | L26: Đã hoàn thành | M26: Công ty | N26: Hồng Hạnh PCN | O26: Bình kiềm | T26: 3 | W26: =SUM(P26:V26) -> 3 | X26: =SUMIFS('Đơn giá'!C:C,'Đơn giá'!B:B,XUẤT!O26) -> 52000 | Y26: =T26*X26 -> 156000 | Z26: TM22/9 | AA26: Nguyễn Thị Hằng | AB26: =W26-V26 -> 3 | AC26: =AB26*5000 -> 15000 | AD26: chị hằng đã thu tiền + 3 vỏ
A27: 30 | B27: 46273 | C27: chị Hằng đen ghi số | D27: Vận chuyển | E27: Hồng Gai | G27: 3 | M27: Xí nghiệp | N27: Nguyễn Thị Thúy Hằng | O27: Vỉ 500ml | P27: 3 | W27: =SUM(P27:V27) -> 3 | X27: =SUMIFS('Đơn giá'!C:C,'Đơn giá'!B:B,XUẤT!O27) -> 98000 | Y27: =X27*P27 -> 294000 | AA27: Nguyễn Thị Thúy Hằng | AB27: =W27-V27 -> 3 | AC27: =AB27*5000 -> 15000
A28: 31 | B28: 46273 | C28: Lại Lan | D28: Vận chuyển | E28: tăng áp | G28: 2 | I28: 2 | L28: Đã hoàn thành | M28: Xí nghiệp | N28: Lại Thị Lan | O28: Vỉ 500ml | P28: 2 | W28: =SUM(P28:V28) -> 2 | X28: =SUMIFS('Đơn giá'!C:C,'Đơn giá'!B:B,XUẤT!O28) -> 98000 | Y28: =X28*P28 -> 196000 | Z28: CK9/9 | AA28: Lại Thị Lan | AB28: =W28-V28 -> 2 | AC28: =AB28*5000 -> 10000
B29: 46273 | C29: Chị Xuân | D29: Vận chuyển | E29: tăng áp | G29: 3 | I29: 3 | L29: Đã hoàn thành | M29: Xí nghiệp | N29: Lê Thanh Xuân | O29: Vỉ 500ml | P29: 3 | W29: =SUM(P29:V29) -> 3 | X29: =SUMIFS('Đơn giá'!C:C,'Đơn giá'!B:B,XUẤT!O29) -> 98000 | Y29: =X29*P29 -> 294000 | Z29: CK3/10 | AA29: Lê Thanh Xuân
A30: 32 | B30: 46273 | C30: Chị Hằng bảo vệ | D30: Vận chuyển | E30: tăng áp | G30: 4 | I30: 4 | J30: Hằng bảo vệ | L30: Đã hoàn thành | M30: Xí nghiệp | N30: Nguyễn Thị Hằng | O30: Vỉ 500ml | P30: 4 | W30: =SUM(P30:V30) -> 4 | X30: =SUMIFS('Đơn giá'!C:C,'Đơn giá'!B:B,XUẤT!O30) -> 98000 | Y30: =X30*P30 -> 392000 | Z30: TM22/9 | AA30: Nguyễn Thị Hằng | AB30: =W30-V30 -> 4 | AC30: =AB30*5000 -> 20000
A31: 33 | B31: 46274 | C31: KH lấy 10 + 1 thùng 500ml, cạnh tòa nhà Đa Năng Hà Tu, ĐT: 0902 009 566 | D31: Vận chuyển | E31: tăng áp | F31: 11 | I31: 11 | J31: Xuân | M31: Xí nghiệp | N31: Đỗ Thị Liễu | O31: Hộp 500ml | R31: 10 | V31: 1 | W31: =SUM(P31:V31) -> 11 | X31: =SUMIFS('Đơn giá'!C:C,'Đơn giá'!B:B,XUẤT!O31) -> 106000 | Y31: =R31*X31 -> 1060000 | Z31: ck11/9 | AA31: Lê Thanh Xuân | AB31: =W31-V31 -> 10 | AC31: =AB31*5000 -> 50000 | AD31: Liễu thu tiền
A32: 34 | B32: 46274 | C32: Lại Lan, 1 bình kiềm | D32: Vận chuyển | E32: tăng áp | H32: 1 | I32: 1 | J32: Lại Lan | L32: hoàn thành | M32: Xí nghiệp | N32: Lại Thị Lan | O32: Bình kiềm | T32: 1 | W32: =SUM(P32:V32) -> 1 | X32: =SUMIFS('Đơn giá'!C:C,'Đơn giá'!B:B,XUẤT!O32) -> 52000 | Y32: =X32*T32 -> 52000 | Z32: CK9/9 | AA32: Lại Thị Lan | AB32: =W32-V32 -> 1 | AC32: =AB32*5000 -> 5000 | AD32: Lại Lan thu tiền
A33: 35 | B33: 46274 | C33: Vũ Anh BKS: Sau nhà văn hóa khu 3, tỉnh ủy cột 5, dốc nhà máy in đi lên, đến nơi gọi chị để chị lên đường vì nhà chị ko có số em ạ, 0948910518, lấy 3 vỉ 500 và 1 vỉ 350, chị tên Thảo. | D33: 3 vỉ 500 + 1 vỉ 350 | E33: tăng áp | G33: 4 | I33: =H33+G33 -> 4 | J33: Lại Lan | L33: hoàn thành | M33: Công ty | N33: Vũ Anh BKS | O33: Bình kiềm | P33: 3 | Q33: 1 | W33: =SUM(P33:V33) -> 4 | X33: =SUMIFS('Đơn giá'!C:C,'Đơn giá'!B:B,XUẤT!O33) -> 52000 | Y33: =X33*P33 -> 156000 | Z33: Chị Lệ thu tiền | AA33: Lại Thị Lan | AB33: =W33-V33 -> 4 | AC33: =AB33*5000 -> 20000 | AD33: CÔNG TY VAY
B34: 46274 | C34: Em chi | E34: tăng áp | H34: 2 | I34: =H34+G34 -> 2 | J34: Chi | L34: hoàn thành | M34: Xí nghiệp | N34: Nguyễn Thị Chi | O34: Bình kiềm | T34: 2 | W34: =SUM(P34:V34) -> 2 | X34: =SUMIFS('Đơn giá'!C:C,'Đơn giá'!B:B,XUẤT!O34) -> 52000 | Y34: =T34*X34 -> 104000 | Z34: CK2/10 | AA34: Nguyễn Thị Chi | AB34: =W34-V34 -> 2 | AC34: =AB34*5000 -> 10000
B35: 46274 | C35: Chị Xuân | E35: tăng áp | G35: 4 | I35: =H35+G35 -> 4 | J35: Chị Xuân | L35: hoàn thành | M35: Xí nghiệp | N35: Lê Thanh Xuân | O35: Vỉ 500ml | P35: 4 | W35: =SUM(P35:V35) -> 4 | X35: =SUMIFS('Đơn giá'!C:C,'Đơn giá'!B:B,XUẤT!O35) -> 98000 | Y35: =X35*P35 -> 392000 | Z35: CK3/10 | AA35: Lê Thanh Xuân | AB35: =W35-V35 -> 4 | AC35: =AB35*5000 -> 20000
A36: 1 | B36: 10/9/2026 | C36: 4 vỉ 500ml vào 315 Cao Xanh. Cửa hàng đt Dũng Tí, 098 4312638 | D36: Vận chuyển | E36: Hồng Gai | G36: 4 | I36: =H36+G36 -> 4 | J36: Tùng + Huế | L36: hoàn thành | M36: Xí nghiệp | N36: Mai Anh Dũng | O36: Vỉ 500ml | P36: 4 | W36: =SUM(P36:V36) -> 4 | X36: =SUMIFS('Đơn giá'!C:C,'Đơn giá'!B:B,XUẤT!O36) -> 98000 | Y36: =X36*P36 -> 392000 | Z36: TM29/9 | AA36: Đinh Thu Huế | AB36: =W36-V36 -> 4 | AC36: =AB36*5000 -> 20000
A37: 2 | B37: 10/9/2026 | C37: Tươi Đá Trắng số 19 Ba Đèo, 8 bình ion+ 11 vỉ 500 ml, 0915158863, chở đến điêm gọi chị tươi đến bốc | D37: Vận chuyển | E37: tăng áp | G37: 11 | I37: =H37+G37 -> 11 | J37: Tùng + Huế | M37: Xí nghiệp | N37: Vũ Thị Tươi | O37: Vỉ 500ml | P37: 10 | V37: 1 | W37: =SUM(P37:V37) -> 11 | X37: =SUMIFS('Đơn giá'!C:C,'Đơn giá'!B:B,XUẤT!O37) -> 98000 | Y37: =X37*P37 -> 980000 | Z37: Ck29/9 | AA37: Vũ Thị Tươi | AB37: =W37-V37 -> 10 | AC37: =AB37*5000 -> 50000
E38: tăng áp | H38: 8 | I38: =H38+G38 -> 8 | J38: Tùng + Huế | M38: Xí nghiệp | N38: Vũ Thị Tươi | O38: Bình kiềm | T38: 7 | V38: 1 | W38: =SUM(P38:V38) -> 8 | X38: =SUMIFS('Đơn giá'!C:C,'Đơn giá'!B:B,XUẤT!O38) -> 52000 | Y38: =T38*X38 -> 364000 | Z38: Ck29/9 | AA38: Vũ Thị Tươi | AB38: =W38-V38 -> 7 | AC38: =AB38*5000 -> 35000
A39: 3 | B39: 10/9/2026 | C39: 15 bình nước cho hội trường cơ sở 2 cạnh trụ sở liên cơ quan số 4, 0988167724 | D39: Vận chuyển | E39: tăng áp | H39: 15 | I39: =H39+G39 -> 15 | J39: Tùng + Huế | K39: Lại Lan + Chi | L39: hoàn thành | M39: Xí nghiệp | N39: Nguyễn Thị Hiếu | O39: Bình kiềm | T39: 15 | W39: =SUM(P39:V39) -> 15 | X39: =SUMIFS('Đơn giá'!C:C,'Đơn giá'!B:B,XUẤT!O39) -> 52000 | Y39: =X39*T39 -> 780000 | AA39: Đinh Thu Huế | AB39: =W39-V39 -> 15 | AC39: =AB39*5000 -> 75000
A40: 4 | B40: 10/9/2026 | C40: Thư Tuyền PXD: E ơi ship giúp c 10 vỉ 500ml (980k) + 1 vỉ khuyến mãi đến nhà chú Thắng ở tổ 13 khu phố Hà Trung 2 (ship 10h30) +84972133886. | D40: Vận chuyển | E40: tăng áp | G40: 11 | I40: =H40+G40 -> 11 | J40: Tùng + Huế | L40: hoàn thành | M40: Công ty | N40: Thư Tuyền | O40: Vỉ 500ml | P40: 10 | V40: 1 | W40: =SUM(P40:V40) -> 11 | X40: =SUMIFS('Đơn giá'!C:C,'Đơn giá'!B:B,XUẤT!O40) -> 98000 | Y40: =X40*P40 -> 980000 | Z40: công ty thu tiền | AA40: Đinh Thu Huế | AB40: =W40-V40 -> 10 | AC40: =AB40*5000 -> 50000 | AD40: CÔNG TY VAY
A41: 5 | B41: 10/9/2026 | C41: chiều 1 đơn karaoke Luxury yết kiêu 30+3 vỉ 500 | D41: Vận chuyển | E41: Hồng Gai | G41: 33 | I41: =H41+G41 -> 33 | J41: Tùng + Huế | K41: trạm Hồng Gai | L41: hoàn thành | M41: Xí nghiệp | N41: Đinh Thu Huế | O41: Vỉ 500ml | P41: 30 | V41: 3 | W41: =SUM(P41:V41) -> 33 | X41: =SUMIFS('Đơn giá'!C:C,'Đơn giá'!B:B,XUẤT!O41) -> 98000 | Y41: =X41*P41 -> 2940000 | Z41: TM29/9 | AA41: Đinh Thu Huế | AB41: =W41-V41 -> 30 | AC41: =AB41*5000 -> 150000
...

Sheet XUẤT (2)
A1: ĐIỀU PHỐI QUAROMI | M1: CHỈ TIÊU | AA1: VẬN CHUYỂN
A3: STT | B3: Ngày | C3: Đơn hàng | D3: Công việc | E3: Kho | F3: Số lượng | J3: Người thực hiện | K3: Hỗ Trợ (trạm QL) | L3: Kết quả | M3: Chỉ tiêu | N3: Chỉ tiêu CBCNV | O3: Sản phẩm | P3: Số lượng | X3: Đơn giá | Y3: Doanh thu | Z3: Thu tiền | AA3: Người vận chuyển | AB3: Số lượng | AC3: Số tiền | AD3: GHI CHÚ
F4: Thùng | G4: Vỉ | H4: Bình | I4: Cộng | M4: XN/CTY | N4: CBCNV | P4: Vỉ 500ml | Q4: Vỉ 350 ml | R4: Hộp 500ml | S4: Hộp 350ml | T4: Bình kiềm | U4: Bình RO | V4: KM | W4: Cộng
P5: =SUBTOTAL(9,P63:P247) -> 1020 | Q5: =SUBTOTAL(9,Q63:Q247) -> 73 | R5: =SUBTOTAL(9,R63:R247) -> 0 | S5: =SUBTOTAL(9,S63:S247) -> 8 | T5: =SUBTOTAL(9,T63:T247) -> 191 | U5: =SUBTOTAL(9,U63:U247) -> 162 | V5: =SUBTOTAL(9,V63:V247) -> 100 | W5: =SUBTOTAL(9,W63:W247) -> 1554 | AB5: =SUBTOTAL(9,AB6:AB153) -> 993 | AC5: =SUBTOTAL(9,AC6:AC153) -> 4965000
A6: 17 | B6: 46273 | C6: Nhà Nghỉ Hà Duy, phố Trần Cao Vân, đường sông 3, 10 vỉ 500ml, ĐT 0977 367679 | D6: Vận chuyển | E6: Xe điện | G6: 11 | I6: 11 | J6: Phương + Huế | L6: Đã hoàn thành | M6: Xí nghiệp | N6: Nguyễn T.Phương Thanh | O6: Vỉ 500ml | P6: 10 | V6: 1 | W6: =SUM(P6:V6) -> 11 | X6: =SUMIFS('Đơn giá'!C:C,'Đơn giá'!B:B,'XUẤT (2)'!O6) -> 98000 | Y6: =X6*P6 -> 980000 | Z6: CK 14/9 | AA6: Đinh Thu Huế | AB6: =W6-V6 -> 10 | AC6: =AB6*5000 -> 50000 | AE6: xuất hóa đơn 15/9
A7: 18 | B7: 46273 | C7: VNPT (Chị Yến): 0915 299 036, vỉ 350 ml | D7: Vận chuyển | E7: tăng áp | G7: 11 | I7: 11 | J7: Phương + Huế | L7: Đã hoàn thành | M7: Xí nghiệp | N7: Nguyễn Thị Lan | O7: Vỉ 350ml | Q7: 10 | V7: 1 | W7: =SUM(P7:V7) -> 11 | X7: =SUMIFS('Đơn giá'!C:C,'Đơn giá'!B:B,'XUẤT (2)'!O7) -> 85000 | Y7: =X7*Q7 -> 850000 | Z7: CK 18/9 | AA7: Đinh Thu Huế | AB7: =W7-V7 -> 10 | AC7: =AB7*5000 -> 50000
A8: 19 | B8: 46273 | C8: Tiểu thủ công nghiệp | D8: Vận chuyển | E8: tăng áp | G8: 22 | I8: 22 | J8: Phương + Huế | L8: Đã hoàn thành | M8: Xí nghiệp | N8: Bùi Thị Thu | O8: Vỉ 500ml | P8: 20 | V8: 2 | W8: =SUM(P8:V8) -> 22 | X8: =SUMIFS('Đơn giá'!C:C,'Đơn giá'!B:B,'XUẤT (2)'!O8) -> 98000 | Y8: =X8*P8 -> 1960000 | Z8: CK11/9 | AA8: Đinh Thu Huế | AB8: =W8-V8 -> 20 | AC8: =AB8*5000 -> 100000 | AD8: Chị Huế đã thu tiền | AE8: xuất hóa đơn 15/9
A9: 20 | B9: 46273 | C9: Sân pick cột 8 | D9: Vận chuyển | E9: tăng áp | G9: 22 | I9: 22 | J9: Phương + Huế | L9: Đã hoàn thành | M9: Xí nghiệp | N9: Nguyễn Thị Thu Hiên | O9: Vỉ 500ml | P9: 10 | V9: 1 | W9: =SUM(P9:V9) -> 11 | X9: =SUMIFS('Đơn giá'!C:C,'Đơn giá'!B:B,'XUẤT (2)'!O9) -> 98000 | Y9: =X9*P9 -> 980000 | Z9: CK11/9 | AA9: Đinh Thu Huế | AB9: =W9-V9 -> 10 | AC9: =AB9*5000 -> 50000
A10: 21 | D10: Vận chuyển | E10: tăng áp | L10: Đã hoàn thành | M10: Xí nghiệp | N10: Lương Thị Vân Mai | O10: Vỉ 500ml | P10: 10 | V10: 1 | W10: =SUM(P10:V10) -> 11 | X10: =SUMIFS('Đơn giá'!C:C,'Đơn giá'!B:B,'XUẤT (2)'!O10) -> 98000 | Y10: =X10*P10 -> 980000 | Z10: CK11/9 | AA10: Đinh Thu Huế | AB10: =W10-V10 -> 10 | AC10: =AB10*5000 -> 50000
A11: 22 | B11: 46273 | C11: Nguyễn Văn Hiếu phòng KT: đki 4 bình kiềm ship qua cửa hàng Monbay A2-01 ạ, ng nhận: Châm nhận +84964566350 - Thu tiền luôn (Quán rượu Mao Đài đối diện thư viện tỉnh) | D11: Vận chuyển | E11: tăng áp | H11: 4 | I11: 4 | J11: Phương + Huế | L11: Đã hoàn thành | M11: Công ty | N11: Nguyễn văn hiếu (kỹ thuật) | O11: Bình kiềm | T11: 4 | W11: =SUM(P11:V11) -> 4 | X11: =SUMIFS('Đơn giá'!C:C,'Đơn giá'!B:B,'XUẤT (2)'!O11) -> 52000 | Y11: =T11*X11 -> 208000 | Z11: công ty thu tiền | AB11: =W11-V11 -> 4 | AC11: =AB11*5000 -> 20000
A12: 23 | B12: 46273 | C12: 3 vỉ to + 3 vỉ nhỏ Địa chỉ : số nhà 45, Lê Chân mới , tổ 7 khu Hồng Hà 2, ĐT: 0934639858 | D12: Vận chuyển | G12: 6 | I12: 6 | J12: Xuân | L12: Đã hoàn thành | M12: Bãi Cháy | O12: Vỉ 500ml | P12: 3 | W12: =SUM(P12:V12) -> 3 | X12: =SUMIFS('Đơn giá'!C:C,'Đơn giá'!B:B,'XUẤT (2)'!O12) -> 98000 | Y12: =X12*P12 -> 294000 | Z12: Bãi Cháy tự thu | AA12: Lê Thanh Xuân | AB12: =W12-V12 -> 3 | AC12: =AB12*5000 -> 15000 | AD12: BÃI CHÁY VAY
M13: Bãi Cháy | O13: Vỉ 350 ml | Q13: 3 | W13: =SUM(P13:V13) -> 3 | X13: 85000 | Y13: =Q13*X13 -> 255000 | Z13: Bãi Cháy tự thu | AA13: Lê Thanh Xuân | AB13: =W13-V13 -> 3 | AC13: =AB13*5000 -> 15000
A14: 24 | B14: 46273 | C14: Hồng Hạnh PCN: 0982835366 Phương Hiền gần chợ Loong Tổng 20+2 vỉ 350ml | D14: Vận chuyển | E14: tăng áp | G14: 22 | I14: 22 | J14: Phương + Huyền + Ly tổ DV | L14: Đã hoàn thành | M14: Công ty | N14: Hồng Hạnh PCN | O14: Vỉ 350 ml | Q14: 20 | V14: 2 | W14: =SUM(P14:V14) -> 22 | X14: 85000 | Y14: =Q14*X14 -> 1700000 | Z14: công ty thu tiền | AA14: Tổ DVCTT | AB14: =W14-V14 -> 20 | AC14: =AB14*5000 -> 100000 | AD14: CÔNG TY VAY
A15: 25 | B15: 46273 | C15: Em Hà ở sảnh 2 chung cư sapphire. 2 vỉ 500ml, 0911898336 | D15: Vận chuyển | E15: Hồng Gai | G15: 2 | I15: 2 | J15: Huyền + Ly tổ DV | L15: Đã hoàn thành | M15: Xí nghiệp | N15: Đoàn Thị Nhung | O15: Vỉ 500ml | P15: 2 | W15: =SUM(P15:V15) -> 2 | X15: =SUMIFS('Đơn giá'!C:C,'Đơn giá'!B:B,'XUẤT (2)'!O15) -> 98000 | Y15: =X15*P15 -> 196000 | Z15: CK11/9 | AA15: Tổ DVCTT | AB15: =W15-V15 -> 2 | AC15: =AB15*5000 -> 10000 | AD15: chị Huyền thu tiền
A16: 26 | B16: 46273 | C16: Em Quỳnh ở 94 Văn Lang ( sau trường Văn Lang) 2 vỉ 500ml, ĐT 0973367844 | D16: Vận chuyển | E16: Hồng Gai | G16: 2 | I16: 2 | J16: Huyền + Ly tổ DV | L16: Đã hoàn thành | M16: Xí nghiệp | N16: Đoàn Thị Nhung | O16: Vỉ 500ml | P16: 2 | W16: =SUM(P16:V16) -> 2 | X16: =SUMIFS('Đơn giá'!C:C,'Đơn giá'!B:B,'XUẤT (2)'!O16) -> 98000 | Y16: =X16*P16 -> 196000 | Z16: CK9/9 | AA16: Tổ DVCTT | AB16: =W16-V16 -> 2 | AC16: =AB16*5000 -> 10000 | AD16: Chị Nguyệt thu ngân cũ thu tiền
A17: 27 | B17: 46273 | C17: 10+1 Vỉ bia Bà Hợi Cao Xanh | D17: Vận chuyển | G17: 11 | I17: 11 | J17: Phương + Huế | L17: Đã hoàn thành | M17: Xí nghiệp | N17: Đinh Thu Huế | O17: Vỉ 500ml | P17: 10 | V17: 1 | W17: =SUM(P17:V17) -> 11 | X17: =SUMIFS('Đơn giá'!C:C,'Đơn giá'!B:B,'XUẤT (2)'!O17) -> 98000 | Y17: =X17*P17 -> 980000 | Z17: TM29/9 | AA17: Phương + Huế | AB17: =W17-V17 -> 10 | AC17: =AB17*5000 -> 50000 | AD17: vay công ty
A18: 28 | B18: 46273 | C18: 10+1 vỉ chế biến than qn | D18: Vận chuyển | G18: 11 | I18: 11 | J18: Phương + Huế | L18: Đã hoàn thành | M18: Xí nghiệp | N18: Nguyễn Thị Hồng Phương | O18: Vỉ 500ml | P18: 10 | V18: 1 | W18: =SUM(P18:V18) -> 11 | X18: =SUMIFS('Đơn giá'!C:C,'Đơn giá'!B:B,'XUẤT (2)'!O18) -> 98000 | Y18: =X18*P18 -> 980000 | Z18: CK11/9 | AA18: Phương + Huế | AB18: =W18-V18 -> 10 | AC18: =AB18*5000 -> 50000 | AD18: vay công ty
A19: 29 | B19: 46273 | C19: hồng hạnh pcn: 0936812781 Số 1 ngõ 5 phố hải long cạnh phòng khám đa khoa Hoàng Anh KH có nhu cầu 3 bình kiem 19l ship ngay, thu tiền + đổi vỏ | D19: Vận chuyển | E19: tăng áp | H19: 3 | I19: 3 | J19: Hằng bảo vệ | L19: Đã hoàn thành | M19: Công ty | N19: Hồng Hạnh PCN | O19: Bình kiềm | T19: 3 | W19: =SUM(P19:V19) -> 3 | X19: =SUMIFS('Đơn giá'!C:C,'Đơn giá'!B:B,'XUẤT (2)'!O19) -> 52000 | Y19: =T19*X19 -> 156000 | Z19: TM22/9 | AA19: Nguyễn Thị Hằng | AB19: =W19-V19 -> 3 | AC19: =AB19*5000 -> 15000 | AD19: chị hằng đã thu tiền + 3 vỏ
A20: 30 | B20: 46273 | C20: chị Hằng đen ghi số | D20: Vận chuyển | E20: Hồng Gai | G20: 3 | M20: Xí nghiệp | N20: Nguyễn Thị Thúy Hằng | O20: Vỉ 500ml | P20: 3 | W20: =SUM(P20:V20) -> 3 | X20: =SUMIFS('Đơn giá'!C:C,'Đơn giá'!B:B,'XUẤT (2)'!O20) -> 98000 | Y20: =X20*P20 -> 294000 | AA20: Nguyễn Thị Thúy Hằng | AB20: =W20-V20 -> 3 | AC20: =AB20*5000 -> 15000
A21: 31 | B21: 46273 | C21: Lại Lan | D21: Vận chuyển | E21: tăng áp | G21: 2 | I21: 2 | L21: Đã hoàn thành | M21: Xí nghiệp | N21: Lại Thị Lan | O21: Vỉ 500ml | P21: 2 | W21: =SUM(P21:V21) -> 2 | X21: =SUMIFS('Đơn giá'!C:C,'Đơn giá'!B:B,'XUẤT (2)'!O21) -> 98000 | Y21: =X21*P21 -> 196000 | Z21: CK9/9 | AA21: Lại Thị Lan | AB21: =W21-V21 -> 2 | AC21: =AB21*5000 -> 10000
A22: 32 | B22: 46273 | C22: Chị Hằng bảo vệ | D22: Vận chuyển | E22: tăng áp | G22: 4 | I22: 4 | J22: Hằng bảo vệ | L22: Đã hoàn thành | M22: Xí nghiệp | N22: Nguyễn Thị Hằng | O22: Vỉ 500ml | P22: 4 | W22: =SUM(P22:V22) -> 4 | X22: =SUMIFS('Đơn giá'!C:C,'Đơn giá'!B:B,'XUẤT (2)'!O22) -> 98000 | Y22: =X22*P22 -> 392000 | Z22: TM22/9 | AA22: Nguyễn Thị Hằng | AB22: =W22-V22 -> 4 | AC22: =AB22*5000 -> 20000
A23: 33 | B23: 46274 | C23: KH lấy 10 + 1 thùng 500ml, cạnh tòa nhà Đa Năng Hà Tu, ĐT: 0902 009 566 | D23: Vận chuyển | E23: tăng áp | F23: 11 | I23: 11 | J23: Xuân | M23: Xí nghiệp | N23: Đỗ Thị Liễu | O23: Hộp 500ml | R23: 10 | V23: 1 | W23: =SUM(P23:V23) -> 11 | X23: =SUMIFS('Đơn giá'!C:C,'Đơn giá'!B:B,'XUẤT (2)'!O23) -> 106000 | Y23: =R23*X23 -> 1060000 | Z23: ck11/9 | AA23: Lê Thanh Xuân | AB23: =W23-V23 -> 10 | AC23: =AB23*5000 -> 50000 | AD23: Liễu thu tiền
A24: 34 | B24: 46274 | C24: Lại Lan, 1 bình kiềm | D24: Vận chuyển | E24: tăng áp | H24: 1 | I24: 1 | J24: Lại Lan | L24: hoàn thành | M24: Xí nghiệp | N24: Lại Thị Lan | O24: Bình kiềm | T24: 1 | W24: =SUM(P24:V24) -> 1 | X24: =SUMIFS('Đơn giá'!C:C,'Đơn giá'!B:B,'XUẤT (2)'!O24) -> 52000 | Y24: =X24*T24 -> 52000 | Z24: CK9/9 | AA24: Lại Thị Lan | AB24: =W24-V24 -> 1 | AC24: =AB24*5000 -> 5000 | AD24: Lại Lan thu tiền
A25: 35 | B25: 46274 | C25: Vũ Anh BKS: Sau nhà văn hóa khu 3, tỉnh ủy cột 5, dốc nhà máy in đi lên, đến nơi gọi chị để chị lên đường vì nhà chị ko có số em ạ, 0948910518, lấy 3 vỉ 500 và 1 vỉ 350, chị tên Thảo. | D25: 3 vỉ 500 + 1 vỉ 350 | E25: tăng áp | G25: 4 | I25: =H25+G25 -> 4 | J25: Lại Lan | L25: hoàn thành | M25: Công ty | N25: Vũ Anh BKS | O25: Bình kiềm | P25: 3 | Q25: 1 | W25: =SUM(P25:V25) -> 4 | X25: =SUMIFS('Đơn giá'!C:C,'Đơn giá'!B:B,'XUẤT (2)'!O25) -> 52000 | Y25: =X25*P25 -> 156000 | Z25: Chị Lệ thu tiền | AA25: Lại Thị Lan | AB25: =W25-V25 -> 4 | AC25: =AB25*5000 -> 20000 | AD25: CÔNG TY VAY
B26: 46274 | C26: Em chi | E26: tăng áp | H26: 2 | I26: =H26+G26 -> 2 | J26: Chi | L26: hoàn thành | M26: Xí nghiệp | N26: Nguyễn Thị Chi | O26: Bình kiềm | T26: 2 | W26: =SUM(P26:V26) -> 2 | X26: =SUMIFS('Đơn giá'!C:C,'Đơn giá'!B:B,'XUẤT (2)'!O26) -> 52000 | Y26: =T26*X26 -> 104000 | AA26: Nguyễn Thị Chi | AB26: =W26-V26 -> 2 | AC26: =AB26*5000 -> 10000
B27: 46274 | C27: Chị Xuân | E27: tăng áp | G27: 4 | I27: =H27+G27 -> 4 | J27: Chị Xuân | L27: hoàn thành | M27: Xí nghiệp | N27: Lê Thanh Xuân | O27: Vỉ 500ml | P27: 4 | W27: =SUM(P27:V27) -> 4 | X27: =SUMIFS('Đơn giá'!C:C,'Đơn giá'!B:B,'XUẤT (2)'!O27) -> 98000 | Y27: =X27*P27 -> 392000 | Z27: Nộp tiền cho chị Thúy | AA27: Lê Thanh Xuân | AB27: =W27-V27 -> 4 | AC27: =AB27*5000 -> 20000
A28: 1 | B28: 10/9/2026 | C28: 4 vỉ 500ml vào 315 Cao Xanh. Cửa hàng đt Dũng Tí, 098 4312638 | D28: Vận chuyển | E28: Hồng Gai | G28: 4 | I28: =H28+G28 -> 4 | J28: Tùng + Huế | L28: hoàn thành | M28: Xí nghiệp | N28: Mai Anh Dũng | O28: Vỉ 500ml | P28: 4 | W28: =SUM(P28:V28) -> 4 | X28: =SUMIFS('Đơn giá'!C:C,'Đơn giá'!B:B,'XUẤT (2)'!O28) -> 98000 | Y28: =X28*P28 -> 392000 | Z28: TM29/9 | AA28: Đinh Thu Huế | AB28: =W28-V28 -> 4 | AC28: =AB28*5000 -> 20000
A29: 2 | B29: 10/9/2026 | C29: Tươi Đá Trắng số 19 Ba Đèo, 8 bình ion+ 11 vỉ 500 ml, 0915158863, chở đến điêm gọi chị tươi đến bốc | D29: Vận chuyển | E29: tăng áp | G29: 11 | I29: =H29+G29 -> 11 | J29: Tùng + Huế | M29: Xí nghiệp | N29: Vũ Thị Tươi | O29: Vỉ 500ml | P29: 10 | V29: 1 | W29: =SUM(P29:V29) -> 11 | X29: =SUMIFS('Đơn giá'!C:C,'Đơn giá'!B:B,'XUẤT (2)'!O29) -> 98000 | Y29: =X29*P29 -> 980000 | Z29: Ck29/9 | AA29: Vũ Thị Tươi | AB29: =W29-V29 -> 10 | AC29: =AB29*5000 -> 50000
E30: tăng áp | H30: 8 | I30: =H30+G30 -> 8 | J30: Tùng + Huế | M30: Xí nghiệp | N30: Vũ Thị Tươi | O30: Bình kiềm | T30: 7 | V30: 1 | W30: =SUM(P30:V30) -> 8 | X30: =SUMIFS('Đơn giá'!C:C,'Đơn giá'!B:B,'XUẤT (2)'!O30) -> 52000 | Y30: =T30*X30 -> 364000 | Z30: Ck29/9 | AA30: Vũ Thị Tươi | AB30: =W30-V30 -> 7 | AC30: =AB30*5000 -> 35000
A31: 3 | B31: 10/9/2026 | C31: 15 bình nước cho hội trường cơ sở 2 cạnh trụ sở liên cơ quan số 4, 0988167724 | D31: Vận chuyển | E31: tăng áp | H31: 15 | I31: =H31+G31 -> 15 | J31: Tùng + Huế | K31: Lại Lan + Chi | L31: hoàn thành | M31: Xí nghiệp | N31: Nguyễn Thị Hiếu | O31: Bình kiềm | T31: 15 | W31: =SUM(P31:V31) -> 15 | X31: =SUMIFS('Đơn giá'!C:C,'Đơn giá'!B:B,'XUẤT (2)'!O31) -> 52000 | Y31: =X31*T31 -> 780000 | AA31: Đinh Thu Huế | AB31: =W31-V31 -> 15 | AC31: =AB31*5000 -> 75000
A32: 4 | B32: 10/9/2026 | C32: Thư Tuyền PXD: E ơi ship giúp c 10 vỉ 500ml (980k) + 1 vỉ khuyến mãi đến nhà chú Thắng ở tổ 13 khu phố Hà Trung 2 (ship 10h30) +84972133886. | D32: Vận chuyển | E32: tăng áp | G32: 11 | I32: =H32+G32 -> 11 | J32: Tùng + Huế | L32: hoàn thành | M32: Công ty | N32: Thư Tuyền | O32: Vỉ 500ml | P32: 10 | V32: 1 | W32: =SUM(P32:V32) -> 11 | X32: =SUMIFS('Đơn giá'!C:C,'Đơn giá'!B:B,'XUẤT (2)'!O32) -> 98000 | Y32: =X32*P32 -> 980000 | Z32: công ty thu tiền | AA32: Đinh Thu Huế | AB32: =W32-V32 -> 10 | AC32: =AB32*5000 -> 50000 | AD32: CÔNG TY VAY
A33: 5 | B33: 10/9/2026 | C33: chiều 1 đơn karaoke Luxury yết kiêu 30+3 vỉ 500 | D33: Vận chuyển | E33: Hồng Gai | G33: 33 | I33: =H33+G33 -> 33 | J33: Tùng + Huế | K33: trạm Hồng Gai | L33: hoàn thành | M33: Xí nghiệp | N33: Đinh Thu Huế | O33: Vỉ 500ml | P33: 30 | V33: 3 | W33: =SUM(P33:V33) -> 33 | X33: =SUMIFS('Đơn giá'!C:C,'Đơn giá'!B:B,'XUẤT (2)'!O33) -> 98000 | Y33: =X33*P33 -> 2940000 | Z33: TM29/9 | AA33: Đinh Thu Huế | AB33: =W33-V33 -> 30 | AC33: =AB33*5000 -> 150000
A34: 6 | B34: 10/9/2026 | C34: 10 vỉ 500ml +1 nc, nhận ở trường dân tộc nội trú, phường Hạ long -0985515202 Phạm việt Hà | D34: Vận chuyển | E34: VPXN | G34: 11 | I34: =H34+G34 -> 11 | J34: Chị Vượng + Chi | K34: Trạm Hạ Long | L34: hoàn thành | M34: Diễn Vọng | N34: Chị Hiền Diễn Vọng | O34: Vỉ 500ml | P34: 10 | V34: 1 | W34: =SUM(P34:V34) -> 11 | X34: =SUMIFS('Đơn giá'!C:C,'Đơn giá'!B:B,'XUẤT (2)'!O34) -> 98000 | Y34: =X34*P34 -> 980000 | AA34: Trần Trọng Khoa | AB34: =W34-V34 -> 10 | AC34: =AB34*5000 -> 50000 | AD34: DIỄN VỌNG VAY
A35: 7 | B35: 10/9/2026 | C35: Hồng Hạnh P.CN Sân pick Star cạnh nhà hàng Lan Hương có nhu cầu 10+1 vỉ 500ml - 0979748188. SHip luôn | D35: Vận chuyển | E35: tăng áp | G35: 11 | I35: =H35+G35 -> 11 | J35: Lại Lan + Xuân | L35: hoàn thành | M35: Công ty | N35: Hồng Hạnh PCN | O35: Vỉ 500ml | P35: 5 | V35: 1 | W35: =SUM(P35:V35) -> 6 | X35: =SUMIFS('Đơn giá'!C:C,'Đơn giá'!B:B,'XUẤT (2)'!O35) -> 98000 | Y35: =X35*P35 -> 490000 | Z35: Chị Lệ thu tiền | AA35: Lại Thị Lan | AB35: =W35-V35 -> 5 | AC35: =AB35*5000 -> 25000 | AD35: CÔNG TY VAY
P36: 5 | W36: =SUM(P36:V36) -> 5 | X36: 98000 | Y36: =X36*P36 -> 490000 | AA36: Lê Thanh Xuân | AB36: =W36-V36 -> 5 | AC36: =AB36*5000 -> 25000
A37: 8 | B37: 10/9/2026 | C37: Lương Vân Mai bán lẻ | D37: Vận chuyển | E37: Văn phòng | G37: 2 | I37: =H37+G37 -> 2 | J37: Lương Thị Vân Mai | L37: hoàn thành | M37: Xí nghiệp | N37: Lương Thị Vân Mai | O37: Vỉ 500ml | P37: 2 | W37: =SUM(P37:V37) -> 2 | X37: =SUMIFS('Đơn giá'!C:C,'Đơn giá'!B:B,'XUẤT (2)'!O37) -> 98000 | Y37: =X37*P37 -> 196000 | Z37: CK29/9 | AA37: Lương Thị Vân Mai | AB37: =W37-V37 -> 2 | AC37: =AB37*5000 -> 10000
A38: 9 | B38: 10/9/2026 | C38: Đơn bốc nước của Công ty 22 bình đến Đảng ủy phường Hạ Long | D38: Bốc xếp | E38: Cẩm Phả | H38: 22 | I38: =H38+G38 -> 22 | J38: 5 ghi số trạm Hạ Long và Liễu, Xuân | K38: Hạ Long | L38: hoàn thành | M38: Công ty | N38: Nguyễn Thị Chi | O38: Bình kiềm | T38: 20 | V38: 2 | W38: =SUM(P38:V38) -> 22 | X38: =SUMIFS('Đơn giá'!C:C,'Đơn giá'!B:B,'XUẤT (2)'!O38) -> 52000 | Y38: =T38*X38 -> 1040000 | AA38: Nguyễn Thị Chi | AB38: =W38-V38 -> 20 | AC38: =AB38*5000 -> 100000
A39: 10 | B39: 10/9/2026 | C39: Hồng Hạnh PCN: 0852091985 khách hàng có nhu cầu ngay 20+2 vỉ 350 ml (cần ngay) đến 32 Phan Đăng Lưu, thu tiền luôn | D39: Vận chuyển | E39: Hồng Gai | G39: 22 | I39: =H39+G39 -> 22 | J39: Tùng + Huế | L39: hoàn thành | M39: Công ty | N39: Hồng Hạnh PCN | O39: Vỉ 500ml | Q39: 10 | V39: 2 | W39: =SUM(P39:V39) -> 12 | X39: 85000 | Y39: =Q39*X39 -> 850000 | Z39: TM11/9 | AA39: Đinh Thu Huế | AB39: =W39-V39 -> 10 | AC39: =AB39*5000 -> 50000 | AD39: CÔNG TY VAY
M40: Công ty | O40: Vỉ 500ml | Q40: 10 | W40: =SUM(P40:V40) -> 10 | X40: 85000 | Y40: =Q40*X40 -> 850000 | Z40: TM11/9 | AA40: Đỗ Thị Vượng | AB40: =W40-V40 -> 10 | AC40: =AB40*5000 -> 50000
A41: 11 | B41: 10/9/2026 | C41: Chiị Bùi Thu lấy 8 vỉ ship ngã 3 thành công | D41: Vận chuyển | E41: Hồng Gai | G41: 8 | I41: =H41+G41 -> 8 | J41: Bùi Thị Thu | L41: hoàn thành | M41: Xí nghiệp | N41: Bùi Thị Thu | O41: Vỉ 500ml | P41: 8 | W41: =SUM(P41:V41) -> 8 | X41: =SUMIFS('Đơn giá'!C:C,'Đơn giá'!B:B,'XUẤT (2)'!O41) -> 98000 | Y41: =X41*P41 -> 784000 | Z41: CK 23/9 cùng 12 vỉ của Hương | AA41: Bùi Thị Thu | AB41: =W41-V41 -> 8 | AC41: =AB41*5000 -> 40000
...

Sheet CBCNV
A1: TT | B1: Họ và Tên | C1: Chức vụ | D1: Tổ/Trạm | E1: Sản phẩm
E2: Vỉ 500ml | G2: Vỉ 350ml | I2: Hộp 500ml | K2: Hộp 350ml | M2: Bình kiềm | O2: Bình RO
E3: Số lượng | F3: Thành tiền | G3: Số lượng | H3: Thành tiền | I3: Số lượng | J3: Thành tiền | K3: Số lượng | L3: Thành tiền | M3: Số lượng | N3: Thành tiền | O3: Số lượng | P3: Thành tiền | Q3: Xí nghiệp
B4: Cộng | E4: =SUM(E7:E200) -> 1029 | F4: =SUM(F7:F200) -> 100842000 | G4: =SUM(G7:G200) -> 75 | H4: =SUM(H7:H200) -> 6375000 | I4: =SUM(I7:I200) -> 10 | J4: =SUM(J7:J200) -> 930000 | K4: =SUM(K7:K200) -> 6 | L4: =SUM(L7:L200) -> 636000 | ... P4: =SUM(P7:P200) -> 5712000
B5: Kiểm tra | E5: =SUMIFS(XUẤT!P:P,XUẤT!$M:$M,CBCNV!$Q$3)-E4 -> 0 | G5: =SUMIFS(XUẤT!Q:Q,XUẤT!M:M,CBCNV!$Q$3)-CBCNV!G4 -> 0 | I5: =SUMIFS(XUẤT!R:R,XUẤT!$M:$M,CBCNV!$Q$3)-CBCNV!I4 -> 0 | K5: =SUMIFS(XUẤT!S:S,XUẤT!M:M,CBCNV!$Q$3)-CBCNV!K4 -> 0 | M5: =SUMIFS(XUẤT!T:T,XUẤT!M:M,CBCNV!$Q$3)-CBCNV!M4 -> 7 | O5: =SUMIFS(XUẤT!U:U,XUẤT!M:M,CBCNV!$Q$3)-CBCNV!O4 -> 5
A7: 1 | B7: Trần Nam Trung | C7: Giám đốc | D7: Văn phòng | E7: =SUMIFS(XUẤT!P:P,XUẤT!N:N,CBCNV!B7,XUẤT!O:O,CBCNV!$E$2) -> 50 | F7: =E7*$T$10 -> 4900000 | G7: =SUMIFS(XUẤT!Q:Q,XUẤT!N:N,CBCNV!B7,XUẤT!O:O,CBCNV!$G$2) -> 0 | H7: =G7*$T$8 -> 0 | I7: =SUMIFS(XUẤT!R:R,XUẤT!N:N,CBCNV!B7,XUẤT!O:O,CBCNV!$I$2) -> 0 | J7: =I7*$T$9 -> 0 | K7: =SUMIFS(XUẤT!S:S,XUẤT!N:N,CBCNV!B7,XUẤT!O:O,CBCNV!$K$2) -> 0 | L7: =K7*$T$11 -> 0 | M7: =SUMIFS(XUẤT!T:T,XUẤT!N:N,CBCNV!B7,XUẤT!O:O,CBCNV!$M$2) -> 0 | N7: =M7*$T$12 -> 0 | O7: =SUMIFS(XUẤT!U:U,XUẤT!N:N,CBCNV!B7,XUẤT!O:O,CBCNV!$O$2) -> 0 | P7: =O7*$T$13 -> 0 | R7: STT | S7: Hàng hóa | T7: Giá bán
A8: 2 | B8: Đỗ Văn Cảnh | C8: P. Giám đốc | D8: Văn phòng | E8: =SUMIFS(XUẤT!P:P,XUẤT!N:N,CBCNV!B8,XUẤT!O:O,CBCNV!$E$2) -> 0 | F8: =E8*$T$10 -> 0 | G8: =SUMIFS(XUẤT!Q:Q,XUẤT!N:N,CBCNV!B8,XUẤT!O:O,CBCNV!$G$2) -> 0 | H8: =G8*$T$8 -> 0 | I8: =SUMIFS(XUẤT!R:R,XUẤT!N:N,CBCNV!B8,XUẤT!O:O,CBCNV!$I$2) -> 0 | J8: =I8*$T$9 -> 0 | K8: =SUMIFS(XUẤT!S:S,XUẤT!N:N,CBCNV!B8,XUẤT!O:O,CBCNV!$K$2) -> 0 | L8: =K8*$T$11 -> 0 | M8: =SUMIFS(XUẤT!T:T,XUẤT!N:N,CBCNV!B8,XUẤT!O:O,CBCNV!$M$2) -> 0 | N8: =M8*$T$12 -> 0 | O8: =SUMIFS(XUẤT!U:U,XUẤT!N:N,CBCNV!B8,XUẤT!O:O,CBCNV!$O$2) -> 0 | P8: =O8*$T$13 -> 0 | R8: 1 | S8: Vỉ 350ml | T8: 85000
A9: 3 | B9: Phạm Quang Tâm | C9: P. Giám Đốc | D9: Văn phòng | E9: =SUMIFS(XUẤT!P:P,XUẤT!N:N,CBCNV!B9,XUẤT!O:O,CBCNV!$E$2) -> 0 | F9: =E9*$T$10 -> 0 | G9: =SUMIFS(XUẤT!Q:Q,XUẤT!N:N,CBCNV!B9,XUẤT!O:O,CBCNV!$G$2) -> 0 | H9: =G9*$T$8 -> 0 | I9: =SUMIFS(XUẤT!R:R,XUẤT!N:N,CBCNV!B9,XUẤT!O:O,CBCNV!$I$2) -> 0 | J9: =I9*$T$9 -> 0 | K9: =SUMIFS(XUẤT!S:S,XUẤT!N:N,CBCNV!B9,XUẤT!O:O,CBCNV!$K$2) -> 0 | L9: =K9*$T$11 -> 0 | M9: =SUMIFS(XUẤT!T:T,XUẤT!N:N,CBCNV!B9,XUẤT!O:O,CBCNV!$M$2) -> 0 | N9: =M9*$T$12 -> 0 | O9: =SUMIFS(XUẤT!U:U,XUẤT!N:N,CBCNV!B9,XUẤT!O:O,CBCNV!$O$2) -> 0 | P9: =O9*$T$13 -> 0 | R9: 2 | S9: Hộp 500ml | T9: 93000
A10: 4 | B10: Vũ Thị Mai Huệ | C10: P. Giám Đốc | D10: Văn phòng | E10: =SUMIFS(XUẤT!P:P,XUẤT!N:N,CBCNV!B10,XUẤT!O:O,CBCNV!$E$2) -> 2 | F10: =E10*$T$10 -> 196000 | G10: =SUMIFS(XUẤT!Q:Q,XUẤT!N:N,CBCNV!B10,XUẤT!O:O,CBCNV!$G$2) -> 0 | H10: =G10*$T$8 -> 0 | I10: =SUMIFS(XUẤT!R:R,XUẤT!N:N,CBCNV!B10,XUẤT!O:O,CBCNV!$I$2) -> 0 | J10: =I10*$T$9 -> 0 | K10: =SUMIFS(XUẤT!S:S,XUẤT!N:N,CBCNV!B10,XUẤT!O:O,CBCNV!$K$2) -> 0 | L10: =K10*$T$11 -> 0 | M10: =SUMIFS(XUẤT!T:T,XUẤT!N:N,CBCNV!B10,XUẤT!O:O,CBCNV!$M$2) -> 0 | N10: =M10*$T$12 -> 0 | O10: =SUMIFS(XUẤT!U:U,XUẤT!N:N,CBCNV!B10,XUẤT!O:O,CBCNV!$O$2) -> 0 | P10: =O10*$T$13 -> 0 | R10: 3 | S10: Vỉ 500ml | T10: 98000
A11: 5 | B11: Phạm Phương Dung | C11: TBP. Kinh doanh | D11: Văn phòng | E11: =SUMIFS(XUẤT!P:P,XUẤT!N:N,CBCNV!B11,XUẤT!O:O,CBCNV!$E$2) -> 2 | F11: =E11*$T$10 -> 196000 | G11: =SUMIFS(XUẤT!Q:Q,XUẤT!N:N,CBCNV!B11,XUẤT!O:O,CBCNV!$G$2) -> 10 | H11: =G11*$T$8 -> 850000 | I11: =SUMIFS(XUẤT!R:R,XUẤT!N:N,CBCNV!B11,XUẤT!O:O,CBCNV!$I$2) -> 0 | J11: =I11*$T$9 -> 0 | K11: =SUMIFS(XUẤT!S:S,XUẤT!N:N,CBCNV!B11,XUẤT!O:O,CBCNV!$K$2) -> 0 | L11: =K11*$T$11 -> 0 | M11: =SUMIFS(XUẤT!T:T,XUẤT!N:N,CBCNV!B11,XUẤT!O:O,CBCNV!$M$2) -> 0 | N11: =M11*$T$12 -> 0 | O11: =SUMIFS(XUẤT!U:U,XUẤT!N:N,CBCNV!B11,XUẤT!O:O,CBCNV!$O$2) -> 0 | P11: =O11*$T$13 -> 0 | R11: 4 | S11: Hộp 350ml | T11: 106000
A12: 6 | B12: Lại Thị Lan | C12: NV kinh doanh | D12: Văn phòng | E12: =SUMIFS(XUẤT!P:P,XUẤT!N:N,CBCNV!B12,XUẤT!O:O,CBCNV!$E$2) -> 2 | F12: =E12*$T$10 -> 196000 | G12: =SUMIFS(XUẤT!Q:Q,XUẤT!N:N,CBCNV!B12,XUẤT!O:O,CBCNV!$G$2) -> 1 | H12: =G12*$T$8 -> 85000 | I12: =SUMIFS(XUẤT!R:R,XUẤT!N:N,CBCNV!B12,XUẤT!O:O,CBCNV!$I$2) -> 0 | J12: =I12*$T$9 -> 0 | K12: =SUMIFS(XUẤT!S:S,XUẤT!N:N,CBCNV!B12,XUẤT!O:O,CBCNV!$K$2) -> 0 | L12: =K12*$T$11 -> 0 | M12: =SUMIFS(XUẤT!T:T,XUẤT!N:N,CBCNV!B12,XUẤT!O:O,CBCNV!$M$2) -> 19 | N12: =M12*$T$12 -> 988000 | O12: =SUMIFS(XUẤT!U:U,XUẤT!N:N,CBCNV!B12,XUẤT!O:O,CBCNV!$O$2) -> 1 | P12: =O12*$T$13 -> 48000 | R12: 5 | S12: Bình kiềm | T12: 52000
A13: 7 | B13: Nguyễn Huyền Thư | C13: NV kinh doanh | D13: Văn phòng | E13: =SUMIFS(XUẤT!P:P,XUẤT!N:N,CBCNV!B13,XUẤT!O:O,CBCNV!$E$2) -> 0 | F13: =E13*$T$10 -> 0 | G13: =SUMIFS(XUẤT!Q:Q,XUẤT!N:N,CBCNV!B13,XUẤT!O:O,CBCNV!$G$2) -> 0 | H13: =G13*$T$8 -> 0 | I13: =SUMIFS(XUẤT!R:R,XUẤT!N:N,CBCNV!B13,XUẤT!O:O,CBCNV!$I$2) -> 0 | J13: =I13*$T$9 -> 0 | K13: =SUMIFS(XUẤT!S:S,XUẤT!N:N,CBCNV!B13,XUẤT!O:O,CBCNV!$K$2) -> 0 | L13: =K13*$T$11 -> 0 | M13: =SUMIFS(XUẤT!T:T,XUẤT!N:N,CBCNV!B13,XUẤT!O:O,CBCNV!$M$2) -> 0 | N13: =M13*$T$12 -> 0 | O13: =SUMIFS(XUẤT!U:U,XUẤT!N:N,CBCNV!B13,XUẤT!O:O,CBCNV!$O$2) -> 0 | P13: =O13*$T$13 -> 0 | R13: 6 | S13: Bình RO | T13: 48000
A14: 8 | B14: Đoàn Thị Nhung | C14: NV kinh doanh | D14: Văn phòng | E14: =SUMIFS(XUẤT!P:P,XUẤT!N:N,CBCNV!B14,XUẤT!O:O,CBCNV!$E$2) -> 4 | F14: =E14*$T$10 -> 392000 | G14: =SUMIFS(XUẤT!Q:Q,XUẤT!N:N,CBCNV!B14,XUẤT!O:O,CBCNV!$G$2) -> 3 | H14: =G14*$T$8 -> 255000 | I14: =SUMIFS(XUẤT!R:R,XUẤT!N:N,CBCNV!B14,XUẤT!O:O,CBCNV!$I$2) -> 0 | J14: =I14*$T$9 -> 0 | K14: =SUMIFS(XUẤT!S:S,XUẤT!N:N,CBCNV!B14,XUẤT!O:O,CBCNV!$K$2) -> 0 | L14: =K14*$T$11 -> 0 | M14: =SUMIFS(XUẤT!T:T,XUẤT!N:N,CBCNV!B14,XUẤT!O:O,CBCNV!$M$2) -> 0 | N14: =M14*$T$12 -> 0 | O14: =SUMIFS(XUẤT!U:U,XUẤT!N:N,CBCNV!B14,XUẤT!O:O,CBCNV!$O$2) -> 0 | P14: =O14*$T$13 -> 0
A15: 9 | B15: Phạm Thị Thu (A) | C15: NV kinh doanh | D15: Văn phòng | E15: =SUMIFS(XUẤT!P:P,XUẤT!N:N,CBCNV!B15,XUẤT!O:O,CBCNV!$E$2) -> 0 | F15: =E15*$T$10 -> 0 | G15: =SUMIFS(XUẤT!Q:Q,XUẤT!N:N,CBCNV!B15,XUẤT!O:O,CBCNV!$G$2) -> 0 | H15: =G15*$T$8 -> 0 | I15: =SUMIFS(XUẤT!R:R,XUẤT!N:N,CBCNV!B15,XUẤT!O:O,CBCNV!$I$2) -> 0 | J15: =I15*$T$9 -> 0 | K15: =SUMIFS(XUẤT!S:S,XUẤT!N:N,CBCNV!B15,XUẤT!O:O,CBCNV!$K$2) -> 0 | L15: =K15*$T$11 -> 0 | M15: =SUMIFS(XUẤT!T:T,XUẤT!N:N,CBCNV!B15,XUẤT!O:O,CBCNV!$M$2) -> 0 | N15: =M15*$T$12 -> 0 | O15: =SUMIFS(XUẤT!U:U,XUẤT!N:N,CBCNV!B15,XUẤT!O:O,CBCNV!$O$2) -> 0 | P15: =O15*$T$13 -> 0
A16: 10 | B16: Trương Thị Hải Yến | C16: NV kinh doanh | D16: Văn phòng | E16: =SUMIFS(XUẤT!P:P,XUẤT!N:N,CBCNV!B16,XUẤT!O:O,CBCNV!$E$2) -> 20 | F16: =E16*$T$10 -> 1960000 | G16: =SUMIFS(XUẤT!Q:Q,XUẤT!N:N,CBCNV!B16,XUẤT!O:O,CBCNV!$G$2) -> 0 | H16: =G16*$T$8 -> 0 | I16: =SUMIFS(XUẤT!R:R,XUẤT!N:N,CBCNV!B16,XUẤT!O:O,CBCNV!$I$2) -> 0 | J16: =I16*$T$9 -> 0 | K16: =SUMIFS(XUẤT!S:S,XUẤT!N:N,CBCNV!B16,XUẤT!O:O,CBCNV!$K$2) -> 0 | L16: =K16*$T$11 -> 0 | M16: =SUMIFS(XUẤT!T:T,XUẤT!N:N,CBCNV!B16,XUẤT!O:O,CBCNV!$M$2) -> 0 | N16: =M16*$T$12 -> 0 | O16: =SUMIFS(XUẤT!U:U,XUẤT!N:N,CBCNV!B16,XUẤT!O:O,CBCNV!$O$2) -> 4 | P16: =O16*$T$13 -> 192000
A17: 11 | B17: Lương Minh Hương | C17: NV kinh doanh | D17: Văn phòng | E17: =SUMIFS(XUẤT!P:P,XUẤT!N:N,CBCNV!B17,XUẤT!O:O,CBCNV!$E$2) -> 10 | F17: =E17*$T$10 -> 980000 | G17: =SUMIFS(XUẤT!Q:Q,XUẤT!N:N,CBCNV!B17,XUẤT!O:O,CBCNV!$G$2) -> 0 | H17: =G17*$T$8 -> 0 | I17: =SUMIFS(XUẤT!R:R,XUẤT!N:N,CBCNV!B17,XUẤT!O:O,CBCNV!$I$2) -> 0 | J17: =I17*$T$9 -> 0 | K17: =SUMIFS(XUẤT!S:S,XUẤT!N:N,CBCNV!B17,XUẤT!O:O,CBCNV!$K$2) -> 6 | L17: =K17*$T$11 -> 636000 | M17: =SUMIFS(XUẤT!T:T,XUẤT!N:N,CBCNV!B17,XUẤT!O:O,CBCNV!$M$2) -> 6 | N17: =M17*$T$12 -> 312000 | O17: =SUMIFS(XUẤT!U:U,XUẤT!N:N,CBCNV!B17,XUẤT!O:O,CBCNV!$O$2) -> 9 | P17: =O17*$T$13 -> 432000
A18: 12 | B18: Hoàng Hồng Nhung | C18: NV kinh doanh | D18: Văn phòng | E18: =SUMIFS(XUẤT!P:P,XUẤT!N:N,CBCNV!B18,XUẤT!O:O,CBCNV!$E$2) -> 0 | F18: =E18*$T$10 -> 0 | G18: =SUMIFS(XUẤT!Q:Q,XUẤT!N:N,CBCNV!B18,XUẤT!O:O,CBCNV!$G$2) -> 0 | H18: =G18*$T$8 -> 0 | I18: =SUMIFS(XUẤT!R:R,XUẤT!N:N,CBCNV!B18,XUẤT!O:O,CBCNV!$I$2) -> 0 | J18: =I18*$T$9 -> 0 | K18: =SUMIFS(XUẤT!S:S,XUẤT!N:N,CBCNV!B18,XUẤT!O:O,CBCNV!$K$2) -> 0 | L18: =K18*$T$11 -> 0 | M18: =SUMIFS(XUẤT!T:T,XUẤT!N:N,CBCNV!B18,XUẤT!O:O,CBCNV!$M$2) -> 0 | N18: =M18*$T$12 -> 0 | O18: =SUMIFS(XUẤT!U:U,XUẤT!N:N,CBCNV!B18,XUẤT!O:O,CBCNV!$O$2) -> 0 | P18: =O18*$T$13 -> 0
A19: 13 | B19: Nguyễn Phương Thảo | C19: NV kinh doanh | D19: Văn phòng | E19: =SUMIFS(XUẤT!P:P,XUẤT!N:N,CBCNV!B19,XUẤT!O:O,CBCNV!$E$2) -> 2 | F19: =E19*$T$10 -> 196000 | G19: =SUMIFS(XUẤT!Q:Q,XUẤT!N:N,CBCNV!B19,XUẤT!O:O,CBCNV!$G$2) -> 0 | H19: =G19*$T$8 -> 0 | I19: =SUMIFS(XUẤT!R:R,XUẤT!N:N,CBCNV!B19,XUẤT!O:O,CBCNV!$I$2) -> 0 | J19: =I19*$T$9 -> 0 | K19: =SUMIFS(XUẤT!S:S,XUẤT!N:N,CBCNV!B19,XUẤT!O:O,CBCNV!$K$2) -> 0 | L19: =K19*$T$11 -> 0 | M19: =SUMIFS(XUẤT!T:T,XUẤT!N:N,CBCNV!B19,XUẤT!O:O,CBCNV!$M$2) -> 0 | N19: =M19*$T$12 -> 0 | O19: =SUMIFS(XUẤT!U:U,XUẤT!N:N,CBCNV!B19,XUẤT!O:O,CBCNV!$O$2) -> 0 | P19: =O19*$T$13 -> 0
A20: 14 | B20: Phạm Thị Đan Thanh | C20: NV kinh doanh | D20: Văn phòng | E20: =SUMIFS(XUẤT!P:P,XUẤT!N:N,CBCNV!B20,XUẤT!O:O,CBCNV!$E$2) -> 10 | F20: =E20*$T$10 -> 980000 | G20: =SUMIFS(XUẤT!Q:Q,XUẤT!N:N,CBCNV!B20,XUẤT!O:O,CBCNV!$G$2) -> 0 | H20: =G20*$T$8 -> 0 | I20: =SUMIFS(XUẤT!R:R,XUẤT!N:N,CBCNV!B20,XUẤT!O:O,CBCNV!$I$2) -> 0 | J20: =I20*$T$9 -> 0 | K20: =SUMIFS(XUẤT!S:S,XUẤT!N:N,CBCNV!B20,XUẤT!O:O,CBCNV!$K$2) -> 0 | L20: =K20*$T$11 -> 0 | M20: =SUMIFS(XUẤT!T:T,XUẤT!N:N,CBCNV!B20,XUẤT!O:O,CBCNV!$M$2) -> 0 | N20: =M20*$T$12 -> 0 | O20: =SUMIFS(XUẤT!U:U,XUẤT!N:N,CBCNV!B20,XUẤT!O:O,CBCNV!$O$2) -> 0 | P20: =O20*$T$13 -> 0
A21: 15 | B21: Phan Hồng Hạnh | C21: NV kinh doanh | D21: Văn phòng | E21: =SUMIFS(XUẤT!P:P,XUẤT!N:N,CBCNV!B21,XUẤT!O:O,CBCNV!$E$2) -> 13 | F21: =E21*$T$10 -> 1274000 | G21: =SUMIFS(XUẤT!Q:Q,XUẤT!N:N,CBCNV!B21,XUẤT!O:O,CBCNV!$G$2) -> 0 | H21: =G21*$T$8 -> 0 | I21: =SUMIFS(XUẤT!R:R,XUẤT!N:N,CBCNV!B21,XUẤT!O:O,CBCNV!$I$2) -> 0 | J21: =I21*$T$9 -> 0 | K21: =SUMIFS(XUẤT!S:S,XUẤT!N:N,CBCNV!B21,XUẤT!O:O,CBCNV!$K$2) -> 0 | L21: =K21*$T$11 -> 0 | M21: =SUMIFS(XUẤT!T:T,XUẤT!N:N,CBCNV!B21,XUẤT!O:O,CBCNV!$M$2) -> 0 | N21: =M21*$T$12 -> 0 | O21: =SUMIFS(XUẤT!U:U,XUẤT!N:N,CBCNV!B21,XUẤT!O:O,CBCNV!$O$2) -> 0 | P21: =O21*$T$13 -> 0
A22: 16 | B22: Đỗ Thị Liễu | C22: CN kẹp chì | D22: Văn phòng | E22: =SUMIFS(XUẤT!P:P,XUẤT!N:N,CBCNV!B22,XUẤT!O:O,CBCNV!$E$2) -> 1 | F22: =E22*$T$10 -> 98000 | G22: =SUMIFS(XUẤT!Q:Q,XUẤT!N:N,CBCNV!B22,XUẤT!O:O,CBCNV!$G$2) -> 0 | H22: =G22*$T$8 -> 0 | I22: =SUMIFS(XUẤT!R:R,XUẤT!N:N,CBCNV!B22,XUẤT!O:O,CBCNV!$I$2) -> 10 | J22: =I22*$T$9 -> 930000 | K22: =SUMIFS(XUẤT!S:S,XUẤT!N:N,CBCNV!B22,XUẤT!O:O,CBCNV!$K$2) -> 0 | L22: =K22*$T$11 -> 0 | M22: =SUMIFS(XUẤT!T:T,XUẤT!N:N,CBCNV!B22,XUẤT!O:O,CBCNV!$M$2) -> 0 | N22: =M22*$T$12 -> 0 | O22: =SUMIFS(XUẤT!U:U,XUẤT!N:N,CBCNV!B22,XUẤT!O:O,CBCNV!$O$2) -> 0 | P22: =O22*$T$13 -> 0
A23: 17 | B23: Vũ Hữu Hoàng | C23: CN quản lý | D23: Văn phòng | E23: =SUMIFS(XUẤT!P:P,XUẤT!N:N,CBCNV!B23,XUẤT!O:O,CBCNV!$E$2) -> 0 | F23: =E23*$T$10 -> 0 | G23: =SUMIFS(XUẤT!Q:Q,XUẤT!N:N,CBCNV!B23,XUẤT!O:O,CBCNV!$G$2) -> 0 | H23: =G23*$T$8 -> 0 | I23: =SUMIFS(XUẤT!R:R,XUẤT!N:N,CBCNV!B23,XUẤT!O:O,CBCNV!$I$2) -> 0 | J23: =I23*$T$9 -> 0 | K23: =SUMIFS(XUẤT!S:S,XUẤT!N:N,CBCNV!B23,XUẤT!O:O,CBCNV!$K$2) -> 0 | L23: =K23*$T$11 -> 0 | M23: =SUMIFS(XUẤT!T:T,XUẤT!N:N,CBCNV!B23,XUẤT!O:O,CBCNV!$M$2) -> 0 | N23: =M23*$T$12 -> 0 | O23: =SUMIFS(XUẤT!U:U,XUẤT!N:N,CBCNV!B23,XUẤT!O:O,CBCNV!$O$2) -> 0 | P23: =O23*$T$13 -> 0
A24: 18 | B24: Lê Như Hùng | C24: NV kiểm tra | D24: Văn phòng | E24: =SUMIFS(XUẤT!P:P,XUẤT!N:N,CBCNV!B24,XUẤT!O:O,CBCNV!$E$2) -> 0 | F24: =E24*$T$10 -> 0 | G24: =SUMIFS(XUẤT!Q:Q,XUẤT!N:N,CBCNV!B24,XUẤT!O:O,CBCNV!$G$2) -> 0 | H24: =G24*$T$8 -> 0 | I24: =SUMIFS(XUẤT!R:R,XUẤT!N:N,CBCNV!B24,XUẤT!O:O,CBCNV!$I$2) -> 0 | J24: =I24*$T$9 -> 0 | K24: =SUMIFS(XUẤT!S:S,XUẤT!N:N,CBCNV!B24,XUẤT!O:O,CBCNV!$K$2) -> 0 | L24: =K24*$T$11 -> 0 | M24: =SUMIFS(XUẤT!T:T,XUẤT!N:N,CBCNV!B24,XUẤT!O:O,CBCNV!$M$2) -> 0 | N24: =M24*$T$12 -> 0 | O24: =SUMIFS(XUẤT!U:U,XUẤT!N:N,CBCNV!B24,XUẤT!O:O,CBCNV!$O$2) -> 0 | P24: =O24*$T$13 -> 0
A25: 19 | B25: Vũ Văn Thảo | C25: NV kiểm tra | D25: Văn phòng | E25: =SUMIFS(XUẤT!P:P,XUẤT!N:N,CBCNV!B25,XUẤT!O:O,CBCNV!$E$2) -> 0 | F25: =E25*$T$10 -> 0 | G25: =SUMIFS(XUẤT!Q:Q,XUẤT!N:N,CBCNV!B25,XUẤT!O:O,CBCNV!$G$2) -> 0 | H25: =G25*$T$8 -> 0 | I25: =SUMIFS(XUẤT!R:R,XUẤT!N:N,CBCNV!B25,XUẤT!O:O,CBCNV!$I$2) -> 0 | J25: =I25*$T$9 -> 0 | K25: =SUMIFS(XUẤT!S:S,XUẤT!N:N,CBCNV!B25,XUẤT!O:O,CBCNV!$K$2) -> 0 | L25: =K25*$T$11 -> 0 | M25: =SUMIFS(XUẤT!T:T,XUẤT!N:N,CBCNV!B25,XUẤT!O:O,CBCNV!$M$2) -> 0 | N25: =M25*$T$12 -> 0 | O25: =SUMIFS(XUẤT!U:U,XUẤT!N:N,CBCNV!B25,XUẤT!O:O,CBCNV!$O$2) -> 0 | P25: =O25*$T$13 -> 0
B26: Vũ Thành Long | C26: NVKD | D26: Văn phòng | E26: =SUMIFS(XUẤT!P:P,XUẤT!N:N,CBCNV!B26,XUẤT!O:O,CBCNV!$E$2) -> 5 | F26: =E26*$T$10 -> 490000 | G26: =SUMIFS(XUẤT!Q:Q,XUẤT!N:N,CBCNV!B26,XUẤT!O:O,CBCNV!$G$2) -> 0 | H26: =G26*$T$8 -> 0 | I26: =SUMIFS(XUẤT!R:R,XUẤT!N:N,CBCNV!B26,XUẤT!O:O,CBCNV!$I$2) -> 0 | J26: =I26*$T$9 -> 0 | K26: =SUMIFS(XUẤT!S:S,XUẤT!N:N,CBCNV!B26,XUẤT!O:O,CBCNV!$K$2) -> 0 | L26: =K26*$T$11 -> 0 | M26: =SUMIFS(XUẤT!T:T,XUẤT!N:N,CBCNV!B26,XUẤT!O:O,CBCNV!$M$2) -> 0 | N26: =M26*$T$12 -> 0 | O26: =SUMIFS(XUẤT!U:U,XUẤT!N:N,CBCNV!B26,XUẤT!O:O,CBCNV!$O$2) -> 0 | P26: =O26*$T$13 -> 0
A27: 20 | B27: Trần Thị Thắm | C27: Kế toán chính | D27: Văn phòng | E27: =SUMIFS(XUẤT!P:P,XUẤT!N:N,CBCNV!B27,XUẤT!O:O,CBCNV!$E$2) -> 0 | F27: =E27*$T$10 -> 0 | G27: =SUMIFS(XUẤT!Q:Q,XUẤT!N:N,CBCNV!B27,XUẤT!O:O,CBCNV!$G$2) -> 0 | H27: =G27*$T$8 -> 0 | I27: =SUMIFS(XUẤT!R:R,XUẤT!N:N,CBCNV!B27,XUẤT!O:O,CBCNV!$I$2) -> 0 | J27: =I27*$T$9 -> 0 | K27: =SUMIFS(XUẤT!S:S,XUẤT!N:N,CBCNV!B27,XUẤT!O:O,CBCNV!$K$2) -> 0 | L27: =K27*$T$11 -> 0 | M27: =SUMIFS(XUẤT!T:T,XUẤT!N:N,CBCNV!B27,XUẤT!O:O,CBCNV!$M$2) -> 0 | N27: =M27*$T$12 -> 0 | O27: =SUMIFS(XUẤT!U:U,XUẤT!N:N,CBCNV!B27,XUẤT!O:O,CBCNV!$O$2) -> 0 | P27: =O27*$T$13 -> 0
A28: 21 | B28: Vũ Thị Thúy Phương | C28: NV thủ kho | D28: Văn phòng | E28: =SUMIFS(XUẤT!P:P,XUẤT!N:N,CBCNV!B28,XUẤT!O:O,CBCNV!$E$2) -> 0 | F28: =E28*$T$10 -> 0 | G28: =SUMIFS(XUẤT!Q:Q,XUẤT!N:N,CBCNV!B28,XUẤT!O:O,CBCNV!$G$2) -> 0 | H28: =G28*$T$8 -> 0 | I28: =SUMIFS(XUẤT!R:R,XUẤT!N:N,CBCNV!B28,XUẤT!O:O,CBCNV!$I$2) -> 0 | J28: =I28*$T$9 -> 0 | K28: =SUMIFS(XUẤT!S:S,XUẤT!N:N,CBCNV!B28,XUẤT!O:O,CBCNV!$K$2) -> 0 | L28: =K28*$T$11 -> 0 | M28: =SUMIFS(XUẤT!T:T,XUẤT!N:N,CBCNV!B28,XUẤT!O:O,CBCNV!$M$2) -> 0 | N28: =M28*$T$12 -> 0 | O28: =SUMIFS(XUẤT!U:U,XUẤT!N:N,CBCNV!B28,XUẤT!O:O,CBCNV!$O$2) -> 0 | P28: =O28*$T$13 -> 0
A29: 22 | B29: Lê Hoàng Anh | C29: NV kế toán | D29: Văn phòng | E29: =SUMIFS(XUẤT!P:P,XUẤT!N:N,CBCNV!B29,XUẤT!O:O,CBCNV!$E$2) -> 1 | F29: =E29*$T$10 -> 98000 | G29: =SUMIFS(XUẤT!Q:Q,XUẤT!N:N,CBCNV!B29,XUẤT!O:O,CBCNV!$G$2) -> 0 | H29: =G29*$T$8 -> 0 | I29: =SUMIFS(XUẤT!R:R,XUẤT!N:N,CBCNV!B29,XUẤT!O:O,CBCNV!$I$2) -> 0 | J29: =I29*$T$9 -> 0 | K29: =SUMIFS(XUẤT!S:S,XUẤT!N:N,CBCNV!B29,XUẤT!O:O,CBCNV!$K$2) -> 0 | L29: =K29*$T$11 -> 0 | M29: =SUMIFS(XUẤT!T:T,XUẤT!N:N,CBCNV!B29,XUẤT!O:O,CBCNV!$M$2) -> 0 | N29: =M29*$T$12 -> 0 | O29: =SUMIFS(XUẤT!U:U,XUẤT!N:N,CBCNV!B29,XUẤT!O:O,CBCNV!$O$2) -> 0 | P29: =O29*$T$13 -> 0
A30: 23 | B30: Phạm Thị Bích Hằng | C30: NV kế toán | D30: Văn phòng | E30: =SUMIFS(XUẤT!P:P,XUẤT!N:N,CBCNV!B30,XUẤT!O:O,CBCNV!$E$2) -> 0 | F30: =E30*$T$10 -> 0 | G30: =SUMIFS(XUẤT!Q:Q,XUẤT!N:N,CBCNV!B30,XUẤT!O:O,CBCNV!$G$2) -> 0 | H30: =G30*$T$8 -> 0 | I30: =SUMIFS(XUẤT!R:R,XUẤT!N:N,CBCNV!B30,XUẤT!O:O,CBCNV!$I$2) -> 0 | J30: =I30*$T$9 -> 0 | K30: =SUMIFS(XUẤT!S:S,XUẤT!N:N,CBCNV!B30,XUẤT!O:O,CBCNV!$K$2) -> 0 | L30: =K30*$T$11 -> 0 | M30: =SUMIFS(XUẤT!T:T,XUẤT!N:N,CBCNV!B30,XUẤT!O:O,CBCNV!$M$2) -> 0 | N30: =M30*$T$12 -> 0 | O30: =SUMIFS(XUẤT!U:U,XUẤT!N:N,CBCNV!B30,XUẤT!O:O,CBCNV!$O$2) -> 0 | P30: =O30*$T$13 -> 0
A31: 24 | B31: Đỗ Thị Thu Hoàn | C31: NV kế toán | D31: Văn phòng | E31: =SUMIFS(XUẤT!P:P,XUẤT!N:N,CBCNV!B31,XUẤT!O:O,CBCNV!$E$2) -> 0 | F31: =E31*$T$10 -> 0 | G31: =SUMIFS(XUẤT!Q:Q,XUẤT!N:N,CBCNV!B31,XUẤT!O:O,CBCNV!$G$2) -> 0 | H31: =G31*$T$8 -> 0 | I31: =SUMIFS(XUẤT!R:R,XUẤT!N:N,CBCNV!B31,XUẤT!O:O,CBCNV!$I$2) -> 0 | J31: =I31*$T$9 -> 0 | K31: =SUMIFS(XUẤT!S:S,XUẤT!N:N,CBCNV!B31,XUẤT!O:O,CBCNV!$K$2) -> 0 | L31: =K31*$T$11 -> 0 | M31: =SUMIFS(XUẤT!T:T,XUẤT!N:N,CBCNV!B31,XUẤT!O:O,CBCNV!$M$2) -> 0 | N31: =M31*$T$12 -> 0 | O31: =SUMIFS(XUẤT!U:U,XUẤT!N:N,CBCNV!B31,XUẤT!O:O,CBCNV!$O$2) -> 0 | P31: =O31*$T$13 -> 0
A32: 25 | B32: Nguyễn Thị Thu Quyên | C32: NV kế toán | D32: Văn phòng | E32: =SUMIFS(XUẤT!P:P,XUẤT!N:N,CBCNV!B32,XUẤT!O:O,CBCNV!$E$2) -> 0 | F32: =E32*$T$10 -> 0 | G32: =SUMIFS(XUẤT!Q:Q,XUẤT!N:N,CBCNV!B32,XUẤT!O:O,CBCNV!$G$2) -> 0 | H32: =G32*$T$8 -> 0 | I32: =SUMIFS(XUẤT!R:R,XUẤT!N:N,CBCNV!B32,XUẤT!O:O,CBCNV!$I$2) -> 0 | J32: =I32*$T$9 -> 0 | K32: =SUMIFS(XUẤT!S:S,XUẤT!N:N,CBCNV!B32,XUẤT!O:O,CBCNV!$K$2) -> 0 | L32: =K32*$T$11 -> 0 | M32: =SUMIFS(XUẤT!T:T,XUẤT!N:N,CBCNV!B32,XUẤT!O:O,CBCNV!$M$2) -> 0 | N32: =M32*$T$12 -> 0 | O32: =SUMIFS(XUẤT!U:U,XUẤT!N:N,CBCNV!B32,XUẤT!O:O,CBCNV!$O$2) -> 0 | P32: =O32*$T$13 -> 0
A33: 26 | B33: Ngô Thị Vân Anh | C33: PT. Quản trị | D33: Văn phòng | E33: =SUMIFS(XUẤT!P:P,XUẤT!N:N,CBCNV!B33,XUẤT!O:O,CBCNV!$E$2) -> 10 | F33: =E33*$T$10 -> 980000 | G33: =SUMIFS(XUẤT!Q:Q,XUẤT!N:N,CBCNV!B33,XUẤT!O:O,CBCNV!$G$2) -> 0 | H33: =G33*$T$8 -> 0 | I33: =SUMIFS(XUẤT!R:R,XUẤT!N:N,CBCNV!B33,XUẤT!O:O,CBCNV!$I$2) -> 0 | J33: =I33*$T$9 -> 0 | K33: =SUMIFS(XUẤT!S:S,XUẤT!N:N,CBCNV!B33,XUẤT!O:O,CBCNV!$K$2) -> 0 | L33: =K33*$T$11 -> 0 | M33: =SUMIFS(XUẤT!T:T,XUẤT!N:N,CBCNV!B33,XUẤT!O:O,CBCNV!$M$2) -> 0 | N33: =M33*$T$12 -> 0 | O33: =SUMIFS(XUẤT!U:U,XUẤT!N:N,CBCNV!B33,XUẤT!O:O,CBCNV!$O$2) -> 0 | P33: =O33*$T$13 -> 0
A34: 27 | B34: Nguyễn Thị Lan | C34: NV Đảng - Đoàn | D34: Văn phòng | E34: =SUMIFS(XUẤT!P:P,XUẤT!N:N,CBCNV!B34,XUẤT!O:O,CBCNV!$E$2) -> 0 | F34: =E34*$T$10 -> 0 | G34: =SUMIFS(XUẤT!Q:Q,XUẤT!N:N,CBCNV!B34,XUẤT!O:O,CBCNV!$G$2) -> 20 | H34: =G34*$T$8 -> 1700000 | I34: =SUMIFS(XUẤT!R:R,XUẤT!N:N,CBCNV!B34,XUẤT!O:O,CBCNV!$I$2) -> 0 | J34: =I34*$T$9 -> 0 | K34: =SUMIFS(XUẤT!S:S,XUẤT!N:N,CBCNV!B34,XUẤT!O:O,CBCNV!$K$2) -> 0 | L34: =K34*$T$11 -> 0 | M34: =SUMIFS(XUẤT!T:T,XUẤT!N:N,CBCNV!B34,XUẤT!O:O,CBCNV!$M$2) -> 0 | N34: =M34*$T$12 -> 0 | O34: =SUMIFS(XUẤT!U:U,XUẤT!N:N,CBCNV!B34,XUẤT!O:O,CBCNV!$O$2) -> 0 | P34: =O34*$T$13 -> 0
A35: 28 | B35: Nguyễn Thị Ngọc Chung | C35: Thủ quỹ - HC | D35: Văn phòng | E35: =SUMIFS(XUẤT!P:P,XUẤT!N:N,CBCNV!B35,XUẤT!O:O,CBCNV!$E$2) -> 0 | F35: =E35*$T$10 -> 0 | G35: =SUMIFS(XUẤT!Q:Q,XUẤT!N:N,CBCNV!B35,XUẤT!O:O,CBCNV!$G$2) -> 4 | H35: =G35*$T$8 -> 340000 | I35: =SUMIFS(XUẤT!R:R,XUẤT!N:N,CBCNV!B35,XUẤT!O:O,CBCNV!$I$2) -> 0 | J35: =I35*$T$9 -> 0 | K35: =SUMIFS(XUẤT!S:S,XUẤT!N:N,CBCNV!B35,XUẤT!O:O,CBCNV!$K$2) -> 0 | L35: =K35*$T$11 -> 0 | M35: =SUMIFS(XUẤT!T:T,XUẤT!N:N,CBCNV!B35,XUẤT!O:O,CBCNV!$M$2) -> 0 | N35: =M35*$T$12 -> 0 | O35: =SUMIFS(XUẤT!U:U,XUẤT!N:N,CBCNV!B35,XUẤT!O:O,CBCNV!$O$2) -> 0 | P35: =O35*$T$13 -> 0
A36: 29 | B36: Bùi Thị Diệu Linh | C36: NV LĐTL | D36: Văn phòng | E36: =SUMIFS(XUẤT!P:P,XUẤT!N:N,CBCNV!B36,XUẤT!O:O,CBCNV!$E$2) -> 0 | F36: =E36*$T$10 -> 0 | G36: =SUMIFS(XUẤT!Q:Q,XUẤT!N:N,CBCNV!B36,XUẤT!O:O,CBCNV!$G$2) -> 0 | H36: =G36*$T$8 -> 0 | I36: =SUMIFS(XUẤT!R:R,XUẤT!N:N,CBCNV!B36,XUẤT!O:O,CBCNV!$I$2) -> 0 | J36: =I36*$T$9 -> 0 | K36: =SUMIFS(XUẤT!S:S,XUẤT!N:N,CBCNV!B36,XUẤT!O:O,CBCNV!$K$2) -> 0 | L36: =K36*$T$11 -> 0 | M36: =SUMIFS(XUẤT!T:T,XUẤT!N:N,CBCNV!B36,XUẤT!O:O,CBCNV!$M$2) -> 0 | N36: =M36*$T$12 -> 0 | O36: =SUMIFS(XUẤT!U:U,XUẤT!N:N,CBCNV!B36,XUẤT!O:O,CBCNV!$O$2) -> 0 | P36: =O36*$T$13 -> 0
A37: 30 | B37: Đỗ Thị Hiền | C37: NV LĐTL | D37: Văn phòng | E37: =SUMIFS(XUẤT!P:P,XUẤT!N:N,CBCNV!B37,XUẤT!O:O,CBCNV!$E$2) -> 0 | F37: =E37*$T$10 -> 0 | G37: =SUMIFS(XUẤT!Q:Q,XUẤT!N:N,CBCNV!B37,XUẤT!O:O,CBCNV!$G$2) -> 0 | H37: =G37*$T$8 -> 0 | I37: =SUMIFS(XUẤT!R:R,XUẤT!N:N,CBCNV!B37,XUẤT!O:O,CBCNV!$I$2) -> 0 | J37: =I37*$T$9 -> 0 | K37: =SUMIFS(XUẤT!S:S,XUẤT!N:N,CBCNV!B37,XUẤT!O:O,CBCNV!$K$2) -> 0 | L37: =K37*$T$11 -> 0 | M37: =SUMIFS(XUẤT!T:T,XUẤT!N:N,CBCNV!B37,XUẤT!O:O,CBCNV!$M$2) -> 0 | N37: =M37*$T$12 -> 0 | O37: =SUMIFS(XUẤT!U:U,XUẤT!N:N,CBCNV!B37,XUẤT!O:O,CBCNV!$O$2) -> 0 | P37: =O37*$T$13 -> 0
A38: 31 | B38: Phạm Thu Quỳnh | C38: CN tạp vụ | D38: Văn phòng | E38: =SUMIFS(XUẤT!P:P,XUẤT!N:N,CBCNV!B38,XUẤT!O:O,CBCNV!$E$2) -> 23 | F38: =E38*$T$10 -> 2254000 | G38: =SUMIFS(XUẤT!Q:Q,XUẤT!N:N,CBCNV!B38,XUẤT!O:O,CBCNV!$G$2) -> 0 | H38: =G38*$T$8 -> 0 | I38: =SUMIFS(XUẤT!R:R,XUẤT!N:N,CBCNV!B38,XUẤT!O:O,CBCNV!$I$2) -> 0 | J38: =I38*$T$9 -> 0 | K38: =SUMIFS(XUẤT!S:S,XUẤT!N:N,CBCNV!B38,XUẤT!O:O,CBCNV!$K$2) -> 0 | L38: =K38*$T$11 -> 0 | M38: =SUMIFS(XUẤT!T:T,XUẤT!N:N,CBCNV!B38,XUẤT!O:O,CBCNV!$M$2) -> 0 | N38: =M38*$T$12 -> 0 | O38: =SUMIFS(XUẤT!U:U,XUẤT!N:N,CBCNV!B38,XUẤT!O:O,CBCNV!$O$2) -> 0 | P38: =O38*$T$13 -> 0
... A48: 41 | B48: Bùi Văn Tình | C48: NV kỹ thuật | D48: Văn phòng | E48: =SUMIFS(XUẤT!P:P,XUẤT!N:N,CBCNV!B48,XUẤT!O:O,CBCNV!$E$2) -> 0 | F48: =E48*$T$10 -> 0 | G48: =SUMIFS(XUẤT!Q:Q,XUẤT!N:N,CBCNV!B48,XUẤT!O:O,CBCNV!$G$2) -> 0 | H48: =G48*$T$8 -> 0 | I48: =SUMIFS(XUẤT!R:R,XUẤT!N:N,CBCNV!B48,XUẤT!O:O,CBCNV!$I$2) -> 0 | J48: =I48*$T$9 -> 0 | K48: =SUMIFS(XUẤT!S:S,XUẤT!N:N,CBCNV!B48,XUẤT!O:O,CBCNV!$K$2) -> 0 | L48: =K48*$T$11 -> 0 | M48: =SUMIFS(XUẤT!T:T,XUẤT!N:N,CBCNV!B48,XUẤT!O:O,CBCNV!$M$2) -> 0 | N48: =M48*$T$12 -> 0 | O48: =SUMIFS(XUẤT!U:U,XUẤT!N:N,CBCNV!B48,XUẤT!O:O,CBCNV!$O$2) -> 0 | P48: =O48*$T$13 -> 0
A49: 42 | C49: NV kỹ thuật | D49: Văn phòng | E49: =SUMIFS(XUẤT!P:P,XUẤT!N:N,XUẤT!N250,XUẤT!O:O,CBCNV!$E$2) -> 30 | F49: =E49*$T$10 -> 2940000 | G49: =SUMIFS(XUẤT!Q:Q,XUẤT!N:N,XUẤT!N250,XUẤT!O:O,CBCNV!$G$2) -> 0 | H49: =G49*$T$8 -> 0 | I49: =SUMIFS(XUẤT!R:R,XUẤT!N:N,XUẤT!N250,XUẤT!O:O,CBCNV!$I$2) -> 0 | J49: =I49*$T$9 -> 0 | K49: =SUMIFS(XUẤT!S:S,XUẤT!N:N,XUẤT!N250,XUẤT!O:O,CBCNV!$K$2) -> 0 | L49: =K49*$T$11 -> 0 | M49: =SUMIFS(XUẤT!T:T,XUẤT!N:N,XUẤT!N250,XUẤT!O:O,CBCNV!$M$2) -> 0 | N49: =M49*$T$12 -> 0 | O49: =SUMIFS(XUẤT!U:U,XUẤT!N:N,XUẤT!N250,XUẤT!O:O,CBCNV!$O$2) -> 0 | P49: =O49*$T$13 -> 0
A50: 43 | B50: Khổng Thị Thu Trang | C50: NV kỹ thuật | D50: Văn phòng | E50: =SUMIFS(XUẤT!P:P,XUẤT!N:N,CBCNV!B50,XUẤT!O:O,CBCNV!$E$2) -> 0 | F50: =E50*$T$10 -> 0 | G50: =SUMIFS(XUẤT!Q:Q,XUẤT!N:N,CBCNV!B50,XUẤT!O:O,CBCNV!$G$2) -> 0 | H50: =G50*$T$8 -> 0 | I50: =SUMIFS(XUẤT!R:R,XUẤT!N:N,CBCNV!B50,XUẤT!O:O,CBCNV!$I$2) -> 0 | J50: =I50*$T$9 -> 0 | K50: =SUMIFS(XUẤT!S:S,XUẤT!N:N,CBCNV!B50,XUẤT!O:O,CBCNV!$K$2) -> 0 | L50: =K50*$T$11 -> 0 | M50: =SUMIFS(XUẤT!T:T,XUẤT!N:N,CBCNV!B50,XUẤT!O:O,CBCNV!$M$2) -> 0 | N50: =M50*$T$12 -> 0 | O50: =SUMIFS(XUẤT!U:U,XUẤT!N:N,CBCNV!B50,XUẤT!O:O,CBCNV!$O$2) -> 0 | P50: =O50*$T$13 -> 0
...

Sheet TỒN
A1: THEO DÕI NHẬP, XUẤT NƯỚC QAROMI
A2: Tháng 9/2026
A4: STT | B4: Ngày | C4: Nhập | J4: Xuất | Q4: Tồn
C5: Vỉ 350ml | D5: Hộp 500ml | E5: Vỉ 500ml | F5: Hộp 350ml | G5: Bình kiềm | H5: Bình RO | I5: Cộng | J5: Vỉ 350ml | K5: Hộp 500ml | L5: Vỉ 500ml | M5: Hộp 350ml | N5: Bình kiềm | O5: Bình RO | P5: Cộng | Q5: Vỉ 350ml | R5: Hộp 500ml | S5: Vỉ 500ml | T5: Hộp 350ml | U5: Bình kiềm | V5: Bình RO | W5: Cộng
A6: 1 | B6: 46266 | J6: =SUMIFS(XUẤT!$W:$W,XUẤT!$B:$B,TỒN!$B$12,XUẤT!$O:$O,TỒN!#REF!) -> 0 | K6: =SUMIFS(XUẤT!$W:$W,XUẤT!$B:$B,TỒN!$B$12,XUẤT!$O:$O,TỒN!#REF!) -> 0 | L6: =SUMIFS(XUẤT!$W:$W,XUẤT!$B:$B,TỒN!$B$12,XUẤT!$O:$O,TỒN!#REF!) -> 0 | M6: =SUMIFS(XUẤT!$W:$W,XUẤT!$B:$B,TỒN!$B$12,XUẤT!$O:$O,TỒN!#REF!) -> 0 | N6: =SUMIFS(XUẤT!$W:$W,XUẤT!$B:$B,TỒN!$B$12,XUẤT!$O:$O,TỒN!#REF!) -> 0 | O6: =SUMIFS(XUẤT!$W:$W,XUẤT!$B:$B,TỒN!$B$12,XUẤT!$O:$O,TỒN!#REF!) -> 0 | P6: =SUM(J6:O6) -> 0
A7: 2 | B7: 46267 | J7: =SUMIFS(XUẤT!$W:$W,XUẤT!$B:$B,TỒN!$B$12,XUẤT!$O:$O,TỒN!#REF!) -> 0 | K7: =SUMIFS(XUẤT!$W:$W,XUẤT!$B:$B,TỒN!$B$12,XUẤT!$O:$O,TỒN!#REF!) -> 0 | L7: =SUMIFS(XUẤT!$W:$W,XUẤT!$B:$B,TỒN!$B$12,XUẤT!$O:$O,TỒN!#REF!) -> 0 | M7: =SUMIFS(XUẤT!$W:$W,XUẤT!$B:$B,TỒN!$B$12,XUẤT!$O:$O,TỒN!#REF!) -> 0 | N7: =SUMIFS(XUẤT!$W:$W,XUẤT!$B:$B,TỒN!$B$12,XUẤT!$O:$O,TỒN!#REF!) -> 0 | O7: =SUMIFS(XUẤT!$W:$W,XUẤT!$B:$B,TỒN!$B$12,XUẤT!$O:$O,TỒN!#REF!) -> 0 | P7: =SUM(J7:O7) -> 0
A8: 3 | B8: 46268 | J8: =SUMIFS(XUẤT!$W:$W,XUẤT!$B:$B,TỒN!$B$12,XUẤT!$O:$O,TỒN!J1) -> 0 | K8: =SUMIFS(XUẤT!$W:$W,XUẤT!$B:$B,TỒN!$B$12,XUẤT!$O:$O,TỒN!K1) -> 0 | L8: =SUMIFS(XUẤT!$W:$W,XUẤT!$B:$B,TỒN!$B$12,XUẤT!$O:$O,TỒN!L1) -> 0 | M8: =SUMIFS(XUẤT!$W:$W,XUẤT!$B:$B,TỒN!$B$12,XUẤT!$O:$O,TỒN!M1) -> 0 | N8: =SUMIFS(XUẤT!$W:$W,XUẤT!$B:$B,TỒN!$B$12,XUẤT!$O:$O,TỒN!N1) -> 0 | O8: =SUMIFS(XUẤT!$W:$W,XUẤT!$B:$B,TỒN!$B$12,XUẤT!$O:$O,TỒN!O1) -> 0 | P8: =SUM(J8:O8) -> 0
A9: 4 | B9: 46269 | J9: =SUMIFS(XUẤT!$W:$W,XUẤT!$B:$B,TỒN!$B$12,XUẤT!$O:$O,TỒN!J2) -> 0 | K9: =SUMIFS(XUẤT!$W:$W,XUẤT!$B:$B,TỒN!$B$12,XUẤT!$O:$O,TỒN!K2) -> 0 | L9: =SUMIFS(XUẤT!$W:$W,XUẤT!$B:$B,TỒN!$B$12,XUẤT!$O:$O,TỒN!L2) -> 0 | M9: =SUMIFS(XUẤT!$W:$W,XUẤT!$B:$B,TỒN!$B$12,XUẤT!$O:$O,TỒN!M2) -> 0 | N9: =SUMIFS(XUẤT!$W:$W,XUẤT!$B:$B,TỒN!$B$12,XUẤT!$O:$O,TỒN!N2) -> 0 | O9: =SUMIFS(XUẤT!$W:$W,XUẤT!$B:$B,TỒN!$B$12,XUẤT!$O:$O,TỒN!O2) -> 0 | P9: =SUM(J9:O9) -> 0
A10: 5 | B10: 46270 | J10: =SUMIFS(XUẤT!$W:$W,XUẤT!$B:$B,TỒN!$B$12,XUẤT!$O:$O,TỒN!J3) -> 0 | K10: =SUMIFS(XUẤT!$W:$W,XUẤT!$B:$B,TỒN!$B$12,XUẤT!$O:$O,TỒN!K3) -> 0 | L10: =SUMIFS(XUẤT!$W:$W,XUẤT!$B:$B,TỒN!$B$12,XUẤT!$O:$O,TỒN!L3) -> 0 | M10: =SUMIFS(XUẤT!$W:$W,XUẤT!$B:$B,TỒN!$B$12,XUẤT!$O:$O,TỒN!M3) -> 0 | N10: =SUMIFS(XUẤT!$W:$W,XUẤT!$B:$B,TỒN!$B$12,XUẤT!$O:$O,TỒN!N3) -> 0 | O10: =SUMIFS(XUẤT!$W:$W,XUẤT!$B:$B,TỒN!$B$12,XUẤT!$O:$O,TỒN!O3) -> 0 | P10: =SUM(J10:O10) -> 0
A11: 6 | B11: 46271 | J11: =SUMIFS(XUẤT!$W:$W,XUẤT!$B:$B,TỒN!$B$12,XUẤT!$O:$O,TỒN!J4) -> 0 | K11: =SUMIFS(XUẤT!$W:$W,XUẤT!$B:$B,TỒN!$B$12,XUẤT!$O:$O,TỒN!K4) -> 0 | L11: =SUMIFS(XUẤT!$W:$W,XUẤT!$B:$B,TỒN!$B$12,XUẤT!$O:$O,TỒN!L4) -> 0 | M11: =SUMIFS(XUẤT!$W:$W,XUẤT!$B:$B,TỒN!$B$12,XUẤT!$O:$O,TỒN!M4) -> 0 | N11: =SUMIFS(XUẤT!$W:$W,XUẤT!$B:$B,TỒN!$B$12,XUẤT!$O:$O,TỒN!N4) -> 0 | O11: =SUMIFS(XUẤT!$W:$W,XUẤT!$B:$B,TỒN!$B$12,XUẤT!$O:$O,TỒN!O4) -> 0 | P11: =SUM(J11:O11) -> 0
A12: 7 | B12: 46272 | J12: =SUMIFS(XUẤT!$W:$W,XUẤT!$B:$B,TỒN!$B$12,XUẤT!$O:$O,TỒN!J5) -> 0 | K12: =SUMIFS(XUẤT!$W:$W,XUẤT!$B:$B,TỒN!$B$12,XUẤT!$O:$O,TỒN!K5) -> 0 | L12: =SUMIFS(XUẤT!$W:$W,XUẤT!$B:$B,TỒN!$B$12,XUẤT!$O:$O,TỒN!L5) -> 30 | M12: =SUMIFS(XUẤT!$W:$W,XUẤT!$B:$B,TỒN!$B$12,XUẤT!$O:$O,TỒN!M5) -> 0 | N12: =SUMIFS(XUẤT!$W:$W,XUẤT!$B:$B,TỒN!$B$12,XUẤT!$O:$O,TỒN!N5) -> 1 | O12: =SUMIFS(XUẤT!$W:$W,XUẤT!$B:$B,TỒN!$B$12,XUẤT!$O:$O,TỒN!O5) -> 11 | P12: =SUM(J12:O12) -> 42
